Workbook

Sheet Readme
A1: Workbook purpose:
A2: Shapes the fuel supply curves that are created around the q-p points received from WEPS
A4: Data source:
A5: The user constructs shapes using step numbers, heights, and elasticities up and down from the central point in cells B6:E14 of each fuel sheet
A6: The resulting curve shapes on sheet _IEMMSuppCurveShaping are then pasted into the Aggregation Controller
A7: These shapes will be multiplied by the prices and quantities received from WEPS during the integration loop (or from the restart file for standalone)
A9: User-modifiable?
A10: Yes, in cells B6:E14 of each fuel sheet. Paste resulting changes on sheet _IEMMSuppCurveShaping into the Aggregation Controller.
A11: Browse in VEDA-FE first to become aware of how these curves are being modified by subsequent scenarios

Sheet Gas-Min
A1: GASNAT | T1: 2010 | U1: 2020 | V1: 2030
A2: Natural Gas | C2: MinGAS | D2: Price | E2: Qty | R2: =R3+($E$10-$D$10)/($D$12-1) -> 3 | S2: =S3-$D$11 -> 0.5 | T2: =ROUND((S2-$S$12)/$S$12/R2*$T$12+$T$12,4) -> 0.8333 | U2: =T2*(1+$D$14)^5 -> 0.89770076 | V2: =T2*(1+$D$14)^10 -> 0.96707867 | X2: 4.5
D3: 1 | E3: 1 | R3: =R4+($E$10-$D$10)/($D$12-1) -> 3 | S3: =S4-$D$11 -> 0.55 | T3: =ROUND((S3-$S$12)/$S$12/R3*$T$12+$T$12,4) -> 0.85 | U3: =T3*(1+$D$14)^5 -> 0.9156914 | V3: =T3*(1+$D$14)^10 -> 0.9864597 | X3: 4.55
R4: =R5+($E$10-$D$10)/($D$12-1) -> 3 | S4: =S5-$D$11 -> 0.6 | T4: =ROUND((S4-$S$12)/$S$12/R4*$T$12+$T$12,4) -> 0.8667 | U4: =T4*(1+$D$14)^5 -> 0.93368205 | V4: =T4*(1+$D$14)^10 -> 1.0058407 | X4: 4.6
R5: =R6+($E$10-$D$10)/($D$12-1) -> 3 | S5: =S6-$D$11 -> 0.65 | T5: =ROUND((S5-$S$12)/$S$12/R5*$T$12+$T$12,4) -> 0.8833 | U5: =T5*(1+$D$14)^5 -> 0.95156496 | V5: =T5*(1+$D$14)^10 -> 1.0251057 | X5: 4.65
D6: Start | E6: End | R6: =R7+($E$10-$D$10)/($D$12-1) -> 3 | S6: =S7-$D$11 -> 0.7 | T6: =ROUND((S6-$S$12)/$S$12/R6*$T$12+$T$12,4) -> 0.9 | U6: =T6*(1+$D$14)^5 -> 0.9695556 | V6: =T6*(1+$D$14)^10 -> 1.0444867 | X6: 4.7
B7: UP | C7: Elasticity | D7: 20 | E7: 5 | R7: =R8+($E$10-$D$10)/($D$12-1) -> 3 | S7: =S8-$D$11 -> 0.75 | T7: =ROUND((S7-$S$12)/$S$12/R7*$T$12+$T$12,4) -> 0.9167 | U7: =T7*(1+$D$14)^5 -> 0.98754625 | V7: =T7*(1+$D$14)^10 -> 1.0638678 | X7: 4.75
C8: StepHeight | D8: 0.1 | R8: =R9+($E$10-$D$10)/($D$12-1) -> 3 | S8: =S9-$D$11 -> 0.8 | T8: =ROUND((S8-$S$12)/$S$12/R8*$T$12+$T$12,4) -> 0.9333 | U8: =T8*(1+$D$14)^5 -> 1.0054292 | V8: =T8*(1+$D$14)^10 -> 1.0831328 | X8: 4.8
C9: StepNum | D9: 10 | R9: =R10+($E$10-$D$10)/($D$12-1) -> 3 | S9: =S10-$D$11 -> 0.85 | T9: =ROUND((S9-$S$12)/$S$12/R9*$T$12+$T$12,4) -> 0.95 | U9: =T9*(1+$D$14)^5 -> 1.0234198 | V9: =T9*(1+$D$14)^10 -> 1.1025138 | X9: 4.85
B10: LO | C10: Elasticity | D10: 3 | E10: 3 | R10: =R11+($E$10-$D$10)/($D$12-1) -> 3 | S10: =S11-$D$11 -> 0.9 | T10: =ROUND((S10-$S$12)/$S$12/R10*$T$12+$T$12,4) -> 0.9667 | U10: =T10*(1+$D$14)^5 -> 1.0414104 | V10: =T10*(1+$D$14)^10 -> 1.1218948 | X10: 4.9
C11: StepHeight | D11: =0.05*E3 -> 0.05 | R11: =D10 -> 3 | S11: =S12-$D$11 -> 0.95 | T11: =ROUND((S11-$S$12)/$S$12/R11*$T$12+$T$12,4) -> 0.9833 | U11: =T11*(1+$D$14)^5 -> 1.0592934 | V11: =T11*(1+$D$14)^10 -> 1.1411598 | X11: 4.95
C12: StepNum | D12: 10 | S12: =E3 -> 1 | T12: =D3 -> 1 | U12: =T12*(1+$D$14)^5 -> 1.077284 | V12: =T12*(1+$D$14)^10 -> 1.1605408 | X12: 5
R13: =D7 -> 20 | S13: =S12+$D$8 -> 1.1 | T13: =ROUND((S13-$S$12)/$S$12/R13*$T$12+$T$12,4) -> 1.005 | U13: =T13*(1+$D$14)^5 -> 1.0826704 | V13: =T13*(1+$D$14)^10 -> 1.1663435 | X13: 5.2
C14: Ann Price change | D14: 0.015 | R14: =R13+($E$7-$D$7)/($D$9-1) -> 18.333333 | S14: =S13+$D$8 -> 1.2 | T14: =ROUND((S14-$S$12)/$S$12/R14*$T$12+$T$12,4) -> 1.0109 | U14: =T14*(1+$D$14)^5 -> 1.0890264 | V14: =T14*(1+$D$14)^10 -> 1.1731907 | X14: 5.4
R15: =R14+($E$7-$D$7)/($D$9-1) -> 16.666667 | S15: =S14+$D$8 -> 1.3 | T15: =ROUND((S15-$S$12)/$S$12/R15*$T$12+$T$12,4) -> 1.018 | U15: =T15*(1+$D$14)^5 -> 1.0966751 | V15: =T15*(1+$D$14)^10 -> 1.1814306 | X15: 5.55
R16: =R15+($E$7-$D$7)/($D$9-1) -> 15 | S16: =S15+$D$8 -> 1.4 | T16: =ROUND((S16-$S$12)/$S$12/R16*$T$12+$T$12,4) -> 1.0267 | U16: =T16*(1+$D$14)^5 -> 1.1060475 | V16: =T16*(1+$D$14)^10 -> 1.1915273 | X16: 5.75
R17: =R16+($E$7-$D$7)/($D$9-1) -> 13.333333 | S17: =S16+$D$8 -> 1.5 | T17: =ROUND((S17-$S$12)/$S$12/R17*$T$12+$T$12,4) -> 1.0375 | U17: =T17*(1+$D$14)^5 -> 1.1176822 | V17: =T17*(1+$D$14)^10 -> 1.2040611 | X17: 5.95
R18: =R17+($E$7-$D$7)/($D$9-1) -> 11.666667 | S18: =S17+$D$8 -> 1.6 | T18: =ROUND((S18-$S$12)/$S$12/R18*$T$12+$T$12,4) -> 1.0514 | U18: =T18*(1+$D$14)^5 -> 1.1326564 | V18: =T18*(1+$D$14)^10 -> 1.2201926 | X18: 6.15
R19: =R18+($E$7-$D$7)/($D$9-1) -> 10 | S19: =S18+$D$8 -> 1.7 | T19: =ROUND((S19-$S$12)/$S$12/R19*$T$12+$T$12,4) -> 1.07 | U19: =T19*(1+$D$14)^5 -> 1.1526939 | V19: =T19*(1+$D$14)^10 -> 1.2417787 | X19: 6.3
R20: =R19+($E$7-$D$7)/($D$9-1) -> 8.3333333 | S20: =S19+$D$8 -> 1.8 | T20: =ROUND((S20-$S$12)/$S$12/R20*$T$12+$T$12,4) -> 1.096 | U20: =T20*(1+$D$14)^5 -> 1.1807033 | V20: =T20*(1+$D$14)^10 -> 1.2719527 | X20: 6.5
R21: =R20+($E$7-$D$7)/($D$9-1) -> 6.6666667 | S21: =S20+$D$8 -> 1.9 | T21: =ROUND((S21-$S$12)/$S$12/R21*$T$12+$T$12,4) -> 1.135 | U21: =T21*(1+$D$14)^5 -> 1.2227173 | V21: =T21*(1+$D$14)^10 -> 1.3172138 | X21: 6.7
R22: =R21+($E$7-$D$7)/($D$9-1) -> 5 | S22: =S21+$D$8 -> 2 | T22: =ROUND((S22-$S$12)/$S$12/R22*$T$12+$T$12,4) -> 1.2 | U22: =T22*(1+$D$14)^5 -> 1.2927408 | V22: =T22*(1+$D$14)^10 -> 1.392649 | X22: 6.9
E27: COST | J27: ~FI_Process | U27: ~FI_T: ACT_COST~UP~USD10
D28: ACT_BND | E28: =T1 -> 2010 | F28: =U1 -> 2020 | G28: =V1 -> 2030 | J28: Sets | K28: TechName | L28: TechDesc | M28: Tact | N28: Tcap | O28: Tslvl | P28: PrimaryCG | Q28: Vintage | S28: TechName | T28: Comm-IN | U28: Comm-OUT | V28: ACT_BND | W28: =E28 -> 2010 | X28: =V28&"~2050" -> ACT_BND~2050
A29: 01 | C29: =$C$2&"-"&A29 -> MinGAS-01 | D29: =S2 -> 0.5 | E29: =T2 -> 0.8333 | F29: =U2 -> 0.89770076 | G29: =V2 -> 0.96707867 | J29: MIN | K29: =C29 -> MinGAS-01 | L29: =$A$2&" Step - "&A29 -> Natural Gas Step - 01 | M29: PJ | N29: PJ-Yr | O29: SEASON | S29: =K29 -> MinGAS-01 | U29: =$A$1 -> GASNAT | V29: =D29 -> 0.5 | W29: =E29 -> 0.8333 | X29: =V29 -> 0.5
A30: 02 | C30: =$C$2&"-"&A30 -> MinGAS-02 | D30: =S3-S2 -> 0.05 | E30: =T3 -> 0.85 | F30: =U3 -> 0.9156914 | G30: =V3 -> 0.9864597 | K30: =C30 -> MinGAS-02 | L30: =$A$2&" Step - "&A30 -> Natural Gas Step - 02 | M30: PJ | N30: PJ-Yr | O30: SEASON | S30: =K30 -> MinGAS-02 | U30: =$A$1 -> GASNAT | V30: =D30 -> 0.05 | W30: =E30 -> 0.85 | X30: =V30 -> 0.05
A31: 03 | C31: =$C$2&"-"&A31 -> MinGAS-03 | D31: =S4-S3 -> 0.05 | E31: =T4 -> 0.8667 | F31: =U4 -> 0.93368205 | G31: =V4 -> 1.0058407 | K31: =C31 -> MinGAS-03 | L31: =$A$2&" Step - "&A31 -> Natural Gas Step - 03 | M31: PJ | N31: PJ-Yr | O31: SEASON | S31: =K31 -> MinGAS-03 | U31: =$A$1 -> GASNAT | V31: =D31 -> 0.05 | W31: =E31 -> 0.8667 | X31: =V31 -> 0.05
A32: 04 | C32: =$C$2&"-"&A32 -> MinGAS-04 | D32: =S5-S4 -> 0.05 | E32: =T5 -> 0.8833 | F32: =U5 -> 0.95156496 | G32: =V5 -> 1.0251057 | K32: =C32 -> MinGAS-04 | L32: =$A$2&" Step - "&A32 -> Natural Gas Step - 04 | M32: PJ | N32: PJ-Yr | O32: SEASON | S32: =K32 -> MinGAS-04 | U32: =$A$1 -> GASNAT | V32: =D32 -> 0.05 | W32: =E32 -> 0.8833 | X32: =V32 -> 0.05
A33: 05 | C33: =$C$2&"-"&A33 -> MinGAS-05 | D33: =S6-S5 -> 0.05 | E33: =T6 -> 0.9 | F33: =U6 -> 0.9695556 | G33: =V6 -> 1.0444867 | K33: =C33 -> MinGAS-05 | L33: =$A$2&" Step - "&A33 -> Natural Gas Step - 05 | M33: PJ | N33: PJ-Yr | O33: SEASON | S33: =K33 -> MinGAS-05 | U33: =$A$1 -> GASNAT | V33: =D33 -> 0.05 | W33: =E33 -> 0.9 | X33: =V33 -> 0.05
A34: 06 | C34: =$C$2&"-"&A34 -> MinGAS-06 | D34: =S7-S6 -> 0.05 | E34: =T7 -> 0.9167 | F34: =U7 -> 0.98754625 | G34: =V7 -> 1.0638678 | K34: =C34 -> MinGAS-06 | L34: =$A$2&" Step - "&A34 -> Natural Gas Step - 06 | M34: PJ | N34: PJ-Yr | O34: SEASON | S34: =K34 -> MinGAS-06 | U34: =$A$1 -> GASNAT | V34: =D34 -> 0.05 | W34: =E34 -> 0.9167 | X34: =V34 -> 0.05
A35: 07 | C35: =$C$2&"-"&A35 -> MinGAS-07 | D35: =S8-S7 -> 0.05 | E35: =T8 -> 0.9333 | F35: =U8 -> 1.0054292 | G35: =V8 -> 1.0831328 | K35: =C35 -> MinGAS-07 | L35: =$A$2&" Step - "&A35 -> Natural Gas Step - 07 | M35: PJ | N35: PJ-Yr | O35: SEASON | S35: =K35 -> MinGAS-07 | U35: =$A$1 -> GASNAT | V35: =D35 -> 0.05 | W35: =E35 -> 0.9333 | X35: =V35 -> 0.05
A36: 08 | C36: =$C$2&"-"&A36 -> MinGAS-08 | D36: =S9-S8 -> 0.05 | E36: =T9 -> 0.95 | F36: =U9 -> 1.0234198 | G36: =V9 -> 1.1025138 | K36: =C36 -> MinGAS-08 | L36: =$A$2&" Step - "&A36 -> Natural Gas Step - 08 | M36: PJ | N36: PJ-Yr | O36: SEASON | S36: =K36 -> MinGAS-08 | U36: =$A$1 -> GASNAT | V36: =D36 -> 0.05 | W36: =E36 -> 0.95 | X36: =V36 -> 0.05
A37: 09 | C37: =$C$2&"-"&A37 -> MinGAS-09 | D37: =S10-S9 -> 0.05 | E37: =T10 -> 0.9667 | F37: =U10 -> 1.0414104 | G37: =V10 -> 1.1218948 | K37: =C37 -> MinGAS-09 | L37: =$A$2&" Step - "&A37 -> Natural Gas Step - 09 | M37: PJ | N37: PJ-Yr | O37: SEASON | S37: =K37 -> MinGAS-09 | U37: =$A$1 -> GASNAT | V37: =D37 -> 0.05 | W37: =E37 -> 0.9667 | X37: =V37 -> 0.05
A38: 10 | C38: =$C$2&"-"&A38 -> MinGAS-10 | D38: =S11-S10 -> 0.05 | E38: =T11 -> 0.9833 | F38: =U11 -> 1.0592934 | G38: =V11 -> 1.1411598 | K38: =C38 -> MinGAS-10 | L38: =$A$2&" Step - "&A38 -> Natural Gas Step - 10 | M38: PJ | N38: PJ-Yr | O38: SEASON | S38: =K38 -> MinGAS-10 | U38: =$A$1 -> GASNAT | V38: =D38 -> 0.05 | W38: =E38 -> 0.9833 | X38: =V38 -> 0.05
A39: 11 | C39: =$C$2&"-"&A39 -> MinGAS-11 | D39: =S12-S11 -> 0.05 | E39: =T12 -> 1 | F39: =U12 -> 1.077284 | G39: =V12 -> 1.1605408 | K39: =C39 -> MinGAS-11 | L39: =$A$2&" Step - "&A39 -> Natural Gas Step - 11 | M39: PJ | N39: PJ-Yr | O39: SEASON | S39: =K39 -> MinGAS-11 | U39: =$A$1 -> GASNAT | V39: =D39 -> 0.05 | W39: =E39 -> 1 | X39: =V39 -> 0.05
A40: 12 | C40: =$C$2&"-"&A40 -> MinGAS-12 | D40: =S13-S12 -> 0.1 | E40: =T13 -> 1.005 | F40: =U13 -> 1.0826704 | G40: =V13 -> 1.1663435 | K40: =C40 -> MinGAS-12 | L40: =$A$2&" Step - "&A40 -> Natural Gas Step - 12 | M40: PJ | N40: PJ-Yr | O40: SEASON | S40: =K40 -> MinGAS-12 | U40: =$A$1 -> GASNAT | V40: =D40 -> 0.1 | W40: =E40 -> 1.005 | X40: =V40 -> 0.1
A41: 13 | C41: =$C$2&"-"&A41 -> MinGAS-13 | D41: =S14-S13 -> 0.1 | E41: =T14 -> 1.0109 | F41: =U14 -> 1.0890264 | G41: =V14 -> 1.1731907 | K41: =C41 -> MinGAS-13 | L41: =$A$2&" Step - "&A41 -> Natural Gas Step - 13 | M41: PJ | N41: PJ-Yr | O41: SEASON | S41: =K41 -> MinGAS-13 | U41: =$A$1 -> GASNAT | V41: =D41 -> 0.1 | W41: =E41 -> 1.0109 | X41: =V41 -> 0.1
... A48: 20 | C48: =$C$2&"-"&A48 -> MinGAS-20 | D48: =S21-S20 -> 0.1 | E48: =T21 -> 1.135 | F48: =U21 -> 1.2227173 | G48: =V21 -> 1.3172138 | K48: =C48 -> MinGAS-20 | L48: =$A$2&" Step - "&A48 -> Natural Gas Step - 20 | M48: PJ | N48: PJ-Yr | O48: SEASON | S48: =K48 -> MinGAS-20 | U48: =$A$1 -> GASNAT | V48: =D48 -> 0.1 | W48: =E48 -> 1.135 | X48: =V48 -> 0.1
A49: 21 | C49: =$C$2&"-"&A49 -> MinGAS-21 | D49: =S22-S21 -> 0.1 | E49: =T22 -> 1.2 | F49: =U22 -> 1.2927408 | G49: =V22 -> 1.392649 | K49: =C49 -> MinGAS-21 | L49: =$A$2&" Step - "&A49 -> Natural Gas Step - 21 | M49: PJ | N49: PJ-Yr | O49: SEASON | S49: =K49 -> MinGAS-21 | U49: =$A$1 -> GASNAT | V49: =D49 -> 0.1 | W49: =E49 -> 1.2

Sheet Coal-Min
A1: COABIT | T1: ='Gas-Min'!$T$1 -> 2010 | U1: ='Gas-Min'!$U$1 -> 2020 | V1: ='Gas-Min'!$V$1 -> 2030
A2: Bituminous Coal | C2: MinCoa | D2: Price | E2: Qty | R2: =R3+($E$10-$D$10)/($D$12-1) -> 3 | S2: =S3-$D$11 -> 0.5 | T2: =ROUND((S2-$S$12)/$S$12/R2*$T$12+$T$12,4) -> 0.8333 | U2: =T2*(1+$D$14)^(U$1-$T$1) -> 0.8501168 | V2: =T2*(1+$D$14)^(V$1-$T$1) -> 0.86727297 | AC2: Real terms (2013 Price)
D3: 1 | E3: 1 | R3: =R4+($E$10-$D$10)/($D$12-1) -> 3 | S3: =S4-$D$11 -> 0.55 | T3: =ROUND((S3-$S$12)/$S$12/R3*$T$12+$T$12,4) -> 0.85 | U3: =T3*(1+$D$14)^(U$1-$T$1) -> 0.86715382 | V3: =T3*(1+$D$14)^(V$1-$T$1) -> 0.88465382 | AB3: New Policies Scenario | AE3: Current Policies Scenario | AH3: 450 Scenario
R4: =R5+($E$10-$D$10)/($D$12-1) -> 3 | S4: =S5-$D$11 -> 0.6 | T4: =ROUND((S4-$S$12)/$S$12/R4*$T$12+$T$12,4) -> 0.8667 | U4: =T4*(1+$D$14)^(U$1-$T$1) -> 0.88419084 | V4: =T4*(1+$D$14)^(V$1-$T$1) -> 0.90203466 | AA4: 2013 | AB4: 2020 | AC4: 2030 | AD4: 2040 | AE4: 2020 | AF4: 2030 | AG4: 2040 | AH4: 2020 | AI4: 2030 | AJ4: 2040
R5: =R6+($E$10-$D$10)/($D$12-1) -> 3 | S5: =S6-$D$11 -> 0.65 | T5: =ROUND((S5-$S$12)/$S$12/R5*$T$12+$T$12,4) -> 0.8833 | U5: =T5*(1+$D$14)^(U$1-$T$1) -> 0.90112584 | V5: =T5*(1+$D$14)^(V$1-$T$1) -> 0.91931143 | Y5: IEA crude oil imports | Z5: ($/barrel) | AA5: 106 | AB5: 112 | AC5: 123 | AD5: 132 | AE5: 116 | AF5: 139 | AG5: 155 | AH5: 105 | AI5: 102 | AJ5: 100 | AL5: =1/5.86152 -> 0.17060421
D6: Start | E6: End | R6: =R7+($E$10-$D$10)/($D$12-1) -> 3 | S6: =S7-$D$11 -> 0.7 | T6: =ROUND((S6-$S$12)/$S$12/R6*$T$12+$T$12,4) -> 0.9 | U6: =T6*(1+$D$14)^(U$1-$T$1) -> 0.91816287 | V6: =T6*(1+$D$14)^(V$1-$T$1) -> 0.93669228 | Y6: Europe Natural Gas imports | Z6: ($/MBtu) | AA6: 10.6 | AB6: 11.1 | AC6: 12.1 | AD6: 12.7 | AE6: 11.5 | AF6: 13.2 | AG6: 14 | AH6: 10.5 | AI6: 10 | AJ6: 9.2 | AL6: =1/1.055055 -> 0.94781789
B7: UP | C7: Elasticity | D7: 20 | E7: 5 | R7: =R8+($E$10-$D$10)/($D$12-1) -> 3 | S7: =S8-$D$11 -> 0.75 | T7: =ROUND((S7-$S$12)/$S$12/R7*$T$12+$T$12,4) -> 0.9167 | U7: =T7*(1+$D$14)^(U$1-$T$1) -> 0.93519989 | V7: =T7*(1+$D$14)^(V$1-$T$1) -> 0.95407312 | Y7: OECD steam coal imports | Z7: ($/tonne) | AA7: 86 | AB7: 101 | AC7: 108 | AD7: 112 | AE7: 107 | AF7: 117 | AG7: 124 | AH7: 88 | AI7: 78 | AJ7: 77 | AL7: =1/29.288 -> 0.034143677
C8: StepHeight | D8: 0.1 | R8: =R9+($E$10-$D$10)/($D$12-1) -> 3 | S8: =S9-$D$11 -> 0.8 | T8: =ROUND((S8-$S$12)/$S$12/R8*$T$12+$T$12,4) -> 0.9333 | U8: =T8*(1+$D$14)^(U$1-$T$1) -> 0.95213489 | V8: =T8*(1+$D$14)^(V$1-$T$1) -> 0.97134989
C9: StepNum | D9: 10 | R9: =R10+($E$10-$D$10)/($D$12-1) -> 3 | S9: =S10-$D$11 -> 0.85 | T9: =ROUND((S9-$S$12)/$S$12/R9*$T$12+$T$12,4) -> 0.95 | U9: =T9*(1+$D$14)^(U$1-$T$1) -> 0.96917192 | V9: =T9*(1+$D$14)^(V$1-$T$1) -> 0.98873074 | Y9: Curr | Z9: 1
B10: LO | C10: Elasticity | D10: 3 | E10: 3 | R10: =R11+($E$10-$D$10)/($D$12-1) -> 3 | S10: =S11-$D$11 -> 0.9 | T10: =ROUND((S10-$S$12)/$S$12/R10*$T$12+$T$12,4) -> 0.9667 | U10: =T10*(1+$D$14)^(U$1-$T$1) -> 0.98620894 | V10: =T10*(1+$D$14)^(V$1-$T$1) -> 1.0061116 | AA10: =AA4 -> 2013 | AB10: =AE4 -> 2020 | AC10: =AF4 -> 2030 | AD10: =AG4 -> 2040 | AE10: AnnGrwRate
C11: StepHeight | D11: =0.05*$E$3 -> 0.05 | R11: =D10 -> 3 | S11: =S12-$D$11 -> 0.95 | T11: =ROUND((S11-$S$12)/$S$12/R11*$T$12+$T$12,4) -> 0.9833 | U11: =T11*(1+$D$14)^(U$1-$T$1) -> 1.0031439 | V11: =T11*(1+$D$14)^(V$1-$T$1) -> 1.0233884 | Z11: Oil | AA11: =AA5*$AL5*$Z$9 -> 18.084046 | AB11: =AE5*$AL5*$Z$9 -> 19.790089 | AC11: =AF5*$AL5*$Z$9 -> 23.713985 | AD11: =AG5*$AL5*$Z$9 -> 26.443653 | AE11: 1.42 | AF11: =AA11*(1+AE11/100)^(2040-2013) -> 26.462629
C12: StepNum | D12: 10 | S12: =E3 -> 1 | T12: =D3 -> 1 | U12: =T12*(1+$D$14)^(U$1-$T$1) -> 1.020181 | V12: =T12*(1+$D$14)^(V$1-$T$1) -> 1.0407692 | Z12: Gas | AA12: =AA6*$AL6*$Z$9 -> 10.04687 | AB12: =AE6*$AL6*$Z$9 -> 10.899906 | AC12: =AF6*$AL6*$Z$9 -> 12.511196 | AD12: =AG6*$AL6*$Z$9 -> 13.26945 | AE12: 1.03 | AF12: =AA12*(1+AE12/100)^(2040-2013) -> 13.24922
R13: =D7 -> 20 | S13: =S12+$D$8 -> 1.1 | T13: =ROUND((S13-$S$12)/$S$12/R13*$T$12+$T$12,4) -> 1.005 | U13: =T13*(1+$D$14)^(U$1-$T$1) -> 1.0252819 | V13: =T13*(1+$D$14)^(V$1-$T$1) -> 1.045973 | Z13: Coal | AA13: =AA7*$AL7*$Z$9 -> 2.9363562 | AB13: =AE7*$AL7*$Z$9 -> 3.6533734 | AC13: =AF7*$AL7*$Z$9 -> 3.9948102 | AD13: =AG7*$AL7*$Z$9 -> 4.2338159 | AE13: 1.38 | AF13: =AA13*(1+AE13/100)^(2040-2013) -> 4.2512876
C14: Ann Price change | D14: 0.002 | R14: =R13+($E$7-$D$7)/($D$9-1) -> 18.333333 | S14: =S13+$D$8 -> 1.2 | T14: =ROUND((S14-$S$12)/$S$12/R14*$T$12+$T$12,4) -> 1.0109 | U14: =T14*(1+$D$14)^(U$1-$T$1) -> 1.0313009 | V14: =T14*(1+$D$14)^(V$1-$T$1) -> 1.0521136
R15: =R14+($E$7-$D$7)/($D$9-1) -> 16.666667 | S15: =S14+$D$8 -> 1.3 | T15: =ROUND((S15-$S$12)/$S$12/R15*$T$12+$T$12,4) -> 1.018 | U15: =T15*(1+$D$14)^(U$1-$T$1) -> 1.0385442 | V15: =T15*(1+$D$14)^(V$1-$T$1) -> 1.059503
R16: =R15+($E$7-$D$7)/($D$9-1) -> 15 | S16: =S15+$D$8 -> 1.4 | T16: =ROUND((S16-$S$12)/$S$12/R16*$T$12+$T$12,4) -> 1.0267 | U16: =T16*(1+$D$14)^(U$1-$T$1) -> 1.0474198 | V16: =T16*(1+$D$14)^(V$1-$T$1) -> 1.0685577
R17: =R16+($E$7-$D$7)/($D$9-1) -> 13.333333 | S17: =S16+$D$8 -> 1.5 | T17: =ROUND((S17-$S$12)/$S$12/R17*$T$12+$T$12,4) -> 1.0375 | U17: =T17*(1+$D$14)^(U$1-$T$1) -> 1.0584377 | V17: =T17*(1+$D$14)^(V$1-$T$1) -> 1.079798
R18: =R17+($E$7-$D$7)/($D$9-1) -> 11.666667 | S18: =S17+$D$8 -> 1.6 | T18: =ROUND((S18-$S$12)/$S$12/R18*$T$12+$T$12,4) -> 1.0514 | U18: =T18*(1+$D$14)^(U$1-$T$1) -> 1.0726183 | V18: =T18*(1+$D$14)^(V$1-$T$1) -> 1.0942647
R19: =R18+($E$7-$D$7)/($D$9-1) -> 10 | S19: =S18+$D$8 -> 1.7 | T19: =ROUND((S19-$S$12)/$S$12/R19*$T$12+$T$12,4) -> 1.07 | U19: =T19*(1+$D$14)^(U$1-$T$1) -> 1.0915936 | V19: =T19*(1+$D$14)^(V$1-$T$1) -> 1.113623
R20: =R19+($E$7-$D$7)/($D$9-1) -> 8.3333333 | S20: =S19+$D$8 -> 1.8 | T20: =ROUND((S20-$S$12)/$S$12/R20*$T$12+$T$12,4) -> 1.096 | U20: =T20*(1+$D$14)^(U$1-$T$1) -> 1.1181183 | V20: =T20*(1+$D$14)^(V$1-$T$1) -> 1.140683
R21: =R20+($E$7-$D$7)/($D$9-1) -> 6.6666667 | S21: =S20+$D$8 -> 1.9 | T21: =ROUND((S21-$S$12)/$S$12/R21*$T$12+$T$12,4) -> 1.135 | U21: =T21*(1+$D$14)^(U$1-$T$1) -> 1.1579054 | V21: =T21*(1+$D$14)^(V$1-$T$1) -> 1.181273
R22: =R21+($E$7-$D$7)/($D$9-1) -> 5 | S22: =S21+$D$8 -> 2 | T22: =ROUND((S22-$S$12)/$S$12/R22*$T$12+$T$12,4) -> 1.2 | U22: =T22*(1+$D$14)^(U$1-$T$1) -> 1.2242172 | V22: =T22*(1+$D$14)^(V$1-$T$1) -> 1.248923
E27: COST | J27: ~FI_Process | U27: ~FI_T: ACT_COST~UP~USD10
D28: ACT_BND | E28: =T1 -> 2010 | F28: =U1 -> 2020 | G28: =V1 -> 2030 | J28: Sets | K28: TechName | L28: TechDesc | M28: Tact | N28: Tcap | O28: Tslvl | P28: PrimaryCG | Q28: Vintage | S28: TechName | T28: Comm-IN | U28: Comm-OUT | V28: ACT_BND | W28: =E28 -> 2010 | X28: =V28&"~2050" -> ACT_BND~2050
A29: 01 | C29: =$C$2&"-"&A29 -> MinCoa-01 | D29: =S2 -> 0.5 | E29: =T2 -> 0.8333 | F29: =U2 -> 0.8501168 | G29: =V2 -> 0.86727297 | J29: MIN | K29: =C29 -> MinCoa-01 | L29: =$A$2&" Step - "&A29 -> Bituminous Coal Step - 01 | M29: PJ | N29: PJ-Yr | S29: =K29 -> MinCoa-01 | U29: =$A$1 -> COABIT | V29: =D29 -> 0.5 | W29: =E29 -> 0.8333 | X29: =V29 -> 0.5
A30: 02 | C30: =$C$2&"-"&A30 -> MinCoa-02 | D30: =S3-S2 -> 0.05 | E30: =T3 -> 0.85 | F30: =U3 -> 0.86715382 | G30: =V3 -> 0.88465382 | K30: =C30 -> MinCoa-02 | L30: =$A$2&" Step - "&A30 -> Bituminous Coal Step - 02 | M30: PJ | N30: PJ-Yr | S30: =K30 -> MinCoa-02 | U30: =$A$1 -> COABIT | V30: =D30 -> 0.05 | W30: =E30 -> 0.85 | X30: =V30 -> 0.05
A31: 03 | C31: =$C$2&"-"&A31 -> MinCoa-03 | D31: =S4-S3 -> 0.05 | E31: =T4 -> 0.8667 | F31: =U4 -> 0.88419084 | G31: =V4 -> 0.90203466 | K31: =C31 -> MinCoa-03 | L31: =$A$2&" Step - "&A31 -> Bituminous Coal Step - 03 | M31: PJ | N31: PJ-Yr | S31: =K31 -> MinCoa-03 | U31: =$A$1 -> COABIT | V31: =D31 -> 0.05 | W31: =E31 -> 0.8667 | X31: =V31 -> 0.05
A32: 04 | C32: =$C$2&"-"&A32 -> MinCoa-04 | D32: =S5-S4 -> 0.05 | E32: =T5 -> 0.8833 | F32: =U5 -> 0.90112584 | G32: =V5 -> 0.91931143 | K32: =C32 -> MinCoa-04 | L32: =$A$2&" Step - "&A32 -> Bituminous Coal Step - 04 | M32: PJ | N32: PJ-Yr | S32: =K32 -> MinCoa-04 | U32: =$A$1 -> COABIT | V32: =D32 -> 0.05 | W32: =E32 -> 0.8833 | X32: =V32 -> 0.05
A33: 05 | C33: =$C$2&"-"&A33 -> MinCoa-05 | D33: =S6-S5 -> 0.05 | E33: =T6 -> 0.9 | F33: =U6 -> 0.91816287 | G33: =V6 -> 0.93669228 | K33: =C33 -> MinCoa-05 | L33: =$A$2&" Step - "&A33 -> Bituminous Coal Step - 05 | M33: PJ | N33: PJ-Yr | S33: =K33 -> MinCoa-05 | U33: =$A$1 -> COABIT | V33: =D33 -> 0.05 | W33: =E33 -> 0.9 | X33: =V33 -> 0.05
A34: 06 | C34: =$C$2&"-"&A34 -> MinCoa-06 | D34: =S7-S6 -> 0.05 | E34: =T7 -> 0.9167 | F34: =U7 -> 0.93519989 | G34: =V7 -> 0.95407312 | K34: =C34 -> MinCoa-06 | L34: =$A$2&" Step - "&A34 -> Bituminous Coal Step - 06 | M34: PJ | N34: PJ-Yr | S34: =K34 -> MinCoa-06 | U34: =$A$1 -> COABIT | V34: =D34 -> 0.05 | W34: =E34 -> 0.9167 | X34: =V34 -> 0.05
A35: 07 | C35: =$C$2&"-"&A35 -> MinCoa-07 | D35: =S8-S7 -> 0.05 | E35: =T8 -> 0.9333 | F35: =U8 -> 0.95213489 | G35: =V8 -> 0.97134989 | K35: =C35 -> MinCoa-07 | L35: =$A$2&" Step - "&A35 -> Bituminous Coal Step - 07 | M35: PJ | N35: PJ-Yr | S35: =K35 -> MinCoa-07 | U35: =$A$1 -> COABIT | V35: =D35 -> 0.05 | W35: =E35 -> 0.9333 | X35: =V35 -> 0.05
A36: 08 | C36: =$C$2&"-"&A36 -> MinCoa-08 | D36: =S9-S8 -> 0.05 | E36: =T9 -> 0.95 | F36: =U9 -> 0.96917192 | G36: =V9 -> 0.98873074 | K36: =C36 -> MinCoa-08 | L36: =$A$2&" Step - "&A36 -> Bituminous Coal Step - 08 | M36: PJ | N36: PJ-Yr | S36: =K36 -> MinCoa-08 | U36: =$A$1 -> COABIT | V36: =D36 -> 0.05 | W36: =E36 -> 0.95 | X36: =V36 -> 0.05
A37: 09 | C37: =$C$2&"-"&A37 -> MinCoa-09 | D37: =S10-S9 -> 0.05 | E37: =T10 -> 0.9667 | F37: =U10 -> 0.98620894 | G37: =V10 -> 1.0061116 | K37: =C37 -> MinCoa-09 | L37: =$A$2&" Step - "&A37 -> Bituminous Coal Step - 09 | M37: PJ | N37: PJ-Yr | S37: =K37 -> MinCoa-09 | U37: =$A$1 -> COABIT | V37: =D37 -> 0.05 | W37: =E37 -> 0.9667 | X37: =V37 -> 0.05
A38: 10 | C38: =$C$2&"-"&A38 -> MinCoa-10 | D38: =S11-S10 -> 0.05 | E38: =T11 -> 0.9833 | F38: =U11 -> 1.0031439 | G38: =V11 -> 1.0233884 | K38: =C38 -> MinCoa-10 | L38: =$A$2&" Step - "&A38 -> Bituminous Coal Step - 10 | M38: PJ | N38: PJ-Yr | S38: =K38 -> MinCoa-10 | U38: =$A$1 -> COABIT | V38: =D38 -> 0.05 | W38: =E38 -> 0.9833 | X38: =V38 -> 0.05
A39: 11 | C39: =$C$2&"-"&A39 -> MinCoa-11 | D39: =S12-S11 -> 0.05 | E39: =T12 -> 1 | F39: =U12 -> 1.020181 | G39: =V12 -> 1.0407692 | K39: =C39 -> MinCoa-11 | L39: =$A$2&" Step - "&A39 -> Bituminous Coal Step - 11 | M39: PJ | N39: PJ-Yr | S39: =K39 -> MinCoa-11 | U39: =$A$1 -> COABIT | V39: =D39 -> 0.05 | W39: =E39 -> 1 | X39: =V39 -> 0.05
A40: 12 | C40: =$C$2&"-"&A40 -> MinCoa-12 | D40: =S13-S12 -> 0.1 | E40: =T13 -> 1.005 | F40: =U13 -> 1.0252819 | G40: =V13 -> 1.045973 | K40: =C40 -> MinCoa-12 | L40: =$A$2&" Step - "&A40 -> Bituminous Coal Step - 12 | M40: PJ | N40: PJ-Yr | S40: =K40 -> MinCoa-12 | U40: =$A$1 -> COABIT | V40: =D40 -> 0.1 | W40: =E40 -> 1.005 | X40: =V40 -> 0.1
A41: 13 | C41: =$C$2&"-"&A41 -> MinCoa-13 | D41: =S14-S13 -> 0.1 | E41: =T14 -> 1.0109 | F41: =U14 -> 1.0313009 | G41: =V14 -> 1.0521136 | K41: =C41 -> MinCoa-13 | L41: =$A$2&" Step - "&A41 -> Bituminous Coal Step - 13 | M41: PJ | N41: PJ-Yr | S41: =K41 -> MinCoa-13 | U41: =$A$1 -> COABIT | V41: =D41 -> 0.1 | W41: =E41 -> 1.0109 | X41: =V41 -> 0.1
... A48: 20 | C48: =$C$2&"-"&A48 -> MinCoa-20 | D48: =S21-S20 -> 0.1 | E48: =T21 -> 1.135 | F48: =U21 -> 1.1579054 | G48: =V21 -> 1.181273 | K48: =C48 -> MinCoa-20 | L48: =$A$2&" Step - "&A48 -> Bituminous Coal Step - 20 | M48: PJ | N48: PJ-Yr | S48: =K48 -> MinCoa-20 | U48: =$A$1 -> COABIT | V48: =D48 -> 0.1 | W48: =E48 -> 1.135 | X48: =V48 -> 0.1
A49: 21 | C49: =$C$2&"-"&A49 -> MinCoa-21 | D49: =S22-S21 -> 0.1 | E49: =T22 -> 1.2 | F49: =U22 -> 1.2242172 | G49: =V22 -> 1.248923 | K49: =C49 -> MinCoa-21 | L49: =$A$2&" Step - "&A49 -> Bituminous Coal Step - 21 | M49: PJ | N49: PJ-Yr | S49: =K49 -> MinCoa-21 | U49: =$A$1 -> COABIT | V49: =D49 -> 0.1 | W49: =E49 -> 1.2

Sheet OilDST-Min
A1: OILDST | T1: ='Gas-Min'!$T$1 -> 2010 | U1: ='Gas-Min'!$U$1 -> 2020 | V1: ='Gas-Min'!$V$1 -> 2030
A2: Dst | C2: MinDst | D2: Price | E2: Qty | R2: =R3+($E$10-$D$10)/($D$12-1) -> 0.5 | S2: =S3-$D$11 -> 0.5 | T2: =ROUND((S2-$S$12)/$S$12/R2*$T$12+$T$12,4) -> 0 | U2: =T2*(1+$D$14)^5 -> 0 | V2: =T2*(1+$D$14)^10 -> 0
D3: 1 | E3: 1 | R3: =R4+($E$10-$D$10)/($D$12-1) -> 0.48888889 | S3: =S4-$D$11 -> 0.55 | T3: =ROUND((S3-$S$12)/$S$12/R3*$T$12+$T$12,4) -> 0.0795 | U3: =T3*(1+$D$14)^5 -> 0.085307096 | V3: =T3*(1+$D$14)^10 -> 0.091538373
R4: =R5+($E$10-$D$10)/($D$12-1) -> 0.47777778 | S4: =S5-$D$11 -> 0.6 | T4: =ROUND((S4-$S$12)/$S$12/R4*$T$12+$T$12,4) -> 0.1628 | U4: =T4*(1+$D$14)^5 -> 0.17469176 | V4: =T4*(1+$D$14)^10 -> 0.18745217
R5: =R6+($E$10-$D$10)/($D$12-1) -> 0.46666667 | S5: =S6-$D$11 -> 0.65 | T5: =ROUND((S5-$S$12)/$S$12/R5*$T$12+$T$12,4) -> 0.25 | U5: =T5*(1+$D$14)^5 -> 0.26826131 | V5: =T5*(1+$D$14)^10 -> 0.28785652
D6: Start | E6: End | R6: =R7+($E$10-$D$10)/($D$12-1) -> 0.45555556 | S6: =S7-$D$11 -> 0.7 | T6: =ROUND((S6-$S$12)/$S$12/R6*$T$12+$T$12,4) -> 0.3415 | U6: =T6*(1+$D$14)^5 -> 0.36644495 | V6: =T6*(1+$D$14)^10 -> 0.39321201
B7: UP | C7: Elasticity | D7: 20 | E7: 20 | R7: =R8+($E$10-$D$10)/($D$12-1) -> 0.44444444 | S7: =S8-$D$11 -> 0.75 | T7: =ROUND((S7-$S$12)/$S$12/R7*$T$12+$T$12,4) -> 0.4375 | U7: =T7*(1+$D$14)^5 -> 0.46945729 | V7: =T7*(1+$D$14)^10 -> 0.50374891
C8: StepHeight | D8: 1 | R8: =R9+($E$10-$D$10)/($D$12-1) -> 0.43333333 | S8: =S9-$D$11 -> 0.8 | T8: =ROUND((S8-$S$12)/$S$12/R8*$T$12+$T$12,4) -> 0.5385 | U8: =T8*(1+$D$14)^5 -> 0.57783486 | V8: =T8*(1+$D$14)^10 -> 0.62004294
C9: StepNum | D9: 10 | R9: =R10+($E$10-$D$10)/($D$12-1) -> 0.42222222 | S9: =S10-$D$11 -> 0.85 | T9: =ROUND((S9-$S$12)/$S$12/R9*$T$12+$T$12,4) -> 0.6447 | U9: =T9*(1+$D$14)^5 -> 0.69179226 | V9: =T9*(1+$D$14)^10 -> 0.74232439
B10: LO | C10: Elasticity | D10: 0.4 | E10: 0.5 | R10: =R11+($E$10-$D$10)/($D$12-1) -> 0.41111111 | S10: =S11-$D$11 -> 0.9 | T10: =ROUND((S10-$S$12)/$S$12/R10*$T$12+$T$12,4) -> 0.7568 | U10: =T10*(1+$D$14)^5 -> 0.81208064 | V10: =T10*(1+$D$14)^10 -> 0.87139926
C11: StepHeight | D11: 0.05 | R11: =D10 -> 0.4 | S11: =S12-$D$11 -> 0.95 | T11: =ROUND((S11-$S$12)/$S$12/R11*$T$12+$T$12,4) -> 0.875 | U11: =T11*(1+$D$14)^5 -> 0.93891458 | V11: =T11*(1+$D$14)^10 -> 1.0074978
C12: StepNum | D12: 10 | S12: =E3 -> 1 | T12: =D3 -> 1 | U12: =T12*(1+$D$14)^5 -> 1.0730452 | V12: =T12*(1+$D$14)^10 -> 1.1514261
R13: =D7 -> 20 | S13: =S12+$D$8 -> 2 | T13: =ROUND((S13-$S$12)/$S$12/R13*$T$12+$T$12,4) -> 1.05 | U13: =T13*(1+$D$14)^5 -> 1.1266975 | V13: =T13*(1+$D$14)^10 -> 1.2089974
C14: Ann Price change | D14: 0.0142 | R14: =R13+($E$7-$D$7)/($D$9-1) -> 20 | S14: =S13+$D$8 -> 3 | T14: =ROUND((S14-$S$12)/$S$12/R14*$T$12+$T$12,4) -> 1.1 | U14: =T14*(1+$D$14)^5 -> 1.1803498 | V14: =T14*(1+$D$14)^10 -> 1.2665687
R15: =R14+($E$7-$D$7)/($D$9-1) -> 20 | S15: =S14+$D$8 -> 4 | T15: =ROUND((S15-$S$12)/$S$12/R15*$T$12+$T$12,4) -> 1.15 | U15: =T15*(1+$D$14)^5 -> 1.234002 | V15: =T15*(1+$D$14)^10 -> 1.32414
R16: =R15+($E$7-$D$7)/($D$9-1) -> 20 | S16: =S15+$D$8 -> 5 | T16: =ROUND((S16-$S$12)/$S$12/R16*$T$12+$T$12,4) -> 1.2 | U16: =T16*(1+$D$14)^5 -> 1.2876543 | V16: =T16*(1+$D$14)^10 -> 1.3817113
R17: =R16+($E$7-$D$7)/($D$9-1) -> 20 | S17: =S16+$D$8 -> 6 | T17: =ROUND((S17-$S$12)/$S$12/R17*$T$12+$T$12,4) -> 1.25 | U17: =T17*(1+$D$14)^5 -> 1.3413065 | V17: =T17*(1+$D$14)^10 -> 1.4392826
R18: =R17+($E$7-$D$7)/($D$9-1) -> 20 | S18: =S17+$D$8 -> 7 | T18: =ROUND((S18-$S$12)/$S$12/R18*$T$12+$T$12,4) -> 1.3 | U18: =T18*(1+$D$14)^5 -> 1.3949588 | V18: =T18*(1+$D$14)^10 -> 1.4968539
R19: =R18+($E$7-$D$7)/($D$9-1) -> 20 | S19: =S18+$D$8 -> 8 | T19: =ROUND((S19-$S$12)/$S$12/R19*$T$12+$T$12,4) -> 1.35 | U19: =T19*(1+$D$14)^5 -> 1.4486111 | V19: =T19*(1+$D$14)^10 -> 1.5544252
R20: =R19+($E$7-$D$7)/($D$9-1) -> 20 | S20: =S19+$D$8 -> 9 | T20: =ROUND((S20-$S$12)/$S$12/R20*$T$12+$T$12,4) -> 1.4 | U20: =T20*(1+$D$14)^5 -> 1.5022633 | V20: =T20*(1+$D$14)^10 -> 1.6119965
R21: =R20+($E$7-$D$7)/($D$9-1) -> 20 | S21: =S20+$D$8 -> 10 | T21: =ROUND((S21-$S$12)/$S$12/R21*$T$12+$T$12,4) -> 1.45 | U21: =T21*(1+$D$14)^5 -> 1.5559156 | V21: =T21*(1+$D$14)^10 -> 1.6695678
R22: =R21+($E$7-$D$7)/($D$9-1) -> 20 | S22: =S21+$D$8 -> 11 | T22: =ROUND((S22-$S$12)/$S$12/R22*$T$12+$T$12,4) -> 1.5 | U22: =T22*(1+$D$14)^5 -> 1.6095679 | V22: =T22*(1+$D$14)^10 -> 1.7271391
E27: COST | J27: ~FI_Process | U27: ~FI_T: ACT_COST~UP~USD10
D28: ACT_BND | E28: =T1 -> 2010 | F28: =U1 -> 2020 | G28: =V1 -> 2030 | J28: Sets | K28: TechName | L28: TechDesc | M28: Tact | N28: Tcap | O28: Tslvl | P28: PrimaryCG | Q28: Vintage | S28: TechName | T28: Comm-IN | U28: Comm-OUT | V28: ACT_BND | W28: =E28 -> 2010 | X28: =V28&"~2050" -> ACT_BND~2050
A29: 01 | C29: =$C$2&"-"&A29 -> MinDst-01 | D29: =S2 -> 0.5 | E29: =T2 -> 0 | F29: =U2 -> 0 | G29: =V2 -> 0 | J29: MIN | K29: =C29 -> MinDst-01 | L29: =$A$2&" Step - "&A29 -> Dst Step - 01 | M29: PJ | N29: PJ-Yr | S29: =K29 -> MinDst-01 | U29: =$A$1 -> OILDST | V29: =D29 -> 0.5 | W29: =E29 -> 0 | X29: =V29 -> 0.5
A30: 02 | C30: =$C$2&"-"&A30 -> MinDst-02 | D30: =S3-S2 -> 0.05 | E30: =T3 -> 0.0795 | F30: =U3 -> 0.085307096 | G30: =V3 -> 0.091538373 | K30: =C30 -> MinDst-02 | L30: =$A$2&" Step - "&A30 -> Dst Step - 02 | M30: PJ | N30: PJ-Yr | S30: =K30 -> MinDst-02 | U30: =$A$1 -> OILDST | V30: =D30 -> 0.05 | W30: =E30 -> 0.0795 | X30: =V30 -> 0.05
A31: 03 | C31: =$C$2&"-"&A31 -> MinDst-03 | D31: =S4-S3 -> 0.05 | E31: =T4 -> 0.1628 | F31: =U4 -> 0.17469176 | G31: =V4 -> 0.18745217 | K31: =C31 -> MinDst-03 | L31: =$A$2&" Step - "&A31 -> Dst Step - 03 | M31: PJ | N31: PJ-Yr | S31: =K31 -> MinDst-03 | U31: =$A$1 -> OILDST | V31: =D31 -> 0.05 | W31: =E31 -> 0.1628 | X31: =V31 -> 0.05
A32: 04 | C32: =$C$2&"-"&A32 -> MinDst-04 | D32: =S5-S4 -> 0.05 | E32: =T5 -> 0.25 | F32: =U5 -> 0.26826131 | G32: =V5 -> 0.28785652 | K32: =C32 -> MinDst-04 | L32: =$A$2&" Step - "&A32 -> Dst Step - 04 | M32: PJ | N32: PJ-Yr | S32: =K32 -> MinDst-04 | U32: =$A$1 -> OILDST | V32: =D32 -> 0.05 | W32: =E32 -> 0.25 | X32: =V32 -> 0.05
A33: 05 | C33: =$C$2&"-"&A33 -> MinDst-05 | D33: =S6-S5 -> 0.05 | E33: =T6 -> 0.3415 | F33: =U6 -> 0.36644495 | G33: =V6 -> 0.39321201 | K33: =C33 -> MinDst-05 | L33: =$A$2&" Step - "&A33 -> Dst Step - 05 | M33: PJ | N33: PJ-Yr | S33: =K33 -> MinDst-05 | U33: =$A$1 -> OILDST | V33: =D33 -> 0.05 | W33: =E33 -> 0.3415 | X33: =V33 -> 0.05
A34: 06 | C34: =$C$2&"-"&A34 -> MinDst-06 | D34: =S7-S6 -> 0.05 | E34: =T7 -> 0.4375 | F34: =U7 -> 0.46945729 | G34: =V7 -> 0.50374891 | K34: =C34 -> MinDst-06 | L34: =$A$2&" Step - "&A34 -> Dst Step - 06 | M34: PJ | N34: PJ-Yr | S34: =K34 -> MinDst-06 | U34: =$A$1 -> OILDST | V34: =D34 -> 0.05 | W34: =E34 -> 0.4375 | X34: =V34 -> 0.05
A35: 07 | C35: =$C$2&"-"&A35 -> MinDst-07 | D35: =S8-S7 -> 0.05 | E35: =T8 -> 0.5385 | F35: =U8 -> 0.57783486 | G35: =V8 -> 0.62004294 | K35: =C35 -> MinDst-07 | L35: =$A$2&" Step - "&A35 -> Dst Step - 07 | M35: PJ | N35: PJ-Yr | S35: =K35 -> MinDst-07 | U35: =$A$1 -> OILDST | V35: =D35 -> 0.05 | W35: =E35 -> 0.5385 | X35: =V35 -> 0.05
A36: 08 | C36: =$C$2&"-"&A36 -> MinDst-08 | D36: =S9-S8 -> 0.05 | E36: =T9 -> 0.6447 | F36: =U9 -> 0.69179226 | G36: =V9 -> 0.74232439 | K36: =C36 -> MinDst-08 | L36: =$A$2&" Step - "&A36 -> Dst Step - 08 | M36: PJ | N36: PJ-Yr | S36: =K36 -> MinDst-08 | U36: =$A$1 -> OILDST | V36: =D36 -> 0.05 | W36: =E36 -> 0.6447 | X36: =V36 -> 0.05
A37: 09 | C37: =$C$2&"-"&A37 -> MinDst-09 | D37: =S10-S9 -> 0.05 | E37: =T10 -> 0.7568 | F37: =U10 -> 0.81208064 | G37: =V10 -> 0.87139926 | K37: =C37 -> MinDst-09 | L37: =$A$2&" Step - "&A37 -> Dst Step - 09 | M37: PJ | N37: PJ-Yr | S37: =K37 -> MinDst-09 | U37: =$A$1 -> OILDST | V37: =D37 -> 0.05 | W37: =E37 -> 0.7568 | X37: =V37 -> 0.05
A38: 10 | C38: =$C$2&"-"&A38 -> MinDst-10 | D38: =S11-S10 -> 0.05 | E38: =T11 -> 0.875 | F38: =U11 -> 0.93891458 | G38: =V11 -> 1.0074978 | K38: =C38 -> MinDst-10 | L38: =$A$2&" Step - "&A38 -> Dst Step - 10 | M38: PJ | N38: PJ-Yr | S38: =K38 -> MinDst-10 | U38: =$A$1 -> OILDST | V38: =D38 -> 0.05 | W38: =E38 -> 0.875 | X38: =V38 -> 0.05
A39: 11 | C39: =$C$2&"-"&A39 -> MinDst-11 | D39: =S12-S11 -> 0.05 | E39: =T12 -> 1 | F39: =U12 -> 1.0730452 | G39: =V12 -> 1.1514261 | K39: =C39 -> MinDst-11 | L39: =$A$2&" Step - "&A39 -> Dst Step - 11 | M39: PJ | N39: PJ-Yr | S39: =K39 -> MinDst-11 | U39: =$A$1 -> OILDST | V39: =D39 -> 0.05 | W39: =E39 -> 1 | X39: =V39 -> 0.05
A40: 12 | C40: =$C$2&"-"&A40 -> MinDst-12 | D40: =S13-S12 -> 1 | E40: =T13 -> 1.05 | F40: =U13 -> 1.1266975 | G40: =V13 -> 1.2089974 | K40: =C40 -> MinDst-12 | L40: =$A$2&" Step - "&A40 -> Dst Step - 12 | M40: PJ | N40: PJ-Yr | S40: =K40 -> MinDst-12 | U40: =$A$1 -> OILDST | V40: =D40 -> 1 | W40: =E40 -> 1.05 | X40: =V40 -> 1
A41: 13 | C41: =$C$2&"-"&A41 -> MinDst-13 | D41: =S14-S13 -> 1 | E41: =T14 -> 1.1 | F41: =U14 -> 1.1803498 | G41: =V14 -> 1.2665687 | K41: =C41 -> MinDst-13 | L41: =$A$2&" Step - "&A41 -> Dst Step - 13 | M41: PJ | N41: PJ-Yr | S41: =K41 -> MinDst-13 | U41: =$A$1 -> OILDST | V41: =D41 -> 1 | W41: =E41 -> 1.1 | X41: =V41 -> 1
... A48: 20 | C48: =$C$2&"-"&A48 -> MinDst-20 | D48: =S21-S20 -> 1 | E48: =T21 -> 1.45 | F48: =U21 -> 1.5559156 | G48: =V21 -> 1.6695678 | K48: =C48 -> MinDst-20 | L48: =$A$2&" Step - "&A48 -> Dst Step - 20 | M48: PJ | N48: PJ-Yr | S48: =K48 -> MinDst-20 | U48: =$A$1 -> OILDST | V48: =D48 -> 1 | W48: =E48 -> 1.45 | X48: =V48 -> 1
A49: 21 | C49: =$C$2&"-"&A49 -> MinDst-21 | D49: =S22-S21 -> 1 | E49: =T22 -> 1.5 | F49: =U22 -> 1.6095679 | G49: =V22 -> 1.7271391 | K49: =C49 -> MinDst-21 | L49: =$A$2&" Step - "&A49 -> Dst Step - 21 | M49: PJ | N49: PJ-Yr | S49: =K49 -> MinDst-21 | U49: =$A$1 -> OILDST | V49: =D49 -> 1 | W49: =E49 -> 1.5

Sheet Bio-MIN
A1: BIOCRP | T1: ='Gas-Min'!$T$1 -> 2010 | U1: ='Gas-Min'!$U$1 -> 2020 | V1: ='Gas-Min'!$V$1 -> 2030
A2: Biomass | C2: MinBio | D2: Price | E2: Qty | R2: =R3+($E$10-$D$10)/($D$12-1) -> 3 | S2: =S3-$D$11 -> 0.5 | T2: =ROUND((S2-$S$12)/$S$12/R2*$T$12+$T$12,4) -> 4.1667 | U2: =T2*(1+$D$14)^5 -> 4.2719144 | V2: =T2*(1+$D$14)^10 -> 4.3797856
D3: 5 | E3: 1 | R3: =R4+($E$10-$D$10)/($D$12-1) -> 3 | S3: =S4-$D$11 -> 0.55 | T3: =ROUND((S3-$S$12)/$S$12/R3*$T$12+$T$12,4) -> 4.25 | U3: =T3*(1+$D$14)^5 -> 4.3573178 | V3: =T3*(1+$D$14)^10 -> 4.4673456
R4: =R5+($E$10-$D$10)/($D$12-1) -> 3 | S4: =S5-$D$11 -> 0.6 | T4: =ROUND((S4-$S$12)/$S$12/R4*$T$12+$T$12,4) -> 4.3333 | U4: =T4*(1+$D$14)^5 -> 4.4427213 | V4: =T4*(1+$D$14)^10 -> 4.5549055
R5: =R6+($E$10-$D$10)/($D$12-1) -> 3 | S5: =S6-$D$11 -> 0.65 | T5: =ROUND((S5-$S$12)/$S$12/R5*$T$12+$T$12,4) -> 4.4167 | U5: =T5*(1+$D$14)^5 -> 4.5282272 | V5: =T5*(1+$D$14)^10 -> 4.6425706
D6: Start | E6: End | R6: =R7+($E$10-$D$10)/($D$12-1) -> 3 | S6: =S7-$D$11 -> 0.7 | T6: =ROUND((S6-$S$12)/$S$12/R6*$T$12+$T$12,4) -> 4.5 | U6: =T6*(1+$D$14)^5 -> 4.6136306 | V6: =T6*(1+$D$14)^10 -> 4.7301306
B7: UP | C7: Elasticity | D7: 3 | E7: 2 | R7: =R8+($E$10-$D$10)/($D$12-1) -> 3 | S7: =S8-$D$11 -> 0.75 | T7: =ROUND((S7-$S$12)/$S$12/R7*$T$12+$T$12,4) -> 4.5833 | U7: =T7*(1+$D$14)^5 -> 4.6990341 | V7: =T7*(1+$D$14)^10 -> 4.8176906
C8: StepHeight | D8: =0.2*E3 -> 0.2 | R8: =R9+($E$10-$D$10)/($D$12-1) -> 3 | S8: =S9-$D$11 -> 0.8 | T8: =ROUND((S8-$S$12)/$S$12/R8*$T$12+$T$12,4) -> 4.6667 | U8: =T8*(1+$D$14)^5 -> 4.78454 | V8: =T8*(1+$D$14)^10 -> 4.9053557
C9: StepNum | D9: 10 | R9: =R10+($E$10-$D$10)/($D$12-1) -> 3 | S9: =S10-$D$11 -> 0.85 | T9: =ROUND((S9-$S$12)/$S$12/R9*$T$12+$T$12,4) -> 4.75 | U9: =T9*(1+$D$14)^5 -> 4.8699435 | V9: =T9*(1+$D$14)^10 -> 4.9929156
B10: LO | C10: Elasticity | D10: 3 | E10: 3 | R10: =R11+($E$10-$D$10)/($D$12-1) -> 3 | S10: =S11-$D$11 -> 0.9 | T10: =ROUND((S10-$S$12)/$S$12/R10*$T$12+$T$12,4) -> 4.8333 | U10: =T10*(1+$D$14)^5 -> 4.9553469 | V10: =T10*(1+$D$14)^10 -> 5.0804756
C11: StepHeight | D11: 0.05 | R11: =D10 -> 3 | S11: =S12-$D$11 -> 0.95 | T11: =ROUND((S11-$S$12)/$S$12/R11*$T$12+$T$12,4) -> 4.9167 | U11: =T11*(1+$D$14)^5 -> 5.0408528 | V11: =T11*(1+$D$14)^10 -> 5.1681407
C12: StepNum | D12: 10 | S12: =E3 -> 1 | T12: =D3 -> 5 | U12: =T12*(1+$D$14)^5 -> 5.1262563 | V12: =T12*(1+$D$14)^10 -> 5.2557007
R13: =D7 -> 3 | S13: =S12+$D$8 -> 1.2 | T13: =ROUND((S13-$S$12)/$S$12/R13*$T$12+$T$12,4) -> 5.3333 | U13: =T13*(1+$D$14)^5 -> 5.4679725 | V13: =T13*(1+$D$14)^10 -> 5.6060457
C14: Ann Price change | D14: 0.005 | R14: =R13+($E$7-$D$7)/($D$9-1) -> 2.8888889 | S14: =S13+$D$8 -> 1.4 | T14: =ROUND((S14-$S$12)/$S$12/R14*$T$12+$T$12,4) -> 5.6923 | U14: =T14*(1+$D$14)^5 -> 5.8360377 | V14: =T14*(1+$D$14)^10 -> 5.983405
R15: =R14+($E$7-$D$7)/($D$9-1) -> 2.7777778 | S15: =S14+$D$8 -> 1.6 | T15: =ROUND((S15-$S$12)/$S$12/R15*$T$12+$T$12,4) -> 6.08 | U15: =T15*(1+$D$14)^5 -> 6.2335276 | V15: =T15*(1+$D$14)^10 -> 6.390932
R16: =R15+($E$7-$D$7)/($D$9-1) -> 2.6666667 | S16: =S15+$D$8 -> 1.8 | T16: =ROUND((S16-$S$12)/$S$12/R16*$T$12+$T$12,4) -> 6.5 | U16: =T16*(1+$D$14)^5 -> 6.6641331 | V16: =T16*(1+$D$14)^10 -> 6.8324109
R17: =R16+($E$7-$D$7)/($D$9-1) -> 2.5555556 | S17: =S16+$D$8 -> 2 | T17: =ROUND((S17-$S$12)/$S$12/R17*$T$12+$T$12,4) -> 6.9565 | U17: =T17*(1+$D$14)^5 -> 7.1321603 | V17: =T17*(1+$D$14)^10 -> 7.3122563
R18: =R17+($E$7-$D$7)/($D$9-1) -> 2.4444444 | S18: =S17+$D$8 -> 2.2 | T18: =ROUND((S18-$S$12)/$S$12/R18*$T$12+$T$12,4) -> 7.4545 | U18: =T18*(1+$D$14)^5 -> 7.6427355 | V18: =T18*(1+$D$14)^10 -> 7.8357241
R19: =R18+($E$7-$D$7)/($D$9-1) -> 2.3333333 | S19: =S18+$D$8 -> 2.4 | T19: =ROUND((S19-$S$12)/$S$12/R19*$T$12+$T$12,4) -> 8 | U19: =T19*(1+$D$14)^5 -> 8.20201 | V19: =T19*(1+$D$14)^10 -> 8.4091211
R20: =R19+($E$7-$D$7)/($D$9-1) -> 2.2222222 | S20: =S19+$D$8 -> 2.6 | T20: =ROUND((S20-$S$12)/$S$12/R20*$T$12+$T$12,4) -> 8.6 | U20: =T20*(1+$D$14)^5 -> 8.8171608 | V20: =T20*(1+$D$14)^10 -> 9.0398051
R21: =R20+($E$7-$D$7)/($D$9-1) -> 2.1111111 | S21: =S20+$D$8 -> 2.8 | T21: =ROUND((S21-$S$12)/$S$12/R21*$T$12+$T$12,4) -> 9.2632 | U21: =T21*(1+$D$14)^5 -> 9.4971074 | V21: =T21*(1+$D$14)^10 -> 9.7369213
R22: =R21+($E$7-$D$7)/($D$9-1) -> 2 | S22: =S21+$D$8 -> 3 | T22: =ROUND((S22-$S$12)/$S$12/R22*$T$12+$T$12,4) -> 10 | U22: =T22*(1+$D$14)^5 -> 10.252513 | V22: =T22*(1+$D$14)^10 -> 10.511401
E27: COST | J27: ~FI_Process | U27: ~FI_T: ACT_COST~UP~USD10
D28: ACT_BND | E28: =T1 -> 2010 | F28: =U1 -> 2020 | G28: =V1 -> 2030 | J28: Sets | K28: TechName | L28: TechDesc | M28: Tact | N28: Tcap | O28: Tslvl | P28: PrimaryCG | Q28: Vintage | S28: TechName | T28: Comm-IN | U28: Comm-OUT | V28: ACT_BND | W28: =E28 -> 2010 | X28: =V28&"~2050" -> ACT_BND~2050
A29: 01 | C29: =$C$2&"-"&A29 -> MinBio-01 | D29: =S2 -> 0.5 | E29: =T2 -> 4.1667 | F29: =U2 -> 4.2719144 | G29: =V2 -> 4.3797856 | J29: MIN | K29: =C29 -> MinBio-01 | L29: =$A$2&" Step - "&A29 -> Biomass Step - 01 | M29: PJ | N29: PJ-Yr | S29: =K29 -> MinBio-01 | U29: =$A$1 -> BIOCRP | V29: =D29 -> 0.5 | W29: =E29 -> 4.1667 | X29: =V29 -> 0.5
A30: 02 | C30: =$C$2&"-"&A30 -> MinBio-02 | D30: =S3-S2 -> 0.05 | E30: =T3 -> 4.25 | F30: =U3 -> 4.3573178 | G30: =V3 -> 4.4673456 | K30: =C30 -> MinBio-02 | L30: =$A$2&" Step - "&A30 -> Biomass Step - 02 | M30: PJ | N30: PJ-Yr | S30: =K30 -> MinBio-02 | U30: =$A$1 -> BIOCRP | V30: =D30 -> 0.05 | W30: =E30 -> 4.25 | X30: =V30 -> 0.05
A31: 03 | C31: =$C$2&"-"&A31 -> MinBio-03 | D31: =S4-S3 -> 0.05 | E31: =T4 -> 4.3333 | F31: =U4 -> 4.4427213 | G31: =V4 -> 4.5549055 | K31: =C31 -> MinBio-03 | L31: =$A$2&" Step - "&A31 -> Biomass Step - 03 | M31: PJ | N31: PJ-Yr | S31: =K31 -> MinBio-03 | U31: =$A$1 -> BIOCRP | V31: =D31 -> 0.05 | W31: =E31 -> 4.3333 | X31: =V31 -> 0.05
A32: 04 | C32: =$C$2&"-"&A32 -> MinBio-04 | D32: =S5-S4 -> 0.05 | E32: =T5 -> 4.4167 | F32: =U5 -> 4.5282272 | G32: =V5 -> 4.6425706 | K32: =C32 -> MinBio-04 | L32: =$A$2&" Step - "&A32 -> Biomass Step - 04 | M32: PJ | N32: PJ-Yr | S32: =K32 -> MinBio-04 | U32: =$A$1 -> BIOCRP | V32: =D32 -> 0.05 | W32: =E32 -> 4.4167 | X32: =V32 -> 0.05
A33: 05 | C33: =$C$2&"-"&A33 -> MinBio-05 | D33: =S6-S5 -> 0.05 | E33: =T6 -> 4.5 | F33: =U6 -> 4.6136306 | G33: =V6 -> 4.7301306 | K33: =C33 -> MinBio-05 | L33: =$A$2&" Step - "&A33 -> Biomass Step - 05 | M33: PJ | N33: PJ-Yr | S33: =K33 -> MinBio-05 | U33: =$A$1 -> BIOCRP | V33: =D33 -> 0.05 | W33: =E33 -> 4.5 | X33: =V33 -> 0.05
A34: 06 | C34: =$C$2&"-"&A34 -> MinBio-06 | D34: =S7-S6 -> 0.05 | E34: =T7 -> 4.5833 | F34: =U7 -> 4.6990341 | G34: =V7 -> 4.8176906 | K34: =C34 -> MinBio-06 | L34: =$A$2&" Step - "&A34 -> Biomass Step - 06 | M34: PJ | N34: PJ-Yr | S34: =K34 -> MinBio-06 | U34: =$A$1 -> BIOCRP | V34: =D34 -> 0.05 | W34: =E34 -> 4.5833 | X34: =V34 -> 0.05
A35: 07 | C35: =$C$2&"-"&A35 -> MinBio-07 | D35: =S8-S7 -> 0.05 | E35: =T8 -> 4.6667 | F35: =U8 -> 4.78454 | G35: =V8 -> 4.9053557 | K35: =C35 -> MinBio-07 | L35: =$A$2&" Step - "&A35 -> Biomass Step - 07 | M35: PJ | N35: PJ-Yr | S35: =K35 -> MinBio-07 | U35: =$A$1 -> BIOCRP | V35: =D35 -> 0.05 | W35: =E35 -> 4.6667 | X35: =V35 -> 0.05
A36: 08 | C36: =$C$2&"-"&A36 -> MinBio-08 | D36: =S9-S8 -> 0.05 | E36: =T9 -> 4.75 | F36: =U9 -> 4.8699435 | G36: =V9 -> 4.9929156 | K36: =C36 -> MinBio-08 | L36: =$A$2&" Step - "&A36 -> Biomass Step - 08 | M36: PJ | N36: PJ-Yr | S36: =K36 -> MinBio-08 | U36: =$A$1 -> BIOCRP | V36: =D36 -> 0.05 | W36: =E36 -> 4.75 | X36: =V36 -> 0.05
A37: 09 | C37: =$C$2&"-"&A37 -> MinBio-09 | D37: =S10-S9 -> 0.05 | E37: =T10 -> 4.8333 | F37: =U10 -> 4.9553469 | G37: =V10 -> 5.0804756 | K37: =C37 -> MinBio-09 | L37: =$A$2&" Step - "&A37 -> Biomass Step - 09 | M37: PJ | N37: PJ-Yr | S37: =K37 -> MinBio-09 | U37: =$A$1 -> BIOCRP | V37: =D37 -> 0.05 | W37: =E37 -> 4.8333 | X37: =V37 -> 0.05
A38: 10 | C38: =$C$2&"-"&A38 -> MinBio-10 | D38: =S11-S10 -> 0.05 | E38: =T11 -> 4.9167 | F38: =U11 -> 5.0408528 | G38: =V11 -> 5.1681407 | K38: =C38 -> MinBio-10 | L38: =$A$2&" Step - "&A38 -> Biomass Step - 10 | M38: PJ | N38: PJ-Yr | S38: =K38 -> MinBio-10 | U38: =$A$1 -> BIOCRP | V38: =D38 -> 0.05 | W38: =E38 -> 4.9167 | X38: =V38 -> 0.05
A39: 11 | C39: =$C$2&"-"&A39 -> MinBio-11 | D39: =S12-S11 -> 0.05 | E39: =T12 -> 5 | F39: =U12 -> 5.1262563 | G39: =V12 -> 5.2557007 | K39: =C39 -> MinBio-11 | L39: =$A$2&" Step - "&A39 -> Biomass Step - 11 | M39: PJ | N39: PJ-Yr | S39: =K39 -> MinBio-11 | U39: =$A$1 -> BIOCRP | V39: =D39 -> 0.05 | W39: =E39 -> 5 | X39: =V39 -> 0.05
A40: 12 | C40: =$C$2&"-"&A40 -> MinBio-12 | D40: =S13-S12 -> 0.2 | E40: =T13 -> 5.3333 | F40: =U13 -> 5.4679725 | G40: =V13 -> 5.6060457 | K40: =C40 -> MinBio-12 | L40: =$A$2&" Step - "&A40 -> Biomass Step - 12 | M40: PJ | N40: PJ-Yr | S40: =K40 -> MinBio-12 | U40: =$A$1 -> BIOCRP | V40: =D40 -> 0.2 | W40: =E40 -> 5.3333 | X40: =V40 -> 0.2
A41: 13 | C41: =$C$2&"-"&A41 -> MinBio-13 | D41: =S14-S13 -> 0.2 | E41: =T14 -> 5.6923 | F41: =U14 -> 5.8360377 | G41: =V14 -> 5.983405 | K41: =C41 -> MinBio-13 | L41: =$A$2&" Step - "&A41 -> Biomass Step - 13 | M41: PJ | N41: PJ-Yr | S41: =K41 -> MinBio-13 | U41: =$A$1 -> BIOCRP | V41: =D41 -> 0.2 | W41: =E41 -> 5.6923 | X41: =V41 -> 0.2
... A48: 20 | C48: =$C$2&"-"&A48 -> MinBio-20 | D48: =S21-S20 -> 0.2 | E48: =T21 -> 9.2632 | F48: =U21 -> 9.4971074 | G48: =V21 -> 9.7369213 | K48: =C48 -> MinBio-20 | L48: =$A$2&" Step - "&A48 -> Biomass Step - 20 | M48: PJ | N48: PJ-Yr | S48: =K48 -> MinBio-20 | U48: =$A$1 -> BIOCRP | V48: =D48 -> 0.2 | W48: =E48 -> 9.2632 | X48: =V48 -> 0.2
A49: 21 | C49: =$C$2&"-"&A49 -> MinBio-21 | D49: =S22-S21 -> 0.2 | E49: =T22 -> 10 | F49: =U22 -> 10.252513 | G49: =V22 -> 10.511401 | K49: =C49 -> MinBio-21 | L49: =$A$2&" Step - "&A49 -> Biomass Step - 21 | M49: PJ | N49: PJ-Yr | S49: =K49 -> MinBio-21 | U49: =$A$1 -> BIOCRP | V49: =D49 -> 0.2 | W49: =E49 -> 10

Sheet Oil-Min
A1: OILRPP | T1: ='Gas-Min'!$T$1 -> 2010 | U1: ='Gas-Min'!$U$1 -> 2020 | V1: ='Gas-Min'!$V$1 -> 2030
A2: Oil | C2: MinOIL | D2: Price | E2: Qty | R2: =R3+($E$10-$D$10)/($D$12-1) -> 0.5 | S2: =S3-$D$11 -> 0.5 | T2: =ROUND((S2-$S$12)/$S$12/R2*$T$12+$T$12,4) -> 0 | U2: =T2*(1+$D$14)^(U$1-$T$1) -> 0 | V2: =T2*(1+$D$14)^(V$1-$T$1) -> 0 | AC2: Real terms (2013 Price)
D3: 1 | E3: 1 | R3: =R4+($E$10-$D$10)/($D$12-1) -> 0.48888889 | S3: =S4-$D$11 -> 0.55 | T3: =ROUND((S3-$S$12)/$S$12/R3*$T$12+$T$12,4) -> 0.0795 | U3: =T3*(1+$D$14)^(U$1-$T$1) -> 0.091538373 | V3: =T3*(1+$D$14)^(V$1-$T$1) -> 0.10539967 | AB3: New Policies Scenario | AE3: Current Policies Scenario | AH3: 450 Scenario
R4: =R5+($E$10-$D$10)/($D$12-1) -> 0.47777778 | S4: =S5-$D$11 -> 0.6 | T4: =ROUND((S4-$S$12)/$S$12/R4*$T$12+$T$12,4) -> 0.1628 | U4: =T4*(1+$D$14)^(U$1-$T$1) -> 0.18745217 | V4: =T4*(1+$D$14)^(V$1-$T$1) -> 0.21583731 | AA4: 2013 | AB4: 2020 | AC4: 2030 | AD4: 2040 | AE4: 2020 | AF4: 2030 | AG4: 2040 | AH4: 2020 | AI4: 2030 | AJ4: 2040
R5: =R6+($E$10-$D$10)/($D$12-1) -> 0.46666667 | S5: =S6-$D$11 -> 0.65 | T5: =ROUND((S5-$S$12)/$S$12/R5*$T$12+$T$12,4) -> 0.25 | U5: =T5*(1+$D$14)^(U$1-$T$1) -> 0.28785652 | V5: =T5*(1+$D$14)^(V$1-$T$1) -> 0.3314455 | Y5: IEA crude oil imports | Z5: ($/barrel) | AA5: 106 | AB5: 112 | AC5: 123 | AD5: 132 | AE5: 116 | AF5: 139 | AG5: 155 | AH5: 105 | AI5: 102 | AJ5: 100 | AL5: =1/5.86152 -> 0.17060421
D6: Start | E6: End | R6: =R7+($E$10-$D$10)/($D$12-1) -> 0.45555556 | S6: =S7-$D$11 -> 0.7 | T6: =ROUND((S6-$S$12)/$S$12/R6*$T$12+$T$12,4) -> 0.3415 | U6: =T6*(1+$D$14)^(U$1-$T$1) -> 0.39321201 | V6: =T6*(1+$D$14)^(V$1-$T$1) -> 0.45275456 | Y6: Europe Natural Gas imports | Z6: ($/MBtu) | AA6: 10.6 | AB6: 11.1 | AC6: 12.1 | AD6: 12.7 | AE6: 11.5 | AF6: 13.2 | AG6: 14 | AH6: 10.5 | AI6: 10 | AJ6: 9.2 | AL6: =1/1.055055 -> 0.94781789
B7: UP | C7: Elasticity | D7: 20 | E7: 20 | R7: =R8+($E$10-$D$10)/($D$12-1) -> 0.44444444 | S7: =S8-$D$11 -> 0.75 | T7: =ROUND((S7-$S$12)/$S$12/R7*$T$12+$T$12,4) -> 0.4375 | U7: =T7*(1+$D$14)^(U$1-$T$1) -> 0.50374891 | V7: =T7*(1+$D$14)^(V$1-$T$1) -> 0.58002963 | Y7: OECD steam coal imports | Z7: ($/tonne) | AA7: 86 | AB7: 101 | AC7: 108 | AD7: 112 | AE7: 107 | AF7: 117 | AG7: 124 | AH7: 88 | AI7: 78 | AJ7: 77 | AL7: =1/29.288 -> 0.034143677
C8: StepHeight | D8: =E3 -> 1 | R8: =R9+($E$10-$D$10)/($D$12-1) -> 0.43333333 | S8: =S9-$D$11 -> 0.8 | T8: =ROUND((S8-$S$12)/$S$12/R8*$T$12+$T$12,4) -> 0.5385 | U8: =T8*(1+$D$14)^(U$1-$T$1) -> 0.62004294 | V8: =T8*(1+$D$14)^(V$1-$T$1) -> 0.71393362
C9: StepNum | D9: 10 | R9: =R10+($E$10-$D$10)/($D$12-1) -> 0.42222222 | S9: =S10-$D$11 -> 0.85 | T9: =ROUND((S9-$S$12)/$S$12/R9*$T$12+$T$12,4) -> 0.6447 | U9: =T9*(1+$D$14)^(U$1-$T$1) -> 0.74232439 | V9: =T9*(1+$D$14)^(V$1-$T$1) -> 0.85473167 | Y9: Curr | Z9: 0.75
B10: LO | C10: Elasticity | D10: 0.4 | E10: 0.5 | R10: =R11+($E$10-$D$10)/($D$12-1) -> 0.41111111 | S10: =S11-$D$11 -> 0.9 | T10: =ROUND((S10-$S$12)/$S$12/R10*$T$12+$T$12,4) -> 0.7568 | U10: =T10*(1+$D$14)^(U$1-$T$1) -> 0.87139926 | V10: =T10*(1+$D$14)^(V$1-$T$1) -> 1.0033518 | AA10: =AA4 -> 2013 | AB10: =AE4 -> 2020 | AC10: =AF4 -> 2030 | AD10: =AG4 -> 2040 | AE10: AnnGrwRate
C11: StepHeight | D11: 0.05 | R11: =D10 -> 0.4 | S11: =S12-$D$11 -> 0.95 | T11: =ROUND((S11-$S$12)/$S$12/R11*$T$12+$T$12,4) -> 0.875 | U11: =T11*(1+$D$14)^(U$1-$T$1) -> 1.0074978 | V11: =T11*(1+$D$14)^(V$1-$T$1) -> 1.1600593 | Z11: Oil | AA11: =AA5*$AL5*$Z$9 -> 13.563035 | AB11: =AE5*$AL5*$Z$9 -> 14.842566 | AC11: =AF5*$AL5*$Z$9 -> 17.785489 | AD11: =AG5*$AL5*$Z$9 -> 19.83274 | AE11: 1.42 | AF11: =AA11*(1+AE11/100)^(2040-2013) -> 19.846971
C12: StepNum | D12: 10 | S12: =E3 -> 1 | T12: =D3 -> 1 | U12: =T12*(1+$D$14)^(U$1-$T$1) -> 1.1514261 | V12: =T12*(1+$D$14)^(V$1-$T$1) -> 1.325782 | Z12: Gas | AA12: =AA6*$AL6*$Z$9 -> 7.5351522 | AB12: =AE6*$AL6*$Z$9 -> 8.1749293 | AC12: =AF6*$AL6*$Z$9 -> 9.3833971 | AD12: =AG6*$AL6*$Z$9 -> 9.9520878 | AE12: 1.03 | AF12: =AA12*(1+AE12/100)^(2040-2013) -> 9.9369146
R13: =D7 -> 20 | S13: =S12+$D$8 -> 2 | T13: =ROUND((S13-$S$12)/$S$12/R13*$T$12+$T$12,4) -> 1.05 | U13: =T13*(1+$D$14)^(U$1-$T$1) -> 1.2089974 | V13: =T13*(1+$D$14)^(V$1-$T$1) -> 1.3920711 | Z13: Coal | AA13: =AA7*$AL7*$Z$9 -> 2.2022671 | AB13: =AE7*$AL7*$Z$9 -> 2.74003 | AC13: =AF7*$AL7*$Z$9 -> 2.9961076 | AD13: =AG7*$AL7*$Z$9 -> 3.1753619 | AE13: 1.38 | AF13: =AA13*(1+AE13/100)^(2040-2013) -> 3.1884657
C14: Ann Price change | D14: =AE11/100 -> 0.0142 | R14: =R13+($E$7-$D$7)/($D$9-1) -> 20 | S14: =S13+$D$8 -> 3 | T14: =ROUND((S14-$S$12)/$S$12/R14*$T$12+$T$12,4) -> 1.1 | U14: =T14*(1+$D$14)^(U$1-$T$1) -> 1.2665687 | V14: =T14*(1+$D$14)^(V$1-$T$1) -> 1.4583602
R15: =R14+($E$7-$D$7)/($D$9-1) -> 20 | S15: =S14+$D$8 -> 4 | T15: =ROUND((S15-$S$12)/$S$12/R15*$T$12+$T$12,4) -> 1.15 | U15: =T15*(1+$D$14)^(U$1-$T$1) -> 1.32414 | V15: =T15*(1+$D$14)^(V$1-$T$1) -> 1.5246493
R16: =R15+($E$7-$D$7)/($D$9-1) -> 20 | S16: =S15+$D$8 -> 5 | T16: =ROUND((S16-$S$12)/$S$12/R16*$T$12+$T$12,4) -> 1.2 | U16: =T16*(1+$D$14)^(U$1-$T$1) -> 1.3817113 | V16: =T16*(1+$D$14)^(V$1-$T$1) -> 1.5909384
R17: =R16+($E$7-$D$7)/($D$9-1) -> 20 | S17: =S16+$D$8 -> 6 | T17: =ROUND((S17-$S$12)/$S$12/R17*$T$12+$T$12,4) -> 1.25 | U17: =T17*(1+$D$14)^(U$1-$T$1) -> 1.4392826 | V17: =T17*(1+$D$14)^(V$1-$T$1) -> 1.6572275
R18: =R17+($E$7-$D$7)/($D$9-1) -> 20 | S18: =S17+$D$8 -> 7 | T18: =ROUND((S18-$S$12)/$S$12/R18*$T$12+$T$12,4) -> 1.3 | U18: =T18*(1+$D$14)^(U$1-$T$1) -> 1.4968539 | V18: =T18*(1+$D$14)^(V$1-$T$1) -> 1.7235166
R19: =R18+($E$7-$D$7)/($D$9-1) -> 20 | S19: =S18+$D$8 -> 8 | T19: =ROUND((S19-$S$12)/$S$12/R19*$T$12+$T$12,4) -> 1.35 | U19: =T19*(1+$D$14)^(U$1-$T$1) -> 1.5544252 | V19: =T19*(1+$D$14)^(V$1-$T$1) -> 1.7898057
R20: =R19+($E$7-$D$7)/($D$9-1) -> 20 | S20: =S19+$D$8 -> 9 | T20: =ROUND((S20-$S$12)/$S$12/R20*$T$12+$T$12,4) -> 1.4 | U20: =T20*(1+$D$14)^(U$1-$T$1) -> 1.6119965 | V20: =T20*(1+$D$14)^(V$1-$T$1) -> 1.8560948
R21: =R20+($E$7-$D$7)/($D$9-1) -> 20 | S21: =S20+$D$8 -> 10 | T21: =ROUND((S21-$S$12)/$S$12/R21*$T$12+$T$12,4) -> 1.45 | U21: =T21*(1+$D$14)^(U$1-$T$1) -> 1.6695678 | V21: =T21*(1+$D$14)^(V$1-$T$1) -> 1.9223839
R22: =R21+($E$7-$D$7)/($D$9-1) -> 20 | S22: =S21+$D$8 -> 11 | T22: =ROUND((S22-$S$12)/$S$12/R22*$T$12+$T$12,4) -> 1.5 | U22: =T22*(1+$D$14)^(U$1-$T$1) -> 1.7271391 | V22: =T22*(1+$D$14)^(V$1-$T$1) -> 1.988673
E27: COST | J27: ~FI_Process | U27: ~FI_T: ACT_COST~UP~USD10
D28: ACT_BND | E28: =T1 -> 2010 | F28: =U1 -> 2020 | G28: =V1 -> 2030 | J28: Sets | K28: TechName | L28: TechDesc | M28: Tact | N28: Tcap | O28: Tslvl | P28: PrimaryCG | Q28: Vintage | S28: TechName | T28: Comm-IN | U28: Comm-OUT | V28: ACT_BND | W28: =E28 -> 2010 | X28: =V28&"~2050" -> ACT_BND~2050
A29: 01 | C29: =$C$2&"-"&A29 -> MinOIL-01 | D29: =S2 -> 0.5 | E29: =T2 -> 0 | F29: =U2 -> 0 | G29: =V2 -> 0 | J29: MIN | K29: =C29 -> MinOIL-01 | L29: =$A$2&" Step - "&A29 -> Oil Step - 01 | M29: PJ | N29: PJ-Yr | S29: =K29 -> MinOIL-01 | U29: =$A$1 -> OILRPP | V29: =D29 -> 0.5 | W29: =E29 -> 0 | X29: =V29 -> 0.5
A30: 02 | C30: =$C$2&"-"&A30 -> MinOIL-02 | D30: =S3-S2 -> 0.05 | E30: =T3 -> 0.0795 | F30: =U3 -> 0.091538373 | G30: =V3 -> 0.10539967 | K30: =C30 -> MinOIL-02 | L30: =$A$2&" Step - "&A30 -> Oil Step - 02 | M30: PJ | N30: PJ-Yr | S30: =K30 -> MinOIL-02 | U30: =$A$1 -> OILRPP | V30: =D30 -> 0.05 | W30: =E30 -> 0.0795 | X30: =V30 -> 0.05
A31: 03 | C31: =$C$2&"-"&A31 -> MinOIL-03 | D31: =S4-S3 -> 0.05 | E31: =T4 -> 0.1628 | F31: =U4 -> 0.18745217 | G31: =V4 -> 0.21583731 | K31: =C31 -> MinOIL-03 | L31: =$A$2&" Step - "&A31 -> Oil Step - 03 | M31: PJ | N31: PJ-Yr | S31: =K31 -> MinOIL-03 | U31: =$A$1 -> OILRPP | V31: =D31 -> 0.05 | W31: =E31 -> 0.1628 | X31: =V31 -> 0.05
A32: 04 | C32: =$C$2&"-"&A32 -> MinOIL-04 | D32: =S5-S4 -> 0.05 | E32: =T5 -> 0.25 | F32: =U5 -> 0.28785652 | G32: =V5 -> 0.3314455 | K32: =C32 -> MinOIL-04 | L32: =$A$2&" Step - "&A32 -> Oil Step - 04 | M32: PJ | N32: PJ-Yr | S32: =K32 -> MinOIL-04 | U32: =$A$1 -> OILRPP | V32: =D32 -> 0.05 | W32: =E32 -> 0.25 | X32: =V32 -> 0.05
A33: 05 | C33: =$C$2&"-"&A33 -> MinOIL-05 | D33: =S6-S5 -> 0.05 | E33: =T6 -> 0.3415 | F33: =U6 -> 0.39321201 | G33: =V6 -> 0.45275456 | K33: =C33 -> MinOIL-05 | L33: =$A$2&" Step - "&A33 -> Oil Step - 05 | M33: PJ | N33: PJ-Yr | S33: =K33 -> MinOIL-05 | U33: =$A$1 -> OILRPP | V33: =D33 -> 0.05 | W33: =E33 -> 0.3415 | X33: =V33 -> 0.05
A34: 06 | C34: =$C$2&"-"&A34 -> MinOIL-06 | D34: =S7-S6 -> 0.05 | E34: =T7 -> 0.4375 | F34: =U7 -> 0.50374891 | G34: =V7 -> 0.58002963 | K34: =C34 -> MinOIL-06 | L34: =$A$2&" Step - "&A34 -> Oil Step - 06 | M34: PJ | N34: PJ-Yr | S34: =K34 -> MinOIL-06 | U34: =$A$1 -> OILRPP | V34: =D34 -> 0.05 | W34: =E34 -> 0.4375 | X34: =V34 -> 0.05
A35: 07 | C35: =$C$2&"-"&A35 -> MinOIL-07 | D35: =S8-S7 -> 0.05 | E35: =T8 -> 0.5385 | F35: =U8 -> 0.62004294 | G35: =V8 -> 0.71393362 | K35: =C35 -> MinOIL-07 | L35: =$A$2&" Step - "&A35 -> Oil Step - 07 | M35: PJ | N35: PJ-Yr | S35: =K35 -> MinOIL-07 | U35: =$A$1 -> OILRPP | V35: =D35 -> 0.05 | W35: =E35 -> 0.5385 | X35: =V35 -> 0.05
A36: 08 | C36: =$C$2&"-"&A36 -> MinOIL-08 | D36: =S9-S8 -> 0.05 | E36: =T9 -> 0.6447 | F36: =U9 -> 0.74232439 | G36: =V9 -> 0.85473167 | K36: =C36 -> MinOIL-08 | L36: =$A$2&" Step - "&A36 -> Oil Step - 08 | M36: PJ | N36: PJ-Yr | S36: =K36 -> MinOIL-08 | U36: =$A$1 -> OILRPP | V36: =D36 -> 0.05 | W36: =E36 -> 0.6447 | X36: =V36 -> 0.05
A37: 09 | C37: =$C$2&"-"&A37 -> MinOIL-09 | D37: =S10-S9 -> 0.05 | E37: =T10 -> 0.7568 | F37: =U10 -> 0.87139926 | G37: =V10 -> 1.0033518 | K37: =C37 -> MinOIL-09 | L37: =$A$2&" Step - "&A37 -> Oil Step - 09 | M37: PJ | N37: PJ-Yr | S37: =K37 -> MinOIL-09 | U37: =$A$1 -> OILRPP | V37: =D37 -> 0.05 | W37: =E37 -> 0.7568 | X37: =V37 -> 0.05
A38: 10 | C38: =$C$2&"-"&A38 -> MinOIL-10 | D38: =S11-S10 -> 0.05 | E38: =T11 -> 0.875 | F38: =U11 -> 1.0074978 | G38: =V11 -> 1.1600593 | K38: =C38 -> MinOIL-10 | L38: =$A$2&" Step - "&A38 -> Oil Step - 10 | M38: PJ | N38: PJ-Yr | S38: =K38 -> MinOIL-10 | U38: =$A$1 -> OILRPP | V38: =D38 -> 0.05 | W38: =E38 -> 0.875 | X38: =V38 -> 0.05
A39: 11 | C39: =$C$2&"-"&A39 -> MinOIL-11 | D39: =S12-S11 -> 0.05 | E39: =T12 -> 1 | F39: =U12 -> 1.1514261 | G39: =V12 -> 1.325782 | K39: =C39 -> MinOIL-11 | L39: =$A$2&" Step - "&A39 -> Oil Step - 11 | M39: PJ | N39: PJ-Yr | S39: =K39 -> MinOIL-11 | U39: =$A$1 -> OILRPP | V39: =D39 -> 0.05 | W39: =E39 -> 1 | X39: =V39 -> 0.05
A40: 12 | C40: =$C$2&"-"&A40 -> MinOIL-12 | D40: =S13-S12 -> 1 | E40: =T13 -> 1.05 | F40: =U13 -> 1.2089974 | G40: =V13 -> 1.3920711 | K40: =C40 -> MinOIL-12 | L40: =$A$2&" Step - "&A40 -> Oil Step - 12 | M40: PJ | N40: PJ-Yr | S40: =K40 -> MinOIL-12 | U40: =$A$1 -> OILRPP | V40: =D40 -> 1 | W40: =E40 -> 1.05 | X40: =V40 -> 1
A41: 13 | C41: =$C$2&"-"&A41 -> MinOIL-13 | D41: =S14-S13 -> 1 | E41: =T14 -> 1.1 | F41: =U14 -> 1.2665687 | G41: =V14 -> 1.4583602 | K41: =C41 -> MinOIL-13 | L41: =$A$2&" Step - "&A41 -> Oil Step - 13 | M41: PJ | N41: PJ-Yr | S41: =K41 -> MinOIL-13 | U41: =$A$1 -> OILRPP | V41: =D41 -> 1 | W41: =E41 -> 1.1 | X41: =V41 -> 1
... A48: 20 | C48: =$C$2&"-"&A48 -> MinOIL-20 | D48: =S21-S20 -> 1 | E48: =T21 -> 1.45 | F48: =U21 -> 1.6695678 | G48: =V21 -> 1.9223839 | K48: =C48 -> MinOIL-20 | L48: =$A$2&" Step - "&A48 -> Oil Step - 20 | M48: PJ | N48: PJ-Yr | S48: =K48 -> MinOIL-20 | U48: =$A$1 -> OILRPP | V48: =D48 -> 1 | W48: =E48 -> 1.45 | X48: =V48 -> 1
A49: 21 | C49: =$C$2&"-"&A49 -> MinOIL-21 | D49: =S22-S21 -> 1 | E49: =T22 -> 1.5 | F49: =U22 -> 1.7271391 | G49: =V22 -> 1.988673 | K49: =C49 -> MinOIL-21 | L49: =$A$2&" Step - "&A49 -> Oil Step - 21 | M49: PJ | N49: PJ-Yr | S49: =K49 -> MinOIL-21 | U49: =$A$1 -> OILRPP | V49: =D49 -> 1 | W49: =E49 -> 1.5

Sheet ELC-Ren
A1: ELCREN | T1: ='Gas-Min'!$T$1 -> 2010 | U1: ='Gas-Min'!$U$1 -> 2020 | V1: ='Gas-Min'!$V$1 -> 2030
A2: Renewable Electricity | C2: RNWElec | D2: Price | E2: Qty | R2: =R3+($E$10-$D$10)/($D$12-1) -> 4 | S2: =S3-$D$11 -> 0.5 | T2: =ROUND((S2-$S$12)/$S$12/R2*$T$12+$T$12,2) -> 0.01 | U2: =T2*(1+$D$14)^5 -> 0.010510101 | V2: =T2*(1+$D$14)^10 -> 0.011046221
D3: 0.01 | E3: 1 | R3: =R4+($E$10-$D$10)/($D$12-1) -> 4.1111111 | S3: =S4-$D$11 -> 0.55 | T3: =ROUND((S3-$S$12)/$S$12/R3*$T$12+$T$12,2) -> 0.01 | U3: =T3*(1+$D$14)^5 -> 0.010510101 | V3: =T3*(1+$D$14)^10 -> 0.011046221
R4: =R5+($E$10-$D$10)/($D$12-1) -> 4.2222222 | S4: =S5-$D$11 -> 0.6 | T4: =ROUND((S4-$S$12)/$S$12/R4*$T$12+$T$12,2) -> 0.01 | U4: =T4*(1+$D$14)^5 -> 0.010510101 | V4: =T4*(1+$D$14)^10 -> 0.011046221
R5: =R6+($E$10-$D$10)/($D$12-1) -> 4.3333333 | S5: =S6-$D$11 -> 0.65 | T5: =ROUND((S5-$S$12)/$S$12/R5*$T$12+$T$12,2) -> 0.01 | U5: =T5*(1+$D$14)^5 -> 0.010510101 | V5: =T5*(1+$D$14)^10 -> 0.011046221
D6: Start | E6: End | R6: =R7+($E$10-$D$10)/($D$12-1) -> 4.4444444 | S6: =S7-$D$11 -> 0.7 | T6: =ROUND((S6-$S$12)/$S$12/R6*$T$12+$T$12,2) -> 0.01 | U6: =T6*(1+$D$14)^5 -> 0.010510101 | V6: =T6*(1+$D$14)^10 -> 0.011046221
B7: UP | C7: Elasticity | D7: 5 | E7: 5 | R7: =R8+($E$10-$D$10)/($D$12-1) -> 4.5555556 | S7: =S8-$D$11 -> 0.75 | T7: =ROUND((S7-$S$12)/$S$12/R7*$T$12+$T$12,2) -> 0.01 | U7: =T7*(1+$D$14)^5 -> 0.010510101 | V7: =T7*(1+$D$14)^10 -> 0.011046221
C8: StepHeight | D8: =0.1*E3 -> 0.1 | R8: =R9+($E$10-$D$10)/($D$12-1) -> 4.6666667 | S8: =S9-$D$11 -> 0.8 | T8: =ROUND((S8-$S$12)/$S$12/R8*$T$12+$T$12,2) -> 0.01 | U8: =T8*(1+$D$14)^5 -> 0.010510101 | V8: =T8*(1+$D$14)^10 -> 0.011046221
C9: StepNum | D9: 10 | R9: =R10+($E$10-$D$10)/($D$12-1) -> 4.7777778 | S9: =S10-$D$11 -> 0.85 | T9: =ROUND((S9-$S$12)/$S$12/R9*$T$12+$T$12,2) -> 0.01 | U9: =T9*(1+$D$14)^5 -> 0.010510101 | V9: =T9*(1+$D$14)^10 -> 0.011046221
B10: LO | C10: Elasticity | D10: =D7 -> 5 | E10: 4 | R10: =R11+($E$10-$D$10)/($D$12-1) -> 4.8888889 | S10: =S11-$D$11 -> 0.9 | T10: =ROUND((S10-$S$12)/$S$12/R10*$T$12+$T$12,2) -> 0.01 | U10: =T10*(1+$D$14)^5 -> 0.010510101 | V10: =T10*(1+$D$14)^10 -> 0.011046221
C11: StepHeight | D11: =0.05*E3 -> 0.05 | R11: =D10 -> 5 | S11: =S12-$D$11 -> 0.95 | T11: =ROUND((S11-$S$12)/$S$12/R11*$T$12+$T$12,2) -> 0.01 | U11: =T11*(1+$D$14)^5 -> 0.010510101 | V11: =T11*(1+$D$14)^10 -> 0.011046221
C12: StepNum | D12: 10 | S12: =E3 -> 1 | T12: =D3 -> 0.01 | U12: =T12*(1+$D$14)^5 -> 0.010510101 | V12: =T12*(1+$D$14)^10 -> 0.011046221
R13: =D7 -> 5 | S13: =S12+$D$8 -> 1.1 | T13: =ROUND((S13-$S$12)/$S$12/R13*$T$12+$T$12,2) -> 0.01 | U13: =T13*(1+$D$14)^5 -> 0.010510101 | V13: =T13*(1+$D$14)^10 -> 0.011046221
C14: Ann Price change | D14: 0.01 | R14: =R13+($E$7-$D$7)/($D$9-1) -> 5 | S14: =S13+$D$8 -> 1.2 | T14: =ROUND((S14-$S$12)/$S$12/R14*$T$12+$T$12,2) -> 0.01 | U14: =T14*(1+$D$14)^5 -> 0.010510101 | V14: =T14*(1+$D$14)^10 -> 0.011046221
R15: =R14+($E$7-$D$7)/($D$9-1) -> 5 | S15: =S14+$D$8 -> 1.3 | T15: =ROUND((S15-$S$12)/$S$12/R15*$T$12+$T$12,2) -> 0.01 | U15: =T15*(1+$D$14)^5 -> 0.010510101 | V15: =T15*(1+$D$14)^10 -> 0.011046221
R16: =R15+($E$7-$D$7)/($D$9-1) -> 5 | S16: =S15+$D$8 -> 1.4 | T16: =ROUND((S16-$S$12)/$S$12/R16*$T$12+$T$12,2) -> 0.01 | U16: =T16*(1+$D$14)^5 -> 0.010510101 | V16: =T16*(1+$D$14)^10 -> 0.011046221
R17: =R16+($E$7-$D$7)/($D$9-1) -> 5 | S17: =S16+$D$8 -> 1.5 | T17: =ROUND((S17-$S$12)/$S$12/R17*$T$12+$T$12,2) -> 0.01 | U17: =T17*(1+$D$14)^5 -> 0.010510101 | V17: =T17*(1+$D$14)^10 -> 0.011046221
R18: =R17+($E$7-$D$7)/($D$9-1) -> 5 | S18: =S17+$D$8 -> 1.6 | T18: =ROUND((S18-$S$12)/$S$12/R18*$T$12+$T$12,2) -> 0.01 | U18: =T18*(1+$D$14)^5 -> 0.010510101 | V18: =T18*(1+$D$14)^10 -> 0.011046221
R19: =R18+($E$7-$D$7)/($D$9-1) -> 5 | S19: =S18+$D$8 -> 1.7 | T19: =ROUND((S19-$S$12)/$S$12/R19*$T$12+$T$12,2) -> 0.01 | U19: =T19*(1+$D$14)^5 -> 0.010510101 | V19: =T19*(1+$D$14)^10 -> 0.011046221
R20: =R19+($E$7-$D$7)/($D$9-1) -> 5 | S20: =S19+$D$8 -> 1.8 | T20: =ROUND((S20-$S$12)/$S$12/R20*$T$12+$T$12,2) -> 0.01 | U20: =T20*(1+$D$14)^5 -> 0.010510101 | V20: =T20*(1+$D$14)^10 -> 0.011046221
R21: =R20+($E$7-$D$7)/($D$9-1) -> 5 | S21: =S20+$D$8 -> 1.9 | T21: =ROUND((S21-$S$12)/$S$12/R21*$T$12+$T$12,2) -> 0.01 | U21: =T21*(1+$D$14)^5 -> 0.010510101 | V21: =T21*(1+$D$14)^10 -> 0.011046221
R22: =R21+($E$7-$D$7)/($D$9-1) -> 5 | S22: =S21+$D$8 -> 2 | T22: =ROUND((S22-$S$12)/$S$12/R22*$T$12+$T$12,2) -> 0.01 | U22: =T22*(1+$D$14)^5 -> 0.010510101 | V22: =T22*(1+$D$14)^10 -> 0.011046221
E27: COST | J27: ~FI_Process | U27: ~FI_T: ACT_COST~UP~USD10
D28: ACT_BND | E28: =T1 -> 2010 | F28: =U1 -> 2020 | G28: =V1 -> 2030 | J28: Sets | K28: TechName | L28: TechDesc | M28: Tact | N28: Tcap | O28: Tslvl | P28: PrimaryCG | Q28: Vintage | S28: TechName | T28: Comm-IN | U28: Comm-OUT | V28: ACT_BND | W28: =E28 -> 2010 | X28: =V28&"~2050" -> ACT_BND~2050
A29: 01 | C29: =$C$2&"-"&A29 -> RNWElec-01 | D29: =S2 -> 0.5 | E29: =T2 -> 0.01 | F29: =U2 -> 0.010510101 | G29: =V2 -> 0.011046221 | J29: MIN | K29: =C29 -> RNWElec-01 | L29: =$A$2&" Step - "&A29 -> Renewable Electricity Step - 01 | M29: PJ | N29: PJ-Yr | S29: =K29 -> RNWElec-01 | U29: =$A$1 -> ELCREN | W29: =E29 -> 0.01
A32: 02 | C32: =$C$2&"-"&A32 -> RNWElec-02 | D32: =S3-S2 -> 0.05 | E32: =T3 -> 0.01 | F32: =U3 -> 0.010510101 | G32: =V3 -> 0.011046221 | K32: =C32 -> RNWElec-02 | L32: =$A$2&" Step - "&A32 -> Renewable Electricity Step - 02 | M32: PJ | N32: PJ-Yr | S32: =K32 -> RNWElec-02 | U32: =$A$1 -> ELCREN | V32: =D32 -> 0.05 | W32: =E32 -> 0.01 | X32: =V32 -> 0.05
