Workbook

Sheet Readme
A1: Workbook purpose:
A2: Creates the available new fossil power plants, CCS storage placeholder infrastructure and battery storage
A4: Data source:
A5: Battery storage from Chris, July 2019; base characteristics for new power plants originally from AEO, some modifications have taken place, and some capital cost are overwritten in Scen_BaseINVCost2050
A7: User-modifiable?
A8: Yes, but browse in VEDA-FE first to see where else values specified here are being modified.
A9: Capital costs get regional multipliers in the Trans file and many get time multipliers elsewhere

Sheet notes
A1: Date | B1: Comment
A2: 43598 | B2: Updated the EFF for new OIlAdvCC technolgies to 30% across years

Sheet ELC_Gen-sdj
D2: **FI_T: EFF**USD11**2010 | P2: **FI_Process
B3: TechName | C3: Comm-IN | D3: Comm-OUT | E3: 2010 | F3: 2050 | G3: INVCOST | H3: FIXOM | I3: VAROM | J3: AFA | K3: LIFE | L3: ELIFE | P3: Sets | Q3: TechName | R3: TechDesc | S3: Tslvl | T3: Tact | U3: Tcap | V3: PrimaryCG | W3: Vintage | AC3: Icost | AD3: Eff
B4: EN_COAPUL | C4: ELCCOA | D4: ELC | E4: 0.38772727 | F4: 0.39038902 | G4: 2882.6578 | H4: 30.636105 | I4: =N4/3.6*1.055 -> 1.2871267 | J4: 0.85 | K4: 40 | L4: 30 | N4: 4.3920913 | P4: ELE | Q4: =B4 -> EN_COAPUL | R4: New: Pulverized coal | S4: SEASON | T4: TBTU | U4: GW | W4: YES | Z4: 1 | AA4: E_SPV* | AB4: Solar PV - fixed tilt | AC4: =MATCH(AB4,ovrcst!$A$4:$W$4,0) -> 21 | AD4: =IFERROR(MATCH(AB4,heatrate!$K$4:$T$4,0),1) -> 1
B5: EN_COAIGCC | C5: ELCCOA | D5: ELC | E5: 0.39218391 | F5: 0.45798658 | G5: 3718.0479 | H5: 50.494167 | I5: =N5/3.6*1.055 -> 2.0792047 | J5: 0.85 | K5: 40 | L5: 30 | N5: 7.0949163 | Q5: =B5 -> EN_COAIGCC | R5: New: Coal IGCC | S5: SEASON | T5: TBTU | U5: GW | W5: YES | Z5: 2 | AA5: E_WON* | AB5: Wind | AC5: =MATCH(AB5,ovrcst!$A$4:$W$4,0) -> 17 | AD5: =IFERROR(MATCH(AB5,heatrate!$K$4:$T$4,0),1) -> 1
B6: EN_ZCOAIGCC | C6: ELCCOA | D6: ELC | H6: 65.308937 | I6: =N6/3.6*1.055 -> 1.2819968 | J6: 0.85 | K6: 40 | L6: 30 | N6: 4.3745861 | Q6: =B6 -> EN_ZCOAIGCC | R6: New: Coal IGCC - CCS | S6: SEASON | T6: TBTU | U6: GW | W6: YES | Z6: 3 | AA6: E_WOF* | AB6: Offshore Wind | AC6: =MATCH(AB6,ovrcst!$A$4:$W$4,0) -> 18 | AD6: =IFERROR(MATCH(AB6,heatrate!$K$4:$T$4,0),1) -> 1
B7: EN_ZGasCCAdv | C7: ELCGAS | D7: ELC | H7: 31.234789 | I7: =N7/3.6*1.055 -> 1.9524927 | J7: 0.87 | K7: 30 | L7: 30 | N7: 6.6625342 | Q7: =B7 -> EN_ZGasCCAdv | R7: New: Gas CC Adv - CCS | S7: DAYNITE | T7: TBTU | U7: GW | W7: YES | Z7: 4 | AA7: EN_COAPUL | AB7: Coal with 30% CCS | AC7: =MATCH(AB7,ovrcst!$A$4:$W$4,0) -> 2 | AD7: =IFERROR(MATCH(AB7,heatrate!$K$4:$T$4,0),1) -> 2
B8: EN_GasCCAdv | C8: ELCGAS | D8: ELC | H8: 15.101861 | I8: =N8/3.6*1.055 -> 0.94136212 | J8: 0.87 | K8: 30 | L8: 30 | N8: 3.2122309 | Q8: =B8 -> EN_GasCCAdv | R8: New: Gas CC Adv | S8: DAYNITE | T8: TBTU | U8: GW | W8: YES | Z8: 5 | AA8: EN_COAIGCC | AB8: Coal with 30% CCS | AC8: =MATCH(AB8,ovrcst!$A$4:$W$4,0) -> 2 | AD8: =IFERROR(MATCH(AB8,heatrate!$K$4:$T$4,0),1) -> 2
B9: EN_GasCC | C9: ELCGAS | D9: ELC | H9: 12.939952 | I9: =N9/3.6*1.055 -> 1.0367808 | J9: 0.87 | K9: 30 | L9: 30 | N9: 3.5378301 | Q9: =B9 -> EN_GasCC | R9: New: Gas CC | S9: DAYNITE | T9: TBTU | U9: GW | W9: YES | Z9: 6 | AA9: EN_ZCOAIGCC | AB9: Coal with 90% CCS | AC9: =MATCH(AB9,ovrcst!$A$4:$W$4,0) -> 3 | AD9: =IFERROR(MATCH(AB9,heatrate!$K$4:$T$4,0),1) -> 3
B10: EN_GasCTAdv | C10: ELCGAS | D10: ELC | H10: 6.9163618 | I10: =N10/3.6*1.055 -> 2.9861955 | J10: 0.06 | K10: 30 | L10: 30 | N10: 10.189861 | Q10: =B10 -> EN_GasCTAdv | R10: New: Gas CT Adv | S10: DAYNITE | T10: TBTU | U10: GW | W10: YES | Z10: 7 | AA10: EN_ZGasCCAdv | AB10: Adv CC w/seq | AC10: =MATCH(AB10,ovrcst!$A$4:$W$4,0) -> 9 | AD10: =IFERROR(MATCH(AB10,heatrate!$K$4:$T$4,0),1) -> 9
B11: EN_GasCT | C11: ELCGAS | D11: ELC | H11: 7.2122021 | I11: =N11/3.6*1.055 -> 4.4487696 | J11: 0.06 | K11: 30 | L11: 30 | N11: 15.180635 | Q11: =B11 -> EN_GasCT | R11: New: Gas CT | S11: DAYNITE | T11: TBTU | U11: GW | W11: YES | Z11: 8 | AA11: EN_GasCCAdv | AB11: Adv CC | AC11: =MATCH(AB11,ovrcst!$A$4:$W$4,0) -> 8 | AD11: =IFERROR(MATCH(AB11,heatrate!$K$4:$T$4,0),1) -> 8
B12: EN_Biomass | C12: ELCBIO | D12: ELC | E12: 0.25274074 | F12: 0.27801481 | H12: 103.78745 | I12: =N12/3.6*1.055 -> 1.5143874 | J12: 0.83 | K12: 30 | L12: 30 | N12: 5.1675777 | Q12: =B12 -> EN_Biomass | R12: New: Biomass | S12: SEASON | T12: TBTU | U12: GW | W12: YES | Z12: 9 | AA12: EN_GasCC | AB12: Comb. Cyc | AC12: =MATCH(AB12,ovrcst!$A$4:$W$4,0) -> 7 | AD12: =IFERROR(MATCH(AB12,heatrate!$K$4:$T$4,0),1) -> 7
B13: EN_ZBiomass | C13: ELCBIO | D13: ELC | H13: 103.78745 | I13: =N13/3.6*1.055 -> 1.5143874 | J13: 0.83 | K13: 30 | L13: 30 | N13: 5.1675777 | Q13: =B13 -> EN_ZBiomass | R13: New: Biomass - CCS | S13: SEASON | T13: TBTU | U13: GW | W13: YES | Z13: 10 | AA13: EN_GasCTAdv | AB13: Adv. CT | AC13: =MATCH(AB13,ovrcst!$A$4:$W$4,0) -> 6 | AD13: =IFERROR(MATCH(AB13,heatrate!$K$4:$T$4,0),1) -> 6
B14: EN_OilCCAdv | C14: ELCOIL | D14: ELC | H14: 15.101861 | I14: =N14/3.6*1.055 -> 0.94136212 | J14: 0.3 | K14: 30 | L14: 30 | N14: 3.2122309 | Q14: =B14 -> EN_OilCCAdv | R14: New: Oil CC Adv | S14: DAYNITE | T14: TBTU | U14: GW | W14: YES | Z14: 11 | AA14: EN_GasCT | AB14: Comb. Turb | AC14: =MATCH(AB14,ovrcst!$A$4:$W$4,0) -> 5 | AD14: =IFERROR(MATCH(AB14,heatrate!$K$4:$T$4,0),1) -> 5
B15: EN_NuclearAdv | C15: ELCNUC | D15: ELC | E15: 0.33 | H15: =H13 -> 103.78745 | I15: =N15/3.6*1.055 -> 1.5143874 | J15: =J6 -> 0.85 | K15: 50 | L15: 30 | N15: =N13 -> 5.1675777 | Q15: =B15 -> EN_NuclearAdv | R15: Advanced Nuclear | S15: SEASON | T15: TBTU | U15: GW | W15: YES | Z15: 12 | AA15: EN_Biomass | AB15: Biomass | AC15: =MATCH(AB15,ovrcst!$A$4:$W$4,0) -> 12 | AD15: =IFERROR(MATCH(AB15,heatrate!$K$4:$T$4,0),1) -> 1
B16: EN_GeoThermal | C16: ELCGEO | D16: ELC | E16: 0.33 | G16: 6999 | H16: 200 | I16: 2 | J16: 0.85 | K16: 50 | L16: 30 | Q16: =B16 -> EN_GeoThermal | R16: New: geothermal (placeholder) | S16: SEASON | T16: TBTU | U16: GW | Z16: 13 | AA16: EN_ZBiomass | AB16: Coal with 90% CCS | AC16: =MATCH(AB16,ovrcst!$A$4:$W$4,0) -> 3 | AD16: =IFERROR(MATCH(AB16,heatrate!$K$4:$T$4,0),1) -> 3
Z17: 14 | AA17: EN_OilCCAdv | AB17: Adv. CT | AC17: =MATCH(AB17,ovrcst!$A$4:$W$4,0) -> 6 | AD17: =IFERROR(MATCH(AB17,heatrate!$K$4:$T$4,0),1) -> 6
Z18: 15 | AA18: EN_Hydro* | AB18: Hydro | AC18: =MATCH(AB18,ovrcst!$A$4:$W$4,0) -> 15 | AD18: =IFERROR(MATCH(AB18,heatrate!$K$4:$T$4,0),1) -> 1
Z19: 16 | AA19: EN_NuclearAdv | AB19: Nuclear | AC19: =MATCH(AB19,ovrcst!$A$4:$W$4,0) -> 11 | AD19: =IFERROR(MATCH(AB19,heatrate!$K$4:$T$4,0),1) -> 1
B21: **FI_T: INVCOST**USD18
B22: TechName | C22: 2019 | D22: 2020 | E22: 2021 | F22: 2022 | G22: 2023 | H22: 2024 | I22: 2025 | J22: 2026 | K22: 2027 | L22: 2028 | M22: 2029 | N22: 2030 | O22: 2031 | P22: 2032 | Q22: 2033 | R22: 2034 | S22: 2035 | T22: 2036 | U22: 2037 | V22: 2038 | W22: 2039 | X22: 2040 | Y22: 2041 | Z22: 2042 | AA22: 2043 | AB22: 2044 | AC22: 2045 | AD22: 2046 | AE22: 2047 | AF22: 2048 | AG22: 2049 | AH22: 2050
B23: =B6 -> EN_ZCOAIGCC | C23: =VLOOKUP(C$22,ovrcst!$A$5:$W$36,VLOOKUP('ELC_Gen-sdj'!$B23,'ELC_Gen-sdj'!$AA$4:$AC$19,3,FALSE)) -> 5715.788 | D23: =VLOOKUP(D$22,ovrcst!$A$5:$W$36,VLOOKUP('ELC_Gen-sdj'!$B23,'ELC_Gen-sdj'!$AA$4:$AC$19,3,FALSE)) -> 5651.6864 | E23: =VLOOKUP(E$22,ovrcst!$A$5:$W$36,VLOOKUP('ELC_Gen-sdj'!$B23,'ELC_Gen-sdj'!$AA$4:$AC$19,3,FALSE)) -> 5513.4993 | F23: =VLOOKUP(F$22,ovrcst!$A$5:$W$36,VLOOKUP('ELC_Gen-sdj'!$B23,'ELC_Gen-sdj'!$AA$4:$AC$19,3,FALSE)) -> 5427.6275 | G23: =VLOOKUP(G$22,ovrcst!$A$5:$W$36,VLOOKUP('ELC_Gen-sdj'!$B23,'ELC_Gen-sdj'!$AA$4:$AC$19,3,FALSE)) -> 5366.8807 | H23: =VLOOKUP(H$22,ovrcst!$A$5:$W$36,VLOOKUP('ELC_Gen-sdj'!$B23,'ELC_Gen-sdj'!$AA$4:$AC$19,3,FALSE)) -> 5317.9442 | I23: =VLOOKUP(I$22,ovrcst!$A$5:$W$36,VLOOKUP('ELC_Gen-sdj'!$B23,'ELC_Gen-sdj'!$AA$4:$AC$19,3,FALSE)) -> 5278.0966 | J23: =VLOOKUP(J$22,ovrcst!$A$5:$W$36,VLOOKUP('ELC_Gen-sdj'!$B23,'ELC_Gen-sdj'!$AA$4:$AC$19,3,FALSE)) -> 5225.5755 | ... AH23: =VLOOKUP(AH$22,ovrcst!$A$5:$W$36,VLOOKUP('ELC_Gen-sdj'!$B23,'ELC_Gen-sdj'!$AA$4:$AC$19,3,FALSE)) -> 3845.2213
B24: =B7 -> EN_ZGasCCAdv | C24: =VLOOKUP(C$22,ovrcst!$A$5:$W$36,VLOOKUP('ELC_Gen-sdj'!$B24,'ELC_Gen-sdj'!$AA$4:$AC$19,3,FALSE)) -> 2204.7527 | D24: =VLOOKUP(D$22,ovrcst!$A$5:$W$36,VLOOKUP('ELC_Gen-sdj'!$B24,'ELC_Gen-sdj'!$AA$4:$AC$19,3,FALSE)) -> 2176.3551 | E24: =VLOOKUP(E$22,ovrcst!$A$5:$W$36,VLOOKUP('ELC_Gen-sdj'!$B24,'ELC_Gen-sdj'!$AA$4:$AC$19,3,FALSE)) -> 2119.5277 | F24: =VLOOKUP(F$22,ovrcst!$A$5:$W$36,VLOOKUP('ELC_Gen-sdj'!$B24,'ELC_Gen-sdj'!$AA$4:$AC$19,3,FALSE)) -> 2082.9271 | G24: =VLOOKUP(G$22,ovrcst!$A$5:$W$36,VLOOKUP('ELC_Gen-sdj'!$B24,'ELC_Gen-sdj'!$AA$4:$AC$19,3,FALSE)) -> 2023.7324 | H24: =VLOOKUP(H$22,ovrcst!$A$5:$W$36,VLOOKUP('ELC_Gen-sdj'!$B24,'ELC_Gen-sdj'!$AA$4:$AC$19,3,FALSE)) -> 1991.6681 | I24: =VLOOKUP(I$22,ovrcst!$A$5:$W$36,VLOOKUP('ELC_Gen-sdj'!$B24,'ELC_Gen-sdj'!$AA$4:$AC$19,3,FALSE)) -> 1962.46 | J24: =VLOOKUP(J$22,ovrcst!$A$5:$W$36,VLOOKUP('ELC_Gen-sdj'!$B24,'ELC_Gen-sdj'!$AA$4:$AC$19,3,FALSE)) -> 1929.6563 | ... AH24: =VLOOKUP(AH$22,ovrcst!$A$5:$W$36,VLOOKUP('ELC_Gen-sdj'!$B24,'ELC_Gen-sdj'!$AA$4:$AC$19,3,FALSE)) -> 1348.3088
B25: =B8 -> EN_GasCCAdv | C25: =VLOOKUP(C$22,ovrcst!$A$5:$W$36,VLOOKUP('ELC_Gen-sdj'!$B25,'ELC_Gen-sdj'!$AA$4:$AC$19,3,FALSE)) -> 794.43952 | D25: =VLOOKUP(D$22,ovrcst!$A$5:$W$36,VLOOKUP('ELC_Gen-sdj'!$B25,'ELC_Gen-sdj'!$AA$4:$AC$19,3,FALSE)) -> 786.43841 | E25: =VLOOKUP(E$22,ovrcst!$A$5:$W$36,VLOOKUP('ELC_Gen-sdj'!$B25,'ELC_Gen-sdj'!$AA$4:$AC$19,3,FALSE)) -> 768.10346 | F25: =VLOOKUP(F$22,ovrcst!$A$5:$W$36,VLOOKUP('ELC_Gen-sdj'!$B25,'ELC_Gen-sdj'!$AA$4:$AC$19,3,FALSE)) -> 757.02855 | G25: =VLOOKUP(G$22,ovrcst!$A$5:$W$36,VLOOKUP('ELC_Gen-sdj'!$B25,'ELC_Gen-sdj'!$AA$4:$AC$19,3,FALSE)) -> 732.12889 | H25: =VLOOKUP(H$22,ovrcst!$A$5:$W$36,VLOOKUP('ELC_Gen-sdj'!$B25,'ELC_Gen-sdj'!$AA$4:$AC$19,3,FALSE)) -> 720.96291 | I25: =VLOOKUP(I$22,ovrcst!$A$5:$W$36,VLOOKUP('ELC_Gen-sdj'!$B25,'ELC_Gen-sdj'!$AA$4:$AC$19,3,FALSE)) -> 710.7139 | J25: =VLOOKUP(J$22,ovrcst!$A$5:$W$36,VLOOKUP('ELC_Gen-sdj'!$B25,'ELC_Gen-sdj'!$AA$4:$AC$19,3,FALSE)) -> 699.33326 | ... AH25: =VLOOKUP(AH$22,ovrcst!$A$5:$W$36,VLOOKUP('ELC_Gen-sdj'!$B25,'ELC_Gen-sdj'!$AA$4:$AC$19,3,FALSE)) -> 532.1579
B26: =B9 -> EN_GasCC | C26: =VLOOKUP(C$22,ovrcst!$A$5:$W$36,VLOOKUP('ELC_Gen-sdj'!$B26,'ELC_Gen-sdj'!$AA$4:$AC$19,3,FALSE)) -> 999.32722 | D26: =VLOOKUP(D$22,ovrcst!$A$5:$W$36,VLOOKUP('ELC_Gen-sdj'!$B26,'ELC_Gen-sdj'!$AA$4:$AC$19,3,FALSE)) -> 990.01963 | E26: =VLOOKUP(E$22,ovrcst!$A$5:$W$36,VLOOKUP('ELC_Gen-sdj'!$B26,'ELC_Gen-sdj'!$AA$4:$AC$19,3,FALSE)) -> 967.68334 | F26: =VLOOKUP(F$22,ovrcst!$A$5:$W$36,VLOOKUP('ELC_Gen-sdj'!$B26,'ELC_Gen-sdj'!$AA$4:$AC$19,3,FALSE)) -> 954.4694 | G26: =VLOOKUP(G$22,ovrcst!$A$5:$W$36,VLOOKUP('ELC_Gen-sdj'!$B26,'ELC_Gen-sdj'!$AA$4:$AC$19,3,FALSE)) -> 945.63999 | H26: =VLOOKUP(H$22,ovrcst!$A$5:$W$36,VLOOKUP('ELC_Gen-sdj'!$B26,'ELC_Gen-sdj'!$AA$4:$AC$19,3,FALSE)) -> 938.87054 | I26: =VLOOKUP(I$22,ovrcst!$A$5:$W$36,VLOOKUP('ELC_Gen-sdj'!$B26,'ELC_Gen-sdj'!$AA$4:$AC$19,3,FALSE)) -> 933.69142 | J26: =VLOOKUP(J$22,ovrcst!$A$5:$W$36,VLOOKUP('ELC_Gen-sdj'!$B26,'ELC_Gen-sdj'!$AA$4:$AC$19,3,FALSE)) -> 926.25482 | ... AH26: =VLOOKUP(AH$22,ovrcst!$A$5:$W$36,VLOOKUP('ELC_Gen-sdj'!$B26,'ELC_Gen-sdj'!$AA$4:$AC$19,3,FALSE)) -> 718.53584
B27: =B10 -> EN_GasCTAdv | C27: =VLOOKUP(C$22,ovrcst!$A$5:$W$36,VLOOKUP('ELC_Gen-sdj'!$B27,'ELC_Gen-sdj'!$AA$4:$AC$19,3,FALSE)) -> 691.07682 | D27: =VLOOKUP(D$22,ovrcst!$A$5:$W$36,VLOOKUP('ELC_Gen-sdj'!$B27,'ELC_Gen-sdj'!$AA$4:$AC$19,3,FALSE)) -> 683.76621 | E27: =VLOOKUP(E$22,ovrcst!$A$5:$W$36,VLOOKUP('ELC_Gen-sdj'!$B27,'ELC_Gen-sdj'!$AA$4:$AC$19,3,FALSE)) -> 667.4804 | F27: =VLOOKUP(F$22,ovrcst!$A$5:$W$36,VLOOKUP('ELC_Gen-sdj'!$B27,'ELC_Gen-sdj'!$AA$4:$AC$19,3,FALSE)) -> 657.51437 | G27: =VLOOKUP(G$22,ovrcst!$A$5:$W$36,VLOOKUP('ELC_Gen-sdj'!$B27,'ELC_Gen-sdj'!$AA$4:$AC$19,3,FALSE)) -> 625.44563 | H27: =VLOOKUP(H$22,ovrcst!$A$5:$W$36,VLOOKUP('ELC_Gen-sdj'!$B27,'ELC_Gen-sdj'!$AA$4:$AC$19,3,FALSE)) -> 612.36513 | I27: =VLOOKUP(I$22,ovrcst!$A$5:$W$36,VLOOKUP('ELC_Gen-sdj'!$B27,'ELC_Gen-sdj'!$AA$4:$AC$19,3,FALSE)) -> 599.88018 | J27: =VLOOKUP(J$22,ovrcst!$A$5:$W$36,VLOOKUP('ELC_Gen-sdj'!$B27,'ELC_Gen-sdj'!$AA$4:$AC$19,3,FALSE)) -> 586.79665 | ... AH27: =VLOOKUP(AH$22,ovrcst!$A$5:$W$36,VLOOKUP('ELC_Gen-sdj'!$B27,'ELC_Gen-sdj'!$AA$4:$AC$19,3,FALSE)) -> 440.18226
B28: =B11 -> EN_GasCT | C28: =VLOOKUP(C$22,ovrcst!$A$5:$W$36,VLOOKUP('ELC_Gen-sdj'!$B28,'ELC_Gen-sdj'!$AA$4:$AC$19,3,FALSE)) -> 1126.0024 | D28: =VLOOKUP(D$22,ovrcst!$A$5:$W$36,VLOOKUP('ELC_Gen-sdj'!$B28,'ELC_Gen-sdj'!$AA$4:$AC$19,3,FALSE)) -> 1115.5153 | E28: =VLOOKUP(E$22,ovrcst!$A$5:$W$36,VLOOKUP('ELC_Gen-sdj'!$B28,'ELC_Gen-sdj'!$AA$4:$AC$19,3,FALSE)) -> 1090.3474 | F28: =VLOOKUP(F$22,ovrcst!$A$5:$W$36,VLOOKUP('ELC_Gen-sdj'!$B28,'ELC_Gen-sdj'!$AA$4:$AC$19,3,FALSE)) -> 1075.4584 | G28: =VLOOKUP(G$22,ovrcst!$A$5:$W$36,VLOOKUP('ELC_Gen-sdj'!$B28,'ELC_Gen-sdj'!$AA$4:$AC$19,3,FALSE)) -> 1065.51 | H28: =VLOOKUP(H$22,ovrcst!$A$5:$W$36,VLOOKUP('ELC_Gen-sdj'!$B28,'ELC_Gen-sdj'!$AA$4:$AC$19,3,FALSE)) -> 1057.8824 | I28: =VLOOKUP(I$22,ovrcst!$A$5:$W$36,VLOOKUP('ELC_Gen-sdj'!$B28,'ELC_Gen-sdj'!$AA$4:$AC$19,3,FALSE)) -> 1052.0468 | J28: =VLOOKUP(J$22,ovrcst!$A$5:$W$36,VLOOKUP('ELC_Gen-sdj'!$B28,'ELC_Gen-sdj'!$AA$4:$AC$19,3,FALSE)) -> 1043.6674 | ... AH28: =VLOOKUP(AH$22,ovrcst!$A$5:$W$36,VLOOKUP('ELC_Gen-sdj'!$B28,'ELC_Gen-sdj'!$AA$4:$AC$19,3,FALSE)) -> 809.61793
B29: =B12 -> EN_Biomass | C29: =VLOOKUP(C$22,ovrcst!$A$5:$W$36,VLOOKUP('ELC_Gen-sdj'!$B29,'ELC_Gen-sdj'!$AA$4:$AC$19,3,FALSE)) -> 3899.5783 | D29: =VLOOKUP(D$22,ovrcst!$A$5:$W$36,VLOOKUP('ELC_Gen-sdj'!$B29,'ELC_Gen-sdj'!$AA$4:$AC$19,3,FALSE)) -> 3858.2388 | E29: =VLOOKUP(E$22,ovrcst!$A$5:$W$36,VLOOKUP('ELC_Gen-sdj'!$B29,'ELC_Gen-sdj'!$AA$4:$AC$19,3,FALSE)) -> 3756.4371 | F29: =VLOOKUP(F$22,ovrcst!$A$5:$W$36,VLOOKUP('ELC_Gen-sdj'!$B29,'ELC_Gen-sdj'!$AA$4:$AC$19,3,FALSE)) -> 3698.74 | G29: =VLOOKUP(G$22,ovrcst!$A$5:$W$36,VLOOKUP('ELC_Gen-sdj'!$B29,'ELC_Gen-sdj'!$AA$4:$AC$19,3,FALSE)) -> 3659.7218 | H29: =VLOOKUP(H$22,ovrcst!$A$5:$W$36,VLOOKUP('ELC_Gen-sdj'!$B29,'ELC_Gen-sdj'!$AA$4:$AC$19,3,FALSE)) -> 3628.7298 | I29: =VLOOKUP(I$22,ovrcst!$A$5:$W$36,VLOOKUP('ELC_Gen-sdj'!$B29,'ELC_Gen-sdj'!$AA$4:$AC$19,3,FALSE)) -> 3603.9216 | J29: =VLOOKUP(J$22,ovrcst!$A$5:$W$36,VLOOKUP('ELC_Gen-sdj'!$B29,'ELC_Gen-sdj'!$AA$4:$AC$19,3,FALSE)) -> 3570.4402 | ... AH29: =VLOOKUP(AH$22,ovrcst!$A$5:$W$36,VLOOKUP('ELC_Gen-sdj'!$B29,'ELC_Gen-sdj'!$AA$4:$AC$19,3,FALSE)) -> 2674.7279
B30: =B13 -> EN_ZBiomass | C30: =VLOOKUP(C$22,ovrcst!$A$5:$W$36,VLOOKUP('ELC_Gen-sdj'!$B30,'ELC_Gen-sdj'!$AA$4:$AC$19,3,FALSE)) -> 5715.788 | D30: =VLOOKUP(D$22,ovrcst!$A$5:$W$36,VLOOKUP('ELC_Gen-sdj'!$B30,'ELC_Gen-sdj'!$AA$4:$AC$19,3,FALSE)) -> 5651.6864 | E30: =VLOOKUP(E$22,ovrcst!$A$5:$W$36,VLOOKUP('ELC_Gen-sdj'!$B30,'ELC_Gen-sdj'!$AA$4:$AC$19,3,FALSE)) -> 5513.4993 | F30: =VLOOKUP(F$22,ovrcst!$A$5:$W$36,VLOOKUP('ELC_Gen-sdj'!$B30,'ELC_Gen-sdj'!$AA$4:$AC$19,3,FALSE)) -> 5427.6275 | G30: =VLOOKUP(G$22,ovrcst!$A$5:$W$36,VLOOKUP('ELC_Gen-sdj'!$B30,'ELC_Gen-sdj'!$AA$4:$AC$19,3,FALSE)) -> 5366.8807 | H30: =VLOOKUP(H$22,ovrcst!$A$5:$W$36,VLOOKUP('ELC_Gen-sdj'!$B30,'ELC_Gen-sdj'!$AA$4:$AC$19,3,FALSE)) -> 5317.9442 | I30: =VLOOKUP(I$22,ovrcst!$A$5:$W$36,VLOOKUP('ELC_Gen-sdj'!$B30,'ELC_Gen-sdj'!$AA$4:$AC$19,3,FALSE)) -> 5278.0966 | J30: =VLOOKUP(J$22,ovrcst!$A$5:$W$36,VLOOKUP('ELC_Gen-sdj'!$B30,'ELC_Gen-sdj'!$AA$4:$AC$19,3,FALSE)) -> 5225.5755 | ... AH30: =VLOOKUP(AH$22,ovrcst!$A$5:$W$36,VLOOKUP('ELC_Gen-sdj'!$B30,'ELC_Gen-sdj'!$AA$4:$AC$19,3,FALSE)) -> 3845.2213
B31: =B14 -> EN_OilCCAdv | C31: =VLOOKUP(C$22,ovrcst!$A$5:$W$36,VLOOKUP('ELC_Gen-sdj'!$B31,'ELC_Gen-sdj'!$AA$4:$AC$19,3,FALSE)) -> 691.07682 | D31: =VLOOKUP(D$22,ovrcst!$A$5:$W$36,VLOOKUP('ELC_Gen-sdj'!$B31,'ELC_Gen-sdj'!$AA$4:$AC$19,3,FALSE)) -> 683.76621 | E31: =VLOOKUP(E$22,ovrcst!$A$5:$W$36,VLOOKUP('ELC_Gen-sdj'!$B31,'ELC_Gen-sdj'!$AA$4:$AC$19,3,FALSE)) -> 667.4804 | F31: =VLOOKUP(F$22,ovrcst!$A$5:$W$36,VLOOKUP('ELC_Gen-sdj'!$B31,'ELC_Gen-sdj'!$AA$4:$AC$19,3,FALSE)) -> 657.51437 | G31: =VLOOKUP(G$22,ovrcst!$A$5:$W$36,VLOOKUP('ELC_Gen-sdj'!$B31,'ELC_Gen-sdj'!$AA$4:$AC$19,3,FALSE)) -> 625.44563 | H31: =VLOOKUP(H$22,ovrcst!$A$5:$W$36,VLOOKUP('ELC_Gen-sdj'!$B31,'ELC_Gen-sdj'!$AA$4:$AC$19,3,FALSE)) -> 612.36513 | I31: =VLOOKUP(I$22,ovrcst!$A$5:$W$36,VLOOKUP('ELC_Gen-sdj'!$B31,'ELC_Gen-sdj'!$AA$4:$AC$19,3,FALSE)) -> 599.88018 | J31: =VLOOKUP(J$22,ovrcst!$A$5:$W$36,VLOOKUP('ELC_Gen-sdj'!$B31,'ELC_Gen-sdj'!$AA$4:$AC$19,3,FALSE)) -> 586.79665 | ... AH31: =VLOOKUP(AH$22,ovrcst!$A$5:$W$36,VLOOKUP('ELC_Gen-sdj'!$B31,'ELC_Gen-sdj'!$AA$4:$AC$19,3,FALSE)) -> 440.18226
B32: =B15 -> EN_NuclearAdv | C32: =VLOOKUP(C$22,ovrcst!$A$5:$W$36,VLOOKUP('ELC_Gen-sdj'!$B32,'ELC_Gen-sdj'!$AA$4:$AC$19,3,FALSE)) -> 6034.2659 | D32: =VLOOKUP(D$22,ovrcst!$A$5:$W$36,VLOOKUP('ELC_Gen-sdj'!$B32,'ELC_Gen-sdj'!$AA$4:$AC$19,3,FALSE)) -> 5962.7387 | E32: =VLOOKUP(E$22,ovrcst!$A$5:$W$36,VLOOKUP('ELC_Gen-sdj'!$B32,'ELC_Gen-sdj'!$AA$4:$AC$19,3,FALSE)) -> 5813.1538 | F32: =VLOOKUP(F$22,ovrcst!$A$5:$W$36,VLOOKUP('ELC_Gen-sdj'!$B32,'ELC_Gen-sdj'!$AA$4:$AC$19,3,FALSE)) -> 5718.8483 | G32: =VLOOKUP(G$22,ovrcst!$A$5:$W$36,VLOOKUP('ELC_Gen-sdj'!$B32,'ELC_Gen-sdj'!$AA$4:$AC$19,3,FALSE)) -> 5651.0839 | H32: =VLOOKUP(H$22,ovrcst!$A$5:$W$36,VLOOKUP('ELC_Gen-sdj'!$B32,'ELC_Gen-sdj'!$AA$4:$AC$19,3,FALSE)) -> 5595.7971 | I32: =VLOOKUP(I$22,ovrcst!$A$5:$W$36,VLOOKUP('ELC_Gen-sdj'!$B32,'ELC_Gen-sdj'!$AA$4:$AC$19,3,FALSE)) -> 5550.1031 | J32: =VLOOKUP(J$22,ovrcst!$A$5:$W$36,VLOOKUP('ELC_Gen-sdj'!$B32,'ELC_Gen-sdj'!$AA$4:$AC$19,3,FALSE)) -> 5491.1155 | ... AH32: =VLOOKUP(AH$22,ovrcst!$A$5:$W$36,VLOOKUP('ELC_Gen-sdj'!$B32,'ELC_Gen-sdj'!$AA$4:$AC$19,3,FALSE)) -> 3965.6701
B35: **FI_T: EFF
B36: TechName | C36: 2019 | D36: 2020 | E36: 2021 | F36: 2022 | G36: 2023 | H36: 2024 | I36: 2025 | J36: 2026 | K36: 2027 | L36: 2028 | M36: 2029 | N36: 2030 | O36: 2031 | P36: 2032 | Q36: 2033 | R36: 2034 | S36: 2035 | T36: 2036 | U36: 2037 | V36: 2038 | W36: 2039 | X36: 2040 | Y36: 2041 | Z36: 2042 | AA36: 2043 | AB36: 2044 | AC36: 2045 | AD36: 2046 | AE36: 2047 | AF36: 2048 | AG36: 2049 | AH36: 2050
B37: =B23 -> EN_ZCOAIGCC | C37: =VLOOKUP(C$22,heatrate!$K$5:$T$36,VLOOKUP('ELC_Gen-sdj'!$B37,'ELC_Gen-sdj'!$AA$4:$AD$19,4,FALSE)) -> 0.2929032 | D37: =VLOOKUP(D$22,heatrate!$K$5:$T$36,VLOOKUP('ELC_Gen-sdj'!$B37,'ELC_Gen-sdj'!$AA$4:$AD$19,4,FALSE)) -> 0.2929032 | E37: =VLOOKUP(E$22,heatrate!$K$5:$T$36,VLOOKUP('ELC_Gen-sdj'!$B37,'ELC_Gen-sdj'!$AA$4:$AD$19,4,FALSE)) -> 0.2929032 | F37: =VLOOKUP(F$22,heatrate!$K$5:$T$36,VLOOKUP('ELC_Gen-sdj'!$B37,'ELC_Gen-sdj'!$AA$4:$AD$19,4,FALSE)) -> 0.2929032 | G37: =VLOOKUP(G$22,heatrate!$K$5:$T$36,VLOOKUP('ELC_Gen-sdj'!$B37,'ELC_Gen-sdj'!$AA$4:$AD$19,4,FALSE)) -> 0.31443213 | H37: =VLOOKUP(H$22,heatrate!$K$5:$T$36,VLOOKUP('ELC_Gen-sdj'!$B37,'ELC_Gen-sdj'!$AA$4:$AD$19,4,FALSE)) -> 0.33937697 | I37: =VLOOKUP(I$22,heatrate!$K$5:$T$36,VLOOKUP('ELC_Gen-sdj'!$B37,'ELC_Gen-sdj'!$AA$4:$AD$19,4,FALSE)) -> 0.36862075 | J37: =VLOOKUP(J$22,heatrate!$K$5:$T$36,VLOOKUP('ELC_Gen-sdj'!$B37,'ELC_Gen-sdj'!$AA$4:$AD$19,4,FALSE)) -> 0.36862075 | ... AH37: =VLOOKUP(AH$22,heatrate!$K$5:$T$36,VLOOKUP('ELC_Gen-sdj'!$B37,'ELC_Gen-sdj'!$AA$4:$AD$19,4,FALSE)) -> 0.36862075
B38: =B24 -> EN_ZGasCCAdv | C38: =VLOOKUP(C$22,heatrate!$K$5:$T$36,VLOOKUP('ELC_Gen-sdj'!$B38,'ELC_Gen-sdj'!$AA$4:$AD$19,4,FALSE)) -> 0.45346475 | D38: =VLOOKUP(D$22,heatrate!$K$5:$T$36,VLOOKUP('ELC_Gen-sdj'!$B38,'ELC_Gen-sdj'!$AA$4:$AD$19,4,FALSE)) -> 0.45346475 | E38: =VLOOKUP(E$22,heatrate!$K$5:$T$36,VLOOKUP('ELC_Gen-sdj'!$B38,'ELC_Gen-sdj'!$AA$4:$AD$19,4,FALSE)) -> 0.45346475 | F38: =VLOOKUP(F$22,heatrate!$K$5:$T$36,VLOOKUP('ELC_Gen-sdj'!$B38,'ELC_Gen-sdj'!$AA$4:$AD$19,4,FALSE)) -> 0.45394736 | G38: =VLOOKUP(G$22,heatrate!$K$5:$T$36,VLOOKUP('ELC_Gen-sdj'!$B38,'ELC_Gen-sdj'!$AA$4:$AD$19,4,FALSE)) -> 0.45443099 | H38: =VLOOKUP(H$22,heatrate!$K$5:$T$36,VLOOKUP('ELC_Gen-sdj'!$B38,'ELC_Gen-sdj'!$AA$4:$AD$19,4,FALSE)) -> 0.45491565 | I38: =VLOOKUP(I$22,heatrate!$K$5:$T$36,VLOOKUP('ELC_Gen-sdj'!$B38,'ELC_Gen-sdj'!$AA$4:$AD$19,4,FALSE)) -> 0.45540134 | J38: =VLOOKUP(J$22,heatrate!$K$5:$T$36,VLOOKUP('ELC_Gen-sdj'!$B38,'ELC_Gen-sdj'!$AA$4:$AD$19,4,FALSE)) -> 0.45540134 | ... AH38: =VLOOKUP(AH$22,heatrate!$K$5:$T$36,VLOOKUP('ELC_Gen-sdj'!$B38,'ELC_Gen-sdj'!$AA$4:$AD$19,4,FALSE)) -> 0.45540134
B39: =B25 -> EN_GasCCAdv | C39: =VLOOKUP(C$22,heatrate!$K$5:$T$36,VLOOKUP('ELC_Gen-sdj'!$B39,'ELC_Gen-sdj'!$AA$4:$AD$19,4,FALSE)) -> 0.54163846 | D39: =VLOOKUP(D$22,heatrate!$K$5:$T$36,VLOOKUP('ELC_Gen-sdj'!$B39,'ELC_Gen-sdj'!$AA$4:$AD$19,4,FALSE)) -> 0.54163846 | E39: =VLOOKUP(E$22,heatrate!$K$5:$T$36,VLOOKUP('ELC_Gen-sdj'!$B39,'ELC_Gen-sdj'!$AA$4:$AD$19,4,FALSE)) -> 0.54163846 | F39: =VLOOKUP(F$22,heatrate!$K$5:$T$36,VLOOKUP('ELC_Gen-sdj'!$B39,'ELC_Gen-sdj'!$AA$4:$AD$19,4,FALSE)) -> 0.54379638 | G39: =VLOOKUP(G$22,heatrate!$K$5:$T$36,VLOOKUP('ELC_Gen-sdj'!$B39,'ELC_Gen-sdj'!$AA$4:$AD$19,4,FALSE)) -> 0.54597156 | H39: =VLOOKUP(H$22,heatrate!$K$5:$T$36,VLOOKUP('ELC_Gen-sdj'!$B39,'ELC_Gen-sdj'!$AA$4:$AD$19,4,FALSE)) -> 0.54816422 | I39: =VLOOKUP(I$22,heatrate!$K$5:$T$36,VLOOKUP('ELC_Gen-sdj'!$B39,'ELC_Gen-sdj'!$AA$4:$AD$19,4,FALSE)) -> 0.55037456 | J39: =VLOOKUP(J$22,heatrate!$K$5:$T$36,VLOOKUP('ELC_Gen-sdj'!$B39,'ELC_Gen-sdj'!$AA$4:$AD$19,4,FALSE)) -> 0.55037456 | ... AH39: =VLOOKUP(AH$22,heatrate!$K$5:$T$36,VLOOKUP('ELC_Gen-sdj'!$B39,'ELC_Gen-sdj'!$AA$4:$AD$19,4,FALSE)) -> 0.55037456
B40: =B26 -> EN_GasCC | C40: =VLOOKUP(C$22,heatrate!$K$5:$T$36,VLOOKUP('ELC_Gen-sdj'!$B40,'ELC_Gen-sdj'!$AA$4:$AD$19,4,FALSE)) -> 0.51701853 | D40: =VLOOKUP(D$22,heatrate!$K$5:$T$36,VLOOKUP('ELC_Gen-sdj'!$B40,'ELC_Gen-sdj'!$AA$4:$AD$19,4,FALSE)) -> 0.51701853 | E40: =VLOOKUP(E$22,heatrate!$K$5:$T$36,VLOOKUP('ELC_Gen-sdj'!$B40,'ELC_Gen-sdj'!$AA$4:$AD$19,4,FALSE)) -> 0.51701853 | F40: =VLOOKUP(F$22,heatrate!$K$5:$T$36,VLOOKUP('ELC_Gen-sdj'!$B40,'ELC_Gen-sdj'!$AA$4:$AD$19,4,FALSE)) -> 0.52196134 | G40: =VLOOKUP(G$22,heatrate!$K$5:$T$36,VLOOKUP('ELC_Gen-sdj'!$B40,'ELC_Gen-sdj'!$AA$4:$AD$19,4,FALSE)) -> 0.52699958 | H40: =VLOOKUP(H$22,heatrate!$K$5:$T$36,VLOOKUP('ELC_Gen-sdj'!$B40,'ELC_Gen-sdj'!$AA$4:$AD$19,4,FALSE)) -> 0.53213603 | I40: =VLOOKUP(I$22,heatrate!$K$5:$T$36,VLOOKUP('ELC_Gen-sdj'!$B40,'ELC_Gen-sdj'!$AA$4:$AD$19,4,FALSE)) -> 0.53737359 | J40: =VLOOKUP(J$22,heatrate!$K$5:$T$36,VLOOKUP('ELC_Gen-sdj'!$B40,'ELC_Gen-sdj'!$AA$4:$AD$19,4,FALSE)) -> 0.53737359 | ... AH40: =VLOOKUP(AH$22,heatrate!$K$5:$T$36,VLOOKUP('ELC_Gen-sdj'!$B40,'ELC_Gen-sdj'!$AA$4:$AD$19,4,FALSE)) -> 0.53737359
B41: =B27 -> EN_GasCTAdv | C41: =VLOOKUP(C$22,heatrate!$K$5:$T$36,VLOOKUP('ELC_Gen-sdj'!$B41,'ELC_Gen-sdj'!$AA$4:$AD$19,4,FALSE)) -> 0.34819615 | D41: =VLOOKUP(D$22,heatrate!$K$5:$T$36,VLOOKUP('ELC_Gen-sdj'!$B41,'ELC_Gen-sdj'!$AA$4:$AD$19,4,FALSE)) -> 0.34819615 | E41: =VLOOKUP(E$22,heatrate!$K$5:$T$36,VLOOKUP('ELC_Gen-sdj'!$B41,'ELC_Gen-sdj'!$AA$4:$AD$19,4,FALSE)) -> 0.35731123 | F41: =VLOOKUP(F$22,heatrate!$K$5:$T$36,VLOOKUP('ELC_Gen-sdj'!$B41,'ELC_Gen-sdj'!$AA$4:$AD$19,4,FALSE)) -> 0.36691637 | G41: =VLOOKUP(G$22,heatrate!$K$5:$T$36,VLOOKUP('ELC_Gen-sdj'!$B41,'ELC_Gen-sdj'!$AA$4:$AD$19,4,FALSE)) -> 0.37705219 | H41: =VLOOKUP(H$22,heatrate!$K$5:$T$36,VLOOKUP('ELC_Gen-sdj'!$B41,'ELC_Gen-sdj'!$AA$4:$AD$19,4,FALSE)) -> 0.38776389 | I41: =VLOOKUP(I$22,heatrate!$K$5:$T$36,VLOOKUP('ELC_Gen-sdj'!$B41,'ELC_Gen-sdj'!$AA$4:$AD$19,4,FALSE)) -> 0.39910202 | J41: =VLOOKUP(J$22,heatrate!$K$5:$T$36,VLOOKUP('ELC_Gen-sdj'!$B41,'ELC_Gen-sdj'!$AA$4:$AD$19,4,FALSE)) -> 0.39910202 | ... AH41: =VLOOKUP(AH$22,heatrate!$K$5:$T$36,VLOOKUP('ELC_Gen-sdj'!$B41,'ELC_Gen-sdj'!$AA$4:$AD$19,4,FALSE)) -> 0.39910202
B42: =B28 -> EN_GasCT | C42: =VLOOKUP(C$22,heatrate!$K$5:$T$36,VLOOKUP('ELC_Gen-sdj'!$B42,'ELC_Gen-sdj'!$AA$4:$AD$19,4,FALSE)) -> 0.34678072 | D42: =VLOOKUP(D$22,heatrate!$K$5:$T$36,VLOOKUP('ELC_Gen-sdj'!$B42,'ELC_Gen-sdj'!$AA$4:$AD$19,4,FALSE)) -> 0.34819615 | E42: =VLOOKUP(E$22,heatrate!$K$5:$T$36,VLOOKUP('ELC_Gen-sdj'!$B42,'ELC_Gen-sdj'!$AA$4:$AD$19,4,FALSE)) -> 0.34962318 | F42: =VLOOKUP(F$22,heatrate!$K$5:$T$36,VLOOKUP('ELC_Gen-sdj'!$B42,'ELC_Gen-sdj'!$AA$4:$AD$19,4,FALSE)) -> 0.35106196 | G42: =VLOOKUP(G$22,heatrate!$K$5:$T$36,VLOOKUP('ELC_Gen-sdj'!$B42,'ELC_Gen-sdj'!$AA$4:$AD$19,4,FALSE)) -> 0.35251263 | H42: =VLOOKUP(H$22,heatrate!$K$5:$T$36,VLOOKUP('ELC_Gen-sdj'!$B42,'ELC_Gen-sdj'!$AA$4:$AD$19,4,FALSE)) -> 0.35397534 | I42: =VLOOKUP(I$22,heatrate!$K$5:$T$36,VLOOKUP('ELC_Gen-sdj'!$B42,'ELC_Gen-sdj'!$AA$4:$AD$19,4,FALSE)) -> 0.35545024 | J42: =VLOOKUP(J$22,heatrate!$K$5:$T$36,VLOOKUP('ELC_Gen-sdj'!$B42,'ELC_Gen-sdj'!$AA$4:$AD$19,4,FALSE)) -> 0.35545024 | ... AH42: =VLOOKUP(AH$22,heatrate!$K$5:$T$36,VLOOKUP('ELC_Gen-sdj'!$B42,'ELC_Gen-sdj'!$AA$4:$AD$19,4,FALSE)) -> 0.35545024
B43: =B30 -> EN_ZBiomass | C43: =VLOOKUP(C$22,heatrate!$K$5:$T$36,VLOOKUP('ELC_Gen-sdj'!$B43,'ELC_Gen-sdj'!$AA$4:$AD$19,4,FALSE)) -> 0.2929032 | D43: =VLOOKUP(D$22,heatrate!$K$5:$T$36,VLOOKUP('ELC_Gen-sdj'!$B43,'ELC_Gen-sdj'!$AA$4:$AD$19,4,FALSE)) -> 0.2929032 | E43: =VLOOKUP(E$22,heatrate!$K$5:$T$36,VLOOKUP('ELC_Gen-sdj'!$B43,'ELC_Gen-sdj'!$AA$4:$AD$19,4,FALSE)) -> 0.2929032 | F43: =VLOOKUP(F$22,heatrate!$K$5:$T$36,VLOOKUP('ELC_Gen-sdj'!$B43,'ELC_Gen-sdj'!$AA$4:$AD$19,4,FALSE)) -> 0.2929032 | G43: =VLOOKUP(G$22,heatrate!$K$5:$T$36,VLOOKUP('ELC_Gen-sdj'!$B43,'ELC_Gen-sdj'!$AA$4:$AD$19,4,FALSE)) -> 0.31443213 | H43: =VLOOKUP(H$22,heatrate!$K$5:$T$36,VLOOKUP('ELC_Gen-sdj'!$B43,'ELC_Gen-sdj'!$AA$4:$AD$19,4,FALSE)) -> 0.33937697 | I43: =VLOOKUP(I$22,heatrate!$K$5:$T$36,VLOOKUP('ELC_Gen-sdj'!$B43,'ELC_Gen-sdj'!$AA$4:$AD$19,4,FALSE)) -> 0.36862075 | J43: =VLOOKUP(J$22,heatrate!$K$5:$T$36,VLOOKUP('ELC_Gen-sdj'!$B43,'ELC_Gen-sdj'!$AA$4:$AD$19,4,FALSE)) -> 0.36862075 | ... AH43: =VLOOKUP(AH$22,heatrate!$K$5:$T$36,VLOOKUP('ELC_Gen-sdj'!$B43,'ELC_Gen-sdj'!$AA$4:$AD$19,4,FALSE)) -> 0.36862075
B44: =B31 -> EN_OilCCAdv | C44: 0.3 | D44: 0.3 | E44: 0.3 | F44: 0.3 | G44: 0.3 | H44: 0.3 | I44: 0.3 | J44: 0.3 | K44: 0.3 | L44: 0.3 | M44: 0.3 | N44: 0.3 | O44: 0.3 | P44: 0.3 | Q44: 0.3 | R44: 0.3 | S44: 0.3 | T44: 0.3 | U44: 0.3 | V44: 0.3 | W44: 0.3 | X44: 0.3 | Y44: 0.3 | Z44: 0.3 | AA44: 0.3 | AB44: 0.3 | AC44: 0.3 | AD44: 0.3 | AE44: 0.3 | AF44: 0.3 | AG44: 0.3 | AH44: 0.3

Sheet ELC_Gen-tjh
D2: ~FI_T: EFF~USD11~2010 | P2: ~FI_Process
B3: TechName | C3: Comm-IN | D3: Comm-OUT | E3: 2010 | F3: 2050 | G3: INVCOST | H3: FIXOM | I3: VAROM | J3: AFA | K3: LIFE | L3: ELIFE | P3: Sets | Q3: TechName | R3: TechDesc | S3: Tslvl | T3: Tact | U3: Tcap | V3: PrimaryCG | W3: Vintage | AC3: Icost | AD3: Eff
B4: EN_COAPUL | C4: ELCCOA | D4: ELC | E4: 0.38772727 | F4: 0.39038902 | G4: 2882.6578 | H4: 30.636105 | I4: =N4/3.6*1.055 -> 1.2871267 | J4: 0.85 | K4: 40 | L4: 30 | N4: 4.3920913 | P4: ELE | Q4: =B4 -> EN_COAPUL | R4: New: Pulverized coal | S4: SEASON | T4: TBTU | U4: GW | W4: YES | Z4: 1 | AA4: E_SPV* | AB4: Solar PV - fixed tilt | AC4: =MATCH(AB4,ovrcst!$A$4:$W$4,0) -> 21 | AD4: =IFERROR(MATCH(AB4,heatrate!$K$4:$T$4,0),1) -> 1
B5: EN_COAIGCC | C5: ELCCOA | D5: ELC | E5: 0.39218391 | F5: 0.45798658 | G5: 3718.0479 | H5: 50.494167 | I5: =N5/3.6*1.055 -> 2.0792047 | J5: 0.85 | K5: 40 | L5: 30 | N5: 7.0949163 | Q5: =B5 -> EN_COAIGCC | R5: New: Coal IGCC | S5: SEASON | T5: TBTU | U5: GW | W5: YES | Z5: 2 | AA5: E_WON* | AB5: Wind | AC5: =MATCH(AB5,ovrcst!$A$4:$W$4,0) -> 17 | AD5: =IFERROR(MATCH(AB5,heatrate!$K$4:$T$4,0),1) -> 1
B6: EN_ZCOAIGCC | C6: ELCCOA | D6: ELC | H6: 65.308937 | I6: =N6/3.6*1.055 -> 1.2819968 | J6: 0.85 | K6: 40 | L6: 30 | N6: 4.3745861 | Q6: =B6 -> EN_ZCOAIGCC | R6: New: Coal IGCC - CCS | S6: SEASON | T6: TBTU | U6: GW | W6: YES | Z6: 3 | AA6: E_WOF* | AB6: Offshore Wind | AC6: =MATCH(AB6,ovrcst!$A$4:$W$4,0) -> 18 | AD6: =IFERROR(MATCH(AB6,heatrate!$K$4:$T$4,0),1) -> 1
B7: EN_ZGasCCAdv | C7: ELCGAS | D7: ELC | H7: 31.234789 | I7: =N7/3.6*1.055 -> 1.9524927 | J7: 0.87 | K7: 30 | L7: 30 | N7: 6.6625342 | Q7: =B7 -> EN_ZGasCCAdv | R7: New: Gas CC Adv - CCS | S7: DAYNITE | T7: TBTU | U7: GW | W7: YES | Z7: 4 | AA7: EN_COAPUL | AB7: Coal with 30% CCS | AC7: =MATCH(AB7,ovrcst!$A$4:$W$4,0) -> 2 | AD7: =IFERROR(MATCH(AB7,heatrate!$K$4:$T$4,0),1) -> 2
B8: EN_GasCCAdv | C8: ELCGAS | D8: ELC | H8: 15.101861 | I8: =N8/3.6*1.055 -> 0.94136212 | J8: 0.87 | K8: 30 | L8: 30 | N8: 3.2122309 | Q8: =B8 -> EN_GasCCAdv | R8: New: Gas CC Adv | S8: DAYNITE | T8: TBTU | U8: GW | W8: YES | Z8: 5 | AA8: EN_COAIGCC | AB8: Coal with 30% CCS | AC8: =MATCH(AB8,ovrcst!$A$4:$W$4,0) -> 2 | AD8: =IFERROR(MATCH(AB8,heatrate!$K$4:$T$4,0),1) -> 2
B9: EN_GasCC | C9: ELCGAS | D9: ELC | H9: 12.939952 | I9: =N9/3.6*1.055 -> 1.0367808 | J9: 0.87 | K9: 30 | L9: 30 | N9: 3.5378301 | Q9: =B9 -> EN_GasCC | R9: New: Gas CC | S9: DAYNITE | T9: TBTU | U9: GW | W9: YES | Z9: 6 | AA9: EN_ZCOAIGCC | AB9: Coal with 90% CCS | AC9: =MATCH(AB9,ovrcst!$A$4:$W$4,0) -> 3 | AD9: =IFERROR(MATCH(AB9,heatrate!$K$4:$T$4,0),1) -> 3
B10: EN_GasCTAdv | C10: ELCGAS | D10: ELC | H10: 6.9163618 | I10: =N10/3.6*1.055 -> 2.9861955 | J10: 0.06 | K10: 30 | L10: 30 | N10: 10.189861 | Q10: =B10 -> EN_GasCTAdv | R10: New: Gas CT Adv | S10: DAYNITE | T10: TBTU | U10: GW | W10: YES | Z10: 7 | AA10: EN_ZGasCCAdv | AB10: Adv CC w/seq | AC10: =MATCH(AB10,ovrcst!$A$4:$W$4,0) -> 9 | AD10: =IFERROR(MATCH(AB10,heatrate!$K$4:$T$4,0),1) -> 9
B11: EN_GasCT | C11: ELCGAS | D11: ELC | H11: 7.2122021 | I11: =N11/3.6*1.055 -> 4.4487696 | J11: 0.06 | K11: 30 | L11: 30 | N11: 15.180635 | Q11: =B11 -> EN_GasCT | R11: New: Gas CT | S11: DAYNITE | T11: TBTU | U11: GW | W11: YES | Z11: 8 | AA11: EN_GasCCAdv | AB11: Adv CC | AC11: =MATCH(AB11,ovrcst!$A$4:$W$4,0) -> 8 | AD11: =IFERROR(MATCH(AB11,heatrate!$K$4:$T$4,0),1) -> 8
B12: EN_Biomass | C12: ELCBIO | D12: ELC | E12: 0.25274074 | F12: 0.27801481 | H12: 103.78745 | I12: =N12/3.6*1.055 -> 1.5143874 | J12: 0.83 | K12: 30 | L12: 30 | N12: 5.1675777 | Q12: =B12 -> EN_Biomass | R12: New: Biomass | S12: SEASON | T12: TBTU | U12: GW | W12: YES | Z12: 9 | AA12: EN_GasCC | AB12: Comb. Cyc | AC12: =MATCH(AB12,ovrcst!$A$4:$W$4,0) -> 7 | AD12: =IFERROR(MATCH(AB12,heatrate!$K$4:$T$4,0),1) -> 7
B13: EN_ZBiomass | C13: ELCBIO | D13: ELC | H13: 103.78745 | I13: =N13/3.6*1.055 -> 1.5143874 | J13: 0.83 | K13: 30 | L13: 30 | N13: 5.1675777 | Q13: =B13 -> EN_ZBiomass | R13: New: Biomass - CCS | S13: SEASON | T13: TBTU | U13: GW | W13: YES | Z13: 10 | AA13: EN_GasCTAdv | AB13: Adv. CT | AC13: =MATCH(AB13,ovrcst!$A$4:$W$4,0) -> 6 | AD13: =IFERROR(MATCH(AB13,heatrate!$K$4:$T$4,0),1) -> 6
B14: EN_OilCCAdv | C14: ELCOIL | D14: ELC | H14: 15.101861 | I14: =N14/3.6*1.055 -> 0.94136212 | J14: 0.3 | K14: 30 | L14: 30 | N14: 3.2122309 | Q14: =B14 -> EN_OilCCAdv | R14: New: Oil CC Adv | S14: DAYNITE | T14: TBTU | U14: GW | W14: YES | Z14: 11 | AA14: EN_GasCT | AB14: Comb. Turb | AC14: =MATCH(AB14,ovrcst!$A$4:$W$4,0) -> 5 | AD14: =IFERROR(MATCH(AB14,heatrate!$K$4:$T$4,0),1) -> 5
B15: EN_NuclearAdv | C15: ELCNUC | D15: ELC | E15: 0.33 | H15: =H13 -> 103.78745 | I15: =N15/3.6*1.055 -> 1.5143874 | J15: =J6 -> 0.85 | K15: 50 | L15: 30 | N15: =N13 -> 5.1675777 | Q15: =B15 -> EN_NuclearAdv | R15: Advanced Nuclear | S15: SEASON | T15: TBTU | U15: GW | W15: YES | Z15: 12 | AA15: EN_Biomass | AB15: Biomass | AC15: =MATCH(AB15,ovrcst!$A$4:$W$4,0) -> 12 | AD15: =IFERROR(MATCH(AB15,heatrate!$K$4:$T$4,0),1) -> 1
B16: EN_GeoThermal | C16: ELCGEO | D16: ELC | E16: 0.33 | G16: 9999 | H16: 500 | I16: 10 | J16: 0.85 | K16: 50 | L16: 30 | Q16: =B16 -> EN_GeoThermal | R16: New: geothermal (placeholder) | S16: SEASON | T16: TBTU | U16: GW | Z16: 13 | AA16: EN_ZBiomass | AB16: Coal with 90% CCS | AC16: =MATCH(AB16,ovrcst!$A$4:$W$4,0) -> 3 | AD16: =IFERROR(MATCH(AB16,heatrate!$K$4:$T$4,0),1) -> 3
B17: EN_ZZCOAIGCC | C17: ELCCOA | D17: ELC | H17: =H6 -> 65.308937 | I17: =I6 -> 1.2819968 | J17: =J6 -> 0.85 | K17: =K6 -> 40 | L17: =L6 -> 30 | Q17: EN_ZZCOAIGCC | R17: New: Coal IGCC - CCS Retrofit | S17: SEASON | T17: TBTU | U17: GW | W17: YES | Z17: 14 | AA17: EN_OilCCAdv | AB17: Adv. CT | AC17: =MATCH(AB17,ovrcst!$A$4:$W$4,0) -> 6 | AD17: =IFERROR(MATCH(AB17,heatrate!$K$4:$T$4,0),1) -> 6
B18: EN_ZZGasCC | C18: ELCGAS | D18: ELC | H18: =H7 -> 31.234789 | I18: =I7 -> 1.9524927 | J18: =J7 -> 0.87 | K18: =K7 -> 30 | L18: =L7 -> 30 | Q18: EN_ZZGasCC | R18: New: Gas CC - CCS Retrofit | S18: DAYNITE | T18: TBTU | U18: GW | W18: YES | Z18: 15 | AA18: EN_Hydro* | AB18: Hydro | AC18: =MATCH(AB18,ovrcst!$A$4:$W$4,0) -> 15 | AD18: =IFERROR(MATCH(AB18,heatrate!$K$4:$T$4,0),1) -> 1
Z19: 16 | AA19: EN_NuclearAdv | AB19: Nuclear | AC19: =MATCH(AB19,ovrcst!$A$4:$W$4,0) -> 11 | AD19: =IFERROR(MATCH(AB19,heatrate!$K$4:$T$4,0),1) -> 1
B21: ~FI_T: INVCOST~USD18
B22: TechName | C22: 2019 | D22: 2020 | E22: 2021 | F22: 2022 | G22: 2023 | H22: 2024 | I22: 2025 | J22: 2026 | K22: 2027 | L22: 2028 | M22: 2029 | N22: 2030 | O22: 2031 | P22: 2032 | Q22: 2033 | R22: 2034 | S22: 2035 | T22: 2036 | U22: 2037 | V22: 2038 | W22: 2039 | X22: 2040 | Y22: 2041 | Z22: 2042 | AA22: 2043 | AB22: 2044 | AC22: 2045 | AD22: 2046 | AE22: 2047 | AF22: 2048 | AG22: 2049 | AH22: 2050
B23: =B6 -> EN_ZCOAIGCC | C23: =VLOOKUP(C$22,ovrcst!$A$5:$W$36,VLOOKUP('ELC_Gen-sdj'!$B23,'ELC_Gen-sdj'!$AA$4:$AC$19,3,FALSE)) -> 5715.788 | D23: =VLOOKUP(D$22,ovrcst!$A$5:$W$36,VLOOKUP('ELC_Gen-sdj'!$B23,'ELC_Gen-sdj'!$AA$4:$AC$19,3,FALSE)) -> 5651.6864 | E23: =VLOOKUP(E$22,ovrcst!$A$5:$W$36,VLOOKUP('ELC_Gen-sdj'!$B23,'ELC_Gen-sdj'!$AA$4:$AC$19,3,FALSE)) -> 5513.4993 | F23: =VLOOKUP(F$22,ovrcst!$A$5:$W$36,VLOOKUP('ELC_Gen-sdj'!$B23,'ELC_Gen-sdj'!$AA$4:$AC$19,3,FALSE)) -> 5427.6275 | G23: =VLOOKUP(G$22,ovrcst!$A$5:$W$36,VLOOKUP('ELC_Gen-sdj'!$B23,'ELC_Gen-sdj'!$AA$4:$AC$19,3,FALSE)) -> 5366.8807 | H23: =VLOOKUP(H$22,ovrcst!$A$5:$W$36,VLOOKUP('ELC_Gen-sdj'!$B23,'ELC_Gen-sdj'!$AA$4:$AC$19,3,FALSE)) -> 5317.9442 | I23: =VLOOKUP(I$22,ovrcst!$A$5:$W$36,VLOOKUP('ELC_Gen-sdj'!$B23,'ELC_Gen-sdj'!$AA$4:$AC$19,3,FALSE)) -> 5278.0966 | J23: =VLOOKUP(J$22,ovrcst!$A$5:$W$36,VLOOKUP('ELC_Gen-sdj'!$B23,'ELC_Gen-sdj'!$AA$4:$AC$19,3,FALSE)) -> 5225.5755 | ... AH23: =VLOOKUP(AH$22,ovrcst!$A$5:$W$36,VLOOKUP('ELC_Gen-sdj'!$B23,'ELC_Gen-sdj'!$AA$4:$AC$19,3,FALSE)) -> 3845.2213
B24: =B7 -> EN_ZGasCCAdv | C24: =VLOOKUP(C$22,ovrcst!$A$5:$W$36,VLOOKUP('ELC_Gen-sdj'!$B24,'ELC_Gen-sdj'!$AA$4:$AC$19,3,FALSE)) -> 2204.7527 | D24: =VLOOKUP(D$22,ovrcst!$A$5:$W$36,VLOOKUP('ELC_Gen-sdj'!$B24,'ELC_Gen-sdj'!$AA$4:$AC$19,3,FALSE)) -> 2176.3551 | E24: =VLOOKUP(E$22,ovrcst!$A$5:$W$36,VLOOKUP('ELC_Gen-sdj'!$B24,'ELC_Gen-sdj'!$AA$4:$AC$19,3,FALSE)) -> 2119.5277 | F24: =VLOOKUP(F$22,ovrcst!$A$5:$W$36,VLOOKUP('ELC_Gen-sdj'!$B24,'ELC_Gen-sdj'!$AA$4:$AC$19,3,FALSE)) -> 2082.9271 | G24: =VLOOKUP(G$22,ovrcst!$A$5:$W$36,VLOOKUP('ELC_Gen-sdj'!$B24,'ELC_Gen-sdj'!$AA$4:$AC$19,3,FALSE)) -> 2023.7324 | H24: =VLOOKUP(H$22,ovrcst!$A$5:$W$36,VLOOKUP('ELC_Gen-sdj'!$B24,'ELC_Gen-sdj'!$AA$4:$AC$19,3,FALSE)) -> 1991.6681 | I24: =VLOOKUP(I$22,ovrcst!$A$5:$W$36,VLOOKUP('ELC_Gen-sdj'!$B24,'ELC_Gen-sdj'!$AA$4:$AC$19,3,FALSE)) -> 1962.46 | J24: =VLOOKUP(J$22,ovrcst!$A$5:$W$36,VLOOKUP('ELC_Gen-sdj'!$B24,'ELC_Gen-sdj'!$AA$4:$AC$19,3,FALSE)) -> 1929.6563 | ... AH24: =VLOOKUP(AH$22,ovrcst!$A$5:$W$36,VLOOKUP('ELC_Gen-sdj'!$B24,'ELC_Gen-sdj'!$AA$4:$AC$19,3,FALSE)) -> 1348.3088
B25: =B8 -> EN_GasCCAdv | C25: =VLOOKUP(C$22,ovrcst!$A$5:$W$36,VLOOKUP('ELC_Gen-sdj'!$B25,'ELC_Gen-sdj'!$AA$4:$AC$19,3,FALSE)) -> 794.43952 | D25: =VLOOKUP(D$22,ovrcst!$A$5:$W$36,VLOOKUP('ELC_Gen-sdj'!$B25,'ELC_Gen-sdj'!$AA$4:$AC$19,3,FALSE)) -> 786.43841 | E25: =VLOOKUP(E$22,ovrcst!$A$5:$W$36,VLOOKUP('ELC_Gen-sdj'!$B25,'ELC_Gen-sdj'!$AA$4:$AC$19,3,FALSE)) -> 768.10346 | F25: =VLOOKUP(F$22,ovrcst!$A$5:$W$36,VLOOKUP('ELC_Gen-sdj'!$B25,'ELC_Gen-sdj'!$AA$4:$AC$19,3,FALSE)) -> 757.02855 | G25: =VLOOKUP(G$22,ovrcst!$A$5:$W$36,VLOOKUP('ELC_Gen-sdj'!$B25,'ELC_Gen-sdj'!$AA$4:$AC$19,3,FALSE)) -> 732.12889 | H25: =VLOOKUP(H$22,ovrcst!$A$5:$W$36,VLOOKUP('ELC_Gen-sdj'!$B25,'ELC_Gen-sdj'!$AA$4:$AC$19,3,FALSE)) -> 720.96291 | I25: =VLOOKUP(I$22,ovrcst!$A$5:$W$36,VLOOKUP('ELC_Gen-sdj'!$B25,'ELC_Gen-sdj'!$AA$4:$AC$19,3,FALSE)) -> 710.7139 | J25: =VLOOKUP(J$22,ovrcst!$A$5:$W$36,VLOOKUP('ELC_Gen-sdj'!$B25,'ELC_Gen-sdj'!$AA$4:$AC$19,3,FALSE)) -> 699.33326 | ... AH25: =VLOOKUP(AH$22,ovrcst!$A$5:$W$36,VLOOKUP('ELC_Gen-sdj'!$B25,'ELC_Gen-sdj'!$AA$4:$AC$19,3,FALSE)) -> 532.1579
B26: =B9 -> EN_GasCC | C26: =VLOOKUP(C$22,ovrcst!$A$5:$W$36,VLOOKUP('ELC_Gen-sdj'!$B26,'ELC_Gen-sdj'!$AA$4:$AC$19,3,FALSE)) -> 999.32722 | D26: =VLOOKUP(D$22,ovrcst!$A$5:$W$36,VLOOKUP('ELC_Gen-sdj'!$B26,'ELC_Gen-sdj'!$AA$4:$AC$19,3,FALSE)) -> 990.01963 | E26: =VLOOKUP(E$22,ovrcst!$A$5:$W$36,VLOOKUP('ELC_Gen-sdj'!$B26,'ELC_Gen-sdj'!$AA$4:$AC$19,3,FALSE)) -> 967.68334 | F26: =VLOOKUP(F$22,ovrcst!$A$5:$W$36,VLOOKUP('ELC_Gen-sdj'!$B26,'ELC_Gen-sdj'!$AA$4:$AC$19,3,FALSE)) -> 954.4694 | G26: =VLOOKUP(G$22,ovrcst!$A$5:$W$36,VLOOKUP('ELC_Gen-sdj'!$B26,'ELC_Gen-sdj'!$AA$4:$AC$19,3,FALSE)) -> 945.63999 | H26: =VLOOKUP(H$22,ovrcst!$A$5:$W$36,VLOOKUP('ELC_Gen-sdj'!$B26,'ELC_Gen-sdj'!$AA$4:$AC$19,3,FALSE)) -> 938.87054 | I26: =VLOOKUP(I$22,ovrcst!$A$5:$W$36,VLOOKUP('ELC_Gen-sdj'!$B26,'ELC_Gen-sdj'!$AA$4:$AC$19,3,FALSE)) -> 933.69142 | J26: =VLOOKUP(J$22,ovrcst!$A$5:$W$36,VLOOKUP('ELC_Gen-sdj'!$B26,'ELC_Gen-sdj'!$AA$4:$AC$19,3,FALSE)) -> 926.25482 | ... AH26: =VLOOKUP(AH$22,ovrcst!$A$5:$W$36,VLOOKUP('ELC_Gen-sdj'!$B26,'ELC_Gen-sdj'!$AA$4:$AC$19,3,FALSE)) -> 718.53584
B27: =B10 -> EN_GasCTAdv | C27: =VLOOKUP(C$22,ovrcst!$A$5:$W$36,VLOOKUP('ELC_Gen-sdj'!$B27,'ELC_Gen-sdj'!$AA$4:$AC$19,3,FALSE)) -> 691.07682 | D27: =VLOOKUP(D$22,ovrcst!$A$5:$W$36,VLOOKUP('ELC_Gen-sdj'!$B27,'ELC_Gen-sdj'!$AA$4:$AC$19,3,FALSE)) -> 683.76621 | E27: =VLOOKUP(E$22,ovrcst!$A$5:$W$36,VLOOKUP('ELC_Gen-sdj'!$B27,'ELC_Gen-sdj'!$AA$4:$AC$19,3,FALSE)) -> 667.4804 | F27: =VLOOKUP(F$22,ovrcst!$A$5:$W$36,VLOOKUP('ELC_Gen-sdj'!$B27,'ELC_Gen-sdj'!$AA$4:$AC$19,3,FALSE)) -> 657.51437 | G27: =VLOOKUP(G$22,ovrcst!$A$5:$W$36,VLOOKUP('ELC_Gen-sdj'!$B27,'ELC_Gen-sdj'!$AA$4:$AC$19,3,FALSE)) -> 625.44563 | H27: =VLOOKUP(H$22,ovrcst!$A$5:$W$36,VLOOKUP('ELC_Gen-sdj'!$B27,'ELC_Gen-sdj'!$AA$4:$AC$19,3,FALSE)) -> 612.36513 | I27: =VLOOKUP(I$22,ovrcst!$A$5:$W$36,VLOOKUP('ELC_Gen-sdj'!$B27,'ELC_Gen-sdj'!$AA$4:$AC$19,3,FALSE)) -> 599.88018 | J27: =VLOOKUP(J$22,ovrcst!$A$5:$W$36,VLOOKUP('ELC_Gen-sdj'!$B27,'ELC_Gen-sdj'!$AA$4:$AC$19,3,FALSE)) -> 586.79665 | ... AH27: =VLOOKUP(AH$22,ovrcst!$A$5:$W$36,VLOOKUP('ELC_Gen-sdj'!$B27,'ELC_Gen-sdj'!$AA$4:$AC$19,3,FALSE)) -> 440.18226
B28: =B11 -> EN_GasCT | C28: =VLOOKUP(C$22,ovrcst!$A$5:$W$36,VLOOKUP('ELC_Gen-sdj'!$B28,'ELC_Gen-sdj'!$AA$4:$AC$19,3,FALSE)) -> 1126.0024 | D28: =VLOOKUP(D$22,ovrcst!$A$5:$W$36,VLOOKUP('ELC_Gen-sdj'!$B28,'ELC_Gen-sdj'!$AA$4:$AC$19,3,FALSE)) -> 1115.5153 | E28: =VLOOKUP(E$22,ovrcst!$A$5:$W$36,VLOOKUP('ELC_Gen-sdj'!$B28,'ELC_Gen-sdj'!$AA$4:$AC$19,3,FALSE)) -> 1090.3474 | F28: =VLOOKUP(F$22,ovrcst!$A$5:$W$36,VLOOKUP('ELC_Gen-sdj'!$B28,'ELC_Gen-sdj'!$AA$4:$AC$19,3,FALSE)) -> 1075.4584 | G28: =VLOOKUP(G$22,ovrcst!$A$5:$W$36,VLOOKUP('ELC_Gen-sdj'!$B28,'ELC_Gen-sdj'!$AA$4:$AC$19,3,FALSE)) -> 1065.51 | H28: =VLOOKUP(H$22,ovrcst!$A$5:$W$36,VLOOKUP('ELC_Gen-sdj'!$B28,'ELC_Gen-sdj'!$AA$4:$AC$19,3,FALSE)) -> 1057.8824 | I28: =VLOOKUP(I$22,ovrcst!$A$5:$W$36,VLOOKUP('ELC_Gen-sdj'!$B28,'ELC_Gen-sdj'!$AA$4:$AC$19,3,FALSE)) -> 1052.0468 | J28: =VLOOKUP(J$22,ovrcst!$A$5:$W$36,VLOOKUP('ELC_Gen-sdj'!$B28,'ELC_Gen-sdj'!$AA$4:$AC$19,3,FALSE)) -> 1043.6674 | ... AH28: =VLOOKUP(AH$22,ovrcst!$A$5:$W$36,VLOOKUP('ELC_Gen-sdj'!$B28,'ELC_Gen-sdj'!$AA$4:$AC$19,3,FALSE)) -> 809.61793
B29: =B12 -> EN_Biomass | C29: =VLOOKUP(C$22,ovrcst!$A$5:$W$36,VLOOKUP('ELC_Gen-sdj'!$B29,'ELC_Gen-sdj'!$AA$4:$AC$19,3,FALSE)) -> 3899.5783 | D29: =VLOOKUP(D$22,ovrcst!$A$5:$W$36,VLOOKUP('ELC_Gen-sdj'!$B29,'ELC_Gen-sdj'!$AA$4:$AC$19,3,FALSE)) -> 3858.2388 | E29: =VLOOKUP(E$22,ovrcst!$A$5:$W$36,VLOOKUP('ELC_Gen-sdj'!$B29,'ELC_Gen-sdj'!$AA$4:$AC$19,3,FALSE)) -> 3756.4371 | F29: =VLOOKUP(F$22,ovrcst!$A$5:$W$36,VLOOKUP('ELC_Gen-sdj'!$B29,'ELC_Gen-sdj'!$AA$4:$AC$19,3,FALSE)) -> 3698.74 | G29: =VLOOKUP(G$22,ovrcst!$A$5:$W$36,VLOOKUP('ELC_Gen-sdj'!$B29,'ELC_Gen-sdj'!$AA$4:$AC$19,3,FALSE)) -> 3659.7218 | H29: =VLOOKUP(H$22,ovrcst!$A$5:$W$36,VLOOKUP('ELC_Gen-sdj'!$B29,'ELC_Gen-sdj'!$AA$4:$AC$19,3,FALSE)) -> 3628.7298 | I29: =VLOOKUP(I$22,ovrcst!$A$5:$W$36,VLOOKUP('ELC_Gen-sdj'!$B29,'ELC_Gen-sdj'!$AA$4:$AC$19,3,FALSE)) -> 3603.9216 | J29: =VLOOKUP(J$22,ovrcst!$A$5:$W$36,VLOOKUP('ELC_Gen-sdj'!$B29,'ELC_Gen-sdj'!$AA$4:$AC$19,3,FALSE)) -> 3570.4402 | ... AH29: =VLOOKUP(AH$22,ovrcst!$A$5:$W$36,VLOOKUP('ELC_Gen-sdj'!$B29,'ELC_Gen-sdj'!$AA$4:$AC$19,3,FALSE)) -> 2674.7279
B30: =B13 -> EN_ZBiomass | C30: =VLOOKUP(C$22,ovrcst!$A$5:$W$36,VLOOKUP('ELC_Gen-sdj'!$B30,'ELC_Gen-sdj'!$AA$4:$AC$19,3,FALSE)) -> 5715.788 | D30: =VLOOKUP(D$22,ovrcst!$A$5:$W$36,VLOOKUP('ELC_Gen-sdj'!$B30,'ELC_Gen-sdj'!$AA$4:$AC$19,3,FALSE)) -> 5651.6864 | E30: =VLOOKUP(E$22,ovrcst!$A$5:$W$36,VLOOKUP('ELC_Gen-sdj'!$B30,'ELC_Gen-sdj'!$AA$4:$AC$19,3,FALSE)) -> 5513.4993 | F30: =VLOOKUP(F$22,ovrcst!$A$5:$W$36,VLOOKUP('ELC_Gen-sdj'!$B30,'ELC_Gen-sdj'!$AA$4:$AC$19,3,FALSE)) -> 5427.6275 | G30: =VLOOKUP(G$22,ovrcst!$A$5:$W$36,VLOOKUP('ELC_Gen-sdj'!$B30,'ELC_Gen-sdj'!$AA$4:$AC$19,3,FALSE)) -> 5366.8807 | H30: =VLOOKUP(H$22,ovrcst!$A$5:$W$36,VLOOKUP('ELC_Gen-sdj'!$B30,'ELC_Gen-sdj'!$AA$4:$AC$19,3,FALSE)) -> 5317.9442 | I30: =VLOOKUP(I$22,ovrcst!$A$5:$W$36,VLOOKUP('ELC_Gen-sdj'!$B30,'ELC_Gen-sdj'!$AA$4:$AC$19,3,FALSE)) -> 5278.0966 | J30: =VLOOKUP(J$22,ovrcst!$A$5:$W$36,VLOOKUP('ELC_Gen-sdj'!$B30,'ELC_Gen-sdj'!$AA$4:$AC$19,3,FALSE)) -> 5225.5755 | ... AH30: =VLOOKUP(AH$22,ovrcst!$A$5:$W$36,VLOOKUP('ELC_Gen-sdj'!$B30,'ELC_Gen-sdj'!$AA$4:$AC$19,3,FALSE)) -> 3845.2213
B31: =B14 -> EN_OilCCAdv | C31: =C25*1.3 -> 1032.7714 | D31: =D25*1.3 -> 1022.3699 | E31: =E25*1.3 -> 998.5345 | F31: =F25*1.3 -> 984.13712 | G31: =G25*1.3 -> 951.76755 | H31: =H25*1.3 -> 937.25179 | I31: =I25*1.3 -> 923.92807 | J31: =J25*1.3 -> 909.13324 | ... Z31: =Z25*1.3 -> 747.35784 | AA31: =VLOOKUP(AA$22,ovrcst!$A$5:$W$36,VLOOKUP('ELC_Gen-sdj'!$B31,'ELC_Gen-sdj'!$AA$4:$AC$19,3,FALSE)) -> 469.65517 | AB31: =VLOOKUP(AB$22,ovrcst!$A$5:$W$36,VLOOKUP('ELC_Gen-sdj'!$B31,'ELC_Gen-sdj'!$AA$4:$AC$19,3,FALSE)) -> 465.07508 | AC31: =VLOOKUP(AC$22,ovrcst!$A$5:$W$36,VLOOKUP('ELC_Gen-sdj'!$B31,'ELC_Gen-sdj'!$AA$4:$AC$19,3,FALSE)) -> 461.08628 | AD31: =VLOOKUP(AD$22,ovrcst!$A$5:$W$36,VLOOKUP('ELC_Gen-sdj'!$B31,'ELC_Gen-sdj'!$AA$4:$AC$19,3,FALSE)) -> 456.59451 | AE31: =VLOOKUP(AE$22,ovrcst!$A$5:$W$36,VLOOKUP('ELC_Gen-sdj'!$B31,'ELC_Gen-sdj'!$AA$4:$AC$19,3,FALSE)) -> 452.50808 | AF31: =VLOOKUP(AF$22,ovrcst!$A$5:$W$36,VLOOKUP('ELC_Gen-sdj'!$B31,'ELC_Gen-sdj'!$AA$4:$AC$19,3,FALSE)) -> 448.39968 | AG31: =VLOOKUP(AG$22,ovrcst!$A$5:$W$36,VLOOKUP('ELC_Gen-sdj'!$B31,'ELC_Gen-sdj'!$AA$4:$AC$19,3,FALSE)) -> 444.27762 | AH31: =VLOOKUP(AH$22,ovrcst!$A$5:$W$36,VLOOKUP('ELC_Gen-sdj'!$B31,'ELC_Gen-sdj'!$AA$4:$AC$19,3,FALSE)) -> 440.18226
B32: =B15 -> EN_NuclearAdv | C32: =VLOOKUP(C$22,ovrcst!$A$5:$W$36,VLOOKUP('ELC_Gen-sdj'!$B32,'ELC_Gen-sdj'!$AA$4:$AC$19,3,FALSE)) -> 6034.2659 | D32: =VLOOKUP(D$22,ovrcst!$A$5:$W$36,VLOOKUP('ELC_Gen-sdj'!$B32,'ELC_Gen-sdj'!$AA$4:$AC$19,3,FALSE)) -> 5962.7387 | E32: =VLOOKUP(E$22,ovrcst!$A$5:$W$36,VLOOKUP('ELC_Gen-sdj'!$B32,'ELC_Gen-sdj'!$AA$4:$AC$19,3,FALSE)) -> 5813.1538 | F32: =VLOOKUP(F$22,ovrcst!$A$5:$W$36,VLOOKUP('ELC_Gen-sdj'!$B32,'ELC_Gen-sdj'!$AA$4:$AC$19,3,FALSE)) -> 5718.8483 | G32: =VLOOKUP(G$22,ovrcst!$A$5:$W$36,VLOOKUP('ELC_Gen-sdj'!$B32,'ELC_Gen-sdj'!$AA$4:$AC$19,3,FALSE)) -> 5651.0839 | H32: =VLOOKUP(H$22,ovrcst!$A$5:$W$36,VLOOKUP('ELC_Gen-sdj'!$B32,'ELC_Gen-sdj'!$AA$4:$AC$19,3,FALSE)) -> 5595.7971 | I32: =VLOOKUP(I$22,ovrcst!$A$5:$W$36,VLOOKUP('ELC_Gen-sdj'!$B32,'ELC_Gen-sdj'!$AA$4:$AC$19,3,FALSE)) -> 5550.1031 | J32: =VLOOKUP(J$22,ovrcst!$A$5:$W$36,VLOOKUP('ELC_Gen-sdj'!$B32,'ELC_Gen-sdj'!$AA$4:$AC$19,3,FALSE)) -> 5491.1155 | ... AH32: =VLOOKUP(AH$22,ovrcst!$A$5:$W$36,VLOOKUP('ELC_Gen-sdj'!$B32,'ELC_Gen-sdj'!$AA$4:$AC$19,3,FALSE)) -> 3965.6701
B33: EN_ZZGasCC | C33: ='Retrofit costs'!$D$16* 'Retrofit costs'!$G$6*'Retrofit costs'!B50 -> 895.86549 | D33: ='Retrofit costs'!$D$16* 'Retrofit costs'!$G$6*'Retrofit costs'!C50 -> 884.32657 | E33: ='Retrofit costs'!$D$16* 'Retrofit costs'!$G$6*'Retrofit costs'!D50 -> 861.23568 | F33: ='Retrofit costs'!$D$16* 'Retrofit costs'!$G$6*'Retrofit costs'!E50 -> 846.36364 | G33: ='Retrofit costs'!$D$16* 'Retrofit costs'!$G$6*'Retrofit costs'!F50 -> 822.31083 | H33: ='Retrofit costs'!$D$16* 'Retrofit costs'!$G$6*'Retrofit costs'!G50 -> 809.28199 | I33: ='Retrofit costs'!$D$16* 'Retrofit costs'!$G$6*'Retrofit costs'!H50 -> 797.41377 | J33: ='Retrofit costs'!$D$16* 'Retrofit costs'!$G$6*'Retrofit costs'!I50 -> 784.08453 | ... AH33: ='Retrofit costs'!$D$16* 'Retrofit costs'!$G$6*'Retrofit costs'!AG50 -> 547.86341
B34: EN_ZZCOAIGCC | C34: ='Retrofit costs'!$C$34*'Retrofit costs'!$G$6*'Retrofit costs'!B51 -> 2357.7759 | D34: ='Retrofit costs'!$C$34*'Retrofit costs'!$G$6*'Retrofit costs'!C51 -> 2331.3338 | E34: ='Retrofit costs'!$C$34*'Retrofit costs'!$G$6*'Retrofit costs'!D51 -> 2274.3314 | F34: ='Retrofit costs'!$C$34*'Retrofit costs'!$G$6*'Retrofit costs'!E51 -> 2238.909 | G34: ='Retrofit costs'!$C$34*'Retrofit costs'!$G$6*'Retrofit costs'!F51 -> 2213.8508 | H34: ='Retrofit costs'!$C$34*'Retrofit costs'!$G$6*'Retrofit costs'!G51 -> 2193.6644 | I34: ='Retrofit costs'!$C$34*'Retrofit costs'!$G$6*'Retrofit costs'!H51 -> 2177.2272 | J34: ='Retrofit costs'!$C$34*'Retrofit costs'!$G$6*'Retrofit costs'!I51 -> 2155.5621 | ... AH34: ='Retrofit costs'!$C$34*'Retrofit costs'!$G$6*'Retrofit costs'!AG51 -> 1586.1628
B37: ~FI_T: EFF
B38: TechName | C38: 2019 | D38: 2020 | E38: 2021 | F38: 2022 | G38: 2023 | H38: 2024 | I38: 2025 | J38: 2026 | K38: 2027 | L38: 2028 | M38: 2029 | N38: 2030 | O38: 2031 | P38: 2032 | Q38: 2033 | R38: 2034 | S38: 2035 | T38: 2036 | U38: 2037 | V38: 2038 | W38: 2039 | X38: 2040 | Y38: 2041 | Z38: 2042 | AA38: 2043 | AB38: 2044 | AC38: 2045 | AD38: 2046 | AE38: 2047 | AF38: 2048 | AG38: 2049 | AH38: 2050
B39: =B23 -> EN_ZCOAIGCC | C39: =VLOOKUP(C$22,heatrate!$K$5:$T$36,VLOOKUP('ELC_Gen-sdj'!$B37,'ELC_Gen-sdj'!$AA$4:$AD$19,4,FALSE)) -> 0.2929032 | D39: =VLOOKUP(D$22,heatrate!$K$5:$T$36,VLOOKUP('ELC_Gen-sdj'!$B37,'ELC_Gen-sdj'!$AA$4:$AD$19,4,FALSE)) -> 0.2929032 | E39: =VLOOKUP(E$22,heatrate!$K$5:$T$36,VLOOKUP('ELC_Gen-sdj'!$B37,'ELC_Gen-sdj'!$AA$4:$AD$19,4,FALSE)) -> 0.2929032 | F39: =VLOOKUP(F$22,heatrate!$K$5:$T$36,VLOOKUP('ELC_Gen-sdj'!$B37,'ELC_Gen-sdj'!$AA$4:$AD$19,4,FALSE)) -> 0.2929032 | G39: =VLOOKUP(G$22,heatrate!$K$5:$T$36,VLOOKUP('ELC_Gen-sdj'!$B37,'ELC_Gen-sdj'!$AA$4:$AD$19,4,FALSE)) -> 0.31443213 | H39: =VLOOKUP(H$22,heatrate!$K$5:$T$36,VLOOKUP('ELC_Gen-sdj'!$B37,'ELC_Gen-sdj'!$AA$4:$AD$19,4,FALSE)) -> 0.33937697 | I39: =VLOOKUP(I$22,heatrate!$K$5:$T$36,VLOOKUP('ELC_Gen-sdj'!$B37,'ELC_Gen-sdj'!$AA$4:$AD$19,4,FALSE)) -> 0.36862075 | J39: =VLOOKUP(J$22,heatrate!$K$5:$T$36,VLOOKUP('ELC_Gen-sdj'!$B37,'ELC_Gen-sdj'!$AA$4:$AD$19,4,FALSE)) -> 0.36862075 | ... AH39: =VLOOKUP(AH$22,heatrate!$K$5:$T$36,VLOOKUP('ELC_Gen-sdj'!$B37,'ELC_Gen-sdj'!$AA$4:$AD$19,4,FALSE)) -> 0.36862075
B40: =B24 -> EN_ZGasCCAdv | C40: =VLOOKUP(C$22,heatrate!$K$5:$T$36,VLOOKUP('ELC_Gen-sdj'!$B38,'ELC_Gen-sdj'!$AA$4:$AD$19,4,FALSE)) -> 0.45346475 | D40: =VLOOKUP(D$22,heatrate!$K$5:$T$36,VLOOKUP('ELC_Gen-sdj'!$B38,'ELC_Gen-sdj'!$AA$4:$AD$19,4,FALSE)) -> 0.45346475 | E40: =VLOOKUP(E$22,heatrate!$K$5:$T$36,VLOOKUP('ELC_Gen-sdj'!$B38,'ELC_Gen-sdj'!$AA$4:$AD$19,4,FALSE)) -> 0.45346475 | F40: =VLOOKUP(F$22,heatrate!$K$5:$T$36,VLOOKUP('ELC_Gen-sdj'!$B38,'ELC_Gen-sdj'!$AA$4:$AD$19,4,FALSE)) -> 0.45394736 | G40: =VLOOKUP(G$22,heatrate!$K$5:$T$36,VLOOKUP('ELC_Gen-sdj'!$B38,'ELC_Gen-sdj'!$AA$4:$AD$19,4,FALSE)) -> 0.45443099 | H40: =VLOOKUP(H$22,heatrate!$K$5:$T$36,VLOOKUP('ELC_Gen-sdj'!$B38,'ELC_Gen-sdj'!$AA$4:$AD$19,4,FALSE)) -> 0.45491565 | I40: =VLOOKUP(I$22,heatrate!$K$5:$T$36,VLOOKUP('ELC_Gen-sdj'!$B38,'ELC_Gen-sdj'!$AA$4:$AD$19,4,FALSE)) -> 0.45540134 | J40: =VLOOKUP(J$22,heatrate!$K$5:$T$36,VLOOKUP('ELC_Gen-sdj'!$B38,'ELC_Gen-sdj'!$AA$4:$AD$19,4,FALSE)) -> 0.45540134 | ... AH40: =VLOOKUP(AH$22,heatrate!$K$5:$T$36,VLOOKUP('ELC_Gen-sdj'!$B38,'ELC_Gen-sdj'!$AA$4:$AD$19,4,FALSE)) -> 0.45540134
B41: =B25 -> EN_GasCCAdv | C41: =VLOOKUP(C$22,heatrate!$K$5:$T$36,VLOOKUP('ELC_Gen-sdj'!$B39,'ELC_Gen-sdj'!$AA$4:$AD$19,4,FALSE)) -> 0.54163846 | D41: =VLOOKUP(D$22,heatrate!$K$5:$T$36,VLOOKUP('ELC_Gen-sdj'!$B39,'ELC_Gen-sdj'!$AA$4:$AD$19,4,FALSE)) -> 0.54163846 | E41: =VLOOKUP(E$22,heatrate!$K$5:$T$36,VLOOKUP('ELC_Gen-sdj'!$B39,'ELC_Gen-sdj'!$AA$4:$AD$19,4,FALSE)) -> 0.54163846 | F41: =VLOOKUP(F$22,heatrate!$K$5:$T$36,VLOOKUP('ELC_Gen-sdj'!$B39,'ELC_Gen-sdj'!$AA$4:$AD$19,4,FALSE)) -> 0.54379638 | G41: =VLOOKUP(G$22,heatrate!$K$5:$T$36,VLOOKUP('ELC_Gen-sdj'!$B39,'ELC_Gen-sdj'!$AA$4:$AD$19,4,FALSE)) -> 0.54597156 | H41: =VLOOKUP(H$22,heatrate!$K$5:$T$36,VLOOKUP('ELC_Gen-sdj'!$B39,'ELC_Gen-sdj'!$AA$4:$AD$19,4,FALSE)) -> 0.54816422 | I41: =VLOOKUP(I$22,heatrate!$K$5:$T$36,VLOOKUP('ELC_Gen-sdj'!$B39,'ELC_Gen-sdj'!$AA$4:$AD$19,4,FALSE)) -> 0.55037456 | J41: =VLOOKUP(J$22,heatrate!$K$5:$T$36,VLOOKUP('ELC_Gen-sdj'!$B39,'ELC_Gen-sdj'!$AA$4:$AD$19,4,FALSE)) -> 0.55037456 | ... AH41: =VLOOKUP(AH$22,heatrate!$K$5:$T$36,VLOOKUP('ELC_Gen-sdj'!$B39,'ELC_Gen-sdj'!$AA$4:$AD$19,4,FALSE)) -> 0.55037456
B42: =B26 -> EN_GasCC | C42: =VLOOKUP(C$22,heatrate!$K$5:$T$36,VLOOKUP('ELC_Gen-sdj'!$B40,'ELC_Gen-sdj'!$AA$4:$AD$19,4,FALSE)) -> 0.51701853 | D42: =VLOOKUP(D$22,heatrate!$K$5:$T$36,VLOOKUP('ELC_Gen-sdj'!$B40,'ELC_Gen-sdj'!$AA$4:$AD$19,4,FALSE)) -> 0.51701853 | E42: =VLOOKUP(E$22,heatrate!$K$5:$T$36,VLOOKUP('ELC_Gen-sdj'!$B40,'ELC_Gen-sdj'!$AA$4:$AD$19,4,FALSE)) -> 0.51701853 | F42: =VLOOKUP(F$22,heatrate!$K$5:$T$36,VLOOKUP('ELC_Gen-sdj'!$B40,'ELC_Gen-sdj'!$AA$4:$AD$19,4,FALSE)) -> 0.52196134 | G42: =VLOOKUP(G$22,heatrate!$K$5:$T$36,VLOOKUP('ELC_Gen-sdj'!$B40,'ELC_Gen-sdj'!$AA$4:$AD$19,4,FALSE)) -> 0.52699958 | H42: =VLOOKUP(H$22,heatrate!$K$5:$T$36,VLOOKUP('ELC_Gen-sdj'!$B40,'ELC_Gen-sdj'!$AA$4:$AD$19,4,FALSE)) -> 0.53213603 | I42: =VLOOKUP(I$22,heatrate!$K$5:$T$36,VLOOKUP('ELC_Gen-sdj'!$B40,'ELC_Gen-sdj'!$AA$4:$AD$19,4,FALSE)) -> 0.53737359 | J42: =VLOOKUP(J$22,heatrate!$K$5:$T$36,VLOOKUP('ELC_Gen-sdj'!$B40,'ELC_Gen-sdj'!$AA$4:$AD$19,4,FALSE)) -> 0.53737359 | ... AH42: =VLOOKUP(AH$22,heatrate!$K$5:$T$36,VLOOKUP('ELC_Gen-sdj'!$B40,'ELC_Gen-sdj'!$AA$4:$AD$19,4,FALSE)) -> 0.53737359
B43: =B27 -> EN_GasCTAdv | C43: =VLOOKUP(C$22,heatrate!$K$5:$T$36,VLOOKUP('ELC_Gen-sdj'!$B41,'ELC_Gen-sdj'!$AA$4:$AD$19,4,FALSE)) -> 0.34819615 | D43: =VLOOKUP(D$22,heatrate!$K$5:$T$36,VLOOKUP('ELC_Gen-sdj'!$B41,'ELC_Gen-sdj'!$AA$4:$AD$19,4,FALSE)) -> 0.34819615 | E43: =VLOOKUP(E$22,heatrate!$K$5:$T$36,VLOOKUP('ELC_Gen-sdj'!$B41,'ELC_Gen-sdj'!$AA$4:$AD$19,4,FALSE)) -> 0.35731123 | F43: =VLOOKUP(F$22,heatrate!$K$5:$T$36,VLOOKUP('ELC_Gen-sdj'!$B41,'ELC_Gen-sdj'!$AA$4:$AD$19,4,FALSE)) -> 0.36691637 | G43: =VLOOKUP(G$22,heatrate!$K$5:$T$36,VLOOKUP('ELC_Gen-sdj'!$B41,'ELC_Gen-sdj'!$AA$4:$AD$19,4,FALSE)) -> 0.37705219 | H43: =VLOOKUP(H$22,heatrate!$K$5:$T$36,VLOOKUP('ELC_Gen-sdj'!$B41,'ELC_Gen-sdj'!$AA$4:$AD$19,4,FALSE)) -> 0.38776389 | I43: =VLOOKUP(I$22,heatrate!$K$5:$T$36,VLOOKUP('ELC_Gen-sdj'!$B41,'ELC_Gen-sdj'!$AA$4:$AD$19,4,FALSE)) -> 0.39910202 | J43: =VLOOKUP(J$22,heatrate!$K$5:$T$36,VLOOKUP('ELC_Gen-sdj'!$B41,'ELC_Gen-sdj'!$AA$4:$AD$19,4,FALSE)) -> 0.39910202 | ... AH43: =VLOOKUP(AH$22,heatrate!$K$5:$T$36,VLOOKUP('ELC_Gen-sdj'!$B41,'ELC_Gen-sdj'!$AA$4:$AD$19,4,FALSE)) -> 0.39910202
B44: =B28 -> EN_GasCT | C44: =VLOOKUP(C$22,heatrate!$K$5:$T$36,VLOOKUP('ELC_Gen-sdj'!$B42,'ELC_Gen-sdj'!$AA$4:$AD$19,4,FALSE)) -> 0.34678072 | D44: =VLOOKUP(D$22,heatrate!$K$5:$T$36,VLOOKUP('ELC_Gen-sdj'!$B42,'ELC_Gen-sdj'!$AA$4:$AD$19,4,FALSE)) -> 0.34819615 | E44: =VLOOKUP(E$22,heatrate!$K$5:$T$36,VLOOKUP('ELC_Gen-sdj'!$B42,'ELC_Gen-sdj'!$AA$4:$AD$19,4,FALSE)) -> 0.34962318 | F44: =VLOOKUP(F$22,heatrate!$K$5:$T$36,VLOOKUP('ELC_Gen-sdj'!$B42,'ELC_Gen-sdj'!$AA$4:$AD$19,4,FALSE)) -> 0.35106196 | G44: =VLOOKUP(G$22,heatrate!$K$5:$T$36,VLOOKUP('ELC_Gen-sdj'!$B42,'ELC_Gen-sdj'!$AA$4:$AD$19,4,FALSE)) -> 0.35251263 | H44: =VLOOKUP(H$22,heatrate!$K$5:$T$36,VLOOKUP('ELC_Gen-sdj'!$B42,'ELC_Gen-sdj'!$AA$4:$AD$19,4,FALSE)) -> 0.35397534 | I44: =VLOOKUP(I$22,heatrate!$K$5:$T$36,VLOOKUP('ELC_Gen-sdj'!$B42,'ELC_Gen-sdj'!$AA$4:$AD$19,4,FALSE)) -> 0.35545024 | J44: =VLOOKUP(J$22,heatrate!$K$5:$T$36,VLOOKUP('ELC_Gen-sdj'!$B42,'ELC_Gen-sdj'!$AA$4:$AD$19,4,FALSE)) -> 0.35545024 | ... AH44: =VLOOKUP(AH$22,heatrate!$K$5:$T$36,VLOOKUP('ELC_Gen-sdj'!$B42,'ELC_Gen-sdj'!$AA$4:$AD$19,4,FALSE)) -> 0.35545024
...

Sheet ELC_Accounting
J5: ~FI_T
D6: Sets | E6: Unts | F6: TechName | G6: Comm-IN-A | H6: Comm-IN | I6: Comm-OUT | J6: YEAR | K6: Input | L6: EFF | M6: Cap2Act | N6: START | O6: LIFE
D7: \I: Units | M7: kt/kt-a
F8: CAPTURE_ELC | H8: ELCCO2-Seq | I8: CO2Captured | K8: 1 | N8: 2010 | O8: 100
F9: CAPTURE_SUP | H9: SUPCO2-Seq | I9: CO2Captured | K9: 1 | N9: 2010 | O9: 100
E16: ~FI_Process
E17: Sets | F17: TechName | G17: TechDesc | H17: Tact | I17: Tcap | J17: Tslvl | K17: PrimaryCG | L17: Vintage
E18: PRE | F18: CAPTURE_ELC | G18: Capture - Electricity and Cogeneration Power Plants | H18: kt | I18: kt-a | L18: NO
E19: PRE | F19: CAPTURE_SUP | G19: Capture - Supply side | H19: kt | I19: kt-a | L19: NO
E25: TobeAdded when industrial supply curve will be modelled
E26: PRE | F26: CAPTURE_IND | G26: Capture - Industrial facilities | H26: kt | I26: kt-a | L26: NO

Sheet ovrcst
A1: Overnight cost by technology and online year - AEO2019 Reference case
A2: 2018 $/KW
A4: Online Year | B4: Coal with 30% CCS | C4: Coal with 90% CCS | D4: Internal Combustion | E4: Comb. Turb | F4: Adv. CT | G4: Comb. Cyc | H4: Adv CC | I4: Adv CC w/seq | J4: Fuel Cell | K4: Nuclear | L4: Biomass | M4: Geothermal | N4: Landfill Gas | O4: Hydro | P4: Battery Storage | Q4: Wind | R4: Offshore Wind | S4: Solar Thermal | T4: Solar PV - tracking | U4: Solar PV - fixed tilt | V4: Dist. Gen Base | W4: Dist Gen Peak
A5: 2019 | B5: 5168.6426 | C5: 5715.788 | D5: 1371.3094 | E5: 1126.0024 | F5: 691.07682 | G5: 999.32722 | H5: 794.43952 | I5: 2204.7527 | J5: 7197.3476 | K5: 6034.2659 | L5: 3899.5783 | M5: 2786.5503 | N5: 8894.7868 | O5: 2947.7593 | P5: 1950.3366 | Q5: 1919.9305 | R5: 6541.9375 | S5: 4291.3345 | T5: 2160.2097 | U5: 2024.4633 | V5: 1576.4642 | W5: 1893.7526
A6: 2020 | B6: 5110.6771 | C6: 5651.6864 | D6: 1358.5378 | E6: 1115.5153 | F6: 683.76621 | G6: 990.01963 | H6: 786.43841 | I6: 2176.3551 | J6: 7055.6868 | K6: 5962.7387 | L6: 3858.2388 | M6: 2753.52 | N6: 8811.9451 | O6: 2920.3037 | P6: 1858.2925 | Q6: 1902.049 | R6: 6455.9899 | S6: 4240.3061 | T6: 2065.762 | U6: 1935.9506 | V6: 1557.7777 | W6: 1871.3051
A7: 2021 | B7: 4985.7178 | C7: 5513.4993 | D7: 1327.8869 | E7: 1090.3474 | F7: 667.4804 | G7: 967.68334 | H7: 768.10346 | I7: 2119.5277 | J7: 6629.8438 | K7: 5813.1538 | L7: 3756.4371 | M7: 2684.4434 | N7: 8613.1331 | O7: 2854.4155 | P7: 1795.5102 | Q7: 1859.1357 | R7: 6285.7541 | S7: 4133.7728 | T7: 1979.5232 | U7: 1855.131 | V7: 1518.6983 | W7: 1824.3605
A8: 2022 | B8: 4908.0667 | C8: 5427.6275 | D8: 1309.7543 | E8: 1075.4584 | F8: 657.51437 | G8: 954.4694 | H8: 757.02855 | I8: 2082.9271 | J8: 6485.3511 | K8: 5718.8483 | L8: 3698.74 | M8: 2607.0372 | N8: 8495.519 | O8: 2815.4363 | P8: 1746.7543 | Q8: 1833.7488 | R8: 6175.5557 | S8: 4066.5532 | T8: 1890.4494 | U8: 1771.6547 | V8: 1494.0608 | W8: 1757.7586
A9: 2023 | B9: 4853.1345 | C9: 5366.8807 | D9: 1297.6385 | E9: 1065.51 | F9: 625.44563 | G9: 945.63999 | H9: 732.12889 | I9: 2023.7324 | J9: 6369.8669 | K9: 5651.0839 | L9: 3659.7218 | M9: 2561.7673 | N9: 8416.9305 | O9: 2789.3909 | P9: 1672.8367 | Q9: 1816.7858 | R9: 6094.1665 | S9: 4018.2098 | T9: 1819.6351 | U9: 1705.2902 | V9: 1476.3571 | W9: 1658.6332
A10: 2024 | B10: 4808.8826 | C10: 5317.9442 | D10: 1288.3491 | E10: 1057.8824 | F10: 612.36513 | G10: 938.87054 | H10: 720.96291 | I10: 1991.6681 | J10: 6268.8924 | K10: 5595.7971 | L10: 3628.7298 | M10: 2498.3133 | N10: 8356.677 | O10: 2769.4211 | P10: 1616.8543 | Q10: 1803.7799 | R10: 6026.3287 | S10: 3978.7404 | T10: 1798.8233 | U10: 1685.7861 | V10: 1461.9132 | W10: 1568.4124
A11: 2025 | B11: 4772.8495 | C11: 5278.0966 | D11: 1281.2422 | E11: 1052.0468 | F11: 599.88018 | G11: 933.69142 | H11: 710.7139 | I11: 1962.46 | J11: 6178.9637 | K11: 5550.1031 | L11: 3603.9216 | M11: 2445.8588 | N11: 8310.5787 | O11: 2754.1423 | P11: 1572.9774 | Q11: 1793.8296 | R11: 5968.8836 | S11: 3946.0934 | T11: 1782.1759 | U11: 1670.1848 | V11: 1449.9756 | W11: 1485.5623
A12: 2026 | B12: 4725.3567 | C12: 5225.5755 | D12: 1271.0375 | E12: 1043.6674 | F12: 586.79665 | G12: 926.25482 | H12: 699.33326 | I12: 1929.6563 | J12: 6074.5643 | K12: 5491.1155 | L12: 3570.4402 | M12: 2378.4937 | N12: 8244.3873 | O12: 2732.2051 | P12: 1531.6347 | Q12: 1779.5424 | R12: 5897.2115 | S12: 3903.9953 | T12: 1768.2437 | U12: 1657.1283 | V12: 1434.565 | W12: 1403.6336
A13: 2027 | B13: 4668.5434 | C13: 5162.7493 | D13: 1258.2928 | E13: 1033.2027 | F13: 573.38688 | G13: 916.96743 | H13: 687.13796 | I13: 1894.1683 | J13: 5958.7454 | K13: 5421.3468 | L13: 3529.8863 | M13: 2256.5214 | N13: 8161.7215 | O13: 2704.8083 | P13: 1495.6826 | Q13: 1761.6991 | R13: 5814.0691 | S13: 3854.2348 | T13: 1750.8764 | U13: 1640.8525 | V13: 1416.3377 | W13: 1384.1294
A14: 2028 | B14: 4605.1159 | C14: 5092.6074 | D14: 1243.7232 | E14: 1021.2394 | F14: 563.08422 | G14: 906.3499 | H14: 676.65862 | I14: 1861.1016 | J14: 5835.1979 | K14: 5343.9588 | L14: 3484.2914 | M14: 2199.7975 | N14: 8067.2182 | O14: 2673.488 | P14: 1457.9031 | Q14: 1741.3005 | R14: 5722.8908 | S14: 3799.0599 | T14: 1731.4284 | U14: 1622.6265 | V14: 1396.1201 | W14: 1362.708
A15: 2029 | B15: 4540.0401 | C15: 5020.6421 | D15: 1228.6608 | E15: 1008.8714 | F15: 552.6894 | G15: 895.37336 | H15: 666.00143 | I15: 1827.586 | J15: 5710.3623 | K15: 5264.7273 | L15: 3437.404 | M15: 2141.3782 | N15: 7969.5182 | O15: 2641.1086 | P15: 1419.9291 | Q15: 1720.2121 | R15: 5629.8919 | S15: 3742.5772 | T15: 1711.2789 | U15: 1603.7432 | V15: 1375.4207 | W15: 1340.8476
A16: 2030 | B16: 4482.7057 | C16: 4957.2381 | D16: 1215.6489 | E16: 998.18723 | F16: 545.18176 | G16: 885.89111 | H16: 657.80878 | I16: 1799.7582 | J16: 5596.0191 | K16: 5194.5399 | L16: 3396.3367 | M16: 2094.6308 | N16: 7885.1187 | O16: 2613.1372 | P16: 1384.6848 | Q16: 1701.9946 | R16: 5546.7102 | S16: 3692.5267 | T16: 1693.9712 | U16: 1587.5229 | V16: 1357.0839 | W16: 1321.32
... A36: 2050 | B36: 3477.1364 | C36: 3845.2213 | D36: 985.99858 | E36: 809.61793 | F36: 440.18226 | G36: 718.53584 | H36: 532.1579 | I36: 1348.3088 | J36: 3612.6634 | K36: 3965.6701 | L36: 2674.7279 | M36: 2690.8333 | N36: 6395.5272 | O36: 2119.4607 | P36: 1019.9226 | Q36: 1380.4678 | R36: 4094.7516 | S36: 2816.3074 | T36: 1425.6793 | U36: 1336.0904 | V36: 1036.0393 | W36: 1049.6275

Sheet heatrate
A1: Heatrate assumptions by year - AEO2019
A2: (BTU/kWh)
L3: =3.6/1.055 -> 3.4123223
A4: Online Year | B4: Coal with 30% CCS | C4: Coal with 90% CCS | D4: Internal Combustion | E4: Comb. Turb | F4: Adv. CT | G4: Comb. Cyc | H4: Adv CC | I4: Adv CC w/seq | J4: Fuel Cell | K4: =A4 -> Online Year | L4: =B4 -> Coal with 30% CCS | M4: =C4 -> Coal with 90% CCS | N4: =D4 -> Internal Combustion | O4: =E4 -> Comb. Turb | P4: =F4 -> Adv. CT | Q4: =G4 -> Comb. Cyc | R4: =H4 -> Adv CC | ... T4: =J4 -> Fuel Cell
A5: 2019 | B5: 9750 | C5: 11650 | D5: 8500 | E5: 9840 | F5: 9800 | G5: 6600 | H5: 6300 | I5: 7525 | J5: 9500 | K5: =A5 -> 2019 | L5: =1000/(B5/$L$3) -> 0.34998177 | M5: =1000/(C5/$L$3) -> 0.2929032 | N5: =1000/(D5/$L$3) -> 0.40144968 | O5: =1000/(E5/$L$3) -> 0.34678072 | P5: =1000/(F5/$L$3) -> 0.34819615 | Q5: =1000/(G5/$L$3) -> 0.51701853 | R5: =1000/(H5/$L$3) -> 0.54163846 | S5: =1000/(I5/$L$3) -> 0.45346475 | T5: =1000/(J5/$L$3) -> 0.35919182
