Workbook

Sheet readme
A1: analyst assumptions
A2: to be used only with india subnational model
A3: such files will be needed for all subnat models

Sheet wind_existing_cap
A1: *to be allocated to techs, depending on class-wise potentials
A4: Region | B4: PASTI
A5: IND | B5: 0.03052216
A6: IND-AP | B6: 6.0988824
A7: IND-DL | B7: 0.13318761
A8: IND-GJ | B8: 8.8680747
A9: IND-KA | B9: 6.4540494
A10: IND-KL | B10: 0.1859077
A11: IND-MH | B11: 8.3935939
A12: IND-MP | B12: 3.632137
A13: IND-RJ | B13: 5.7104186
A14: IND-TG | B14: 0.27469944
A15: IND-TN | B15: 7.0783663

Sheet cap bnd
BH1: this came from Manussawee
AM2: process | AN2: 0 | AO2: 2010 | AU2: State | AV2: C1 | AW2: C2 | AX2: C3 | AY2: C4 | AZ2: C5 | BA2: C6 | BB2: C7 | BC2: C8 | BD2: C9 | BE2: Total | BH2: State | BI2: C1 | BJ2: C2 | BK2: C3 | BL2: C4 | BM2: C5 | BN2: C6 | BO2: C7 | BP2: C8 | BQ2: C9 | BR2: Total
AM3: E_WON_Far_C1_IND | AN3: 3 | AO3: 0.14525 | AP3: =MID(AM3,11,2) -> C1 | AQ3: C6 | AR3: =SUMIF($AP$3:$AP$15,AQ3,$AO$3:$AO$15) -> 22.327 | AT3: IND-AN | AU3: Andaman and Nicobar | AV3: =BI3/BI$38 -> 4.3985326e-06 | AW3: =BJ3/BJ$38 -> 7.1355891e-05 | AX3: =BK3/BK$38 -> 0.00013506991 | AY3: =BL3/BL$38 -> 0.00048990852 | AZ3: =BM3/BM$38 -> 0.0012009817 | BA3: =BN3/BN$38 -> 8.9577641e-05 | BB3: 0 | BC3: 0 | BD3: 0 | BE3: 554 | BH3: Andaman and Nicobar | BI3: 11 | BJ3: 127 | BK3: 136 | BL3: 233 | BM3: 46 | BN3: 2 | BO3: 0 | BP3: 0 | BQ3: 0 | BR3: 554
AM4: E_WON_Far_C4_IND | AN4: 3 | AO4: 0.416 | AP4: =MID(AM4,11,2) -> C4 | AQ4: C5 | AR4: =SUMIF($AP$3:$AP$15,AQ4,$AO$3:$AO$15) -> 38.3015 | AT4: IND-AP | AU4: Andhra Pradesh | AV4: =BI4/BI$38 -> 0.018834517 | AW4: =BJ4/BJ$38 -> 0.053470846 | AX4: =BK4/BK$38 -> 0.078926512 | AY4: =BL4/BL$38 -> 0.0369534 | AZ4: =BM4/BM$38 -> 0.026473813 | BA4: =BN4/BN$38 -> 0.0063600125 | BB4: 0 | BC4: 0 | BD4: 0 | BE4: 240471 | BH4: Andhra Pradesh | BI4: 47102 | BJ4: 95168 | BK4: 79470 | BL4: 17575 | BM4: 1014 | BN4: 142 | BO4: 0 | BP4: 0 | BQ4: 0 | BR4: 240471
AM5: E_WON_Near_C1_IND | AN5: 3 | AO5: 2414.211 | AP5: =MID(AM5,12,2) -> C1 | AQ5: C4 | AR5: =SUMIF($AP$3:$AP$15,AQ5,$AO$3:$AO$15) -> 475.599 | AT5: IND-AR | AU5: Arunachal Pradesh | AV5: =BI5/BI$38 -> 0.0023796062 | AW5: =BJ5/BJ$38 -> 0.0015125201 | AX5: =BK5/BK$38 -> 0.0032178419 | AY5: =BL5/BL$38 -> 0.014583714 | AZ5: =BM5/BM$38 -> 0.035193985 | BA5: =BN5/BN$38 -> 0.067496753 | BB5: 0 | BC5: 0 | BD5: 0 | BE5: 21674 | BH5: Arunachal Pradesh | BI5: 5951 | BJ5: 2692 | BK5: 3240 | BL5: 6936 | BM5: 1348 | BN5: 1507 | BO5: 0 | BP5: 0 | BQ5: 0 | BR5: 21674
AM6: E_WON_Near_C2_IND | AN6: 3 | AO6: 1743.9427 | AP6: =MID(AM6,12,2) -> C2 | AQ6: C3 | AR6: =SUMIF($AP$3:$AP$15,AQ6,$AO$3:$AO$15) -> 1006.8862 | AT6: IND-AS | AU6: Assam | AV6: =BI6/BI$38 -> 0.0061683422 | AW6: =BJ6/BJ$38 -> 0.00037082589 | AX6: =BK6/BK$38 -> 0 | AY6: =BL6/BL$38 -> 0 | AZ6: =BM6/BM$38 -> 0 | BA6: =BN6/BN$38 -> 0 | BB6: 0 | BC6: 0 | BD6: 0 | BE6: 16086 | BH6: Assam | BI6: 15426 | BJ6: 660 | BK6: 0 | BL6: 0 | BM6: 0 | BN6: 0 | BO6: 0 | BP6: 0 | BQ6: 0 | BR6: 16086
AM7: E_WON_Near_C3_IND | AN7: 3 | AO7: 975.94675 | AP7: =MID(AM7,12,2) -> C3 | AQ7: C2 | AR7: =SUMIF($AP$3:$AP$15,AQ7,$AO$3:$AO$15) -> 1779.8107 | AT7: IND-BR | AU7: Bihar | AV7: =BI7/BI$38 -> 0.044288026 | AW7: =BJ7/BJ$38 -> 0.0048415253 | AX7: =BK7/BK$38 -> 0 | AY7: =BL7/BL$38 -> 0 | AZ7: =BM7/BM$38 -> 0 | BA7: =BN7/BN$38 -> 0 | BB7: 0 | BC7: 0 | BD7: 0 | BE7: 119374 | BH7: Bihar | BI7: 110757 | BJ7: 8617 | BK7: 0 | BL7: 0 | BM7: 0 | BN7: 0 | BO7: 0 | BP7: 0 | BQ7: 0 | BR7: 119374
AM8: E_WON_Near_C4_IND | AN8: 3 | AO8: 467.6225 | AP8: =MID(AM8,12,2) -> C4 | AQ8: C1 | AR8: =SUMIF($AP$3:$AP$15,AQ8,$AO$3:$AO$15) -> 2500.8342 | AU8: Chandigarh | AV8: =BI8/BI$38 -> 5.6781058e-05 | AW8: =BJ8/BJ$38 -> 0 | AX8: =BK8/BK$38 -> 0 | AY8: =BL8/BL$38 -> 0 | AZ8: =BM8/BM$38 -> 0 | BA8: =BN8/BN$38 -> 0 | BB8: 0 | BC8: 0 | BD8: 0 | BE8: 142 | BH8: Chandigarh | BI8: 142 | BJ8: 0 | BK8: 0 | BL8: 0 | BM8: 0 | BN8: 0 | BO8: 0 | BP8: 0 | BQ8: 0 | BR8: 142
AM9: E_WON_Near_C5_IND | AN9: 3 | AO9: 32.7165 | AP9: =MID(AM9,12,2) -> C5 | AT9: IND-CT | AU9: Chhattisgarh | AV9: =BI9/BI$38 -> 0.06708522 | AW9: =BJ9/BJ$38 -> 0.00097931747 | AX9: =BK9/BK$38 -> 0.0001122272 | AY9: =BL9/BL$38 -> 0 | AZ9: =BM9/BM$38 -> 0 | BA9: =BN9/BN$38 -> 0 | BB9: 0 | BC9: 0 | BD9: 0 | BE9: 169625 | BH9: Chhattisgarh | BI9: 167769 | BJ9: 1743 | BK9: 113 | BL9: 0 | BM9: 0 | BN9: 0 | BO9: 0 | BP9: 0 | BQ9: 0 | BR9: 169625
C10: C6 | D10: =SUMIF($AT$43:$AT$48,$C10,AU$43:AU$48) -> 8.9577641e-05 | E10: =SUMIF($AT$43:$AT$48,$C10,AV$43:AV$48) -> 0.0063600125 | F10: =SUMIF($AT$43:$AT$48,$C10,AW$43:AW$48) -> 0.067496753 | G10: =SUMIF($AT$43:$AT$48,$C10,AX$43:AX$48) -> 0 | H10: =SUMIF($AT$43:$AT$48,$C10,AY$43:AY$48) -> 0 | I10: =SUMIF($AT$43:$AT$48,$C10,AZ$43:AZ$48) -> 0 | J10: =SUMIF($AT$43:$AT$48,$C10,BA$43:BA$48) -> 0 | K10: =SUMIF($AT$43:$AT$48,$C10,BB$43:BB$48) -> 0 | ... AK10: =SUMIF($AT$43:$AT$48,$C10,CB$43:CB$48) -> 0 | AM10: E_WON_Near_C6_IND | AN10: 3 | AO10: 22.327 | AP10: =MID(AM10,12,2) -> C6 | AT10: IND-DD | AU10: Dadra and Nagar Haveli | AV10: =BI10/BI$38 -> 0.0002431189 | AW10: =BJ10/BJ$38 -> 0.00033486702 | AX10: =BK10/BK$38 -> 0.00011322036 | AY10: =BL10/BL$38 -> 0 | AZ10: =BM10/BM$38 -> 0 | BA10: =BN10/BN$38 -> 0 | BB10: 0 | BC10: 0 | BD10: 0 | BE10: 1318 | BH10: Dadra and Nagar Haveli | BI10: 608 | BJ10: 596 | BK10: 114 | BL10: 0 | BM10: 0 | BN10: 0 | BO10: 0 | BP10: 0 | BQ10: 0 | BR10: 1318
C11: C5 | D11: =SUMIF($AT$43:$AT$48,$C11,AU$43:AU$48) -> 0.0012009817 | E11: =SUMIF($AT$43:$AT$48,$C11,AV$43:AV$48) -> 0.026473813 | F11: =SUMIF($AT$43:$AT$48,$C11,AW$43:AW$48) -> 0.035193985 | G11: =SUMIF($AT$43:$AT$48,$C11,AX$43:AX$48) -> 0 | H11: =SUMIF($AT$43:$AT$48,$C11,AY$43:AY$48) -> 0 | I11: =SUMIF($AT$43:$AT$48,$C11,AZ$43:AZ$48) -> 0 | J11: =SUMIF($AT$43:$AT$48,$C11,BA$43:BA$48) -> 0 | K11: =SUMIF($AT$43:$AT$48,$C11,BB$43:BB$48) -> 0.0014359563 | ... AK11: =SUMIF($AT$43:$AT$48,$C11,CB$43:CB$48) -> 7.8324892e-05 | AM11: E_WON_Trans_C1_IND | AN11: 3 | AO11: 86.478 | AP11: =MID(AM11,13,2) -> C1 | AT11: IND-DN | AU11: Daman and Diu | AV11: =BI11/BI$38 -> 0 | AW11: =BJ11/BJ$38 -> 0 | AX11: =BK11/BK$38 -> 0.0033529118 | AY11: =BL11/BL$38 -> 0.00371952 | AZ11: =BM11/BM$38 -> 0.0014359563 | BA11: =BN11/BN$38 -> 0 | BB11: 0 | BC11: 0 | BD11: 0 | BE11: 5201 | BH11: Daman and Diu | BI11: 0 | BJ11: 0 | BK11: 3376 | BL11: 1769 | BM11: 55 | BN11: 0 | BO11: 0 | BP11: 0 | BQ11: 0 | BR11: 5201
C12: C4 | D12: =SUMIF($AT$43:$AT$48,$C12,AU$43:AU$48) -> 0.00048990852 | E12: =SUMIF($AT$43:$AT$48,$C12,AV$43:AV$48) -> 0.0369534 | F12: =SUMIF($AT$43:$AT$48,$C12,AW$43:AW$48) -> 0.014583714 | G12: =SUMIF($AT$43:$AT$48,$C12,AX$43:AX$48) -> 0 | H12: =SUMIF($AT$43:$AT$48,$C12,AY$43:AY$48) -> 0 | I12: =SUMIF($AT$43:$AT$48,$C12,AZ$43:AZ$48) -> 0 | J12: =SUMIF($AT$43:$AT$48,$C12,BA$43:BA$48) -> 0 | K12: =SUMIF($AT$43:$AT$48,$C12,BB$43:BB$48) -> 0.00371952 | ... AK12: =SUMIF($AT$43:$AT$48,$C12,CB$43:CB$48) -> 6.9386185e-05 | AM12: E_WON_Trans_C2_IND | AN12: 3 | AO12: 35.868 | AP12: =MID(AM12,13,2) -> C2 | AT12: IND-DL | AU12: Delhi | AV12: =BI12/BI$38 -> 0.00078173921 | AW12: =BJ12/BJ$38 -> 0 | AX12: =BK12/BK$38 -> 0 | AY12: =BL12/BL$38 -> 0 | AZ12: =BM12/BM$38 -> 0 | BA12: =BN12/BN$38 -> 0 | BB12: 0 | BC12: 0 | BD12: 0 | BE12: 1955 | BH12: Delhi | BI12: 1955 | BJ12: 0 | BK12: 0 | BL12: 0 | BM12: 0 | BN12: 0 | BO12: 0 | BP12: 0 | BQ12: 0 | BR12: 1955
C13: C3 | D13: =SUMIF($AT$43:$AT$48,$C13,AU$43:AU$48) -> 0.00013506991 | E13: =SUMIF($AT$43:$AT$48,$C13,AV$43:AV$48) -> 0.078926512 | F13: =SUMIF($AT$43:$AT$48,$C13,AW$43:AW$48) -> 0.0032178419 | G13: =SUMIF($AT$43:$AT$48,$C13,AX$43:AX$48) -> 0 | H13: =SUMIF($AT$43:$AT$48,$C13,AY$43:AY$48) -> 0 | I13: =SUMIF($AT$43:$AT$48,$C13,AZ$43:AZ$48) -> 0.0001122272 | J13: =SUMIF($AT$43:$AT$48,$C13,BA$43:BA$48) -> 0.00011322036 | K13: =SUMIF($AT$43:$AT$48,$C13,BB$43:BB$48) -> 0.0033529118 | ... AK13: =SUMIF($AT$43:$AT$48,$C13,CB$43:CB$48) -> 0.00042606611 | AM13: E_WON_Trans_C3_IND | AN13: 3 | AO13: 30.9395 | AP13: =MID(AM13,13,2) -> C3 | AT13: IND-GA | AU13: Goa | AV13: =BI13/BI$38 -> 0.0010528488 | AW13: =BJ13/BJ$38 -> 0.0013102515 | AX13: =BK13/BK$38 -> 0.00019962538 | AY13: =BL13/BL$38 -> 1.0513058e-05 | AZ13: =BM13/BM$38 -> 0 | BA13: =BN13/BN$38 -> 0 | BB13: 0 | BC13: 0 | BD13: 0 | BE13: 5171 | BH13: Goa | BI13: 2633 | BJ13: 2332 | BK13: 201 | BL13: 5 | BM13: 0 | BN13: 0 | BO13: 0 | BP13: 0 | BQ13: 0 | BR13: 5171
C14: C2 | D14: =SUMIF($AT$43:$AT$48,$C14,AU$43:AU$48) -> 7.1355891e-05 | E14: =SUMIF($AT$43:$AT$48,$C14,AV$43:AV$48) -> 0.053470846 | F14: =SUMIF($AT$43:$AT$48,$C14,AW$43:AW$48) -> 0.0015125201 | G14: =SUMIF($AT$43:$AT$48,$C14,AX$43:AX$48) -> 0.00037082589 | H14: =SUMIF($AT$43:$AT$48,$C14,AY$43:AY$48) -> 0.0048415253 | I14: =SUMIF($AT$43:$AT$48,$C14,AZ$43:AZ$48) -> 0.00097931747 | J14: =SUMIF($AT$43:$AT$48,$C14,BA$43:BA$48) -> 0.00033486702 | K14: =SUMIF($AT$43:$AT$48,$C14,BB$43:BB$48) -> 0 | ... AK14: =SUMIF($AT$43:$AT$48,$C14,CB$43:CB$48) -> 0.0016142163 | AM14: E_WON_Trans_C4_IND | AN14: 3 | AO14: 7.5605 | AP14: =MID(AM14,13,2) -> C4 | AT14: IND-GJ | AU14: Gujarat | AV14: =BI14/BI$38 -> 0.027874301 | AW14: =BJ14/BJ$38 -> 0.20757822 | AX14: =BK14/BK$38 -> 0.33304465 | AY14: =BL14/BL$38 -> 0.22831839 | AZ14: =BM14/BM$38 -> 0.3643674 | BA14: =BN14/BN$38 -> 0.065167734 | BB14: 0 | BC14: 0 | BD14: 0 | BE14: 898496 | BH14: Gujarat | BI14: 69709 | BJ14: 369450 | BK14: 335338 | BL14: 108588 | BM14: 13956 | BN14: 1455 | BO14: 0 | BP14: 0 | BQ14: 0 | BR14: 898496
C15: C1 | D15: =SUMIF($AT$43:$AT$48,$C15,AU$43:AU$48) -> 4.3985326e-06 | E15: =SUMIF($AT$43:$AT$48,$C15,AV$43:AV$48) -> 0.018834517 | F15: =SUMIF($AT$43:$AT$48,$C15,AW$43:AW$48) -> 0.0023796062 | G15: =SUMIF($AT$43:$AT$48,$C15,AX$43:AX$48) -> 0.0061683422 | H15: =SUMIF($AT$43:$AT$48,$C15,AY$43:AY$48) -> 0.044288026 | I15: =SUMIF($AT$43:$AT$48,$C15,AZ$43:AZ$48) -> 0.06708522 | J15: =SUMIF($AT$43:$AT$48,$C15,BA$43:BA$48) -> 0.0002431189 | K15: =SUMIF($AT$43:$AT$48,$C15,BB$43:BB$48) -> 0 | ... AK15: =SUMIF($AT$43:$AT$48,$C15,CB$43:CB$48) -> 0.024894095 | AM15: E_WON_Trans_C5_IND | AN15: 3 | AO15: 5.585 | AP15: =MID(AM15,13,2) -> C5 | AT15: IND-HR | AU15: Haryana | AV15: =BI15/BI$38 -> 0.027833915 | AW15: =BJ15/BJ$38 -> 0.00013877878 | AX15: =BK15/BK$38 -> 1.1917933e-05 | AY15: =BL15/BL$38 -> 0.00013246453 | AZ15: =BM15/BM$38 -> 0 | BA15: =BN15/BN$38 -> 0 | BB15: 0 | BC15: 0 | BD15: 0 | BE15: 69930 | BH15: Haryana | BI15: 69608 | BJ15: 247 | BK15: 12 | BL15: 63 | BM15: 0 | BN15: 0 | BO15: 0 | BP15: 0 | BQ15: 0 | BR15: 69930
AT16: IND-HP | AU16: Himachal Pradesh | AV16: =BI16/BI$38 -> 0.0079905344 | AW16: =BJ16/BJ$38 -> 0.0031660665 | AX16: =BK16/BK$38 -> 0.0055130372 | AY16: =BL16/BL$38 -> 0.019205255 | AZ16: =BM16/BM$38 -> 0.050858963 | BA16: =BN16/BN$38 -> 0.088592287 | BB16: 0 | BC16: 0 | BD16: 0 | BE16: 44229 | BH16: Himachal Pradesh | BI16: 19983 | BJ16: 5635 | BK16: 5551 | BL16: 9134 | BM16: 1948 | BN16: 1978 | BO16: 0 | BP16: 0 | BQ16: 0 | BR16: 44229
B17: ~TFM_INS | AT17: IND-JK | AU17: Jammu & Kashmir | AV17: =BI17/BI$38 -> 0.014001329 | AW17: =BJ17/BJ$38 -> 0.0093054824 | AX17: =BK17/BK$38 -> 0.018675401 | AY17: =BL17/BL$38 -> 0.081505638 | AZ17: =BM17/BM$38 -> 0.26071746 | BA17: =BN17/BN$38 -> 0.66600976 | BB17: 0 | BC17: 0 | BD17: 0 | BE17: 134000 | BH17: Jammu & Kashmir | BI17: 35015 | BJ17: 16562 | BK17: 18804 | BL17: 38764 | BM17: 9986 | BN17: 14870 | BO17: 0 | BP17: 0 | BQ17: 0 | BR17: 134000
A18: Year | B18: Attribute | C18: PSET_PN | D18: =AU41 -> IND-AN | E18: =AV41 -> IND-AP | F18: =AW41 -> IND-AR | G18: =AX41 -> IND-AS | H18: =AY41 -> IND-BR | I18: =AZ41 -> IND-CT | J18: =BA41 -> IND-DD | K18: =BB41 -> IND-DN | ... AK18: =CB41 -> IND-WB | AT18: IND-JH | AU18: Jharkhand | AV18: =BI18/BI$38 -> 0.032250841 | AW18: =BJ18/BJ$38 -> 9.551576e-05 | AX18: =BK18/BK$38 -> 1.9863222e-05 | AY18: =BL18/BL$38 -> 0 | AZ18: =BM18/BM$38 -> 0 | BA18: =BN18/BN$38 -> 0 | BB18: 0 | BC18: 0 | BD18: 0 | BE18: 80844 | BH18: Jharkhand | BI18: 80654 | BJ18: 170 | BK18: 20 | BL18: 0 | BM18: 0 | BN18: 0 | BO18: 0 | BP18: 0 | BQ18: 0 | BR18: 80844
B19: CAP_BND | C19: ="E_WON-BySt_"&C10&"_IND" -> E_WON-BySt_C6_IND | D19: =D10*$AR3 -> 0.002 | E19: =E10*$AR3 -> 0.142 | F19: =F10*$AR3 -> 1.507 | G19: =G10*$AR3 -> 0 | H19: =H10*$AR3 -> 0 | I19: =I10*$AR3 -> 0 | J19: =J10*$AR3 -> 0 | K19: =K10*$AR3 -> 0 | ... AK19: =AK10*$AR3 -> 0 | AT19: IND-KA | AU19: Karnataka | AV19: =BI19/BI$38 -> 0.011942416 | AW19: =BJ19/BJ$38 -> 0.10873795 | AX19: =BK19/BK$38 -> 0.3727423 | AY19: =BL19/BL$38 -> 0.47691648 | AZ19: =BM19/BM$38 -> 0.13761683 | BA19: =BN19/BN$38 -> 0.021140323 | BB19: 0 | BC19: 0 | BD19: 0 | BE19: 831272 | BH19: Karnataka | BI19: 29866 | BJ19: 193533 | BK19: 375309 | BL19: 226821 | BM19: 5271 | BN19: 472 | BO19: 0 | BP19: 0 | BQ19: 0 | BR19: 831272
B20: CAP_BND | C20: ="E_WON-BySt_"&C11&"_IND" -> E_WON-BySt_C5_IND | D20: =D11*$AR4 -> 0.0459994 | E20: =E11*$AR4 -> 1.0139868 | F20: =F11*$AR4 -> 1.3479824 | G20: =G11*$AR4 -> 0 | H20: =H11*$AR4 -> 0 | I20: =I11*$AR4 -> 0 | J20: =J11*$AR4 -> 0 | K20: =K11*$AR4 -> 0.054999282 | ... AK20: =AK11*$AR4 -> 0.0029999608 | AT20: IND-KL | AU20: Kerala | AV20: =BI20/BI$38 -> 0.0078025971 | AW20: =BJ20/BJ$38 -> 0.00036576917 | AX20: =BK20/BK$38 -> 0.00019763906 | AY20: =BL20/BL$38 -> 4.4154845e-05 | AZ20: =BM20/BM$38 -> 0 | BA20: =BN20/BN$38 -> 0.00031352174 | BB20: 0 | BC20: 0 | BD20: 0 | BE20: 20392 | BH20: Kerala | BI20: 19513 | BJ20: 651 | BK20: 199 | BL20: 21 | BM20: 0 | BN20: 7 | BO20: 0 | BP20: 0 | BQ20: 0 | BR20: 20392
B21: CAP_BND | C21: ="E_WON-BySt_"&C12&"_IND" -> E_WON-BySt_C4_IND | D21: =D12*$AR5 -> 0.233 | E21: =E12*$AR5 -> 17.575 | F21: =F12*$AR5 -> 6.936 | G21: =G12*$AR5 -> 0 | H21: =H12*$AR5 -> 0 | I21: =I12*$AR5 -> 0 | J21: =J12*$AR5 -> 0 | K21: =K12*$AR5 -> 1.769 | ... AK21: =AK12*$AR5 -> 0.033 | AT21: IND-MP | AU21: Madhya Pradesh | AV21: =BI21/BI$38 -> 0.16941588 | AW21: =BJ21/BJ$38 -> 0.091657485 | AX21: =BK21/BK$38 -> 0.0030986626 | AY21: =BL21/BL$38 -> 0.0020563542 | AZ21: =BM21/BM$38 -> 0.00018275808 | BA21: =BN21/BN$38 -> 0.0002239441 | BB21: 0 | BC21: 0 | BD21: 0 | BE21: 590925 | BH21: Madhya Pradesh | BI21: 423681 | BJ21: 163133 | BK21: 3120 | BL21: 978 | BM21: 7 | BN21: 5 | BO21: 0 | BP21: 0 | BQ21: 0 | BR21: 590925
B22: CAP_BND | C22: ="E_WON-BySt_"&C13&"_IND" -> E_WON-BySt_C3_IND | D22: =D13*$AR6 -> 0.13600003 | E22: =E13*$AR6 -> 79.47002 | F22: =F13*$AR6 -> 3.2400008 | G22: =G13*$AR6 -> 0 | H22: =H13*$AR6 -> 0 | I22: =I13*$AR6 -> 0.11300003 | J22: =J13*$AR6 -> 0.11400003 | K22: =K13*$AR6 -> 3.3760008 | ... AK22: =AK13*$AR6 -> 0.42900011 | AT22: IND-MH | AU22: Maharashtra | AV22: =BI22/BI$38 -> 0.099873882 | AW22: =BJ22/BJ$38 -> 0.19612813 | AX22: =BK22/BK$38 -> 0.064077761 | AY22: =BL22/BL$38 -> 0.036638008 | AZ22: =BM22/BM$38 -> 0.032426505 | BA22: =BN22/BN$38 -> 0.00873382 | BB22: 0 | BC22: 0 | BD22: 0 | BE22: 682219 | BH22: Maharashtra | BI22: 249768 | BJ22: 349071 | BK22: 64519 | BL22: 17425 | BM22: 1242 | BN22: 195 | BO22: 0 | BP22: 0 | BQ22: 0 | BR22: 682219
B23: CAP_BND | C23: ="E_WON-BySt_"&C14&"_IND" -> E_WON-BySt_C2_IND | D23: =D14*$AR7 -> 0.12699998 | E23: =E14*$AR7 -> 95.167987 | F23: =F14*$AR7 -> 2.6919996 | G23: =G14*$AR7 -> 0.65999991 | H23: =H14*$AR7 -> 8.6169988 | I23: =I14*$AR7 -> 1.7429998 | J23: =J14*$AR7 -> 0.59599992 | K23: =K14*$AR7 -> 0 | ... AK23: =AK14*$AR7 -> 2.8729996 | AT23: IND-MN | AU23: Manipur | AV23: =BI23/BI$38 -> 0.00053981992 | AW23: =BJ23/BJ$38 -> 2.9216585e-05 | AX23: =BK23/BK$38 -> 5.0651216e-05 | AY23: =BL23/BL$38 -> 0.00012405409 | AZ23: =BM23/BM$38 -> 2.6108297e-05 | BA23: =BN23/BN$38 -> 0 | BB23: 0 | BC23: 0 | BD23: 0 | BE23: 1513 | BH23: Manipur | BI23: 1350 | BJ23: 52 | BK23: 51 | BL23: 59 | BM23: 1 | BN23: 0 | BO23: 0 | BP23: 0 | BQ23: 0 | BR23: 1513
B24: CAP_BND | C24: ="E_WON-BySt_"&C15&"_IND" -> E_WON-BySt_C1_IND | D24: =D15*$AR8 -> 0.011000001 | E24: =E15*$AR8 -> 47.102005 | F24: =F15*$AR8 -> 5.9510006 | G24: =G15*$AR8 -> 15.426002 | H24: =H15*$AR8 -> 110.75701 | I24: =I15*$AR8 -> 167.76902 | J24: =J15*$AR8 -> 0.60800006 | K24: =K15*$AR8 -> 0 | ... AK24: =AK15*$AR8 -> 62.256006 | AT24: IND-ML | AU24: Meghalaya | AV24: =BI24/BI$38 -> 0.00099246891 | AW24: =BJ24/BJ$38 -> 0 | AX24: =BK24/BK$38 -> 0 | AY24: =BL24/BL$38 -> 0 | AZ24: =BM24/BM$38 -> 0 | BA24: =BN24/BN$38 -> 0 | BB24: 0 | BC24: 0 | BD24: 0 | BE24: 2482 | BH24: Meghalaya | BI24: 2482 | BJ24: 0 | BK24: 0 | BL24: 0 | BM24: 0 | BN24: 0 | BO24: 0 | BP24: 0 | BQ24: 0 | BR24: 2482
D25: =IFERROR(VLOOKUP(D18,wind_existing_cap!$A$5:$B$167,2,FALSE),0) -> 0 | E25: =IFERROR(VLOOKUP(E18,wind_existing_cap!$A$5:$B$167,2,FALSE),0) -> 6.0988824 | F25: =IFERROR(VLOOKUP(F18,wind_existing_cap!$A$5:$B$167,2,FALSE),0) -> 0 | G25: =IFERROR(VLOOKUP(G18,wind_existing_cap!$A$5:$B$167,2,FALSE),0) -> 0 | H25: =IFERROR(VLOOKUP(H18,wind_existing_cap!$A$5:$B$167,2,FALSE),0) -> 0 | I25: =IFERROR(VLOOKUP(I18,wind_existing_cap!$A$5:$B$167,2,FALSE),0) -> 0 | J25: =IFERROR(VLOOKUP(J18,wind_existing_cap!$A$5:$B$167,2,FALSE),0) -> 0 | K25: =IFERROR(VLOOKUP(K18,wind_existing_cap!$A$5:$B$167,2,FALSE),0) -> 0 | ... AK25: =IFERROR(VLOOKUP(AK18,wind_existing_cap!$A$5:$B$167,2,FALSE),0) -> 0 | AT25: IND-MZ | AU25: Mizoram | AV25: =BI25/BI$38 -> 4.238586e-05 | AW25: =BJ25/BJ$38 -> 1.6855722e-06 | AX25: =BK25/BK$38 -> 2.9794833e-06 | AY25: =BL25/BL$38 -> 0 | AZ25: =BM25/BM$38 -> 0 | BA25: =BN25/BN$38 -> 0 | BB25: 0 | BC25: 0 | BD25: 0 | BE25: 112 | BH25: Mizoram | BI25: 106 | BJ25: 3 | BK25: 3 | BL25: 0 | BM25: 0 | BN25: 0 | BO25: 0 | BP25: 0 | BQ25: 0 | BR25: 112
A26: 2010 | B26: PASTI | C26: =C19 -> E_WON-BySt_C6_IND | D26: =MIN(D19,D$25) -> 0 | E26: =MIN(E19,E$25) -> 0.142 | F26: =MIN(F19,F$25) -> 0 | G26: =MIN(G19,G$25) -> 0 | H26: =MIN(H19,H$25) -> 0 | I26: =MIN(I19,I$25) -> 0 | J26: =MIN(J19,J$25) -> 0 | K26: =MIN(K19,K$25) -> 0 | ... AK26: =MIN(AK19,AK$25) -> 0 | AT26: IND-NL | AU26: Nagaland | AV26: =BI26/BI$38 -> 0.0004094634 | AW26: =BJ26/BJ$38 -> 1.741758e-05 | AX26: =BK26/BK$38 -> 7.9452887e-06 | AY26: =BL26/BL$38 -> 0 | AZ26: =BM26/BM$38 -> 5.2216594e-05 | BA26: =BN26/BN$38 -> 0 | BB26: 0 | BC26: 0 | BD26: 0 | BE26: 1064 | BH26: Nagaland | BI26: 1024 | BJ26: 31 | BK26: 8 | BL26: 0 | BM26: 2 | BN26: 0 | BO26: 0 | BP26: 0 | BQ26: 0 | BR26: 1064
A27: 2010 | B27: PASTI | C27: =C20 -> E_WON-BySt_C5_IND | D27: =MIN(D20,D$25-SUM(D$26:D26)) -> 0 | E27: =MIN(E20,E$25-SUM(E$26:E26)) -> 1.0139868 | F27: =MIN(F20,F$25-SUM(F$26:F26)) -> 0 | G27: =MIN(G20,G$25-SUM(G$26:G26)) -> 0 | H27: =MIN(H20,H$25-SUM(H$26:H26)) -> 0 | I27: =MIN(I20,I$25-SUM(I$26:I26)) -> 0 | J27: =MIN(J20,J$25-SUM(J$26:J26)) -> 0 | K27: =MIN(K20,K$25-SUM(K$26:K26)) -> 0 | ... AK27: =MIN(AK20,AK$25-SUM(AK$26:AK26)) -> 0 | AT27: IND-OR | AU27: Orissa | AV27: =BI27/BI$38 -> 0.050815048 | AW27: =BJ27/BJ$38 -> 0.011501783 | AX27: =BK27/BK$38 -> 0.0033469529 | AY27: =BL27/BL$38 -> 0.0016148058 | AZ27: =BM27/BM$38 -> 0.00080935721 | BA27: =BN27/BN$38 -> 0 | BB27: 0 | BC27: 0 | BD27: 0 | BE27: 151721 | BH27: Orissa | BI27: 127080 | BJ27: 20471 | BK27: 3370 | BL27: 768 | BM27: 31 | BN27: 0 | BO27: 0 | BP27: 0 | BQ27: 0 | BR27: 151721
A28: 2010 | B28: PASTI | C28: =C21 -> E_WON-BySt_C4_IND | D28: =MIN(D21,D$25-SUM(D$26:D27)) -> 0 | E28: =MIN(E21,E$25-SUM(E$26:E27)) -> 4.9428957 | F28: =MIN(F21,F$25-SUM(F$26:F27)) -> 0 | G28: =MIN(G21,G$25-SUM(G$26:G27)) -> 0 | H28: =MIN(H21,H$25-SUM(H$26:H27)) -> 0 | I28: =MIN(I21,I$25-SUM(I$26:I27)) -> 0 | J28: =MIN(J21,J$25-SUM(J$26:J27)) -> 0 | K28: =MIN(K21,K$25-SUM(K$26:K27)) -> 0 | ... AK28: =MIN(AK21,AK$25-SUM(AK$26:AK27)) -> 0 | AT28: IND-PY | AU28: Puducherry | AV28: =BI28/BI$38 -> 4.4385193e-05 | AW28: =BJ28/BJ$38 -> 0.00011405705 | AX28: =BK28/BK$38 -> 0.00031284574 | AY28: =BL28/BL$38 -> 2.1026117e-06 | AZ28: =BM28/BM$38 -> 0 | BA28: =BN28/BN$38 -> 0 | BB28: 0 | BC28: 0 | BD28: 0 | BE28: 630 | BH28: Puducherry | BI28: 111 | BJ28: 203 | BK28: 315 | BL28: 1 | BM28: 0 | BN28: 0 | BO28: 0 | BP28: 0 | BQ28: 0 | BR28: 630
A29: 2010 | B29: PASTI | C29: =C22 -> E_WON-BySt_C3_IND | D29: =MIN(D22,D$25-SUM(D$26:D28)) -> 0 | E29: =MIN(E22,E$25-SUM(E$26:E28)) -> 0 | F29: =MIN(F22,F$25-SUM(F$26:F28)) -> 0 | G29: =MIN(G22,G$25-SUM(G$26:G28)) -> 0 | H29: =MIN(H22,H$25-SUM(H$26:H28)) -> 0 | I29: =MIN(I22,I$25-SUM(I$26:I28)) -> 0 | J29: =MIN(J22,J$25-SUM(J$26:J28)) -> 0 | K29: =MIN(K22,K$25-SUM(K$26:K28)) -> 0 | ... AK29: =MIN(AK22,AK$25-SUM(AK$26:AK28)) -> 0 | AT29: IND-PB | AU29: Punjab | AV29: =BI29/BI$38 -> 0.012891299 | AW29: =BJ29/BJ$38 -> 0 | AX29: =BK29/BK$38 -> 0 | AY29: =BL29/BL$38 -> 0 | AZ29: =BM29/BM$38 -> 0 | BA29: =BN29/BN$38 -> 0 | BB29: 0 | BC29: 0 | BD29: 0 | BE29: 32239 | BH29: Punjab | BI29: 32239 | BJ29: 0 | BK29: 0 | BL29: 0 | BM29: 0 | BN29: 0 | BO29: 0 | BP29: 0 | BQ29: 0 | BR29: 32239
A30: 2010 | B30: PASTI | C30: =C23 -> E_WON-BySt_C2_IND | D30: =MIN(D23,D$25-SUM(D$26:D29)) -> 0 | E30: =MIN(E23,E$25-SUM(E$26:E29)) -> 0 | F30: =MIN(F23,F$25-SUM(F$26:F29)) -> 0 | G30: =MIN(G23,G$25-SUM(G$26:G29)) -> 0 | H30: =MIN(H23,H$25-SUM(H$26:H29)) -> 0 | I30: =MIN(I23,I$25-SUM(I$26:I29)) -> 0 | J30: =MIN(J23,J$25-SUM(J$26:J29)) -> 0 | K30: =MIN(K23,K$25-SUM(K$26:K29)) -> 0 | ... AK30: =MIN(AK23,AK$25-SUM(AK$26:AK29)) -> 0 | AT30: IND-RJ | AU30: Rajasthan | AV30: =BI30/BI$38 -> 0.17760875 | AW30: =BJ30/BJ$38 -> 0.20386378 | AX30: =BK30/BK$38 -> 0.08178483 | AY30: =BL30/BL$38 -> 0.046860906 | AZ30: =BM30/BM$38 -> 0.0094250953 | BA30: =BN30/BN$38 -> 0.0027321181 | BB30: 0 | BC30: 0 | BD30: 0 | BE30: 912065 | BH30: Rajasthan | BI30: 444170 | BJ30: 362839 | BK30: 82348 | BL30: 22287 | BM30: 361 | BN30: 61 | BO30: 0 | BP30: 0 | BQ30: 0 | BR30: 912065
A31: 2010 | B31: PASTI | C31: =C24 -> E_WON-BySt_C1_IND | D31: =MIN(D24,D$25-SUM(D$26:D30)) -> 0 | E31: =MIN(E24,E$25-SUM(E$26:E30)) -> 0 | F31: =MIN(F24,F$25-SUM(F$26:F30)) -> 0 | G31: =MIN(G24,G$25-SUM(G$26:G30)) -> 0 | H31: =MIN(H24,H$25-SUM(H$26:H30)) -> 0 | I31: =MIN(I24,I$25-SUM(I$26:I30)) -> 0 | J31: =MIN(J24,J$25-SUM(J$26:J30)) -> 0 | K31: =MIN(K24,K$25-SUM(K$26:K30)) -> 0 | ... AK31: =MIN(AK24,AK$25-SUM(AK$26:AK30)) -> 0 | AT31: IND-SK | AU31: Sikkim | AV31: =BI31/BI$38 -> 7.1576122e-05 | AW31: =BJ31/BJ$38 -> 0.00019159338 | AX31: =BK31/BK$38 -> 0.00042407979 | AY31: =BL31/BL$38 -> 0.0025483653 | AZ31: =BM31/BM$38 -> 0.0074147564 | BA31: =BN31/BN$38 -> 0.019169615 | BB31: 0 | BC31: 0 | BD31: 0 | BE31: 2871 | BH31: Sikkim | BI31: 179 | BJ31: 341 | BK31: 427 | BL31: 1212 | BM31: 284 | BN31: 428 | BO31: 0 | BP31: 0 | BQ31: 0 | BR31: 2871
AT32: IND-TN | AU32: Tamil Nadu | AV32: =BI32/BI$38 -> 0.0061183589 | AW32: =BJ32/BJ$38 -> 0.020876374 | AX32: =BK32/BK$38 -> 0.017540218 | AY32: =BL32/BL$38 -> 0.029167429 | AZ32: =BM32/BM$38 -> 0.041982142 | BA32: =BN32/BN$38 -> 0.0045236709 | BB32: 0 | BC32: 0 | BD32: 0 | BE32: 85699 | BH32: Tamil Nadu | BI32: 15301 | BJ32: 37156 | BK32: 17661 | BL32: 13872 | BM32: 1608 | BN32: 101 | BO32: 0 | BP32: 0 | BQ32: 0 | BR32: 85699
AT33: IND-TG | AU33: Telangana | AV33: =BI33/BI$38 -> 0.040282162 | AW33: =BJ33/BJ$38 -> 0.042016259 | AX33: =BK33/BK$38 -> 0.0075162431 | AY33: =BL33/BL$38 -> 0.0046404639 | AZ33: =BM33/BM$38 -> 0.00015664978 | BA33: =BN33/BN$38 -> 0 | BB33: 0 | BC33: 0 | BD33: 0 | BE33: 185301 | BH33: Telangana | BI33: 100739 | BJ33: 74781 | BK33: 7568 | BL33: 2207 | BM33: 6 | BN33: 0 | BO33: 0 | BP33: 0 | BQ33: 0 | BR33: 185301
AT34: IND-TR | AU34: Tripura | AV34: =BI34/BI$38 -> 0.00036347874 | AW34: =BJ34/BJ$38 -> 0 | AX34: =BK34/BK$38 -> 0 | AY34: =BL34/BL$38 -> 0 | AZ34: =BM34/BM$38 -> 0 | BA34: =BN34/BN$38 -> 0 | BB34: 0 | BC34: 0 | BD34: 0 | BE34: 909 | BH34: Tripura | BI34: 909 | BJ34: 0 | BK34: 0 | BL34: 0 | BM34: 0 | BN34: 0 | BO34: 0 | BP34: 0 | BQ34: 0 | BR34: 909
AT35: IND-UP | AU35: Uttar Pradesh | AV35: =BI35/BI$38 -> 0.13566274 | AW35: =BJ35/BJ$38 -> 0.035744245 | AX35: =BK35/BK$38 -> 0 | AY35: =BL35/BL$38 -> 0 | AZ35: =BM35/BM$38 -> 0 | BA35: =BN35/BN$38 -> 0 | BB35: 0 | BC35: 0 | BD35: 0 | BE35: 402888 | BH35: Uttar Pradesh | BI35: 339270 | BJ35: 63618 | BK35: 0 | BL35: 0 | BM35: 0 | BN35: 0 | BO35: 0 | BP35: 0 | BQ35: 0 | BR35: 402888
AT36: IND-UT | AU36: Uttarakhand | AV36: =BI36/BI$38 -> 0.0093836696 | AW36: =BJ36/BJ$38 -> 0.003963904 | AX36: =BK36/BK$38 -> 0.0051465608 | AY36: =BL36/BL$38 -> 0.014398685 | AZ36: =BM36/BM$38 -> 0.029659026 | BA36: =BN36/BN$38 -> 0.049491647 | BB36: 0 | BC36: 0 | BD36: 0 | BE36: 44793 | BH36: Uttarakhand | BI36: 23467 | BJ36: 7055 | BK36: 5182 | BL36: 6848 | BM36: 1136 | BN36: 1105 | BO36: 0 | BP36: 0 | BQ36: 0 | BR36: 44793
AT37: IND-WB | AU37: West Bengal | AV37: =BI37/BI$38 -> 0.024894095 | AW37: =BJ37/BJ$38 -> 0.0016142163 | AX37: =BK37/BK$38 -> 0.00042606611 | AY37: =BL37/BL$38 -> 6.9386185e-05 | AZ37: =BM37/BM$38 -> 7.8324892e-05 | BA37: =BN37/BN$38 -> 0 | BB37: 0 | BC37: 0 | BD37: 0 | BE37: 65594 | BH37: West Bengal | BI37: 62256 | BJ37: 2873 | BK37: 429 | BL37: 33 | BM37: 3 | BN37: 0 | BO37: 0 | BP37: 0 | BQ37: 0 | BR37: 65594
BI38: 2500834 | BJ38: 1779811 | BK38: 1006886 | BL38: 475599 | BM38: 38302 | BN38: 22327 | BO38: 0 | BP38: 0 | BQ38: 0 | BR38: 5823759
AU41: IND-AN | AV41: IND-AP | AW41: IND-AR | AX41: IND-AS | AY41: IND-BR | AZ41: IND-CT | BA41: IND-DD | BB41: IND-DN | BC41: IND-DL | BD41: IND-GA | BE41: IND-GJ | BF41: IND-HR | BG41: IND-HP | BH41: IND-JK | BI41: IND-JH | BJ41: IND-KA | BK41: IND-KL | BL41: IND-MP | BM41: IND-MH | BN41: IND-MN | BO41: IND-ML | BP41: IND-MZ | BQ41: IND-NL | BR41: IND-OR | BS41: IND-PY | BT41: IND-PB | BU41: IND-RJ | BV41: IND-SK | BW41: IND-TN | BX41: IND-TG | BY41: IND-TR | BZ41: IND-UP | CA41: IND-UT | CB41: IND-WB
AT42: State | AU42: Andaman and Nicobar | AV42: Andhra Pradesh | AW42: Arunachal Pradesh | AX42: Assam | AY42: Bihar | AZ42: Chhattisgarh | BA42: Dadra and Nagar Haveli | BB42: Daman and Diu | BC42: Delhi | BD42: Goa | BE42: Gujarat | BF42: Haryana | BG42: Himachal Pradesh | BH42: Jammu & Kashmir | BI42: Jharkhand | BJ42: Karnataka | BK42: Kerala | BL42: Madhya Pradesh | BM42: Maharashtra | BN42: Manipur | BO42: Meghalaya | BP42: Mizoram | BQ42: Nagaland | BR42: Orissa | BS42: Puducherry | BT42: Punjab | BU42: Rajasthan | BV42: Sikkim | BW42: Tamil Nadu | BX42: Telangana | BY42: Tripura | BZ42: Uttar Pradesh | CA42: Uttarakhand | CB42: West Bengal
...

Sheet coal regional
D3: AP | E3: AR | F3: AS | G3: BR | H3: CT | I3: DL | J3: GA | K3: GJ | L3: HP | M3: HR | N3: JH | O3: JK | P3: KA | Q3: KL | R3: MH | S3: ML | T3: MN | U3: MP | V3: NL | W3: OR | X3: PB | Y3: PY | Z3: RJ | AA3: SK | AB3: TG | AC3: TN | AD3: TR | AE3: UT | AF3: UU | AG3: WB
B6: ~TFM_INS
B7: Attribute | C7: PSET_PN | D7: ="IND-"&D3 -> IND-AP | E7: ="IND-"&E3 -> IND-AR | F7: ="IND-"&F3 -> IND-AS | G7: ="IND-"&G3 -> IND-BR | H7: ="IND-"&H3 -> IND-CT | I7: ="IND-"&I3 -> IND-DL | J7: ="IND-"&J3 -> IND-GA | K7: ="IND-"&K3 -> IND-GJ | ... AG7: ="IND-"&AG3 -> IND-WB
B8: ACT_COST | C8: FT_ELCCOA | D8: -0.20188765 | E8: 99 | F8: 0.29317688 | G8: -0.14023524 | H8: -0.32457708 | I8: 0.32617781 | J8: 99 | K8: 0.12655933 | L8: 99 | M8: 0.22688933 | N8: -0.26990464 | O8: 99 | P8: 0.011267897 | Q8: 99 | R8: -0.12078598 | S8: 99 | T8: 99 | U8: -0.16236331 | V8: 99 | W8: -0.33962526 | X8: 0.36497783 | Y8: 99 | Z8: 0.17303238 | AA8: 99 | AB8: 99 | AC8: 0.11239675 | AD8: 99 | AE8: 99 | AF8: -0.065415914 | AG8: -0.009683139
