Workbook

Sheet ReadMe
A1: Workbook purpose:
A2: Creates time series for capital cost decline over time
A4: Data source:
A5: AEO Reference case costs (NEMS learning sheet)
A7: User-modifiable?
A8: Learning rates on NEMS learning can be modified, replaced with a new AEO or with trajectories derived from ETL runs. Note VLOOKUP structure driven by columns J-L on INS sheet.

Sheet Calculation
A1: Original cost from the IEMM | D1: constant backward extrapolation | G1: original data from AEO 2021 (table 123) | J1: Calculation (annual learning rates)
B3: utility PV | G3: Wind Onshore | L3: Wind Offshore
B5: ts_mid.3.0617a | G5: ts_mid.1.0618a | L5: ts_mid.3.0617a
A6: year | B6: Central | C6: learnig rate | F6: year | G6: Central | H6: learning rate | K6: year | L6: Central | M6: learning rate
A7: 2010 | B7: 1417 | F7: 2010 | G7: 1460 | K7: 2010 | L7: 9667
A8: 2017 | B8: 1231.9 | C8: =B8/$B$7 -> 0.86937191 | F8: 2017 | G8: 1267.7 | H8: =G8/$G$7 -> 0.86828767 | K8: 2017 | L8: 2563.2 | M8: =L8/$L$7 -> 0.26514948
A9: 2020 | B9: 1231.9 | C9: =B9/$B$7 -> 0.86937191 | F9: 2020 | G9: 1267.7 | H9: =G9/$G$7 -> 0.86828767 | K9: 2020 | L9: 2563.2 | M9: =L9/$L$7 -> 0.26514948
A10: 2021 | B10: 1231.9 | C10: =B10/$B$7 -> 0.86937191 | F10: 2021 | G10: 1267.7 | H10: =G10/$G$7 -> 0.86828767 | K10: 2021 | L10: 2563.2 | M10: =L10/$L$7 -> 0.26514948
A11: 2022 | B11: 1178.3 | C11: =B11/$B$7 -> 0.83154552 | F11: 2022 | G11: 1275.6 | H11: =G11/$G$7 -> 0.87369863 | K11: 2022 | L11: 2436 | M11: =L11/$L$7 -> 0.25199131
A12: 2023 | B12: 1132.6 | C12: =B12/$B$7 -> 0.79929428 | F12: 2023 | G12: 1279.6 | H12: =G12/$G$7 -> 0.87643836 | K12: 2023 | L12: 2320.8 | M12: =L12/$L$7 -> 0.24007448
A13: 2024 | B13: 1092.8 | C13: =B13/$B$7 -> 0.77120677 | F13: 2024 | G13: 1281.6 | H13: =G13/$G$7 -> 0.87780822 | K13: 2024 | L13: 2213.5 | M13: =L13/$L$7 -> 0.22897486
A14: 2025 | B14: 1069 | C14: =B14/$B$7 -> 0.75441073 | F14: 2025 | G14: 1277.6 | H14: =G14/$G$7 -> 0.87506849 | K14: 2025 | L14: 2116.1 | M14: =L14/$L$7 -> 0.21889935
A15: 2026 | B15: 1049.1 | C15: =B15/$B$7 -> 0.74036697 | F15: 2026 | G15: 1265.7 | H15: =G15/$G$7 -> 0.86691781 | K15: 2026 | L15: 2026.7 | M15: =L15/$L$7 -> 0.20965139
A16: 2027 | B16: 997.468 | C16: =B16/$B$7 -> 0.70392943 | F16: 2027 | G16: 1251.8 | H16: =G16/$G$7 -> 0.85739726 | K16: 2027 | L16: 1947.2 | M16: =L16/$L$7 -> 0.20142754
A17: 2028 | B17: 945.806 | C17: =B17/$B$7 -> 0.66747071 | F17: 2028 | G17: 1235.9 | H17: =G17/$G$7 -> 0.84650685 | K17: 2028 | L17: 1873.7 | M17: =L17/$L$7 -> 0.19382435
A18: 2029 | B18: 892.158 | C18: =B18/$B$7 -> 0.62961044 | F18: 2029 | G18: 1220 | H18: =G18/$G$7 -> 0.83561644 | K18: 2029 | L18: 1808.2 | M18: =L18/$L$7 -> 0.18704872
A19: 2030 | B19: 840.496 | C19: =B19/$B$7 -> 0.59315173 | F19: 2030 | G19: 1202.1 | H19: =G19/$G$7 -> 0.82335616 | K19: 2030 | L19: 1748.5 | M19: =L19/$L$7 -> 0.18087307
... A39: 2050 | B39: 691.472 | C39: =B39/$B$7 -> 0.48798306 | F39: 2050 | G39: 965.676 | H39: =G39/$G$7 -> 0.66142192 | K39: 2050 | L39: 1229.9 | M39: =L39/$L$7 -> 0.12722665

Sheet NEMS learning
A1: Online Year | B1: Coal with 30% CCS | C1: Coal with 90% CCS | D1: Comb. Turb | E1: Adv. CT | F1: Comb. Cyc | G1: Adv CC | H1: Adv CC w/seq | I1: Fuel Cell | J1: Nuclear | K1: Biomass | L1: Geothermal | M1: Landfill Gas | N1: Hydro | O1: Battery Storage | P1: Wind | Q1: Offshore Wind | R1: Solar Thermal | S1: Solar PV - tracking | T1: Solar PV - fixed tilt | U1: Dist. Gen Base | V1: Dist Gen Peak
A2: 2015 | B2: 3 | C2: 3 | D2: 3 | E2: 3 | F2: 3 | G2: 3 | H2: 3 | I2: 3 | J2: 3 | K2: 3 | L2: 3 | M2: 3 | N2: 3 | O2: 3 | P2: 3 | Q2: 3 | R2: 3 | S2: 3 | T2: 3 | U2: 3 | V2: 3
A3: 2016 | B3: 3 | C3: 3 | D3: 3 | E3: 3 | F3: 3 | G3: 3 | H3: 3 | I3: 3 | J3: 3 | K3: 3 | L3: 3 | M3: 3 | N3: 3 | O3: 3 | P3: 3 | Q3: 3 | R3: 3 | S3: 3 | T3: 3 | U3: 3 | V3: 3
A4: 2017 | B4: 0.996 | C4: 0.996 | D4: 0.997 | E4: 0.996 | F4: 0.998 | G4: 0.997 | H4: 0.994 | I4: 0.99 | J4: 0.995 | K4: 0.996 | L4: 0.995 | M4: 0.997 | N4: 0.998 | O4: 0.99 | P4: 0.998 | Q4: 0.994 | R4: 0.988 | S4: 0.938 | T4: 0.938 | U4: 0.995 | V4: 0.995
A5: 2018 | B5: 0.99125 | C5: 0.99125 | D5: 0.995 | E5: 0.9925 | F5: 0.995 | G5: 0.9935 | H5: 0.988 | I5: 0.964729 | J5: 0.99 | K5: 0.9925 | L5: 0.99 | M5: 0.995 | N5: 0.995 | O5: 0.98 | P5: 0.995 | Q5: 0.9875 | R5: 0.982718 | S5: 0.862163 | T5: 0.862163 | U5: 0.99 | V5: 0.99
A6: 2019 | B6: 0.986875 | C6: 0.986875 | D6: 0.9925 | E6: 0.98875 | F6: 0.9925 | G6: 0.99025 | H6: 0.982 | I6: 0.950974 | J6: 0.985 | K6: 0.98875 | L6: 0.985 | M6: 0.9925 | N6: 0.99117 | O6: 0.97 | P6: 0.9925 | Q6: 0.98125 | R6: 0.977718 | S6: 0.823791 | T6: 0.823791 | U6: 0.985 | V6: 0.985
A7: 2020 | B7: 0.9825 | C7: 0.9825 | D7: 0.99 | E7: 0.985 | F7: 0.99 | G7: 0.987 | H7: 0.976 | I7: 0.940974 | J7: 0.98 | K7: 0.981119 | L7: 0.98 | M7: 0.99 | N7: 0.987982 | O7: 0.96 | P7: 0.99 | Q7: 0.975 | R7: 0.972718 | S7: 0.801734 | T7: 0.801734 | U7: 0.98 | V7: 0.98
A8: 2021 | B8: 0.978125 | C8: 0.978125 | D8: 0.9875 | E8: 0.98125 | F8: 0.9875 | G8: 0.98375 | H8: 0.97 | I8: 0.930974 | J8: 0.975 | K8: 0.972991 | L8: 0.975 | M8: 0.9875 | N8: 0.985482 | O8: 0.95 | P8: 0.9875 | Q8: 0.96875 | R8: 0.967718 | S8: 0.756083 | T8: 0.756083 | U8: 0.975 | V8: 0.95
A9: 2022 | B9: 0.97375 | C9: 0.97375 | D9: 0.985 | E9: 0.97626 | F9: 0.985 | G9: 0.979756 | H9: 0.963504 | I9: 0.920974 | J9: 0.964398 | K9: 0.969241 | L9: 0.97 | M9: 0.985 | N9: 0.982982 | O9: 0.94 | P9: 0.985 | Q9: 0.9625 | R9: 0.962718 | S9: 0.74016 | T9: 0.74016 | U9: 0.97 | V9: 0.9025
A10: 2023 | B10: 0.969375 | C10: 0.969375 | D10: 0.9825 | E10: 0.968714 | F10: 0.9825 | G10: 0.974229 | H10: 0.955986 | I10: 0.910974 | J10: 0.959398 | K10: 0.965491 | L10: 0.943864 | M10: 0.9825 | N10: 0.980482 | O10: 0.93 | P10: 0.9825 | Q10: 0.95625 | R10: 0.957718 | S10: 0.729182 | T10: 0.729182 | U10: 0.965 | V10: 0.857375
A11: 2024 | B11: 0.965 | C11: 0.965 | D11: 0.98 | E11: 0.958721 | F11: 0.98 | G11: 0.967233 | H11: 0.947488 | I11: 0.900974 | J11: 0.954398 | K11: 0.961741 | L11: 0.9104 | M11: 0.98 | N11: 0.977982 | O11: 0.92 | P11: 0.98 | Q11: 0.95 | R11: 0.952718 | S11: 0.727658 | T11: 0.727658 | U11: 0.96 | V11: 0.848083
A12: 2025 | B12: 0.960625 | C12: 0.960625 | D12: 0.9775 | E12: 0.943278 | F12: 0.9775 | G12: 0.956967 | H12: 0.936811 | I12: 0.890974 | J12: 0.949398 | K12: 0.957991 | L12: 0.882506 | M12: 0.9775 | N12: 0.975482 | O12: 0.91 | P12: 0.9775 | Q12: 0.94375 | R12: 0.947719 | S12: 0.726158 | T12: 0.726158 | U12: 0.955 | V12: 0.837693
A13: 2026 | B13: 0.95625 | C13: 0.95625 | D13: 0.975 | E13: 0.929111 | F13: 0.975 | G13: 0.947466 | H13: 0.926644 | I13: 0.880974 | J13: 0.944398 | K13: 0.954241 | L13: 0.86381 | M13: 0.975 | N13: 0.972982 | O13: 0.9 | P13: 0.975 | Q13: 0.9375 | R13: 0.942719 | S13: 0.724658 | T13: 0.724658 | U13: 0.95 | V13: 0.829928
... A37: 2050 | B37: 0.85125 | C37: 0.85125 | D37: 0.915 | E37: 0.8075 | F37: 0.915 | G37: 0.8505 | H37: 0.77 | I37: 0.640974 | J37: 0.824398 | K37: 0.864241 | L37: 0.7 | M37: 0.915 | N37: 0.912982 | O37: 0.66 | P37: 0.915 | Q37: 0.7875 | R37: 0.822719 | S37: 0.7 | T37: 0.7 | U37: 0.795049 | V37: 0.7

Sheet INS
B2: ~TFM_MIG | O2: ~TFM_MIG
B3: SourceScen | C3: Attribute | D3: Year2 | E3: AllRegions | F3: PSET_PN | J3: 1 | K3: E_SPV* | L3: Solar PV - fixed tilt | O3: SourceScen | P3: Attribute | Q3: Year2 | R3: AllRegions | S3: PSET_PN
C4: INVCOST | D4: 2015 | F4: EN_COAPUL | J4: 2 | K4: E_WON* | L4: Wind | O4: BehaviourControl | P4: INVCOST | Q4: 2015
C5: INVCOST | D5: 2016 | F5: EN_COAPUL | J5: 3 | K5: E_WOF* | L5: Offshore Wind | O5: BehaviourControl | P5: INVCOST | Q5: 2016
C6: INVCOST | D6: 2017 | E6: *0.996 | F6: EN_COAPUL | J6: 4 | K6: EN_COAPUL | L6: Coal with 30% CCS | O6: BehaviourControl | P6: INVCOST | Q6: 2017 | R6: *0.938 | S6: EBldRateStep*SOL*
C7: INVCOST | D7: 2020 | E7: *0.9825 | F7: EN_COAPUL | J7: 5 | K7: EN_COAIGCC | L7: Coal with 30% CCS | O7: BehaviourControl | P7: INVCOST | Q7: 2020 | R7: *0.801734 | S7: EBldRateStep*SOL*
C8: INVCOST | D8: 2025 | E8: *0.960625 | F8: EN_COAPUL | J8: 6 | K8: EN_ZCOAIGCC | L8: Coal with 90% CCS | O8: BehaviourControl | P8: INVCOST | Q8: 2025 | R8: *0.726158 | S8: EBldRateStep*SOL*
C9: INVCOST | D9: 2030 | E9: *0.93875 | F9: EN_COAPUL | J9: 7 | K9: EN_ZGasCCAdv | L9: Adv CC w/seq | O9: BehaviourControl | P9: INVCOST | Q9: 2030 | R9: *0.717941 | S9: EBldRateStep*SOL*
C10: INVCOST | D10: 2035 | E10: *0.916875 | F10: EN_COAPUL | J10: 8 | K10: EN_GasCCAdv | L10: Adv CC | O10: BehaviourControl | P10: INVCOST | Q10: 2035 | R10: *0.704942 | S10: EBldRateStep*SOL*
C11: INVCOST | D11: 2040 | E11: *0.895 | F11: EN_COAPUL | J11: 9 | K11: EN_GasCC | L11: Comb. Cyc | O11: BehaviourControl | P11: INVCOST | Q11: 2040 | R11: *0.7 | S11: EBldRateStep*SOL*
C12: INVCOST | D12: 2045 | E12: *0.873125 | F12: EN_COAPUL | J12: 10 | K12: EN_GasCTAdv | L12: Adv. CT | O12: BehaviourControl | P12: INVCOST | Q12: 2045 | R12: *0.7 | S12: EBldRateStep*SOL*
C13: INVCOST | D13: 2050 | E13: *0.85125 | F13: EN_COAPUL | J13: 11 | K13: EN_GasCT | L13: Comb. Turb | O13: BehaviourControl | P13: INVCOST | Q13: 2050 | R13: *0.7 | S13: EBldRateStep*SOL*
C14: INVCOST | D14: 2015 | F14: EN_COAIGCC | J14: 12 | K14: EN_Biomass | L14: Biomass | O14: BehaviourControl | P14: INVCOST | Q14: 2015
C15: INVCOST | D15: 2016 | F15: EN_COAIGCC | J15: 13 | K15: EN_ZBiomass | L15: =L8 -> Coal with 90% CCS | O15: BehaviourControl | P15: INVCOST | Q15: 2016
C16: INVCOST | D16: 2017 | E16: *0.996 | F16: EN_COAIGCC | J16: 14 | K16: EN_OilCCAdv | L16: =L12 -> Adv. CT | O16: BehaviourControl | P16: INVCOST | Q16: 2017 | R16: *0.998 | S16: EBldRateStep*WIN*
C17: INVCOST | D17: 2020 | E17: *0.9825 | F17: EN_COAIGCC | J17: 15 | K17: EN_Hydro* | L17: Hydro | O17: BehaviourControl | P17: INVCOST | Q17: 2020 | R17: *0.99 | S17: EBldRateStep*WIN*
C18: INVCOST | D18: 2025 | E18: *0.960625 | F18: EN_COAIGCC | O18: BehaviourControl | P18: INVCOST | Q18: 2025 | R18: *0.9775 | S18: EBldRateStep*WIN*
C19: INVCOST | D19: 2030 | E19: *0.93875 | F19: EN_COAIGCC | O19: BehaviourControl | P19: INVCOST | Q19: 2030 | R19: *0.965 | S19: EBldRateStep*WIN*
C20: INVCOST | D20: 2035 | E20: *0.916875 | F20: EN_COAIGCC | O20: BehaviourControl | P20: INVCOST | Q20: 2035 | R20: *0.9525 | S20: EBldRateStep*WIN*
C21: INVCOST | D21: 2040 | E21: *0.895 | F21: EN_COAIGCC | O21: BehaviourControl | P21: INVCOST | Q21: 2040 | R21: *0.94 | S21: EBldRateStep*WIN*
C22: INVCOST | D22: 2045 | E22: *0.873125 | F22: EN_COAIGCC | O22: BehaviourControl | P22: INVCOST | Q22: 2045 | R22: *0.9275 | S22: EBldRateStep*WIN*
C23: INVCOST | D23: 2050 | E23: *0.85125 | F23: EN_COAIGCC | O23: BehaviourControl | P23: INVCOST | Q23: 2050 | R23: *0.915 | S23: EBldRateStep*WIN*
B24: Solar-EIA-c,Solar-StateLev | C24: =C21 -> INVCOST | D24: =Calculation!A8 -> 2017 | E24: ="*"&Calculation!C8 -> *0.869371912491179 | F24: E*SPV*
B25: Solar-EIA-c,Solar-StateLev | C25: =C22 -> INVCOST | D25: =Calculation!A9 -> 2020 | E25: ="*"&Calculation!C9 -> *0.869371912491179 | F25: E*SPV*
B26: Solar-EIA-c,Solar-StateLev | C26: =C23 -> INVCOST | D26: =Calculation!A10 -> 2021 | E26: ="*"&Calculation!C10 -> *0.869371912491179 | F26: E*SPV*
B27: Solar-EIA-c,Solar-StateLev | C27: =C26 -> INVCOST | D27: =Calculation!A11 -> 2022 | E27: ="*"&Calculation!C11 -> *0.831545518701482 | F27: E*SPV*
B28: Solar-EIA-c,Solar-StateLev | C28: =C27 -> INVCOST | D28: =Calculation!A12 -> 2023 | E28: ="*"&Calculation!C12 -> *0.799294283697953 | F28: E*SPV*
B29: Solar-EIA-c,Solar-StateLev | C29: =C28 -> INVCOST | D29: =Calculation!A13 -> 2024 | E29: ="*"&Calculation!C13 -> *0.7712067748765 | F29: E*SPV*
B30: Solar-EIA-c,Solar-StateLev | C30: =C29 -> INVCOST | D30: =Calculation!A14 -> 2025 | E30: ="*"&Calculation!C14 -> *0.754410726887791 | F30: E*SPV*
B31: Solar-EIA-c,Solar-StateLev | C31: =C30 -> INVCOST | D31: =Calculation!A15 -> 2026 | E31: ="*"&Calculation!C15 -> *0.740366972477064 | F31: E*SPV*
B32: Solar-EIA-c,Solar-StateLev | C32: =C31 -> INVCOST | D32: =Calculation!A16 -> 2027 | E32: ="*"&Calculation!C16 -> *0.703929428369795 | F32: E*SPV*
B33: Solar-EIA-c,Solar-StateLev | C33: =C32 -> INVCOST | D33: =Calculation!A17 -> 2028 | E33: ="*"&Calculation!C17 -> *0.667470712773465 | F33: E*SPV*
B34: Solar-EIA-c,Solar-StateLev | C34: =C33 -> INVCOST | D34: =Calculation!A18 -> 2029 | E34: ="*"&Calculation!C18 -> *0.62961044460127 | F34: E*SPV*
B35: Solar-EIA-c,Solar-StateLev | C35: =C34 -> INVCOST | D35: =Calculation!A19 -> 2030 | E35: ="*"&Calculation!C19 -> *0.59315172900494 | F35: E*SPV*
B36: Solar-EIA-c,Solar-StateLev | C36: =C35 -> INVCOST | D36: =Calculation!A20 -> 2031 | E36: ="*"&Calculation!C20 -> *0.587542695836274 | F36: E*SPV*
B37: Solar-EIA-c,Solar-StateLev | C37: =C36 -> INVCOST | D37: =Calculation!A21 -> 2032 | E37: ="*"&Calculation!C21 -> *0.583335920959774 | F37: E*SPV*
B38: Solar-EIA-c,Solar-StateLev | C38: =C37 -> INVCOST | D38: =Calculation!A22 -> 2033 | E38: ="*"&Calculation!C22 -> *0.577726887791108 | F38: E*SPV*
... B55: Solar-EIA-c,Solar-StateLev | C55: =C54 -> INVCOST | D55: =Calculation!A39 -> 2050 | E55: ="*"&Calculation!C39 -> *0.487983062808751 | F55: E*SPV*
B56: BaseExtra | C56: =C53 -> INVCOST | D56: =Calculation!F8 -> 2017 | E56: ="*"&Calculation!H8 -> *0.868287671232877 | F56: E*WON*
B57: BaseExtra | C57: =C54 -> INVCOST | D57: =Calculation!F9 -> 2020 | E57: ="*"&Calculation!H9 -> *0.868287671232877 | F57: E*WON*
...
