Workbook

Sheet forScenList
A1: 1 | B1: =A1 -> 1
A2: 4 | B2: =B1&","&A2 -> 1,4
A3: 7 | B3: =B2&","&A3 -> 1,4,7
A4: 10 | B4: =B3&","&A4 -> 1,4,7,10
A5: 13 | B5: =B4&","&A5 -> 1,4,7,10,13
A6: 16 | B6: =B5&","&A6 -> 1,4,7,10,13,16
A7: 19 | B7: =B6&","&A7 -> 1,4,7,10,13,16,19
A8: 22 | B8: =B7&","&A8 -> 1,4,7,10,13,16,19,22
A9: 25 | B9: =B8&","&A9 -> 1,4,7,10,13,16,19,22,25
A10: 28 | B10: =B9&","&A10 -> 1,4,7,10,13,16,19,22,25,28
A11: 31 | B11: =B10&","&A11 -> 1,4,7,10,13,16,19,22,25,28,31
A12: 34 | B12: =B11&","&A12 -> 1,4,7,10,13,16,19,22,25,28,31,34
A13: 37 | B13: =B12&","&A13 -> 1,4,7,10,13,16,19,22,25,28,31,34,37
... A72: 108 | B72: =B71&","&A72 -> 1,4,7,10,13,16,19,22,25,28,31,34,37,40,43,46,49,52,55,58,61,64,67,70,73,76,79,82,85,88,91,94,97,100,103,106,127,144,59,60,62,63,65,66,68,69,71,72,74,75,77,78,80,81,83,84,86,87,89,90,92,93,95,96,98,99,101,102,104,105,107,108

Sheet controller
B2: ~InputCell: 1,51,54,57,60
B3: 60
C5: 2 | D5: 3 | E5: 4 | F5: 5 | G5: 6 | H5: 7
C7: =VLOOKUP($B$3,$B$9:$F$999,C$5,FALSE) -> Hi | D7: =VLOOKUP($B$3,$B$9:$F$999,D$5,FALSE) -> Hi | E7: =VLOOKUP($B$3,$B$9:$F$999,E$5,FALSE) -> Lo | F7: =VLOOKUP($B$3,$B$9:$I$999,F$5,FALSE) -> Lo | G7: =VLOOKUP($B$3,$B$9:$I$999,G$5,FALSE) -> Yes | H7: =VLOOKUP($B$3,$B$9:$I$999,H$5,FALSE) -> Ref
C8: GasPrice | D8: CO2Price | E8: REGridCost | F8: RECost | G8: Storage | H8: Nuc_O-M
B9: 1 | C9: Ref | D9: Ref | E9: Ref | F9: Ref | G9: Yes | H9: Ref
B10: =B9+1 -> 2 | C10: Lo | D10: Ref | E10: Ref | F10: Ref | G10: Yes | H10: Ref
B11: =B10+1 -> 3 | C11: Hi | D11: Ref | E11: Ref | F11: Ref | G11: Yes | H11: Ref
B12: =B11+1 -> 4 | C12: =C9 -> Ref | D12: Lo | E12: Ref | F12: Ref | G12: Yes | H12: Ref
B13: =B12+1 -> 5 | C13: =C10 -> Lo | D13: Lo | E13: Ref | F13: Ref | G13: Yes | H13: Ref
B14: =B13+1 -> 6 | C14: =C11 -> Hi | D14: Lo | E14: Ref | F14: Ref | G14: Yes | H14: Ref
B15: =B14+1 -> 7 | C15: =C12 -> Ref | D15: Med | E15: Ref | F15: Ref | G15: Yes | H15: Ref
B16: =B15+1 -> 8 | C16: =C13 -> Lo | D16: Med | E16: Ref | F16: Ref | G16: Yes | H16: Ref
B17: =B16+1 -> 9 | C17: =C14 -> Hi | D17: Med | E17: Ref | F17: Ref | G17: Yes | H17: Ref
B18: =B17+1 -> 10 | C18: =C15 -> Ref | D18: Hi | E18: Ref | F18: Ref | G18: Yes | H18: Ref
B19: =B18+1 -> 11 | C19: =C16 -> Lo | D19: Hi | E19: Ref | F19: Ref | G19: Yes | H19: Ref
B20: =B19+1 -> 12 | C20: =C17 -> Hi | D20: Hi | E20: Ref | F20: Ref | G20: Yes | H20: Ref
B21: =B20+1 -> 13 | C21: =C18 -> Ref | D21: =D9 -> Ref | E21: Lo | F21: Ref | G21: Yes | H21: Ref
B22: =B21+1 -> 14 | C22: =C19 -> Lo | D22: =D10 -> Ref | E22: Lo | F22: Ref | G22: Yes | H22: Ref
B23: =B22+1 -> 15 | C23: =C20 -> Hi | D23: =D11 -> Ref | E23: Lo | F23: Ref | G23: Yes | H23: Ref
B24: =B23+1 -> 16 | C24: =C21 -> Ref | D24: =D12 -> Lo | E24: Lo | F24: Ref | G24: Yes | H24: Ref
B25: =B24+1 -> 17 | C25: =C22 -> Lo | D25: =D13 -> Lo | E25: Lo | F25: Ref | G25: Yes | H25: Ref
B26: =B25+1 -> 18 | C26: =C23 -> Hi | D26: =D14 -> Lo | E26: Lo | F26: Ref | G26: Yes | H26: Ref
B27: =B26+1 -> 19 | C27: =C24 -> Ref | D27: =D15 -> Med | E27: Lo | F27: Ref | G27: Yes | H27: Ref
B28: =B27+1 -> 20 | C28: =C25 -> Lo | D28: =D16 -> Med | E28: Lo | F28: Ref | G28: Yes | H28: Ref
B29: =B28+1 -> 21 | C29: =C26 -> Hi | D29: =D17 -> Med | E29: Lo | F29: Ref | G29: Yes | H29: Ref
B30: =B29+1 -> 22 | C30: =C27 -> Ref | D30: =D18 -> Hi | E30: Lo | F30: Ref | G30: Yes | H30: Ref
B31: =B30+1 -> 23 | C31: =C28 -> Lo | D31: =D19 -> Hi | E31: Lo | F31: Ref | G31: Yes | H31: Ref
B32: =B31+1 -> 24 | C32: =C29 -> Hi | D32: =D20 -> Hi | E32: Lo | F32: Ref | G32: Yes | H32: Ref
... B44: =B43+1 -> 36 | C44: =C41 -> Hi | D44: =D32 -> Hi | E44: Hi | F44: Ref | G44: Yes | H44: Ref
B45: =B44+1 -> 37 | C45: =C42 -> Ref | D45: =D33 -> Ref | E45: =E9 -> Ref | F45: Lo | G45: Yes | H45: Ref
B46: =B45+1 -> 38 | C46: =C43 -> Lo | D46: =D34 -> Ref | E46: =E10 -> Ref | F46: Lo | G46: Yes | H46: Ref
B47: =B46+1 -> 39 | C47: =C44 -> Hi | D47: =D35 -> Ref | E47: =E11 -> Ref | F47: Lo | G47: Yes | H47: Ref
B48: =B47+1 -> 40 | C48: =C45 -> Ref | D48: =D36 -> Lo | E48: =E12 -> Ref | F48: Lo | G48: Yes | H48: Ref
B49: =B48+1 -> 41 | C49: =C46 -> Lo | D49: =D37 -> Lo | E49: =E13 -> Ref | F49: Lo | G49: Yes | H49: Ref
B50: =B49+1 -> 42 | C50: =C47 -> Hi | D50: =D38 -> Lo | E50: =E14 -> Ref | F50: Lo | G50: Yes | H50: Ref
B51: =B50+1 -> 43 | C51: =C48 -> Ref | D51: =D39 -> Med | E51: =E15 -> Ref | F51: Lo | G51: Yes | H51: Ref
B52: =B51+1 -> 44 | C52: =C49 -> Lo | D52: =D40 -> Med | E52: =E16 -> Ref | F52: Lo | G52: Yes | H52: Ref
B53: =B52+1 -> 45 | C53: =C50 -> Hi | D53: =D41 -> Med | E53: =E17 -> Ref | F53: Lo | G53: Yes | H53: Ref
B54: =B53+1 -> 46 | C54: =C51 -> Ref | D54: =D42 -> Hi | E54: =E18 -> Ref | F54: Lo | G54: Yes | H54: Ref
...

Sheet Nuc_O-M
A1: =controller!$H$7 -> Ref
D4: =IF($A$1="Hi","~TFM_UPD","deact") -> deact
D5: Attribute | E5: AllRegions | F5: PSET_PN
D6: ACT_COST | E6: *1.2 | F6: EN_Nuclear*
D7: FIXOM | E7: *1.2 | F7: EN_Nuclear*

Sheet Storage
A1: =controller!$G$7 -> Yes
D4: =IF($A$1="No","~TFM_INS","deact") -> deact
D5: Attribute | E5: AllRegions | F5: PSET_PN
D6: START | E6: 2100 | F6: EN_Stg*

Sheet REGridCost
A1: =controller!$E$7 -> Lo
C5: =IF(A1="Ref","DeACT","~TFM_UPD") -> ~TFM_UPD
C6: Attribute | D6: PSET_PN | E6: AllRegions
C7: INVCOST | D7: NatGrdExt* | E7: ="*"&IF(A1="Hi","2",".5") -> *.5

Sheet CO2Price
A1: =controller!D7 -> Hi | J1: growth | K1: 0.05 | L1: 0.05 | M1: 0.05
J2: start | K2: 25 | L2: 37 | M2: 75
C3: ~TFM_INS
C4: Attribute | D4: CSET_CN | E4: Year | F4: AllRegions
C5: COM_TAXNET | D5: ELCCO2Net | E5: 2019 | F5: 0 | K5: Lo | L5: Med | M5: Hi
C6: COM_TAXNET | D6: ELCCO2Net | E6: 2020 | F6: =IFERROR(OFFSET(J6,0,MATCH($A$1,$K$5:$M$5,0))/1000,"") -> 0.2 | J6: =E6 -> 2020 | K6: 75 | L6: 125 | M6: 200
C7: COM_TAXNET | D7: ELCCO2Net | E7: 2021 | F7: =IFERROR(OFFSET(J7,0,MATCH($A$1,$K$5:$M$5,0))/1000,"") -> 0.21 | J7: =E7 -> 2021 | K7: =K6*(1+K$1) -> 78.75 | L7: =L6*(1+L$1) -> 131.25 | M7: =M6*(1+M$1) -> 210
C8: COM_TAXNET | D8: ELCCO2Net | E8: 2022 | F8: =IFERROR(OFFSET(J8,0,MATCH($A$1,$K$5:$M$5,0))/1000,"") -> 0.2205 | J8: =E8 -> 2022 | K8: =K7*(1+K$1) -> 82.6875 | L8: =L7*(1+L$1) -> 137.8125 | M8: =M7*(1+M$1) -> 220.5
C9: COM_TAXNET | D9: ELCCO2Net | E9: 2023 | F9: =IFERROR(OFFSET(J9,0,MATCH($A$1,$K$5:$M$5,0))/1000,"") -> 0.231525 | J9: =E9 -> 2023 | K9: =K8*(1+K$1) -> 86.821875 | L9: =L8*(1+L$1) -> 144.70312 | M9: =M8*(1+M$1) -> 231.525
C10: COM_TAXNET | D10: ELCCO2Net | E10: 2024 | F10: =IFERROR(OFFSET(J10,0,MATCH($A$1,$K$5:$M$5,0))/1000,"") -> 0.24310125 | J10: =E10 -> 2024 | K10: =K9*(1+K$1) -> 91.162969 | L10: =L9*(1+L$1) -> 151.93828 | M10: =M9*(1+M$1) -> 243.10125
C11: COM_TAXNET | D11: ELCCO2Net | E11: 2025 | F11: =IFERROR(OFFSET(J11,0,MATCH($A$1,$K$5:$M$5,0))/1000,"") -> 0.25525631 | J11: =E11 -> 2025 | K11: =K10*(1+K$1) -> 95.721117 | L11: =L10*(1+L$1) -> 159.5352 | M11: =M10*(1+M$1) -> 255.25631
C12: COM_TAXNET | D12: ELCCO2Net | E12: 2026 | F12: =IFERROR(OFFSET(J12,0,MATCH($A$1,$K$5:$M$5,0))/1000,"") -> 0.26801913 | J12: =E12 -> 2026 | K12: =K11*(1+K$1) -> 100.50717 | L12: =L11*(1+L$1) -> 167.51196 | M12: =M11*(1+M$1) -> 268.01913
C13: COM_TAXNET | D13: ELCCO2Net | E13: 2027 | F13: =IFERROR(OFFSET(J13,0,MATCH($A$1,$K$5:$M$5,0))/1000,"") -> 0.28142008 | J13: =E13 -> 2027 | K13: =K12*(1+K$1) -> 105.53253 | L13: =L12*(1+L$1) -> 175.88755 | M13: =M12*(1+M$1) -> 281.42008
C14: COM_TAXNET | D14: ELCCO2Net | E14: 2028 | F14: =IFERROR(OFFSET(J14,0,MATCH($A$1,$K$5:$M$5,0))/1000,"") -> 0.29549109 | J14: =E14 -> 2028 | K14: =K13*(1+K$1) -> 110.80916 | L14: =L13*(1+L$1) -> 184.68193 | M14: =M13*(1+M$1) -> 295.49109
C15: COM_TAXNET | D15: ELCCO2Net | E15: 2029 | F15: =IFERROR(OFFSET(J15,0,MATCH($A$1,$K$5:$M$5,0))/1000,"") -> 0.31026564 | J15: =E15 -> 2029 | K15: =K14*(1+K$1) -> 116.34962 | L15: =L14*(1+L$1) -> 193.91603 | M15: =M14*(1+M$1) -> 310.26564
C16: COM_TAXNET | D16: ELCCO2Net | E16: 2030 | F16: =IFERROR(OFFSET(J16,0,MATCH($A$1,$K$5:$M$5,0))/1000,"") -> 0.32577893 | J16: =E16 -> 2030 | K16: =K15*(1+K$1) -> 122.1671 | L16: =L15*(1+L$1) -> 203.61183 | M16: =M15*(1+M$1) -> 325.77893
C17: COM_TAXNET | D17: ELCCO2Net | E17: 2031 | F17: =IFERROR(OFFSET(J17,0,MATCH($A$1,$K$5:$M$5,0))/1000,"") -> 0.34206787 | J17: =E17 -> 2031 | K17: =K16*(1+K$1) -> 128.27545 | L17: =L16*(1+L$1) -> 213.79242 | M17: =M16*(1+M$1) -> 342.06787
C18: COM_TAXNET | D18: ELCCO2Net | E18: 2032 | F18: =IFERROR(OFFSET(J18,0,MATCH($A$1,$K$5:$M$5,0))/1000,"") -> 0.35917127 | J18: =E18 -> 2032 | K18: =K17*(1+K$1) -> 134.68922 | L18: =L17*(1+L$1) -> 224.48204 | M18: =M17*(1+M$1) -> 359.17127
... C36: COM_TAXNET | D36: ELCCO2Net | E36: 2050 | F36: =IFERROR(OFFSET(J36,0,MATCH($A$1,$K$5:$M$5,0))/1000,"") -> 0.86438848 | J36: =E36 -> 2050 | K36: =K35*(1+K$1) -> 324.14568 | L36: =L35*(1+L$1) -> 540.2428 | M36: =M35*(1+M$1) -> 864.38848

Sheet GasPrice
A1: =controller!$C$7 -> Hi | I1: 2015 | J1: 2050
I2: 1 | J2: =VLOOKUP(A1,$M$2:$N$4,2,FALSE) -> 3 | M2: Hi | N2: 3
C3: =IF(A1="Ref","DeACT","~TFM_UPD") -> ~TFM_UPD | M3: Lo | N3: 2
C4: SourceScen | D4: Attribute | E4: PSET_PN | F4: Year | G4: AllRegions | M4: Ref | N4: 2 | Q4: 2015 | R4: 2016 | S4: 2017 | T4: 2018 | U4: 2019 | V4: 2020 | W4: 2021 | X4: 2022 | Y4: 2023 | Z4: 2024 | AA4: 2025 | AB4: 2026 | AC4: 2027 | AD4: 2028 | AE4: 2029 | AF4: 2030 | AG4: 2031 | AH4: 2032 | AI4: 2033 | AJ4: 2034 | AK4: 2035 | AL4: 2036 | AM4: 2037 | AN4: 2038 | AO4: 2039 | AP4: 2040 | AQ4: 2041 | AR4: 2042 | AS4: 2043 | AT4: 2044 | AU4: 2045 | AV4: 2046 | AW4: 2047 | AX4: 2048 | AY4: 2049 | AZ4: 2050
C5: Base | D5: ACT_COST | E5: MinGas* | F5: 2018 | G5: =HLOOKUP(F5,$Q$4:$AZ$6,VLOOKUP($A$1,$M$2:$N$4,2,FALSE),FALSE) -> *0.95405973473104 | P5: LOGS | Q5: *1 | R5: *1 | S5: *1 | T5: *1.17520089486453 | U5: *1.11353129901131 | V5: *0.723768671513585 | W5: *0.667282868775325 | X5: *0.677341072852966 | Y5: *0.685076397749664 | Z5: *0.723537825547089 | AA5: *0.752050719229276 | AB5: *0.79483054311137 | AC5: *0.814884778912248 | AD5: *0.81816234674846 | AE5: *0.827726894497462 | AF5: *0.832773500880391 | AG5: *0.819160631816951 | AH5: *0.8453201045679 | AI5: *0.847012828318711 | AJ5: *0.848437096514626 | AK5: *0.844172539308103 | AL5: *0.839259692735875 | AM5: *0.839562296298786 | AN5: *0.84526310369353 | AO5: *0.835208639972468 | AP5: *0.834932582193331 | AQ5: *0.832113247338162 | AR5: *0.832850508136456 | AS5: *0.842226931591444 | AT5: *0.812537982409902 | AU5: *0.817092002488588 | AV5: *0.809108823271049 | AW5: *0.797858211680652 | AX5: *0.785114490936803 | AY5: *0.771747440222102 | AZ5: *0.754176380589704
C6: Base | D6: ACT_COST | E6: MinGas* | F6: 2019 | G6: =HLOOKUP(F6,$Q$4:$AZ$6,VLOOKUP($A$1,$M$2:$N$4,2,FALSE),FALSE) -> *0.965824749104333 | P6: HOGS | Q6: *1 | R6: *1 | S6: *1 | T6: *0.95405973473104 | U6: *0.965824749104333 | V6: *1.42621699435605 | W6: *1.44714120110334 | X6: *1.51010788562888 | Y6: *1.58415882759654 | Z6: *1.60288395688783 | AA6: *1.60208734544499 | AB6: *1.55444925632777 | AC6: *1.49773737793382 | AD6: *1.45660272564172 | AE6: *1.41460460380904 | AF6: *1.36790852696526 | AG6: *1.32721505196477 | AH6: *1.26213081025743 | AI6: *1.21902314813471 | AJ6: *1.17728843470502 | AK6: *1.14350460082343 | AL6: *1.12315878998893 | AM6: *1.11701389805454 | AN6: *1.10218767501199 | AO6: *1.09572046138954 | AP6: *1.09528004137033 | AQ6: *1.11061746808653 | AR6: *1.11271499525458 | AS6: *1.11320462013965 | AT6: *1.11696836410708 | AU6: *1.11505924506397 | AV6: *1.10960694385015 | AW6: *1.10395305584941 | AX6: *1.09846262374728 | AY6: *1.09231257134127 | AZ6: *1.08599277939943
C7: Base | D7: ACT_COST | E7: MinGas* | F7: 2020 | G7: =HLOOKUP(F7,$Q$4:$AZ$6,VLOOKUP($A$1,$M$2:$N$4,2,FALSE),FALSE) -> *1.42621699435605
C8: Base | D8: ACT_COST | E8: MinGas* | F8: 2021 | G8: =HLOOKUP(F8,$Q$4:$AZ$6,VLOOKUP($A$1,$M$2:$N$4,2,FALSE),FALSE) -> *1.44714120110334
C9: Base | D9: ACT_COST | E9: MinGas* | F9: 2022 | G9: =HLOOKUP(F9,$Q$4:$AZ$6,VLOOKUP($A$1,$M$2:$N$4,2,FALSE),FALSE) -> *1.51010788562888
C10: Base | D10: ACT_COST | E10: MinGas* | F10: 2023 | G10: =HLOOKUP(F10,$Q$4:$AZ$6,VLOOKUP($A$1,$M$2:$N$4,2,FALSE),FALSE) -> *1.58415882759654
C11: Base | D11: ACT_COST | E11: MinGas* | F11: 2024 | G11: =HLOOKUP(F11,$Q$4:$AZ$6,VLOOKUP($A$1,$M$2:$N$4,2,FALSE),FALSE) -> *1.60288395688783
C12: Base | D12: ACT_COST | E12: MinGas* | F12: 2025 | G12: =HLOOKUP(F12,$Q$4:$AZ$6,VLOOKUP($A$1,$M$2:$N$4,2,FALSE),FALSE) -> *1.60208734544499
C13: Base | D13: ACT_COST | E13: MinGas* | F13: 2026 | G13: =HLOOKUP(F13,$Q$4:$AZ$6,VLOOKUP($A$1,$M$2:$N$4,2,FALSE),FALSE) -> *1.55444925632777
C14: Base | D14: ACT_COST | E14: MinGas* | F14: 2027 | G14: =HLOOKUP(F14,$Q$4:$AZ$6,VLOOKUP($A$1,$M$2:$N$4,2,FALSE),FALSE) -> *1.49773737793382
C15: Base | D15: ACT_COST | E15: MinGas* | F15: 2028 | G15: =HLOOKUP(F15,$Q$4:$AZ$6,VLOOKUP($A$1,$M$2:$N$4,2,FALSE),FALSE) -> *1.45660272564172
C16: Base | D16: ACT_COST | E16: MinGas* | F16: 2029 | G16: =HLOOKUP(F16,$Q$4:$AZ$6,VLOOKUP($A$1,$M$2:$N$4,2,FALSE),FALSE) -> *1.41460460380904
C17: Base | D17: ACT_COST | E17: MinGas* | F17: 2030 | G17: =HLOOKUP(F17,$Q$4:$AZ$6,VLOOKUP($A$1,$M$2:$N$4,2,FALSE),FALSE) -> *1.36790852696526
C18: Base | D18: ACT_COST | E18: MinGas* | F18: 2031 | G18: =HLOOKUP(F18,$Q$4:$AZ$6,VLOOKUP($A$1,$M$2:$N$4,2,FALSE),FALSE) -> *1.32721505196477
... C37: Base | D37: ACT_COST | E37: MinGas* | F37: 2050 | G37: =HLOOKUP(F37,$Q$4:$AZ$6,VLOOKUP($A$1,$M$2:$N$4,2,FALSE),FALSE) -> *1.08599277939943

Sheet RECost
A1: =controller!F7 -> Lo
N2: =VLOOKUP($A$1,$Y$2:$Z$4,2,FALSE) -> 15 | R2: =IF(A1="Ref","DeACT","~TFM_MIG") -> ~TFM_MIG | Y2: Lo | Z2: 15
C3: Year2 | D3: AllRegions | E3: PSET_PN | J3: 1 | K3: E_SPV* | L3: Solar PV - fixed tilt | R3: SourceScen | S3: Attribute | T3: Year2 | U3: AllRegions | V3: PSET_PN | Y3: Hi | Z3: 2
C4: 2017 | D4: =VLOOKUP($C4,'NEMS learning'!$A$2:$V$37,MATCH(VLOOKUP(RECost!H4,RECost!$J$3:$L$17,3,FALSE),'NEMS learning'!$A$1:$V$1,0)) -> 0.938 | E4: =VLOOKUP(H4,$J$3:$K$17,2,FALSE) -> E_SPV* | G4: =TREND($C$30:$C$31,$B$30:$B$31,C4) -> 0 | H4: 1 | J4: 2 | K4: E_WON* | L4: Wind | N4: =ROUND(MIN(D4*(1+G4),1),3) -> 0.938 | R4: Solar-EIA-c | S4: INVCOST | T4: 2017 | U4: ="*"&N4 -> *0.938 | V4: E_SPV* | Y4: Ref | Z4: 1
C5: 2020 | D5: =VLOOKUP($C5,'NEMS learning'!$A$2:$V$37,MATCH(VLOOKUP(RECost!H5,RECost!$J$3:$L$17,3,FALSE),'NEMS learning'!$A$1:$V$1,0)) -> 0.801734 | E5: =VLOOKUP(H5,$J$3:$K$17,2,FALSE) -> E_SPV* | G5: =TREND($C$30:$C$31,$B$30:$B$31,C5) -> -0.027272727 | H5: 1 | J5: 3 | K5: E_WOF* | L5: Offshore Wind | N5: =IF($N$2=2,N4,ROUND(MIN(D5*(1+G5),1),3)) -> 0.78 | R5: Solar-EIA-c | S5: INVCOST | T5: 2020 | U5: ="*"&N5 -> *0.78 | V5: E_SPV*
C6: 2025 | D6: =VLOOKUP($C6,'NEMS learning'!$A$2:$V$37,MATCH(VLOOKUP(RECost!H6,RECost!$J$3:$L$17,3,FALSE),'NEMS learning'!$A$1:$V$1,0)) -> 0.726158 | E6: =VLOOKUP(H6,$J$3:$K$17,2,FALSE) -> E_SPV* | G6: =TREND($C$30:$C$31,$B$30:$B$31,C6) -> -0.072727273 | H6: 1 | J6: 4 | K6: EN_COAPUL | L6: Coal with 30% CCS | N6: =IF($N$2=2,N5,ROUND(MIN(D6*(1+G6),1),3)) -> 0.673 | R6: Solar-EIA-c | S6: INVCOST | T6: 2025 | U6: ="*"&N6 -> *0.673 | V6: E_SPV*
C7: =C6+5 -> 2030 | D7: =VLOOKUP($C7,'NEMS learning'!$A$2:$V$37,MATCH(VLOOKUP(RECost!H7,RECost!$J$3:$L$17,3,FALSE),'NEMS learning'!$A$1:$V$1,0)) -> 0.717941 | E7: =VLOOKUP(H7,$J$3:$K$17,2,FALSE) -> E_SPV* | G7: =TREND($C$30:$C$31,$B$30:$B$31,C7) -> -0.11818182 | H7: 1 | J7: 5 | K7: EN_COAIGCC | L7: Coal with 30% CCS | N7: =IF($N$2=2,N6,ROUND(MIN(D7*(1+G7),1),3)) -> 0.633 | R7: Solar-EIA-c | S7: INVCOST | T7: 2030 | U7: ="*"&N7 -> *0.633 | V7: E_SPV*
C8: =C7+5 -> 2035 | D8: =VLOOKUP($C8,'NEMS learning'!$A$2:$V$37,MATCH(VLOOKUP(RECost!H8,RECost!$J$3:$L$17,3,FALSE),'NEMS learning'!$A$1:$V$1,0)) -> 0.704942 | E8: =VLOOKUP(H8,$J$3:$K$17,2,FALSE) -> E_SPV* | G8: =TREND($C$30:$C$31,$B$30:$B$31,C8) -> -0.16363636 | H8: 1 | J8: 6 | K8: EN_ZCOAIGCC | L8: Coal with 90% CCS | N8: =IF($N$2=2,N7,ROUND(MIN(D8*(1+G8),1),3)) -> 0.59 | R8: Solar-EIA-c | S8: INVCOST | T8: 2035 | U8: ="*"&N8 -> *0.59 | V8: E_SPV*
C9: =C8+5 -> 2040 | D9: =VLOOKUP($C9,'NEMS learning'!$A$2:$V$37,MATCH(VLOOKUP(RECost!H9,RECost!$J$3:$L$17,3,FALSE),'NEMS learning'!$A$1:$V$1,0)) -> 0.7 | E9: =VLOOKUP(H9,$J$3:$K$17,2,FALSE) -> E_SPV* | G9: =TREND($C$30:$C$31,$B$30:$B$31,C9) -> -0.20909091 | H9: 1 | J9: 7 | K9: EN_ZGasCCAdv | L9: Adv CC w/seq | N9: =IF($N$2=2,N8,ROUND(MIN(D9*(1+G9),1),3)) -> 0.554 | R9: Solar-EIA-c | S9: INVCOST | T9: 2040 | U9: ="*"&N9 -> *0.554 | V9: E_SPV*
C10: =C9+5 -> 2045 | D10: =VLOOKUP($C10,'NEMS learning'!$A$2:$V$37,MATCH(VLOOKUP(RECost!H10,RECost!$J$3:$L$17,3,FALSE),'NEMS learning'!$A$1:$V$1,0)) -> 0.7 | E10: =VLOOKUP(H10,$J$3:$K$17,2,FALSE) -> E_SPV* | G10: =TREND($C$30:$C$31,$B$30:$B$31,C10) -> -0.25454545 | H10: 1 | J10: 8 | K10: EN_GasCCAdv | L10: Adv CC | N10: =IF($N$2=2,N9,ROUND(MIN(D10*(1+G10),1),3)) -> 0.522 | R10: Solar-EIA-c | S10: INVCOST | T10: 2045 | U10: ="*"&N10 -> *0.522 | V10: E_SPV*
C11: =C10+5 -> 2050 | D11: =VLOOKUP($C11,'NEMS learning'!$A$2:$V$37,MATCH(VLOOKUP(RECost!H11,RECost!$J$3:$L$17,3,FALSE),'NEMS learning'!$A$1:$V$1,0)) -> 0.7 | E11: =VLOOKUP(H11,$J$3:$K$17,2,FALSE) -> E_SPV* | G11: =TREND($C$30:$C$31,$B$30:$B$31,C11) -> -0.3 | H11: 1 | J11: 9 | K11: EN_GasCC | L11: Comb. Cyc | N11: =IF($N$2=2,N10,ROUND(MIN(D11*(1+G11),1),3)) -> 0.49 | R11: Solar-EIA-c | S11: INVCOST | T11: 2050 | U11: ="*"&N11 -> *0.49 | V11: E_SPV*
C12: =C4 -> 2017 | D12: =VLOOKUP($C12,'NEMS learning'!$A$2:$V$37,MATCH(VLOOKUP(RECost!H12,RECost!$J$3:$L$17,3,FALSE),'NEMS learning'!$A$1:$V$1,0)) -> 0.998 | E12: =VLOOKUP(H12,$J$3:$K$17,2,FALSE) -> E_WON* | G12: =TREND($C$30:$C$31,$B$30:$B$31,C12) -> 0 | H12: =H4+1 -> 2 | J12: 10 | K12: EN_GasCTAdv | L12: Adv. CT | N12: =ROUND(MIN(D12*(1+G12),1),3) -> 0.998 | R12: BaseExtra | S12: INVCOST | T12: 2017 | U12: ="*"&N12 -> *0.998 | V12: E_WON*
C13: =C5 -> 2020 | D13: =VLOOKUP($C13,'NEMS learning'!$A$2:$V$37,MATCH(VLOOKUP(RECost!H13,RECost!$J$3:$L$17,3,FALSE),'NEMS learning'!$A$1:$V$1,0)) -> 0.99 | E13: =VLOOKUP(H13,$J$3:$K$17,2,FALSE) -> E_WON* | G13: =TREND($C$30:$C$31,$B$30:$B$31,C13) -> -0.027272727 | H13: =H5+1 -> 2 | J13: 11 | K13: EN_GasCT | L13: Comb. Turb | N13: =IF($N$2=2,N12,ROUND(MIN(D13*(1+G13),1),3)) -> 0.963 | R13: BaseExtra | S13: INVCOST | T13: 2020 | U13: ="*"&N13 -> *0.963 | V13: E_WON*
C14: =C6 -> 2025 | D14: =VLOOKUP($C14,'NEMS learning'!$A$2:$V$37,MATCH(VLOOKUP(RECost!H14,RECost!$J$3:$L$17,3,FALSE),'NEMS learning'!$A$1:$V$1,0)) -> 0.9775 | E14: =VLOOKUP(H14,$J$3:$K$17,2,FALSE) -> E_WON* | G14: =TREND($C$30:$C$31,$B$30:$B$31,C14) -> -0.072727273 | H14: =H6+1 -> 2 | J14: 12 | K14: EN_Biomass | L14: Biomass | N14: =IF($N$2=2,N13,ROUND(MIN(D14*(1+G14),1),3)) -> 0.906 | R14: BaseExtra | S14: INVCOST | T14: 2025 | U14: ="*"&N14 -> *0.906 | V14: E_WON*
C15: =C7 -> 2030 | D15: =VLOOKUP($C15,'NEMS learning'!$A$2:$V$37,MATCH(VLOOKUP(RECost!H15,RECost!$J$3:$L$17,3,FALSE),'NEMS learning'!$A$1:$V$1,0)) -> 0.965 | E15: =VLOOKUP(H15,$J$3:$K$17,2,FALSE) -> E_WON* | G15: =TREND($C$30:$C$31,$B$30:$B$31,C15) -> -0.11818182 | H15: =H7+1 -> 2 | J15: 13 | K15: EN_ZBiomass | L15: =L8 -> Coal with 90% CCS | N15: =IF($N$2=2,N14,ROUND(MIN(D15*(1+G15),1),3)) -> 0.851 | R15: BaseExtra | S15: INVCOST | T15: 2030 | U15: ="*"&N15 -> *0.851 | V15: E_WON*
C16: =C8 -> 2035 | D16: =VLOOKUP($C16,'NEMS learning'!$A$2:$V$37,MATCH(VLOOKUP(RECost!H16,RECost!$J$3:$L$17,3,FALSE),'NEMS learning'!$A$1:$V$1,0)) -> 0.9525 | E16: =VLOOKUP(H16,$J$3:$K$17,2,FALSE) -> E_WON* | G16: =TREND($C$30:$C$31,$B$30:$B$31,C16) -> -0.16363636 | H16: =H8+1 -> 2 | J16: 14 | K16: EN_OilCCAdv | L16: =L12 -> Adv. CT | N16: =IF($N$2=2,N15,ROUND(MIN(D16*(1+G16),1),3)) -> 0.797 | R16: BaseExtra | S16: INVCOST | T16: 2035 | U16: ="*"&N16 -> *0.797 | V16: E_WON*
C17: =C9 -> 2040 | D17: =VLOOKUP($C17,'NEMS learning'!$A$2:$V$37,MATCH(VLOOKUP(RECost!H17,RECost!$J$3:$L$17,3,FALSE),'NEMS learning'!$A$1:$V$1,0)) -> 0.94 | E17: =VLOOKUP(H17,$J$3:$K$17,2,FALSE) -> E_WON* | G17: =TREND($C$30:$C$31,$B$30:$B$31,C17) -> -0.20909091 | H17: =H9+1 -> 2 | J17: 15 | K17: EN_Hydro* | L17: Hydro | N17: =IF($N$2=2,N16,ROUND(MIN(D17*(1+G17),1),3)) -> 0.743 | R17: BaseExtra | S17: INVCOST | T17: 2040 | U17: ="*"&N17 -> *0.743 | V17: E_WON*
C18: =C10 -> 2045 | D18: =VLOOKUP($C18,'NEMS learning'!$A$2:$V$37,MATCH(VLOOKUP(RECost!H18,RECost!$J$3:$L$17,3,FALSE),'NEMS learning'!$A$1:$V$1,0)) -> 0.9275 | E18: =VLOOKUP(H18,$J$3:$K$17,2,FALSE) -> E_WON* | G18: =TREND($C$30:$C$31,$B$30:$B$31,C18) -> -0.25454545 | H18: =H10+1 -> 2 | N18: =IF($N$2=2,N17,ROUND(MIN(D18*(1+G18),1),3)) -> 0.691 | R18: BaseExtra | S18: INVCOST | T18: 2045 | U18: ="*"&N18 -> *0.691 | V18: E_WON*
C19: =C11 -> 2050 | D19: =VLOOKUP($C19,'NEMS learning'!$A$2:$V$37,MATCH(VLOOKUP(RECost!H19,RECost!$J$3:$L$17,3,FALSE),'NEMS learning'!$A$1:$V$1,0)) -> 0.915 | E19: =VLOOKUP(H19,$J$3:$K$17,2,FALSE) -> E_WON* | G19: =TREND($C$30:$C$31,$B$30:$B$31,C19) -> -0.3 | H19: =H11+1 -> 2 | N19: =IF($N$2=2,N18,ROUND(MIN(D19*(1+G19),1),3)) -> 0.64 | R19: BaseExtra | S19: INVCOST | T19: 2050 | U19: ="*"&N19 -> *0.64 | V19: E_WON*
C20: =C12 -> 2017 | D20: =VLOOKUP($C20,'NEMS learning'!$A$2:$V$37,MATCH(VLOOKUP(RECost!H20,RECost!$J$3:$L$17,3,FALSE),'NEMS learning'!$A$1:$V$1,0)) -> 0.994 | E20: =VLOOKUP(H20,$J$3:$K$17,2,FALSE) -> E_WOF* | G20: =TREND($C$30:$C$31,$B$30:$B$31,C20) -> 0 | H20: =H12+1 -> 3 | N20: =ROUND(MIN(D20*(1+G20),1),3) -> 0.994 | R20: BaseExtra | S20: INVCOST | T20: 2017 | U20: ="*"&N20 -> *0.994 | V20: E_WOF*
C21: =C13 -> 2020 | D21: =VLOOKUP($C21,'NEMS learning'!$A$2:$V$37,MATCH(VLOOKUP(RECost!H21,RECost!$J$3:$L$17,3,FALSE),'NEMS learning'!$A$1:$V$1,0)) -> 0.975 | E21: =VLOOKUP(H21,$J$3:$K$17,2,FALSE) -> E_WOF* | G21: =TREND($C$30:$C$31,$B$30:$B$31,C21) -> -0.027272727 | H21: =H13+1 -> 3 | N21: =IF($N$2=2,N20,ROUND(MIN(D21*(1+G21),1),3)) -> 0.948 | R21: BaseExtra | S21: INVCOST | T21: 2020 | U21: ="*"&N21 -> *0.948 | V21: E_WOF*
C22: =C14 -> 2025 | D22: =VLOOKUP($C22,'NEMS learning'!$A$2:$V$37,MATCH(VLOOKUP(RECost!H22,RECost!$J$3:$L$17,3,FALSE),'NEMS learning'!$A$1:$V$1,0)) -> 0.94375 | E22: =VLOOKUP(H22,$J$3:$K$17,2,FALSE) -> E_WOF* | G22: =TREND($C$30:$C$31,$B$30:$B$31,C22) -> -0.072727273 | H22: =H14+1 -> 3 | K22: Run # | L22: reduction by 2050 (in add'n to NEMS learning) 0 = default cost reduction (NEMS learning); 1 = frozen cost | N22: =IF($N$2=2,N21,ROUND(MIN(D22*(1+G22),1),3)) -> 0.875 | R22: BaseExtra | S22: INVCOST | T22: 2025 | U22: ="*"&N22 -> *0.875 | V22: E_WOF*
C23: =C15 -> 2030 | D23: =VLOOKUP($C23,'NEMS learning'!$A$2:$V$37,MATCH(VLOOKUP(RECost!H23,RECost!$J$3:$L$17,3,FALSE),'NEMS learning'!$A$1:$V$1,0)) -> 0.9125 | E23: =VLOOKUP(H23,$J$3:$K$17,2,FALSE) -> E_WOF* | G23: =TREND($C$30:$C$31,$B$30:$B$31,C23) -> -0.11818182 | H23: =H15+1 -> 3 | K23: 1 | L23: 0 | N23: =IF($N$2=2,N22,ROUND(MIN(D23*(1+G23),1),3)) -> 0.805 | R23: BaseExtra | S23: INVCOST | T23: 2030 | U23: ="*"&N23 -> *0.805 | V23: E_WOF*
C24: =C16 -> 2035 | D24: =VLOOKUP($C24,'NEMS learning'!$A$2:$V$37,MATCH(VLOOKUP(RECost!H24,RECost!$J$3:$L$17,3,FALSE),'NEMS learning'!$A$1:$V$1,0)) -> 0.88125 | E24: =VLOOKUP(H24,$J$3:$K$17,2,FALSE) -> E_WOF* | G24: =TREND($C$30:$C$31,$B$30:$B$31,C24) -> -0.16363636 | H24: =H16+1 -> 3 | K24: 2 | L24: 1 | N24: =IF($N$2=2,N23,ROUND(MIN(D24*(1+G24),1),3)) -> 0.737 | R24: BaseExtra | S24: INVCOST | T24: 2035 | U24: ="*"&N24 -> *0.737 | V24: E_WOF*
C25: =C17 -> 2040 | D25: =VLOOKUP($C25,'NEMS learning'!$A$2:$V$37,MATCH(VLOOKUP(RECost!H25,RECost!$J$3:$L$17,3,FALSE),'NEMS learning'!$A$1:$V$1,0)) -> 0.85 | E25: =VLOOKUP(H25,$J$3:$K$17,2,FALSE) -> E_WOF* | G25: =TREND($C$30:$C$31,$B$30:$B$31,C25) -> -0.20909091 | H25: =H17+1 -> 3 | K25: 3 | L25: =L23+0.02 -> 0.02 | N25: =IF($N$2=2,N24,ROUND(MIN(D25*(1+G25),1),3)) -> 0.672 | R25: BaseExtra | S25: INVCOST | T25: 2040 | U25: ="*"&N25 -> *0.672 | V25: E_WOF*
C26: =C18 -> 2045 | D26: =VLOOKUP($C26,'NEMS learning'!$A$2:$V$37,MATCH(VLOOKUP(RECost!H26,RECost!$J$3:$L$17,3,FALSE),'NEMS learning'!$A$1:$V$1,0)) -> 0.81875 | E26: =VLOOKUP(H26,$J$3:$K$17,2,FALSE) -> E_WOF* | G26: =TREND($C$30:$C$31,$B$30:$B$31,C26) -> -0.25454545 | H26: =H18+1 -> 3 | K26: 4 | L26: =L25+0.02 -> 0.04 | N26: =IF($N$2=2,N25,ROUND(MIN(D26*(1+G26),1),3)) -> 0.61 | R26: BaseExtra | S26: INVCOST | T26: 2045 | U26: ="*"&N26 -> *0.61 | V26: E_WOF*
C27: =C19 -> 2050 | D27: =VLOOKUP($C27,'NEMS learning'!$A$2:$V$37,MATCH(VLOOKUP(RECost!H27,RECost!$J$3:$L$17,3,FALSE),'NEMS learning'!$A$1:$V$1,0)) -> 0.7875 | E27: =VLOOKUP(H27,$J$3:$K$17,2,FALSE) -> E_WOF* | G27: =TREND($C$30:$C$31,$B$30:$B$31,C27) -> -0.3 | H27: =H19+1 -> 3 | K27: 5 | L27: =L26+0.02 -> 0.06 | N27: =IF($N$2=2,N26,ROUND(MIN(D27*(1+G27),1),3)) -> 0.551 | R27: BaseExtra | S27: INVCOST | T27: 2050 | U27: ="*"&N27 -> *0.551 | V27: E_WOF*
K28: 6 | L28: =L27+0.02 -> 0.08
K29: 7 | L29: =L28+0.02 -> 0.1
B30: 2017 | C30: 0 | K30: 8 | L30: =L29+0.02 -> 0.12
B31: 2050 | C31: =VLOOKUP(N2,$K$23:$L$36,2,FALSE) -> -0.3 | K31: 9 | L31: =L30+0.02 -> 0.14
K32: 10 | L32: =L31+0.02 -> 0.16
K33: 11 | L33: =L32+0.02 -> 0.18
K34: 12 | L34: =L33+0.02 -> 0.2
K35: 15 | L35: -0.3

Sheet NEMS learning
A1: Online Year | B1: Coal with 30% CCS | C1: Coal with 90% CCS | D1: Comb. Turb | E1: Adv. CT | F1: Comb. Cyc | G1: Adv CC | H1: Adv CC w/seq | I1: Fuel Cell | J1: Nuclear | K1: Biomass | L1: Geothermal | M1: Landfill Gas | N1: Hydro | O1: Battery Storage | P1: Wind | Q1: Offshore Wind | R1: Solar Thermal | S1: Solar PV - tracking | T1: Solar PV - fixed tilt | U1: Dist. Gen Base | V1: Dist Gen Peak
A2: 2015 | B2: 3 | C2: 3 | D2: 3 | E2: 3 | F2: 3 | G2: 3 | H2: 3 | I2: 3 | J2: 3 | K2: 3 | L2: 3 | M2: 3 | N2: 3 | O2: 3 | P2: 3 | Q2: 3 | R2: 3 | S2: 3 | T2: 3 | U2: 3 | V2: 3
A3: 2016 | B3: 3 | C3: 3 | D3: 3 | E3: 3 | F3: 3 | G3: 3 | H3: 3 | I3: 3 | J3: 3 | K3: 3 | L3: 3 | M3: 3 | N3: 3 | O3: 3 | P3: 3 | Q3: 3 | R3: 3 | S3: 3 | T3: 3 | U3: 3 | V3: 3
A4: 2017 | B4: 0.996 | C4: 0.996 | D4: 0.997 | E4: 0.996 | F4: 0.998 | G4: 0.997 | H4: 0.994 | I4: 0.99 | J4: 0.995 | K4: 0.996 | L4: 0.995 | M4: 0.997 | N4: 0.998 | O4: 0.99 | P4: 0.998 | Q4: 0.994 | R4: 0.988 | S4: 0.938 | T4: 0.938 | U4: 0.995 | V4: 0.995
A5: 2018 | B5: 0.99125 | C5: 0.99125 | D5: 0.995 | E5: 0.9925 | F5: 0.995 | G5: 0.9935 | H5: 0.988 | I5: 0.964729 | J5: 0.99 | K5: 0.9925 | L5: 0.99 | M5: 0.995 | N5: 0.995 | O5: 0.98 | P5: 0.995 | Q5: 0.9875 | R5: 0.982718 | S5: 0.862163 | T5: 0.862163 | U5: 0.99 | V5: 0.99
A6: 2019 | B6: 0.986875 | C6: 0.986875 | D6: 0.9925 | E6: 0.98875 | F6: 0.9925 | G6: 0.99025 | H6: 0.982 | I6: 0.950974 | J6: 0.985 | K6: 0.98875 | L6: 0.985 | M6: 0.9925 | N6: 0.99117 | O6: 0.97 | P6: 0.9925 | Q6: 0.98125 | R6: 0.977718 | S6: 0.823791 | T6: 0.823791 | U6: 0.985 | V6: 0.985
A7: 2020 | B7: 0.9825 | C7: 0.9825 | D7: 0.99 | E7: 0.985 | F7: 0.99 | G7: 0.987 | H7: 0.976 | I7: 0.940974 | J7: 0.98 | K7: 0.981119 | L7: 0.98 | M7: 0.99 | N7: 0.987982 | O7: 0.96 | P7: 0.99 | Q7: 0.975 | R7: 0.972718 | S7: 0.801734 | T7: 0.801734 | U7: 0.98 | V7: 0.98
A8: 2021 | B8: 0.978125 | C8: 0.978125 | D8: 0.9875 | E8: 0.98125 | F8: 0.9875 | G8: 0.98375 | H8: 0.97 | I8: 0.930974 | J8: 0.975 | K8: 0.972991 | L8: 0.975 | M8: 0.9875 | N8: 0.985482 | O8: 0.95 | P8: 0.9875 | Q8: 0.96875 | R8: 0.967718 | S8: 0.756083 | T8: 0.756083 | U8: 0.975 | V8: 0.95
A9: 2022 | B9: 0.97375 | C9: 0.97375 | D9: 0.985 | E9: 0.97626 | F9: 0.985 | G9: 0.979756 | H9: 0.963504 | I9: 0.920974 | J9: 0.964398 | K9: 0.969241 | L9: 0.97 | M9: 0.985 | N9: 0.982982 | O9: 0.94 | P9: 0.985 | Q9: 0.9625 | R9: 0.962718 | S9: 0.74016 | T9: 0.74016 | U9: 0.97 | V9: 0.9025
A10: 2023 | B10: 0.969375 | C10: 0.969375 | D10: 0.9825 | E10: 0.968714 | F10: 0.9825 | G10: 0.974229 | H10: 0.955986 | I10: 0.910974 | J10: 0.959398 | K10: 0.965491 | L10: 0.943864 | M10: 0.9825 | N10: 0.980482 | O10: 0.93 | P10: 0.9825 | Q10: 0.95625 | R10: 0.957718 | S10: 0.729182 | T10: 0.729182 | U10: 0.965 | V10: 0.857375
A11: 2024 | B11: 0.965 | C11: 0.965 | D11: 0.98 | E11: 0.958721 | F11: 0.98 | G11: 0.967233 | H11: 0.947488 | I11: 0.900974 | J11: 0.954398 | K11: 0.961741 | L11: 0.9104 | M11: 0.98 | N11: 0.977982 | O11: 0.92 | P11: 0.98 | Q11: 0.95 | R11: 0.952718 | S11: 0.727658 | T11: 0.727658 | U11: 0.96 | V11: 0.848083
A12: 2025 | B12: 0.960625 | C12: 0.960625 | D12: 0.9775 | E12: 0.943278 | F12: 0.9775 | G12: 0.956967 | H12: 0.936811 | I12: 0.890974 | J12: 0.949398 | K12: 0.957991 | L12: 0.882506 | M12: 0.9775 | N12: 0.975482 | O12: 0.91 | P12: 0.9775 | Q12: 0.94375 | R12: 0.947719 | S12: 0.726158 | T12: 0.726158 | U12: 0.955 | V12: 0.837693
A13: 2026 | B13: 0.95625 | C13: 0.95625 | D13: 0.975 | E13: 0.929111 | F13: 0.975 | G13: 0.947466 | H13: 0.926644 | I13: 0.880974 | J13: 0.944398 | K13: 0.954241 | L13: 0.86381 | M13: 0.975 | N13: 0.972982 | O13: 0.9 | P13: 0.975 | Q13: 0.9375 | R13: 0.942719 | S13: 0.724658 | T13: 0.724658 | U13: 0.95 | V13: 0.829928
... A37: 2050 | B37: 0.85125 | C37: 0.85125 | D37: 0.915 | E37: 0.8075 | F37: 0.915 | G37: 0.8505 | H37: 0.77 | I37: 0.640974 | J37: 0.824398 | K37: 0.864241 | L37: 0.7 | M37: 0.915 | N37: 0.912982 | O37: 0.66 | P37: 0.915 | Q37: 0.7875 | R37: 0.822719 | S37: 0.7 | T37: 0.7 | U37: 0.795049 | V37: 0.7

Sheet Sheet9
