Workbook

Sheet Readme
A1: Workbook purpose:
A2: Creates time series for capital cost decline over time
A4: Data source:
A5: AEO Reference case costs (NEMS learning sheet)
A7: User-modifiable?
A8: Learning rates on NEMS learning can be modified, replaced with a new AEO or with trajectories derived from ETL runs. Note VLOOKUP structure driven by columns J-L on INS sheet.

Sheet INS
B2: ~TFM_MIG | O2: ~TFM_MIG
B3: SourceScen | C3: Attribute | D3: Year2 | E3: AllRegions | F3: PSET_PN | J3: 1 | K3: E_SPV* | L3: Solar PV - fixed tilt | O3: SourceScen | P3: Attribute | Q3: Year2 | R3: AllRegions | S3: PSET_PN
B4: Solar-EIA-c,Solar-StateLev | C4: INVCOST | D4: 2015 | F4: =VLOOKUP(H4,$J$3:$K$17,2,FALSE) -> E_SPV* | H4: 1 | J4: 2 | K4: E_WON* | L4: Wind | O4: BehaviourControl | P4: INVCOST | Q4: 2015
B5: Solar-EIA-c,Solar-StateLev | C5: INVCOST | D5: 2016 | F5: =VLOOKUP(H5,$J$3:$K$17,2,FALSE) -> E_SPV* | H5: 1 | J5: 3 | K5: E_WOF* | L5: Offshore Wind | O5: BehaviourControl | P5: INVCOST | Q5: 2016
B6: Solar-EIA-c,Solar-StateLev | C6: INVCOST | D6: 2017 | E6: ="*"&VLOOKUP($D6,'NEMS learning'!$A$2:$V$37,MATCH(VLOOKUP(INS!$H6,INS!$J$3:$L$17,3,FALSE),'NEMS learning'!$A$1:$V$1,0)) -> *0.938 | F6: =VLOOKUP(H6,$J$3:$K$17,2,FALSE) -> E_SPV* | H6: 1 | J6: 4 | K6: EN_COAPUL | L6: Coal with 30% CCS | O6: BehaviourControl | P6: INVCOST | Q6: 2017 | R6: ="*"&VLOOKUP($D6,'NEMS learning'!$A$2:$V$37,MATCH(VLOOKUP(INS!$H6,INS!$J$3:$L$17,3,FALSE),'NEMS learning'!$A$1:$V$1,0)) -> *0.938 | S6: EBldRateStep*SOL*
B7: Solar-EIA-c,Solar-StateLev | C7: INVCOST | D7: 2020 | E7: ="*"&VLOOKUP($D7,'NEMS learning'!$A$2:$V$37,MATCH(VLOOKUP(INS!$H7,INS!$J$3:$L$17,3,FALSE),'NEMS learning'!$A$1:$V$1,0)) -> *0.801734 | F7: =VLOOKUP(H7,$J$3:$K$17,2,FALSE) -> E_SPV* | H7: 1 | J7: 5 | K7: EN_COAIGCC | L7: Coal with 30% CCS | O7: BehaviourControl | P7: INVCOST | Q7: 2020 | R7: ="*"&VLOOKUP($D7,'NEMS learning'!$A$2:$V$37,MATCH(VLOOKUP(INS!$H7,INS!$J$3:$L$17,3,FALSE),'NEMS learning'!$A$1:$V$1,0)) -> *0.801734 | S7: EBldRateStep*SOL*
B8: Solar-EIA-c,Solar-StateLev | C8: INVCOST | D8: 2025 | E8: ="*"&VLOOKUP($D8,'NEMS learning'!$A$2:$V$37,MATCH(VLOOKUP(INS!$H8,INS!$J$3:$L$17,3,FALSE),'NEMS learning'!$A$1:$V$1,0)) -> *0.726158 | F8: =VLOOKUP(H8,$J$3:$K$17,2,FALSE) -> E_SPV* | H8: 1 | J8: 6 | K8: EN_ZCOAIGCC | L8: Coal with 90% CCS | O8: BehaviourControl | P8: INVCOST | Q8: 2025 | R8: ="*"&VLOOKUP($D8,'NEMS learning'!$A$2:$V$37,MATCH(VLOOKUP(INS!$H8,INS!$J$3:$L$17,3,FALSE),'NEMS learning'!$A$1:$V$1,0)) -> *0.726158 | S8: EBldRateStep*SOL*
B9: Solar-EIA-c,Solar-StateLev | C9: INVCOST | D9: =D8+5 -> 2030 | E9: ="*"&VLOOKUP($D9,'NEMS learning'!$A$2:$V$37,MATCH(VLOOKUP(INS!$H9,INS!$J$3:$L$17,3,FALSE),'NEMS learning'!$A$1:$V$1,0)) -> *0.717941 | F9: =VLOOKUP(H9,$J$3:$K$17,2,FALSE) -> E_SPV* | H9: 1 | J9: 7 | K9: EN_ZGasCCAdv | L9: Adv CC w/seq | O9: BehaviourControl | P9: INVCOST | Q9: =Q8+5 -> 2030 | R9: ="*"&VLOOKUP($D9,'NEMS learning'!$A$2:$V$37,MATCH(VLOOKUP(INS!$H9,INS!$J$3:$L$17,3,FALSE),'NEMS learning'!$A$1:$V$1,0)) -> *0.717941 | S9: EBldRateStep*SOL*
B10: Solar-EIA-c,Solar-StateLev | C10: INVCOST | D10: =D9+5 -> 2035 | E10: ="*"&VLOOKUP($D10,'NEMS learning'!$A$2:$V$37,MATCH(VLOOKUP(INS!$H10,INS!$J$3:$L$17,3,FALSE),'NEMS learning'!$A$1:$V$1,0)) -> *0.704942 | F10: =VLOOKUP(H10,$J$3:$K$17,2,FALSE) -> E_SPV* | H10: 1 | J10: 8 | K10: EN_GasCCAdv | L10: Adv CC | O10: BehaviourControl | P10: INVCOST | Q10: =Q9+5 -> 2035 | R10: ="*"&VLOOKUP($D10,'NEMS learning'!$A$2:$V$37,MATCH(VLOOKUP(INS!$H10,INS!$J$3:$L$17,3,FALSE),'NEMS learning'!$A$1:$V$1,0)) -> *0.704942 | S10: EBldRateStep*SOL*
B11: Solar-EIA-c,Solar-StateLev | C11: INVCOST | D11: =D10+5 -> 2040 | E11: ="*"&VLOOKUP($D11,'NEMS learning'!$A$2:$V$37,MATCH(VLOOKUP(INS!$H11,INS!$J$3:$L$17,3,FALSE),'NEMS learning'!$A$1:$V$1,0)) -> *0.7 | F11: =VLOOKUP(H11,$J$3:$K$17,2,FALSE) -> E_SPV* | H11: 1 | J11: 9 | K11: EN_GasCC | L11: Comb. Cyc | O11: BehaviourControl | P11: INVCOST | Q11: =Q10+5 -> 2040 | R11: ="*"&VLOOKUP($D11,'NEMS learning'!$A$2:$V$37,MATCH(VLOOKUP(INS!$H11,INS!$J$3:$L$17,3,FALSE),'NEMS learning'!$A$1:$V$1,0)) -> *0.7 | S11: EBldRateStep*SOL*
B12: Solar-EIA-c,Solar-StateLev | C12: INVCOST | D12: =D11+5 -> 2045 | E12: ="*"&VLOOKUP($D12,'NEMS learning'!$A$2:$V$37,MATCH(VLOOKUP(INS!$H12,INS!$J$3:$L$17,3,FALSE),'NEMS learning'!$A$1:$V$1,0)) -> *0.7 | F12: =VLOOKUP(H12,$J$3:$K$17,2,FALSE) -> E_SPV* | H12: 1 | J12: 10 | K12: EN_GasCTAdv | L12: Adv. CT | O12: BehaviourControl | P12: INVCOST | Q12: =Q11+5 -> 2045 | R12: ="*"&VLOOKUP($D12,'NEMS learning'!$A$2:$V$37,MATCH(VLOOKUP(INS!$H12,INS!$J$3:$L$17,3,FALSE),'NEMS learning'!$A$1:$V$1,0)) -> *0.7 | S12: EBldRateStep*SOL*
B13: Solar-EIA-c,Solar-StateLev | C13: INVCOST | D13: =D12+5 -> 2050 | E13: ="*"&VLOOKUP($D13,'NEMS learning'!$A$2:$V$37,MATCH(VLOOKUP(INS!$H13,INS!$J$3:$L$17,3,FALSE),'NEMS learning'!$A$1:$V$1,0)) -> *0.7 | F13: =VLOOKUP(H13,$J$3:$K$17,2,FALSE) -> E_SPV* | H13: 1 | J13: 11 | K13: EN_GasCT | L13: Comb. Turb | O13: BehaviourControl | P13: INVCOST | Q13: =Q12+5 -> 2050 | R13: ="*"&VLOOKUP($D13,'NEMS learning'!$A$2:$V$37,MATCH(VLOOKUP(INS!$H13,INS!$J$3:$L$17,3,FALSE),'NEMS learning'!$A$1:$V$1,0)) -> *0.7 | S13: EBldRateStep*SOL*
B14: BaseExtra,Wind-StateLev | C14: INVCOST | D14: =D4 -> 2015 | F14: =VLOOKUP(H14,$J$3:$K$17,2,FALSE) -> E_WON* | H14: =H4+1 -> 2 | J14: 12 | K14: EN_Biomass | L14: Biomass | O14: BehaviourControl | P14: INVCOST | Q14: =Q4 -> 2015
B15: BaseExtra,Wind-StateLev | C15: INVCOST | D15: =D5 -> 2016 | F15: =VLOOKUP(H15,$J$3:$K$17,2,FALSE) -> E_WON* | H15: =H5+1 -> 2 | J15: 13 | K15: EN_ZBiomass | L15: =L8 -> Coal with 90% CCS | O15: BehaviourControl | P15: INVCOST | Q15: =Q5 -> 2016
B16: BaseExtra,Wind-StateLev | C16: INVCOST | D16: =D6 -> 2017 | E16: ="*"&VLOOKUP($D16,'NEMS learning'!$A$2:$V$37,MATCH(VLOOKUP(INS!$H16,INS!$J$3:$L$17,3,FALSE),'NEMS learning'!$A$1:$V$1,0)) -> *0.998 | F16: =VLOOKUP(H16,$J$3:$K$17,2,FALSE) -> E_WON* | H16: =H6+1 -> 2 | J16: 14 | K16: EN_OilCCAdv | L16: =L12 -> Adv. CT | O16: BehaviourControl | P16: INVCOST | Q16: =Q6 -> 2017 | R16: ="*"&VLOOKUP($D16,'NEMS learning'!$A$2:$V$37,MATCH(VLOOKUP(INS!$H16,INS!$J$3:$L$17,3,FALSE),'NEMS learning'!$A$1:$V$1,0)) -> *0.998 | S16: EBldRateStep*WIN*
B17: BaseExtra,Wind-StateLev | C17: INVCOST | D17: =D7 -> 2020 | E17: ="*"&VLOOKUP($D17,'NEMS learning'!$A$2:$V$37,MATCH(VLOOKUP(INS!$H17,INS!$J$3:$L$17,3,FALSE),'NEMS learning'!$A$1:$V$1,0)) -> *0.99 | F17: =VLOOKUP(H17,$J$3:$K$17,2,FALSE) -> E_WON* | H17: =H7+1 -> 2 | J17: 15 | K17: EN_Hydro* | L17: Hydro | O17: BehaviourControl | P17: INVCOST | Q17: =Q7 -> 2020 | R17: ="*"&VLOOKUP($D17,'NEMS learning'!$A$2:$V$37,MATCH(VLOOKUP(INS!$H17,INS!$J$3:$L$17,3,FALSE),'NEMS learning'!$A$1:$V$1,0)) -> *0.99 | S17: EBldRateStep*WIN*
B18: BaseExtra,Wind-StateLev | C18: INVCOST | D18: =D8 -> 2025 | E18: ="*"&VLOOKUP($D18,'NEMS learning'!$A$2:$V$37,MATCH(VLOOKUP(INS!$H18,INS!$J$3:$L$17,3,FALSE),'NEMS learning'!$A$1:$V$1,0)) -> *0.9775 | F18: =VLOOKUP(H18,$J$3:$K$17,2,FALSE) -> E_WON* | H18: =H8+1 -> 2 | O18: BehaviourControl | P18: INVCOST | Q18: =Q8 -> 2025 | R18: ="*"&VLOOKUP($D18,'NEMS learning'!$A$2:$V$37,MATCH(VLOOKUP(INS!$H18,INS!$J$3:$L$17,3,FALSE),'NEMS learning'!$A$1:$V$1,0)) -> *0.9775 | S18: EBldRateStep*WIN*
B19: BaseExtra,Wind-StateLev | C19: INVCOST | D19: =D9 -> 2030 | E19: ="*"&VLOOKUP($D19,'NEMS learning'!$A$2:$V$37,MATCH(VLOOKUP(INS!$H19,INS!$J$3:$L$17,3,FALSE),'NEMS learning'!$A$1:$V$1,0)) -> *0.965 | F19: =VLOOKUP(H19,$J$3:$K$17,2,FALSE) -> E_WON* | H19: =H9+1 -> 2 | O19: BehaviourControl | P19: INVCOST | Q19: =Q9 -> 2030 | R19: ="*"&VLOOKUP($D19,'NEMS learning'!$A$2:$V$37,MATCH(VLOOKUP(INS!$H19,INS!$J$3:$L$17,3,FALSE),'NEMS learning'!$A$1:$V$1,0)) -> *0.965 | S19: EBldRateStep*WIN*
B20: BaseExtra,Wind-StateLev | C20: INVCOST | D20: =D10 -> 2035 | E20: ="*"&VLOOKUP($D20,'NEMS learning'!$A$2:$V$37,MATCH(VLOOKUP(INS!$H20,INS!$J$3:$L$17,3,FALSE),'NEMS learning'!$A$1:$V$1,0)) -> *0.9525 | F20: =VLOOKUP(H20,$J$3:$K$17,2,FALSE) -> E_WON* | H20: =H10+1 -> 2 | O20: BehaviourControl | P20: INVCOST | Q20: =Q10 -> 2035 | R20: ="*"&VLOOKUP($D20,'NEMS learning'!$A$2:$V$37,MATCH(VLOOKUP(INS!$H20,INS!$J$3:$L$17,3,FALSE),'NEMS learning'!$A$1:$V$1,0)) -> *0.9525 | S20: EBldRateStep*WIN*
B21: BaseExtra,Wind-StateLev | C21: INVCOST | D21: =D11 -> 2040 | E21: ="*"&VLOOKUP($D21,'NEMS learning'!$A$2:$V$37,MATCH(VLOOKUP(INS!$H21,INS!$J$3:$L$17,3,FALSE),'NEMS learning'!$A$1:$V$1,0)) -> *0.94 | F21: =VLOOKUP(H21,$J$3:$K$17,2,FALSE) -> E_WON* | H21: =H11+1 -> 2 | O21: BehaviourControl | P21: INVCOST | Q21: =Q11 -> 2040 | R21: ="*"&VLOOKUP($D21,'NEMS learning'!$A$2:$V$37,MATCH(VLOOKUP(INS!$H21,INS!$J$3:$L$17,3,FALSE),'NEMS learning'!$A$1:$V$1,0)) -> *0.94 | S21: EBldRateStep*WIN*
B22: BaseExtra,Wind-StateLev | C22: INVCOST | D22: =D12 -> 2045 | E22: ="*"&VLOOKUP($D22,'NEMS learning'!$A$2:$V$37,MATCH(VLOOKUP(INS!$H22,INS!$J$3:$L$17,3,FALSE),'NEMS learning'!$A$1:$V$1,0)) -> *0.9275 | F22: =VLOOKUP(H22,$J$3:$K$17,2,FALSE) -> E_WON* | H22: =H12+1 -> 2 | O22: BehaviourControl | P22: INVCOST | Q22: =Q12 -> 2045 | R22: ="*"&VLOOKUP($D22,'NEMS learning'!$A$2:$V$37,MATCH(VLOOKUP(INS!$H22,INS!$J$3:$L$17,3,FALSE),'NEMS learning'!$A$1:$V$1,0)) -> *0.9275 | S22: EBldRateStep*WIN*
B23: BaseExtra,Wind-StateLev | C23: INVCOST | D23: =D13 -> 2050 | E23: ="*"&VLOOKUP($D23,'NEMS learning'!$A$2:$V$37,MATCH(VLOOKUP(INS!$H23,INS!$J$3:$L$17,3,FALSE),'NEMS learning'!$A$1:$V$1,0)) -> *0.915 | F23: =VLOOKUP(H23,$J$3:$K$17,2,FALSE) -> E_WON* | H23: =H13+1 -> 2 | O23: BehaviourControl | P23: INVCOST | Q23: =Q13 -> 2050 | R23: ="*"&VLOOKUP($D23,'NEMS learning'!$A$2:$V$37,MATCH(VLOOKUP(INS!$H23,INS!$J$3:$L$17,3,FALSE),'NEMS learning'!$A$1:$V$1,0)) -> *0.915 | S23: EBldRateStep*WIN*
B24: BaseExtra,Wind-StateLev | C24: INVCOST | D24: =D14 -> 2015 | F24: =VLOOKUP(H24,$J$3:$K$17,2,FALSE) -> E_WOF* | H24: =H14+1 -> 3
B25: BaseExtra,Wind-StateLev | C25: INVCOST | D25: =D15 -> 2016 | F25: =VLOOKUP(H25,$J$3:$K$17,2,FALSE) -> E_WOF* | H25: =H15+1 -> 3
B26: BaseExtra,Wind-StateLev | C26: INVCOST | D26: =D16 -> 2017 | E26: ="*"&VLOOKUP($D26,'NEMS learning'!$A$2:$V$37,MATCH(VLOOKUP(INS!H26,INS!$J$3:$L$17,3,FALSE),'NEMS learning'!$A$1:$V$1,0)) -> *0.994 | F26: =VLOOKUP(H26,$J$3:$K$17,2,FALSE) -> E_WOF* | H26: =H16+1 -> 3
B27: BaseExtra,Wind-StateLev | C27: INVCOST | D27: =D17 -> 2020 | E27: ="*"&VLOOKUP($D27,'NEMS learning'!$A$2:$V$37,MATCH(VLOOKUP(INS!H27,INS!$J$3:$L$17,3,FALSE),'NEMS learning'!$A$1:$V$1,0)) -> *0.975 | F27: =VLOOKUP(H27,$J$3:$K$17,2,FALSE) -> E_WOF* | H27: =H17+1 -> 3
B28: BaseExtra,Wind-StateLev | C28: INVCOST | D28: =D18 -> 2025 | E28: ="*"&VLOOKUP($D28,'NEMS learning'!$A$2:$V$37,MATCH(VLOOKUP(INS!H28,INS!$J$3:$L$17,3,FALSE),'NEMS learning'!$A$1:$V$1,0)) -> *0.94375 | F28: =VLOOKUP(H28,$J$3:$K$17,2,FALSE) -> E_WOF* | H28: =H18+1 -> 3
B29: BaseExtra,Wind-StateLev | C29: INVCOST | D29: =D19 -> 2030 | E29: ="*"&VLOOKUP($D29,'NEMS learning'!$A$2:$V$37,MATCH(VLOOKUP(INS!H29,INS!$J$3:$L$17,3,FALSE),'NEMS learning'!$A$1:$V$1,0)) -> *0.9125 | F29: =VLOOKUP(H29,$J$3:$K$17,2,FALSE) -> E_WOF* | H29: =H19+1 -> 3
B30: BaseExtra,Wind-StateLev | C30: INVCOST | D30: =D20 -> 2035 | E30: ="*"&VLOOKUP($D30,'NEMS learning'!$A$2:$V$37,MATCH(VLOOKUP(INS!H30,INS!$J$3:$L$17,3,FALSE),'NEMS learning'!$A$1:$V$1,0)) -> *0.88125 | F30: =VLOOKUP(H30,$J$3:$K$17,2,FALSE) -> E_WOF* | H30: =H20+1 -> 3
B31: BaseExtra,Wind-StateLev | C31: INVCOST | D31: =D21 -> 2040 | E31: ="*"&VLOOKUP($D31,'NEMS learning'!$A$2:$V$37,MATCH(VLOOKUP(INS!H31,INS!$J$3:$L$17,3,FALSE),'NEMS learning'!$A$1:$V$1,0)) -> *0.85 | F31: =VLOOKUP(H31,$J$3:$K$17,2,FALSE) -> E_WOF* | H31: =H21+1 -> 3
B32: BaseExtra,Wind-StateLev | C32: INVCOST | D32: =D22 -> 2045 | E32: ="*"&VLOOKUP($D32,'NEMS learning'!$A$2:$V$37,MATCH(VLOOKUP(INS!H32,INS!$J$3:$L$17,3,FALSE),'NEMS learning'!$A$1:$V$1,0)) -> *0.81875 | F32: =VLOOKUP(H32,$J$3:$K$17,2,FALSE) -> E_WOF* | H32: =H22+1 -> 3
B33: BaseExtra,Wind-StateLev | C33: INVCOST | D33: =D23 -> 2050 | E33: ="*"&VLOOKUP($D33,'NEMS learning'!$A$2:$V$37,MATCH(VLOOKUP(INS!H33,INS!$J$3:$L$17,3,FALSE),'NEMS learning'!$A$1:$V$1,0)) -> *0.7875 | F33: =VLOOKUP(H33,$J$3:$K$17,2,FALSE) -> E_WOF* | H33: =H23+1 -> 3
C34: INVCOST | D34: =D24 -> 2015 | F34: =VLOOKUP(H34,$J$3:$K$17,2,FALSE) -> EN_COAPUL | H34: =H24+1 -> 4
C35: INVCOST | D35: =D25 -> 2016 | F35: =VLOOKUP(H35,$J$3:$K$17,2,FALSE) -> EN_COAPUL | H35: =H25+1 -> 4
C36: INVCOST | D36: =D26 -> 2017 | E36: ="*"&VLOOKUP($D36,'NEMS learning'!$A$2:$V$37,MATCH(VLOOKUP(INS!H36,INS!$J$3:$L$17,3,FALSE),'NEMS learning'!$A$1:$V$1,0)) -> *0.996 | F36: =VLOOKUP(H36,$J$3:$K$17,2,FALSE) -> EN_COAPUL | H36: =H26+1 -> 4
C37: INVCOST | D37: =D27 -> 2020 | E37: ="*"&VLOOKUP($D37,'NEMS learning'!$A$2:$V$37,MATCH(VLOOKUP(INS!H37,INS!$J$3:$L$17,3,FALSE),'NEMS learning'!$A$1:$V$1,0)) -> *0.9825 | F37: =VLOOKUP(H37,$J$3:$K$17,2,FALSE) -> EN_COAPUL | H37: =H27+1 -> 4
C38: INVCOST | D38: =D28 -> 2025 | E38: ="*"&VLOOKUP($D38,'NEMS learning'!$A$2:$V$37,MATCH(VLOOKUP(INS!H38,INS!$J$3:$L$17,3,FALSE),'NEMS learning'!$A$1:$V$1,0)) -> *0.960625 | F38: =VLOOKUP(H38,$J$3:$K$17,2,FALSE) -> EN_COAPUL | H38: =H28+1 -> 4
C39: INVCOST | D39: =D29 -> 2030 | E39: ="*"&VLOOKUP($D39,'NEMS learning'!$A$2:$V$37,MATCH(VLOOKUP(INS!H39,INS!$J$3:$L$17,3,FALSE),'NEMS learning'!$A$1:$V$1,0)) -> *0.93875 | F39: =VLOOKUP(H39,$J$3:$K$17,2,FALSE) -> EN_COAPUL | H39: =H29+1 -> 4
C40: INVCOST | D40: =D30 -> 2035 | E40: ="*"&VLOOKUP($D40,'NEMS learning'!$A$2:$V$37,MATCH(VLOOKUP(INS!H40,INS!$J$3:$L$17,3,FALSE),'NEMS learning'!$A$1:$V$1,0)) -> *0.916875 | F40: =VLOOKUP(H40,$J$3:$K$17,2,FALSE) -> EN_COAPUL | H40: =H30+1 -> 4
C41: INVCOST | D41: =D31 -> 2040 | E41: ="*"&VLOOKUP($D41,'NEMS learning'!$A$2:$V$37,MATCH(VLOOKUP(INS!H41,INS!$J$3:$L$17,3,FALSE),'NEMS learning'!$A$1:$V$1,0)) -> *0.895 | F41: =VLOOKUP(H41,$J$3:$K$17,2,FALSE) -> EN_COAPUL | H41: =H31+1 -> 4
...

Sheet NEMS learning
A1: Online Year | B1: Coal with 30% CCS | C1: Coal with 90% CCS | D1: Comb. Turb | E1: Adv. CT | F1: Comb. Cyc | G1: Adv CC | H1: Adv CC w/seq | I1: Fuel Cell | J1: Nuclear | K1: Biomass | L1: Geothermal | M1: Landfill Gas | N1: Hydro | O1: Battery Storage | P1: Wind | Q1: Offshore Wind | R1: Solar Thermal | S1: Solar PV - tracking | T1: Solar PV - fixed tilt | U1: Dist. Gen Base | V1: Dist Gen Peak
A2: 2015 | B2: 3 | C2: 3 | D2: 3 | E2: 3 | F2: 3 | G2: 3 | H2: 3 | I2: 3 | J2: 3 | K2: 3 | L2: 3 | M2: 3 | N2: 3 | O2: 3 | P2: 3 | Q2: 3 | R2: 3 | S2: 3 | T2: 3 | U2: 3 | V2: 3
A3: 2016 | B3: 3 | C3: 3 | D3: 3 | E3: 3 | F3: 3 | G3: 3 | H3: 3 | I3: 3 | J3: 3 | K3: 3 | L3: 3 | M3: 3 | N3: 3 | O3: 3 | P3: 3 | Q3: 3 | R3: 3 | S3: 3 | T3: 3 | U3: 3 | V3: 3
A4: 2017 | B4: 0.996 | C4: 0.996 | D4: 0.997 | E4: 0.996 | F4: 0.998 | G4: 0.997 | H4: 0.994 | I4: 0.99 | J4: 0.995 | K4: 0.996 | L4: 0.995 | M4: 0.997 | N4: 0.998 | O4: 0.99 | P4: 0.998 | Q4: 0.994 | R4: 0.988 | S4: 0.938 | T4: 0.938 | U4: 0.995 | V4: 0.995
A5: 2018 | B5: 0.99125 | C5: 0.99125 | D5: 0.995 | E5: 0.9925 | F5: 0.995 | G5: 0.9935 | H5: 0.988 | I5: 0.964729 | J5: 0.99 | K5: 0.9925 | L5: 0.99 | M5: 0.995 | N5: 0.995 | O5: 0.98 | P5: 0.995 | Q5: 0.9875 | R5: 0.982718 | S5: 0.862163 | T5: 0.862163 | U5: 0.99 | V5: 0.99
A6: 2019 | B6: 0.986875 | C6: 0.986875 | D6: 0.9925 | E6: 0.98875 | F6: 0.9925 | G6: 0.99025 | H6: 0.982 | I6: 0.950974 | J6: 0.985 | K6: 0.98875 | L6: 0.985 | M6: 0.9925 | N6: 0.99117 | O6: 0.97 | P6: 0.9925 | Q6: 0.98125 | R6: 0.977718 | S6: 0.823791 | T6: 0.823791 | U6: 0.985 | V6: 0.985
A7: 2020 | B7: 0.9825 | C7: 0.9825 | D7: 0.99 | E7: 0.985 | F7: 0.99 | G7: 0.987 | H7: 0.976 | I7: 0.940974 | J7: 0.98 | K7: 0.981119 | L7: 0.98 | M7: 0.99 | N7: 0.987982 | O7: 0.96 | P7: 0.99 | Q7: 0.975 | R7: 0.972718 | S7: 0.801734 | T7: 0.801734 | U7: 0.98 | V7: 0.98
A8: 2021 | B8: 0.978125 | C8: 0.978125 | D8: 0.9875 | E8: 0.98125 | F8: 0.9875 | G8: 0.98375 | H8: 0.97 | I8: 0.930974 | J8: 0.975 | K8: 0.972991 | L8: 0.975 | M8: 0.9875 | N8: 0.985482 | O8: 0.95 | P8: 0.9875 | Q8: 0.96875 | R8: 0.967718 | S8: 0.756083 | T8: 0.756083 | U8: 0.975 | V8: 0.95
A9: 2022 | B9: 0.97375 | C9: 0.97375 | D9: 0.985 | E9: 0.97626 | F9: 0.985 | G9: 0.979756 | H9: 0.963504 | I9: 0.920974 | J9: 0.964398 | K9: 0.969241 | L9: 0.97 | M9: 0.985 | N9: 0.982982 | O9: 0.94 | P9: 0.985 | Q9: 0.9625 | R9: 0.962718 | S9: 0.74016 | T9: 0.74016 | U9: 0.97 | V9: 0.9025
A10: 2023 | B10: 0.969375 | C10: 0.969375 | D10: 0.9825 | E10: 0.968714 | F10: 0.9825 | G10: 0.974229 | H10: 0.955986 | I10: 0.910974 | J10: 0.959398 | K10: 0.965491 | L10: 0.943864 | M10: 0.9825 | N10: 0.980482 | O10: 0.93 | P10: 0.9825 | Q10: 0.95625 | R10: 0.957718 | S10: 0.729182 | T10: 0.729182 | U10: 0.965 | V10: 0.857375
A11: 2024 | B11: 0.965 | C11: 0.965 | D11: 0.98 | E11: 0.958721 | F11: 0.98 | G11: 0.967233 | H11: 0.947488 | I11: 0.900974 | J11: 0.954398 | K11: 0.961741 | L11: 0.9104 | M11: 0.98 | N11: 0.977982 | O11: 0.92 | P11: 0.98 | Q11: 0.95 | R11: 0.952718 | S11: 0.727658 | T11: 0.727658 | U11: 0.96 | V11: 0.848083
A12: 2025 | B12: 0.960625 | C12: 0.960625 | D12: 0.9775 | E12: 0.943278 | F12: 0.9775 | G12: 0.956967 | H12: 0.936811 | I12: 0.890974 | J12: 0.949398 | K12: 0.957991 | L12: 0.882506 | M12: 0.9775 | N12: 0.975482 | O12: 0.91 | P12: 0.9775 | Q12: 0.94375 | R12: 0.947719 | S12: 0.726158 | T12: 0.726158 | U12: 0.955 | V12: 0.837693
A13: 2026 | B13: 0.95625 | C13: 0.95625 | D13: 0.975 | E13: 0.929111 | F13: 0.975 | G13: 0.947466 | H13: 0.926644 | I13: 0.880974 | J13: 0.944398 | K13: 0.954241 | L13: 0.86381 | M13: 0.975 | N13: 0.972982 | O13: 0.9 | P13: 0.975 | Q13: 0.9375 | R13: 0.942719 | S13: 0.724658 | T13: 0.724658 | U13: 0.95 | V13: 0.829928
... A37: 2050 | B37: 0.85125 | C37: 0.85125 | D37: 0.915 | E37: 0.8075 | F37: 0.915 | G37: 0.8505 | H37: 0.77 | I37: 0.640974 | J37: 0.824398 | K37: 0.864241 | L37: 0.7 | M37: 0.915 | N37: 0.912982 | O37: 0.66 | P37: 0.915 | Q37: 0.7875 | R37: 0.822719 | S37: 0.7 | T37: 0.7 | U37: 0.795049 | V37: 0.7

Sheet Sheet9
