Workbook

Sheet readme
A1: Workbook purpose:
A2: Performs historical calibration for 2015 and 2016 and sets utilization limits on fossil, solar,and CHP techs, as well as EFF and (for now) heat ratio for CHP techs
A4: Data source:
A5: Historical capacity, generation, and heat production data from the restart file is read by the MIG and shared to the country level based on Platts capacity
A6: then written here as utilization limits and CHP parameters
A8: User-modifiable?
A9: No, user overrides should be made in a user scenario
A12: date | B12: initials | C12: description
A13: 43588 | B13: mas | C13: revised UtilizationLim-LO_Oil to stimulate oil generation in AFR and MID
A14: 43591 | B14: mas | C14: revised UtilizationLim-UP_Oil and utilization history to stimulate oil generation in MID
A15: 43591 | B15: mas | C15: revised utilization history in AFR
A16: 44154 | B16: AK | C16: override CHP EFF where effective EFF more than a user-specified limit (80% default); sheet CHP_elecEFF
A17: 44549 | B17: MahmoudMobir | C17: Changed all "interpolation and forward extrapolation" rules to "interpolation and no extrapolation" in the utiliszation_limlits UCs. Some of these UCs induced to dummy imports in the region USA.
A18: 44552 | B18: MahmoudMObir | C18: Changed the heat to power rate equations from FX to UP. Having FX equations leads to negative heat prices in the model. This is just a workaround. Will troubleshoot this issue when mitigation techs will have been added to the model

Sheet utilzation_limits
D1: ~UC_SETS: R_E: AllRegions
H3: ~UC_T: UC_CAP
D4: UC_N | E4: Region | F4: PSET_PN | G4: Year | H4: PSET_SET | I4: PSET_CI | J4: LimType | K4: UC_ACT | L4: UC_CAP | M4: UC_RHSRT | N4: UC_RHSRT~0
D5: UC_Calib_CFs_shucpbmCHPlo | E5: AFR_N | F5: -*ReTargDum* | G5: 2017 | H5: CHP | I5: ELCBIO | J5: LO | K5: 1 | L5: -9.4504597 | M5: 0 | N5: 1
D6: UC_Calib_CFs_shucpbmCHPlo | E6: AFR_N | F6: -*ReTargDum* | G6: 2018 | H6: CHP | I6: ELCBIO | J6: LO | K6: 1 | L6: -8.8750861 | M6: 0 | N6: 1
D7: UC_Calib_CFs_shucpbmCHPlo | E7: AFR_S | F7: -*ReTargDum* | G7: 2017 | H7: CHP | I7: ELCBIO | J7: LO | K7: 1 | L7: -9.4504597 | M7: 0 | N7: 1
D8: UC_Calib_CFs_shucpbmCHPlo | E8: AFR_S | F8: -*ReTargDum* | G8: 2018 | H8: CHP | I8: ELCBIO | J8: LO | K8: 1 | L8: -8.8750861 | M8: 0 | N8: 1
D9: UC_Calib_CFs_shucpbmCHPlo | E9: ANZ | F9: -*ReTargDum* | G9: 2017 | H9: CHP | I9: ELCBIO | J9: LO | K9: 1 | L9: -14.332823 | M9: 0 | N9: 1
D10: UC_Calib_CFs_shucpbmCHPlo | E10: ANZ | F10: -*ReTargDum* | G10: 2018 | H10: CHP | I10: ELCBIO | J10: LO | K10: 1 | L10: -13.866353 | M10: 0 | N10: 1
D11: UC_Calib_CFs_shucpbmCHPlo | E11: BRZ | F11: -*ReTargDum* | G11: 2017 | H11: CHP | I11: ELCBIO | J11: LO | K11: 1 | L11: -13.481717 | M11: 0 | N11: 1
D12: UC_Calib_CFs_shucpbmCHPlo | E12: BRZ | F12: -*ReTargDum* | G12: 2018 | H12: CHP | I12: ELCBIO | J12: LO | K12: 1 | L12: -13.646268 | M12: 0 | N12: 1
D13: UC_Calib_CFs_shucpbmCHPlo | E13: CSA | F13: -*ReTargDum* | G13: 2017 | H13: CHP | I13: ELCBIO | J13: LO | K13: 1 | L13: -11.455261 | M13: 0 | N13: 1
D14: UC_Calib_CFs_shucpbmCHPlo | E14: CSA | F14: -*ReTargDum* | G14: 2018 | H14: CHP | I14: ELCBIO | J14: LO | K14: 1 | L14: -10.989442 | M14: 0 | N14: 1
D15: UC_Calib_CFs_shucpbmCHPlo | E15: EUR | F15: -*ReTargDum* | G15: 2017 | H15: CHP | I15: ELCBIO | J15: LO | K15: 1 | L15: -17.068022 | M15: 0 | N15: 1
D16: UC_Calib_CFs_shucpbmCHPlo | E16: EUR | F16: -*ReTargDum* | G16: 2018 | H16: CHP | I16: ELCBIO | J16: LO | K16: 1 | L16: -16.185177 | M16: 0 | N16: 1
... D159: UC_Calib_CFs_shucpclCHPlo | E159: ANZ | F159: -*ReTargDum* | G159: 2020 | H159: CHP | I159: ELCCOA | J159: LO | K159: 1 | L159: 0 | M159: 0 | N159: 1
D160: UC_Calib_CFs_shucpclCHPlo | E160: ANZ | F160: -*ReTargDum* | G160: 2030, 2021 | H160: CHP | I160: ELCCOA | J160: LO | K160: 1 | L160: -10.372616 | M160: 0 | N160: 1
D161: UC_Calib_CFs_shucpclCHPlo | E161: BRZ | F161: -*ReTargDum* | G161: 2017 | H161: CHP | I161: ELCCOA | J161: LO | K161: 1 | L161: -20.398946 | M161: 0 | N161: 1
D162: UC_Calib_CFs_shucpclCHPlo | E162: BRZ | F162: -*ReTargDum* | G162: 2018 | H162: CHP | I162: ELCCOA | J162: LO | K162: 1 | L162: -19.698875 | M162: 0 | N162: 1
D163: UC_Calib_CFs_shucpclCHPlo | E163: BRZ | F163: -*ReTargDum* | G163: 2020 | H163: CHP | I163: ELCCOA | J163: LO | K163: 1 | L163: 0 | M163: 0 | N163: 1
D164: UC_Calib_CFs_shucpclCHPlo | E164: BRZ | F164: -*ReTargDum* | G164: 2030, 2021 | H164: CHP | I164: ELCCOA | J164: LO | K164: 1 | L164: -10.199473 | M164: 0 | N164: 1
D165: UC_Calib_CFs_shucpclCHPlo | E165: CHI | F165: -*ReTargDum* | G165: 2017 | H165: CHP | I165: ELCCOA | J165: LO | K165: 1 | L165: -13.692441 | M165: 0 | N165: 1
D166: UC_Calib_CFs_shucpclCHPlo | E166: CHI | F166: -*ReTargDum* | G166: 2018 | H166: CHP | I166: ELCCOA | J166: LO | K166: 1 | L166: -14.207167 | M166: 0 | N166: 1
D167: UC_Calib_CFs_shucpclCHPlo | E167: CHI | F167: -*ReTargDum* | G167: 2020 | H167: CHP | I167: ELCCOA | J167: LO | K167: 1 | L167: 0 | M167: 0 | N167: 1
D168: UC_Calib_CFs_shucpclCHPlo | E168: CHI | F168: -*ReTargDum* | G168: 2030, 2021 | H168: CHP | I168: ELCCOA | J168: LO | K168: 1 | L168: -7.1035834 | M168: 0 | N168: 1
D169: UC_Calib_CFs_shucpclCHPlo | E169: EUR | F169: -*ReTargDum* | G169: 2017 | H169: CHP | I169: ELCCOA | J169: LO | K169: 1 | L169: -14.415443 | M169: 0 | N169: 1
D170: UC_Calib_CFs_shucpclCHPlo | E170: EUR | F170: -*ReTargDum* | G170: 2018 | H170: CHP | I170: ELCCOA | J170: LO | K170: 1 | L170: -13.949504 | M170: 0 | N170: 1
D171: UC_Calib_CFs_shucpclCHPlo | E171: EUR | F171: -*ReTargDum* | G171: 2020 | H171: CHP | I171: ELCCOA | J171: LO | K171: 1 | L171: 0 | M171: 0 | N171: 1
D172: UC_Calib_CFs_shucpclCHPlo | E172: EUR | F172: -*ReTargDum* | G172: 2030, 2021 | H172: CHP | I172: ELCCOA | J172: LO | K172: 1 | L172: -7.2077216 | M172: 0 | N172: 1
D173: UC_Calib_CFs_shucpclCHPlo | E173: OAS | F173: -*ReTargDum* | G173: 2017 | H173: CHP | I173: ELCCOA | J173: LO | K173: 1 | L173: -17.893465 | M173: 0 | N173: 1
D174: UC_Calib_CFs_shucpclCHPlo | E174: OAS | F174: -*ReTargDum* | G174: 2018 | H174: CHP | I174: ELCCOA | J174: LO | K174: 1 | L174: -19.346971 | M174: 0 | N174: 1
D175: UC_Calib_CFs_shucpclCHPlo | E175: OAS | F175: -*ReTargDum* | G175: 2020 | H175: CHP | I175: ELCCOA | J175: LO | K175: 1 | L175: 0 | M175: 0 | N175: 1
D176: UC_Calib_CFs_shucpclCHPlo | E176: OAS | F176: -*ReTargDum* | G176: 2030, 2021 | H176: CHP | I176: ELCCOA | J176: LO | K176: 1 | L176: -9.6734853 | M176: 0 | N176: 1
D177: UC_Calib_CFs_shucpclCHPlo | E177: RUS | F177: -*ReTargDum* | G177: 2017 | H177: CHP | I177: ELCCOA | J177: LO | K177: 1 | L177: -10.345425 | M177: 0 | N177: 1
D178: UC_Calib_CFs_shucpclCHPlo | E178: RUS | F178: -*ReTargDum* | G178: 2018 | H178: CHP | I178: ELCCOA | J178: LO | K178: 1 | L178: -10.513926 | M178: 0 | N178: 1
D179: UC_Calib_CFs_shucpclCHPlo | E179: RUS | F179: -*ReTargDum* | G179: 2020 | H179: CHP | I179: ELCCOA | J179: LO | K179: 1 | L179: 0 | M179: 0 | N179: 1
D180: UC_Calib_CFs_shucpclCHPlo | E180: RUS | F180: -*ReTargDum* | G180: 2030, 2021 | H180: CHP | I180: ELCCOA | J180: LO | K180: 1 | L180: -5.256963 | M180: 0 | N180: 1
D181: UC_Calib_CFs_shucpclCHPlo | E181: SKO | F181: -*ReTargDum* | G181: 2017 | H181: CHP | I181: ELCCOA | J181: LO | K181: 1 | L181: -19.903171 | M181: 0 | N181: 1
D182: UC_Calib_CFs_shucpclCHPlo | E182: SKO | F182: -*ReTargDum* | G182: 2018 | H182: CHP | I182: ELCCOA | J182: LO | K182: 1 | L182: -19.744621 | M182: 0 | N182: 1
D183: UC_Calib_CFs_shucpclCHPlo | E183: SKO | F183: -*ReTargDum* | G183: 2020 | H183: CHP | I183: ELCCOA | J183: LO | K183: 1 | L183: 0 | M183: 0 | N183: 1
...

Sheet CHP_elecEFF
A1: RestartCHPChar_EFF | AC1: 0.8 | AD1: Max CHP eff
V2: ~TFM_DINS-TS
A3: Region | B3: PSET_PN | C3: 2002 | D3: 2003 | E3: 2004 | F3: 2005 | G3: 2006 | H3: 2007 | I3: 2008 | J3: 2009 | K3: 2010 | L3: 2011 | M3: 2012 | N3: 2013 | O3: 2014 | P3: 2015 | Q3: 2016 | R3: 2017 | S3: 2018 | V3: Attribute | W3: Region | X3: Techname | Y3: EFF_WtdAvg | Z3: ts_filter | AA3: 2020
A4: AFR_N | B4: EP_Bio-CHP | L4: 0 | M4: 0 | N4: 0 | O4: 0 | P4: 0 | Q4: 0 | R4: 0 | S4: 0 | V4: EFF | W4: AFR_N | X4: EP_Bio-CHP | Y4: 0.30304839 | Z4: 0 | AA4: =IF(SUMIFS(CHP_CHPR!$AA$4:$AA$283,CHP_CHPR!$Y$4:$Y$283,CHP_elecEFF!$W4,CHP_CHPR!$Z$4:$Z$283,CHP_elecEFF!$X4)*Y4+Y4<=$AC$1,"",Y4*$AC$1/(SUMIFS(CHP_CHPR!$AA$4:$AA$283,CHP_CHPR!$Y$4:$Y$283,CHP_elecEFF!$W4,CHP_CHPR!$Z$4:$Z$283,CHP_elecEFF!$X4)*Y4+Y4))
A5: AFR_N | B5: EP_Coa-CHP | S5: 0.33 | V5: EFF | W5: AFR_N | X5: EP_Coa-CHP | Z5: 0 | AA5: =IF(SUMIFS(CHP_CHPR!$AA$4:$AA$283,CHP_CHPR!$Y$4:$Y$283,CHP_elecEFF!$W5,CHP_CHPR!$Z$4:$Z$283,CHP_elecEFF!$X5)*Y5+Y5<=$AC$1,"",Y5*$AC$1/(SUMIFS(CHP_CHPR!$AA$4:$AA$283,CHP_CHPR!$Y$4:$Y$283,CHP_elecEFF!$W5,CHP_CHPR!$Z$4:$Z$283,CHP_elecEFF!$X5)*Y5+Y5))
A6: AFR_N | B6: EP_Gas-CHP | K6: 0 | L6: 0 | M6: 0 | N6: 0 | O6: 0 | P6: 0 | Q6: 0 | R6: 0 | S6: 0 | V6: EFF | W6: AFR_N | X6: EP_Gas-CHP | Y6: 0.31358537 | Z6: 0 | AA6: =IF(SUMIFS(CHP_CHPR!$AA$4:$AA$283,CHP_CHPR!$Y$4:$Y$283,CHP_elecEFF!$W6,CHP_CHPR!$Z$4:$Z$283,CHP_elecEFF!$X6)*Y6+Y6<=$AC$1,"",Y6*$AC$1/(SUMIFS(CHP_CHPR!$AA$4:$AA$283,CHP_CHPR!$Y$4:$Y$283,CHP_elecEFF!$W6,CHP_CHPR!$Z$4:$Z$283,CHP_elecEFF!$X6)*Y6+Y6))
A7: AFR_N | B7: EP_Oil-CHP | S7: 0.33 | V7: EFF | W7: AFR_N | X7: EP_Oil-CHP | Z7: 0 | AA7: =IF(SUMIFS(CHP_CHPR!$AA$4:$AA$283,CHP_CHPR!$Y$4:$Y$283,CHP_elecEFF!$W7,CHP_CHPR!$Z$4:$Z$283,CHP_elecEFF!$X7)*Y7+Y7<=$AC$1,"",Y7*$AC$1/(SUMIFS(CHP_CHPR!$AA$4:$AA$283,CHP_CHPR!$Y$4:$Y$283,CHP_elecEFF!$W7,CHP_CHPR!$Z$4:$Z$283,CHP_elecEFF!$X7)*Y7+Y7))
A8: AFR_N | B8: EP_Oil_CRD-CHP | S8: 0.33 | V8: EFF | W8: AFR_N | X8: EP_Oil_CRD-CHP | Z8: 0 | AA8: =IF(SUMIFS(CHP_CHPR!$AA$4:$AA$283,CHP_CHPR!$Y$4:$Y$283,CHP_elecEFF!$W8,CHP_CHPR!$Z$4:$Z$283,CHP_elecEFF!$X8)*Y8+Y8<=$AC$1,"",Y8*$AC$1/(SUMIFS(CHP_CHPR!$AA$4:$AA$283,CHP_CHPR!$Y$4:$Y$283,CHP_elecEFF!$W8,CHP_CHPR!$Z$4:$Z$283,CHP_elecEFF!$X8)*Y8+Y8))
A9: AFR_N | B9: EP_Oil_DST-CHP | S9: 0.33 | V9: EFF | W9: AFR_N | X9: EP_Oil_DST-CHP | Z9: 0 | AA9: =IF(SUMIFS(CHP_CHPR!$AA$4:$AA$283,CHP_CHPR!$Y$4:$Y$283,CHP_elecEFF!$W9,CHP_CHPR!$Z$4:$Z$283,CHP_elecEFF!$X9)*Y9+Y9<=$AC$1,"",Y9*$AC$1/(SUMIFS(CHP_CHPR!$AA$4:$AA$283,CHP_CHPR!$Y$4:$Y$283,CHP_elecEFF!$W9,CHP_CHPR!$Z$4:$Z$283,CHP_elecEFF!$X9)*Y9+Y9))
A10: AFR_N | B10: EP_Was-CHP | S10: 0.33 | V10: EFF | W10: AFR_N | X10: EP_Was-CHP | Z10: 0 | AA10: =IF(SUMIFS(CHP_CHPR!$AA$4:$AA$283,CHP_CHPR!$Y$4:$Y$283,CHP_elecEFF!$W10,CHP_CHPR!$Z$4:$Z$283,CHP_elecEFF!$X10)*Y10+Y10<=$AC$1,"",Y10*$AC$1/(SUMIFS(CHP_CHPR!$AA$4:$AA$283,CHP_CHPR!$Y$4:$Y$283,CHP_elecEFF!$W10,CHP_CHPR!$Z$4:$Z$283,CHP_elecEFF!$X10)*Y10+Y10))
A11: AFR_S | B11: EP_Bio-CHP | L11: 0 | M11: 0 | N11: 0 | O11: 0 | P11: 0 | Q11: 0 | R11: 0 | S11: 0 | V11: EFF | W11: AFR_S | X11: EP_Bio-CHP | Y11: 0.2989452 | Z11: 0 | AA11: =IF(SUMIFS(CHP_CHPR!$AA$4:$AA$283,CHP_CHPR!$Y$4:$Y$283,CHP_elecEFF!$W11,CHP_CHPR!$Z$4:$Z$283,CHP_elecEFF!$X11)*Y11+Y11<=$AC$1,"",Y11*$AC$1/(SUMIFS(CHP_CHPR!$AA$4:$AA$283,CHP_CHPR!$Y$4:$Y$283,CHP_elecEFF!$W11,CHP_CHPR!$Z$4:$Z$283,CHP_elecEFF!$X11)*Y11+Y11))
A12: AFR_S | B12: EP_Coa-CHP | S12: 0.33 | V12: EFF | W12: AFR_S | X12: EP_Coa-CHP | Z12: 0 | AA12: =IF(SUMIFS(CHP_CHPR!$AA$4:$AA$283,CHP_CHPR!$Y$4:$Y$283,CHP_elecEFF!$W12,CHP_CHPR!$Z$4:$Z$283,CHP_elecEFF!$X12)*Y12+Y12<=$AC$1,"",Y12*$AC$1/(SUMIFS(CHP_CHPR!$AA$4:$AA$283,CHP_CHPR!$Y$4:$Y$283,CHP_elecEFF!$W12,CHP_CHPR!$Z$4:$Z$283,CHP_elecEFF!$X12)*Y12+Y12))
A13: AFR_S | B13: EP_Gas-CHP | K13: 0 | L13: 0 | M13: 0 | N13: 0 | O13: 0 | P13: 0 | Q13: 0 | R13: 0 | S13: 0 | V13: EFF | W13: AFR_S | X13: EP_Gas-CHP | Y13: 0.28532783 | Z13: 0 | AA13: =IF(SUMIFS(CHP_CHPR!$AA$4:$AA$283,CHP_CHPR!$Y$4:$Y$283,CHP_elecEFF!$W13,CHP_CHPR!$Z$4:$Z$283,CHP_elecEFF!$X13)*Y13+Y13<=$AC$1,"",Y13*$AC$1/(SUMIFS(CHP_CHPR!$AA$4:$AA$283,CHP_CHPR!$Y$4:$Y$283,CHP_elecEFF!$W13,CHP_CHPR!$Z$4:$Z$283,CHP_elecEFF!$X13)*Y13+Y13))
A14: AFR_S | B14: EP_Oil-CHP | S14: 0.33 | V14: EFF | W14: AFR_S | X14: EP_Oil-CHP | Z14: 0 | AA14: =IF(SUMIFS(CHP_CHPR!$AA$4:$AA$283,CHP_CHPR!$Y$4:$Y$283,CHP_elecEFF!$W14,CHP_CHPR!$Z$4:$Z$283,CHP_elecEFF!$X14)*Y14+Y14<=$AC$1,"",Y14*$AC$1/(SUMIFS(CHP_CHPR!$AA$4:$AA$283,CHP_CHPR!$Y$4:$Y$283,CHP_elecEFF!$W14,CHP_CHPR!$Z$4:$Z$283,CHP_elecEFF!$X14)*Y14+Y14))
A15: AFR_S | B15: EP_Oil_DST-CHP | S15: 0.33 | V15: EFF | W15: AFR_S | X15: EP_Oil_DST-CHP | Z15: 0 | AA15: =IF(SUMIFS(CHP_CHPR!$AA$4:$AA$283,CHP_CHPR!$Y$4:$Y$283,CHP_elecEFF!$W15,CHP_CHPR!$Z$4:$Z$283,CHP_elecEFF!$X15)*Y15+Y15<=$AC$1,"",Y15*$AC$1/(SUMIFS(CHP_CHPR!$AA$4:$AA$283,CHP_CHPR!$Y$4:$Y$283,CHP_elecEFF!$W15,CHP_CHPR!$Z$4:$Z$283,CHP_elecEFF!$X15)*Y15+Y15))
A16: AFR_S | B16: EP_Was-CHP | S16: 0.33 | V16: EFF | W16: AFR_S | X16: EP_Was-CHP | Z16: 0 | AA16: =IF(SUMIFS(CHP_CHPR!$AA$4:$AA$283,CHP_CHPR!$Y$4:$Y$283,CHP_elecEFF!$W16,CHP_CHPR!$Z$4:$Z$283,CHP_elecEFF!$X16)*Y16+Y16<=$AC$1,"",Y16*$AC$1/(SUMIFS(CHP_CHPR!$AA$4:$AA$283,CHP_CHPR!$Y$4:$Y$283,CHP_elecEFF!$W16,CHP_CHPR!$Z$4:$Z$283,CHP_elecEFF!$X16)*Y16+Y16))
A17: ANZ | B17: EP_Bio-CHP | C17: 0 | D17: 0 | E17: 0 | F17: 0 | G17: 0 | H17: 0 | I17: 0 | J17: 0 | K17: 0 | L17: 0 | M17: 0 | N17: 0 | O17: 0 | P17: 0 | Q17: 0 | R17: 0 | S17: 0 | V17: EFF | W17: ANZ | X17: EP_Bio-CHP | Y17: 0.3088406 | Z17: 0 | AA17: =IF(SUMIFS(CHP_CHPR!$AA$4:$AA$283,CHP_CHPR!$Y$4:$Y$283,CHP_elecEFF!$W17,CHP_CHPR!$Z$4:$Z$283,CHP_elecEFF!$X17)*Y17+Y17<=$AC$1,"",Y17*$AC$1/(SUMIFS(CHP_CHPR!$AA$4:$AA$283,CHP_CHPR!$Y$4:$Y$283,CHP_elecEFF!$W17,CHP_CHPR!$Z$4:$Z$283,CHP_elecEFF!$X17)*Y17+Y17))
A18: ANZ | B18: EP_Coa-CHP | C18: 0.097021397 | D18: 0.10336374 | E18: 0.10140425 | F18: 0.097912118 | G18: 0.10134815 | H18: 0.093295995 | I18: 0.091840379 | J18: 0.10827728 | K18: 0.12062904 | L18: 0.11841452 | M18: 0.1203152 | N18: 0.12271427 | O18: 0.12382609 | P18: 0.12037153 | Q18: 0.12174402 | R18: 0.13259109 | S18: 0.14406676 | V18: EFF | W18: ANZ | X18: EP_Coa-CHP | Y18: 0.28716933 | Z18: 0 | AA18: =IF(SUMIFS(CHP_CHPR!$AA$4:$AA$283,CHP_CHPR!$Y$4:$Y$283,CHP_elecEFF!$W18,CHP_CHPR!$Z$4:$Z$283,CHP_elecEFF!$X18)*Y18+Y18<=$AC$1,"",Y18*$AC$1/(SUMIFS(CHP_CHPR!$AA$4:$AA$283,CHP_CHPR!$Y$4:$Y$283,CHP_elecEFF!$W18,CHP_CHPR!$Z$4:$Z$283,CHP_elecEFF!$X18)*Y18+Y18))
A19: ANZ | B19: EP_Gas-CHP | C19: 0.19765142 | D19: 0.21936556 | E19: 0.23917644 | F19: 0.17167037 | G19: 0.18885271 | H19: 0.19231066 | I19: 0.18361601 | J19: 0.18403571 | K19: 0.19416967 | L19: 0.20945681 | M19: 0.19748565 | N19: 0.20963987 | O19: 0.22029022 | P19: 0.20453341 | Q19: 0.19103983 | R19: 0.22930318 | S19: 0.25482334 | V19: EFF | W19: ANZ | X19: EP_Gas-CHP | Y19: 0.30194587 | Z19: 0 | AA19: =IF(SUMIFS(CHP_CHPR!$AA$4:$AA$283,CHP_CHPR!$Y$4:$Y$283,CHP_elecEFF!$W19,CHP_CHPR!$Z$4:$Z$283,CHP_elecEFF!$X19)*Y19+Y19<=$AC$1,"",Y19*$AC$1/(SUMIFS(CHP_CHPR!$AA$4:$AA$283,CHP_CHPR!$Y$4:$Y$283,CHP_elecEFF!$W19,CHP_CHPR!$Z$4:$Z$283,CHP_elecEFF!$X19)*Y19+Y19))
A20: ANZ | B20: EP_Geo-CHP | C20: 0 | D20: 0 | E20: 0 | F20: 0 | G20: 0 | H20: 0 | I20: 0 | J20: 0 | K20: 0 | L20: 0 | M20: 0 | N20: 0 | O20: 0 | P20: 0 | Q20: 0 | R20: 0 | S20: 0 | V20: EFF | W20: ANZ | X20: EP_Geo-CHP | Y20: 0.257 | Z20: 0 | AA20: =IF(SUMIFS(CHP_CHPR!$AA$4:$AA$283,CHP_CHPR!$Y$4:$Y$283,CHP_elecEFF!$W20,CHP_CHPR!$Z$4:$Z$283,CHP_elecEFF!$X20)*Y20+Y20<=$AC$1,"",Y20*$AC$1/(SUMIFS(CHP_CHPR!$AA$4:$AA$283,CHP_CHPR!$Y$4:$Y$283,CHP_elecEFF!$W20,CHP_CHPR!$Z$4:$Z$283,CHP_elecEFF!$X20)*Y20+Y20))
A21: ANZ | B21: EP_Oil-CHP | J21: 0 | K21: 0 | L21: 0 | M21: 0 | N21: 0 | O21: 0 | P21: 0 | Q21: 0 | R21: 0 | S21: 0 | V21: EFF | W21: ANZ | X21: EP_Oil-CHP | Y21: 0.25549206 | Z21: 0 | AA21: =IF(SUMIFS(CHP_CHPR!$AA$4:$AA$283,CHP_CHPR!$Y$4:$Y$283,CHP_elecEFF!$W21,CHP_CHPR!$Z$4:$Z$283,CHP_elecEFF!$X21)*Y21+Y21<=$AC$1,"",Y21*$AC$1/(SUMIFS(CHP_CHPR!$AA$4:$AA$283,CHP_CHPR!$Y$4:$Y$283,CHP_elecEFF!$W21,CHP_CHPR!$Z$4:$Z$283,CHP_elecEFF!$X21)*Y21+Y21))
A22: ANZ | B22: EP_Oil_DST-CHP | S22: 0.33 | V22: EFF | W22: ANZ | X22: EP_Oil_DST-CHP | Z22: 0 | AA22: =IF(SUMIFS(CHP_CHPR!$AA$4:$AA$283,CHP_CHPR!$Y$4:$Y$283,CHP_elecEFF!$W22,CHP_CHPR!$Z$4:$Z$283,CHP_elecEFF!$X22)*Y22+Y22<=$AC$1,"",Y22*$AC$1/(SUMIFS(CHP_CHPR!$AA$4:$AA$283,CHP_CHPR!$Y$4:$Y$283,CHP_elecEFF!$W22,CHP_CHPR!$Z$4:$Z$283,CHP_elecEFF!$X22)*Y22+Y22))
A23: ANZ | B23: EP_Was-CHP | C23: 0 | D23: 0 | E23: 0 | F23: 0 | G23: 0 | H23: 0 | I23: 0 | J23: 0 | K23: 0 | L23: 0 | M23: 0 | N23: 0 | O23: 0 | P23: 0 | Q23: 0 | R23: 0 | S23: 0 | V23: EFF | W23: ANZ | X23: EP_Was-CHP | Y23: 0.25997917 | Z23: 0 | AA23: =IF(SUMIFS(CHP_CHPR!$AA$4:$AA$283,CHP_CHPR!$Y$4:$Y$283,CHP_elecEFF!$W23,CHP_CHPR!$Z$4:$Z$283,CHP_elecEFF!$X23)*Y23+Y23<=$AC$1,"",Y23*$AC$1/(SUMIFS(CHP_CHPR!$AA$4:$AA$283,CHP_CHPR!$Y$4:$Y$283,CHP_elecEFF!$W23,CHP_CHPR!$Z$4:$Z$283,CHP_elecEFF!$X23)*Y23+Y23))
A24: BRZ | B24: EP_Bio-CHP | C24: 0 | D24: 0 | E24: 0 | F24: 0 | G24: 0 | H24: 0 | I24: 0 | J24: 0 | K24: 0 | L24: 0 | M24: 0 | N24: 0 | O24: 0 | P24: 0 | Q24: 0 | R24: 0 | S24: 0 | V24: EFF | W24: BRZ | X24: EP_Bio-CHP | Y24: 0.32740002 | Z24: 0 | AA24: =IF(SUMIFS(CHP_CHPR!$AA$4:$AA$283,CHP_CHPR!$Y$4:$Y$283,CHP_elecEFF!$W24,CHP_CHPR!$Z$4:$Z$283,CHP_elecEFF!$X24)*Y24+Y24<=$AC$1,"",Y24*$AC$1/(SUMIFS(CHP_CHPR!$AA$4:$AA$283,CHP_CHPR!$Y$4:$Y$283,CHP_elecEFF!$W24,CHP_CHPR!$Z$4:$Z$283,CHP_elecEFF!$X24)*Y24+Y24))
A25: BRZ | B25: EP_Coa-CHP | C25: 0 | D25: 0 | E25: 0 | F25: 0 | G25: 0 | H25: 0 | I25: 0 | J25: 0 | K25: 0 | L25: 0 | M25: 0 | N25: 0 | O25: 0 | P25: 0 | Q25: 0 | R25: 0 | S25: 0 | V25: EFF | W25: BRZ | X25: EP_Coa-CHP | Y25: 0.30673833 | Z25: 0 | AA25: =IF(SUMIFS(CHP_CHPR!$AA$4:$AA$283,CHP_CHPR!$Y$4:$Y$283,CHP_elecEFF!$W25,CHP_CHPR!$Z$4:$Z$283,CHP_elecEFF!$X25)*Y25+Y25<=$AC$1,"",Y25*$AC$1/(SUMIFS(CHP_CHPR!$AA$4:$AA$283,CHP_CHPR!$Y$4:$Y$283,CHP_elecEFF!$W25,CHP_CHPR!$Z$4:$Z$283,CHP_elecEFF!$X25)*Y25+Y25))
A26: BRZ | B26: EP_Gas-CHP | C26: 0 | D26: 0 | E26: 0 | F26: 0 | G26: 0 | H26: 0 | I26: 0 | J26: 0 | K26: 0 | L26: 0 | M26: 0 | N26: 0 | O26: 0 | P26: 0 | Q26: 0 | R26: 0 | S26: 0 | V26: EFF | W26: BRZ | X26: EP_Gas-CHP | Y26: 0.38811846 | Z26: 0 | AA26: =IF(SUMIFS(CHP_CHPR!$AA$4:$AA$283,CHP_CHPR!$Y$4:$Y$283,CHP_elecEFF!$W26,CHP_CHPR!$Z$4:$Z$283,CHP_elecEFF!$X26)*Y26+Y26<=$AC$1,"",Y26*$AC$1/(SUMIFS(CHP_CHPR!$AA$4:$AA$283,CHP_CHPR!$Y$4:$Y$283,CHP_elecEFF!$W26,CHP_CHPR!$Z$4:$Z$283,CHP_elecEFF!$X26)*Y26+Y26))
A27: BRZ | B27: EP_Oil-CHP | C27: 0 | D27: 0 | E27: 0 | F27: 0 | G27: 0 | H27: 0 | I27: 0 | J27: 0 | K27: 0 | L27: 0 | M27: 0 | N27: 0 | O27: 0 | P27: 0 | Q27: 0 | R27: 0 | S27: 0 | V27: EFF | W27: BRZ | X27: EP_Oil-CHP | Y27: 0.2714 | Z27: 0 | AA27: =IF(SUMIFS(CHP_CHPR!$AA$4:$AA$283,CHP_CHPR!$Y$4:$Y$283,CHP_elecEFF!$W27,CHP_CHPR!$Z$4:$Z$283,CHP_elecEFF!$X27)*Y27+Y27<=$AC$1,"",Y27*$AC$1/(SUMIFS(CHP_CHPR!$AA$4:$AA$283,CHP_CHPR!$Y$4:$Y$283,CHP_elecEFF!$W27,CHP_CHPR!$Z$4:$Z$283,CHP_elecEFF!$X27)*Y27+Y27))
A28: BRZ | B28: EP_Oil_DST-CHP | S28: 0.33 | V28: EFF | W28: BRZ | X28: EP_Oil_DST-CHP | Z28: 0 | AA28: =IF(SUMIFS(CHP_CHPR!$AA$4:$AA$283,CHP_CHPR!$Y$4:$Y$283,CHP_elecEFF!$W28,CHP_CHPR!$Z$4:$Z$283,CHP_elecEFF!$X28)*Y28+Y28<=$AC$1,"",Y28*$AC$1/(SUMIFS(CHP_CHPR!$AA$4:$AA$283,CHP_CHPR!$Y$4:$Y$283,CHP_elecEFF!$W28,CHP_CHPR!$Z$4:$Z$283,CHP_elecEFF!$X28)*Y28+Y28))
A29: BRZ | B29: EP_Was-CHP | I29: 0 | J29: 0 | K29: 0 | L29: 0 | M29: 0 | N29: 0 | O29: 0 | P29: 0 | Q29: 0 | R29: 0 | S29: 0 | V29: EFF | W29: BRZ | X29: EP_Was-CHP | Y29: 0.26875 | Z29: 0 | AA29: =IF(SUMIFS(CHP_CHPR!$AA$4:$AA$283,CHP_CHPR!$Y$4:$Y$283,CHP_elecEFF!$W29,CHP_CHPR!$Z$4:$Z$283,CHP_elecEFF!$X29)*Y29+Y29<=$AC$1,"",Y29*$AC$1/(SUMIFS(CHP_CHPR!$AA$4:$AA$283,CHP_CHPR!$Y$4:$Y$283,CHP_elecEFF!$W29,CHP_CHPR!$Z$4:$Z$283,CHP_elecEFF!$X29)*Y29+Y29))
A30: CAN | B30: EP_Bio-CHP | S30: 0.33 | V30: EFF | W30: CAN | X30: EP_Bio-CHP | Z30: 0 | AA30: =IF(SUMIFS(CHP_CHPR!$AA$4:$AA$283,CHP_CHPR!$Y$4:$Y$283,CHP_elecEFF!$W30,CHP_CHPR!$Z$4:$Z$283,CHP_elecEFF!$X30)*Y30+Y30<=$AC$1,"",Y30*$AC$1/(SUMIFS(CHP_CHPR!$AA$4:$AA$283,CHP_CHPR!$Y$4:$Y$283,CHP_elecEFF!$W30,CHP_CHPR!$Z$4:$Z$283,CHP_elecEFF!$X30)*Y30+Y30))
A31: CAN | B31: EP_Coa-CHP | S31: 0.33 | V31: EFF | W31: CAN | X31: EP_Coa-CHP | Z31: 0 | AA31: =IF(SUMIFS(CHP_CHPR!$AA$4:$AA$283,CHP_CHPR!$Y$4:$Y$283,CHP_elecEFF!$W31,CHP_CHPR!$Z$4:$Z$283,CHP_elecEFF!$X31)*Y31+Y31<=$AC$1,"",Y31*$AC$1/(SUMIFS(CHP_CHPR!$AA$4:$AA$283,CHP_CHPR!$Y$4:$Y$283,CHP_elecEFF!$W31,CHP_CHPR!$Z$4:$Z$283,CHP_elecEFF!$X31)*Y31+Y31))
A32: CAN | B32: EP_Gas-CHP | C32: 0.08736898 | D32: 0.072965049 | E32: 0.077847403 | F32: 0.076132228 | G32: 0.094950112 | H32: 0.11120079 | I32: 0.11329788 | J32: 0.075607446 | K32: 0.094198788 | L32: 0.11522185 | M32: 0.12248302 | N32: 0.096569148 | O32: 0.095108747 | P32: 0.096959395 | Q32: 0.098226486 | R32: 0.093768384 | S32: 0.096179228 | V32: EFF | W32: CAN | X32: EP_Gas-CHP | Y32: 0.34027451 | Z32: 0 | AA32: =IF(SUMIFS(CHP_CHPR!$AA$4:$AA$283,CHP_CHPR!$Y$4:$Y$283,CHP_elecEFF!$W32,CHP_CHPR!$Z$4:$Z$283,CHP_elecEFF!$X32)*Y32+Y32<=$AC$1,"",Y32*$AC$1/(SUMIFS(CHP_CHPR!$AA$4:$AA$283,CHP_CHPR!$Y$4:$Y$283,CHP_elecEFF!$W32,CHP_CHPR!$Z$4:$Z$283,CHP_elecEFF!$X32)*Y32+Y32))
A33: CAN | B33: EP_Oil-CHP | C33: 0.0023386859 | D33: 0.0014596411 | E33: 0.0013851647 | F33: 0.0013850179 | G33: 0.0010600816 | H33: 0.0016929078 | I33: 0.0025394032 | J33: 0.0038471427 | K33: 0.0051778756 | L33: 0.013530586 | M33: 0.044003182 | N33: 0.073163057 | O33: 0.071571108 | P33: 0.0067964361 | Q33: 0.024174676 | R33: 0.10877011 | S33: 0.072480013 | V33: EFF | W33: CAN | X33: EP_Oil-CHP | Y33: 0.31447651 | Z33: 0 | AA33: =IF(SUMIFS(CHP_CHPR!$AA$4:$AA$283,CHP_CHPR!$Y$4:$Y$283,CHP_elecEFF!$W33,CHP_CHPR!$Z$4:$Z$283,CHP_elecEFF!$X33)*Y33+Y33<=$AC$1,"",Y33*$AC$1/(SUMIFS(CHP_CHPR!$AA$4:$AA$283,CHP_CHPR!$Y$4:$Y$283,CHP_elecEFF!$W33,CHP_CHPR!$Z$4:$Z$283,CHP_elecEFF!$X33)*Y33+Y33))
A34: CAN | B34: EP_Oil_DST-CHP | S34: 0.33 | V34: EFF | W34: CAN | X34: EP_Oil_DST-CHP | Z34: 0 | AA34: =IF(SUMIFS(CHP_CHPR!$AA$4:$AA$283,CHP_CHPR!$Y$4:$Y$283,CHP_elecEFF!$W34,CHP_CHPR!$Z$4:$Z$283,CHP_elecEFF!$X34)*Y34+Y34<=$AC$1,"",Y34*$AC$1/(SUMIFS(CHP_CHPR!$AA$4:$AA$283,CHP_CHPR!$Y$4:$Y$283,CHP_elecEFF!$W34,CHP_CHPR!$Z$4:$Z$283,CHP_elecEFF!$X34)*Y34+Y34))
A35: CAN | B35: EP_Was-CHP | C35: 0 | D35: 0 | E35: 0 | F35: 0 | G35: 0 | H35: 0 | I35: 0 | J35: 0 | K35: 0 | L35: 0 | M35: 0 | N35: 0 | O35: 0 | P35: 0 | Q35: 0 | R35: 0 | S35: 0 | V35: EFF | W35: CAN | X35: EP_Was-CHP | Y35: 0.27605941 | Z35: 0 | AA35: =IF(SUMIFS(CHP_CHPR!$AA$4:$AA$283,CHP_CHPR!$Y$4:$Y$283,CHP_elecEFF!$W35,CHP_CHPR!$Z$4:$Z$283,CHP_elecEFF!$X35)*Y35+Y35<=$AC$1,"",Y35*$AC$1/(SUMIFS(CHP_CHPR!$AA$4:$AA$283,CHP_CHPR!$Y$4:$Y$283,CHP_elecEFF!$W35,CHP_CHPR!$Z$4:$Z$283,CHP_elecEFF!$X35)*Y35+Y35))
A36: CHI | B36: EP_Bio-CHP | S36: 0.33 | V36: EFF | W36: CHI | X36: EP_Bio-CHP | Z36: 0 | AA36: =IF(SUMIFS(CHP_CHPR!$AA$4:$AA$283,CHP_CHPR!$Y$4:$Y$283,CHP_elecEFF!$W36,CHP_CHPR!$Z$4:$Z$283,CHP_elecEFF!$X36)*Y36+Y36<=$AC$1,"",Y36*$AC$1/(SUMIFS(CHP_CHPR!$AA$4:$AA$283,CHP_CHPR!$Y$4:$Y$283,CHP_elecEFF!$W36,CHP_CHPR!$Z$4:$Z$283,CHP_elecEFF!$X36)*Y36+Y36))
A37: CHI | B37: EP_Coa-CHP | F37: 0.0685579 | G37: 0.069783689 | H37: 0.073614181 | I37: 0.07335554 | J37: 0.073123341 | K37: 0.073190339 | L37: 0.072344786 | M37: 0.067065685 | N37: 0.069773553 | O37: 0.073972235 | P37: 0.076447826 | Q37: 0.081861567 | R37: 0.079092097 | S37: 0.075783744 | V37: EFF | W37: CHI | X37: EP_Coa-CHP | Y37: 0.30060905 | Z37: 0 | AA37: =IF(SUMIFS(CHP_CHPR!$AA$4:$AA$283,CHP_CHPR!$Y$4:$Y$283,CHP_elecEFF!$W37,CHP_CHPR!$Z$4:$Z$283,CHP_elecEFF!$X37)*Y37+Y37<=$AC$1,"",Y37*$AC$1/(SUMIFS(CHP_CHPR!$AA$4:$AA$283,CHP_CHPR!$Y$4:$Y$283,CHP_elecEFF!$W37,CHP_CHPR!$Z$4:$Z$283,CHP_elecEFF!$X37)*Y37+Y37))
A38: CHI | B38: EP_CoaG-CHP | S38: 0.33 | V38: EFF | W38: CHI | X38: EP_CoaG-CHP | Z38: 0 | AA38: =IF(SUMIFS(CHP_CHPR!$AA$4:$AA$283,CHP_CHPR!$Y$4:$Y$283,CHP_elecEFF!$W38,CHP_CHPR!$Z$4:$Z$283,CHP_elecEFF!$X38)*Y38+Y38<=$AC$1,"",Y38*$AC$1/(SUMIFS(CHP_CHPR!$AA$4:$AA$283,CHP_CHPR!$Y$4:$Y$283,CHP_elecEFF!$W38,CHP_CHPR!$Z$4:$Z$283,CHP_elecEFF!$X38)*Y38+Y38))
A39: CHI | B39: EP_Gas-CHP | F39: 0.055994832 | G39: 0.056414623 | H39: 0.051754069 | I39: 0.056986944 | J39: 0.051670866 | K39: 0.034285258 | L39: 0.049582721 | M39: 0.051240492 | N39: 0.059245753 | O39: 0.065098119 | P39: 0.064446289 | Q39: 0.063687163 | R39: 0.062145317 | S39: 0.062495257 | V39: EFF | W39: CHI | X39: EP_Gas-CHP | Y39: 0.49302379 | Z39: 0 | AA39: =IF(SUMIFS(CHP_CHPR!$AA$4:$AA$283,CHP_CHPR!$Y$4:$Y$283,CHP_elecEFF!$W39,CHP_CHPR!$Z$4:$Z$283,CHP_elecEFF!$X39)*Y39+Y39<=$AC$1,"",Y39*$AC$1/(SUMIFS(CHP_CHPR!$AA$4:$AA$283,CHP_CHPR!$Y$4:$Y$283,CHP_elecEFF!$W39,CHP_CHPR!$Z$4:$Z$283,CHP_elecEFF!$X39)*Y39+Y39)) -> 0.23418829
A40: CHI | B40: EP_Nuc-CHP | S40: 0.33 | V40: EFF | W40: CHI | X40: EP_Nuc-CHP | Z40: 0 | AA40: =IF(SUMIFS(CHP_CHPR!$AA$4:$AA$283,CHP_CHPR!$Y$4:$Y$283,CHP_elecEFF!$W40,CHP_CHPR!$Z$4:$Z$283,CHP_elecEFF!$X40)*Y40+Y40<=$AC$1,"",Y40*$AC$1/(SUMIFS(CHP_CHPR!$AA$4:$AA$283,CHP_CHPR!$Y$4:$Y$283,CHP_elecEFF!$W40,CHP_CHPR!$Z$4:$Z$283,CHP_elecEFF!$X40)*Y40+Y40))
...

Sheet CHP_CHPR
A1: RestartCHPChar_CHPR | AF1: 0.25 | AG1: if zero
Y2: Deactivated~TFM_INS-TS | AH2: ~TFM_INS-TS
A3: Region | B3: PSET_PN | C3: 2002 | D3: 2003 | E3: 2004 | F3: 2005 | G3: 2006 | H3: 2007 | I3: 2008 | J3: 2009 | K3: 2010 | L3: 2011 | M3: 2012 | N3: 2013 | O3: 2014 | P3: 2015 | Q3: 2016 | R3: 2017 | S3: 2018 | Y3: Region | Z3: PSET_PN | AA3: =S3 -> 2018 | AB3: 0 | AC3: Attribute | AD3: LimType | AH3: Region | AI3: PSET_PN | AJ3: 2018 | AK3: 0 | AL3: Attribute | AM3: LimType
A4: AFR_N | B4: EP_Bio-CHP | L4: 0 | M4: 0 | N4: 0 | O4: 0 | P4: 0 | Q4: 0 | R4: 0 | S4: 0 | Y4: =IF($A4="","\I:",A4) -> AFR_N | Z4: =B4 -> EP_Bio-CHP | AA4: =MAX(IFERROR(AVERAGE(R4:S4),$AF$1),$AF$1) -> 0.25 | AB4: 3 | AC4: =IF($A4="","\I:","NCAP_CHPR") -> NCAP_CHPR | AD4: FX | AH4: AFR_N | AI4: EP_Bio-CHP | AJ4: 2 | AK4: 3 | AL4: NCAP_CHPR | AM4: UP
A5: AFR_N | B5: EP_Coa-CHP | S5: 1.5 | Y5: =IF($A5="","\I:",A5) -> AFR_N | Z5: =B5 -> EP_Coa-CHP | AA5: =MAX(IFERROR(AVERAGE(R5:S5),$AF$1),$AF$1) -> 1.5 | AB5: 3 | AC5: =IF($A5="","\I:","NCAP_CHPR") -> NCAP_CHPR | AD5: FX | AH5: AFR_N | AI5: EP_Coa-CHP | AJ5: 2 | AK5: 3 | AL5: NCAP_CHPR | AM5: UP
A6: AFR_N | B6: EP_Gas-CHP | K6: 0 | L6: 0 | M6: 0 | N6: 0 | O6: 0 | P6: 0 | Q6: 0 | R6: 0 | S6: 0 | Y6: =IF($A6="","\I:",A6) -> AFR_N | Z6: =B6 -> EP_Gas-CHP | AA6: =MAX(IFERROR(AVERAGE(R6:S6),$AF$1),$AF$1) -> 0.25 | AB6: 3 | AC6: =IF($A6="","\I:","NCAP_CHPR") -> NCAP_CHPR | AD6: FX | AH6: AFR_N | AI6: EP_Gas-CHP | AJ6: 2 | AK6: 3 | AL6: NCAP_CHPR | AM6: UP
A7: AFR_N | B7: EP_Oil-CHP | S7: 1.5 | Y7: =IF($A7="","\I:",A7) -> AFR_N | Z7: =B7 -> EP_Oil-CHP | AA7: =MAX(IFERROR(AVERAGE(R7:S7),$AF$1),$AF$1) -> 1.5 | AB7: 3 | AC7: =IF($A7="","\I:","NCAP_CHPR") -> NCAP_CHPR | AD7: FX | AH7: AFR_N | AI7: EP_Oil-CHP | AJ7: 2 | AK7: 3 | AL7: NCAP_CHPR | AM7: UP
A8: AFR_N | B8: EP_Oil_CRD-CHP | S8: 1.5 | Y8: =IF($A8="","\I:",A8) -> AFR_N | Z8: =B8 -> EP_Oil_CRD-CHP | AA8: =MAX(IFERROR(AVERAGE(R8:S8),$AF$1),$AF$1) -> 1.5 | AB8: 3 | AC8: =IF($A8="","\I:","NCAP_CHPR") -> NCAP_CHPR | AD8: FX | AH8: AFR_N | AI8: EP_Oil_CRD-CHP | AJ8: 2 | AK8: 3 | AL8: NCAP_CHPR | AM8: UP
A9: AFR_N | B9: EP_Oil_DST-CHP | S9: 1.5 | Y9: =IF($A9="","\I:",A9) -> AFR_N | Z9: =B9 -> EP_Oil_DST-CHP | AA9: =MAX(IFERROR(AVERAGE(R9:S9),$AF$1),$AF$1) -> 1.5 | AB9: 3 | AC9: =IF($A9="","\I:","NCAP_CHPR") -> NCAP_CHPR | AD9: FX | AH9: AFR_N | AI9: EP_Oil_DST-CHP | AJ9: 2 | AK9: 3 | AL9: NCAP_CHPR | AM9: UP
A10: AFR_N | B10: EP_Was-CHP | S10: 1.5 | Y10: =IF($A10="","\I:",A10) -> AFR_N | Z10: =B10 -> EP_Was-CHP | AA10: =MAX(IFERROR(AVERAGE(R10:S10),$AF$1),$AF$1) -> 1.5 | AB10: 3 | AC10: =IF($A10="","\I:","NCAP_CHPR") -> NCAP_CHPR | AD10: FX | AH10: AFR_N | AI10: EP_Was-CHP | AJ10: 2 | AK10: 3 | AL10: NCAP_CHPR | AM10: UP
A11: AFR_S | B11: EP_Bio-CHP | L11: 0 | M11: 0 | N11: 0 | O11: 0 | P11: 0 | Q11: 0 | R11: 0 | S11: 0 | Y11: =IF($A11="","\I:",A11) -> AFR_S | Z11: =B11 -> EP_Bio-CHP | AA11: =MAX(IFERROR(AVERAGE(R11:S11),$AF$1),$AF$1) -> 0.25 | AB11: 3 | AC11: =IF($A11="","\I:","NCAP_CHPR") -> NCAP_CHPR | AD11: FX | AH11: AFR_S | AI11: EP_Bio-CHP | AJ11: 2 | AK11: 3 | AL11: NCAP_CHPR | AM11: UP
A12: AFR_S | B12: EP_Coa-CHP | S12: 1.5 | Y12: =IF($A12="","\I:",A12) -> AFR_S | Z12: =B12 -> EP_Coa-CHP | AA12: =MAX(IFERROR(AVERAGE(R12:S12),$AF$1),$AF$1) -> 1.5 | AB12: 3 | AC12: =IF($A12="","\I:","NCAP_CHPR") -> NCAP_CHPR | AD12: FX | AH12: AFR_S | AI12: EP_Coa-CHP | AJ12: 2 | AK12: 3 | AL12: NCAP_CHPR | AM12: UP
A13: AFR_S | B13: EP_Gas-CHP | K13: 0 | L13: 0 | M13: 0 | N13: 0 | O13: 0 | P13: 0 | Q13: 0 | R13: 0 | S13: 0 | Y13: =IF($A13="","\I:",A13) -> AFR_S | Z13: =B13 -> EP_Gas-CHP | AA13: =MAX(IFERROR(AVERAGE(R13:S13),$AF$1),$AF$1) -> 0.25 | AB13: 3 | AC13: =IF($A13="","\I:","NCAP_CHPR") -> NCAP_CHPR | AD13: FX | AH13: AFR_S | AI13: EP_Gas-CHP | AJ13: 2 | AK13: 3 | AL13: NCAP_CHPR | AM13: UP
A14: AFR_S | B14: EP_Oil-CHP | S14: 1.5 | Y14: =IF($A14="","\I:",A14) -> AFR_S | Z14: =B14 -> EP_Oil-CHP | AA14: =MAX(IFERROR(AVERAGE(R14:S14),$AF$1),$AF$1) -> 1.5 | AB14: 3 | AC14: =IF($A14="","\I:","NCAP_CHPR") -> NCAP_CHPR | AD14: FX | AH14: AFR_S | AI14: EP_Oil-CHP | AJ14: 2 | AK14: 3 | AL14: NCAP_CHPR | AM14: UP
A15: AFR_S | B15: EP_Oil_DST-CHP | S15: 1.5 | Y15: =IF($A15="","\I:",A15) -> AFR_S | Z15: =B15 -> EP_Oil_DST-CHP | AA15: =MAX(IFERROR(AVERAGE(R15:S15),$AF$1),$AF$1) -> 1.5 | AB15: 3 | AC15: =IF($A15="","\I:","NCAP_CHPR") -> NCAP_CHPR | AD15: FX | AH15: AFR_S | AI15: EP_Oil_DST-CHP | AJ15: 2 | AK15: 3 | AL15: NCAP_CHPR | AM15: UP
A16: AFR_S | B16: EP_Was-CHP | S16: 1.5 | Y16: =IF($A16="","\I:",A16) -> AFR_S | Z16: =B16 -> EP_Was-CHP | AA16: =MAX(IFERROR(AVERAGE(R16:S16),$AF$1),$AF$1) -> 1.5 | AB16: 3 | AC16: =IF($A16="","\I:","NCAP_CHPR") -> NCAP_CHPR | AD16: FX | AH16: AFR_S | AI16: EP_Was-CHP | AJ16: 2 | AK16: 3 | AL16: NCAP_CHPR | AM16: UP
A17: ANZ | B17: EP_Bio-CHP | C17: 0 | D17: 0 | E17: 0 | F17: 0 | G17: 0 | H17: 0 | I17: 0 | J17: 0 | K17: 0 | L17: 0 | M17: 0 | N17: 0 | O17: 0 | P17: 0 | Q17: 0 | R17: 0 | S17: 0 | Y17: =IF($A17="","\I:",A17) -> ANZ | Z17: =B17 -> EP_Bio-CHP | AA17: =MAX(IFERROR(AVERAGE(R17:S17),$AF$1),$AF$1) -> 0.25 | AB17: 3 | AC17: =IF($A17="","\I:","NCAP_CHPR") -> NCAP_CHPR | AD17: FX | AH17: ANZ | AI17: EP_Bio-CHP | AJ17: 2 | AK17: 3 | AL17: NCAP_CHPR | AM17: UP
A18: ANZ | B18: EP_Coa-CHP | C18: 0 | D18: 0 | E18: 0 | F18: 0 | G18: 0 | H18: 0 | I18: 0 | J18: 0 | K18: 0 | L18: 0 | M18: 0 | N18: 0 | O18: 0 | P18: 0 | Q18: 0 | R18: 0 | S18: 0 | Y18: =IF($A18="","\I:",A18) -> ANZ | Z18: =B18 -> EP_Coa-CHP | AA18: =MAX(IFERROR(AVERAGE(R18:S18),$AF$1),$AF$1) -> 0.25 | AB18: 3 | AC18: =IF($A18="","\I:","NCAP_CHPR") -> NCAP_CHPR | AD18: FX | AH18: ANZ | AI18: EP_Coa-CHP | AJ18: 2 | AK18: 3 | AL18: NCAP_CHPR | AM18: UP
A19: ANZ | B19: EP_Gas-CHP | C19: 0 | D19: 0 | E19: 0 | F19: 0 | G19: 0 | H19: 0 | I19: 0 | J19: 0 | K19: 0 | L19: 0 | M19: 0 | N19: 0 | O19: 0 | P19: 0 | Q19: 0 | R19: 0 | S19: 0 | Y19: =IF($A19="","\I:",A19) -> ANZ | Z19: =B19 -> EP_Gas-CHP | AA19: =MAX(IFERROR(AVERAGE(R19:S19),$AF$1),$AF$1) -> 0.25 | AB19: 3 | AC19: =IF($A19="","\I:","NCAP_CHPR") -> NCAP_CHPR | AD19: FX | AH19: ANZ | AI19: EP_Gas-CHP | AJ19: 2 | AK19: 3 | AL19: NCAP_CHPR | AM19: UP
A20: ANZ | B20: EP_Geo-CHP | C20: 0 | D20: 0 | E20: 0 | F20: 0 | G20: 0 | H20: 0 | I20: 0 | J20: 0 | K20: 0 | L20: 0 | M20: 0 | N20: 0 | O20: 0 | P20: 0 | Q20: 0 | R20: 0 | S20: 0 | Y20: =IF($A20="","\I:",A20) -> ANZ | Z20: =B20 -> EP_Geo-CHP | AA20: =MAX(IFERROR(AVERAGE(R20:S20),$AF$1),$AF$1) -> 0.25 | AB20: 3 | AC20: =IF($A20="","\I:","NCAP_CHPR") -> NCAP_CHPR | AD20: FX | AH20: ANZ | AI20: EP_Geo-CHP | AJ20: 2 | AK20: 3 | AL20: NCAP_CHPR | AM20: UP
A21: ANZ | B21: EP_Oil-CHP | J21: 0 | K21: 0 | L21: 0 | M21: 0 | N21: 0 | O21: 0 | P21: 0 | Q21: 0 | R21: 0 | S21: 0 | Y21: =IF($A21="","\I:",A21) -> ANZ | Z21: =B21 -> EP_Oil-CHP | AA21: =MAX(IFERROR(AVERAGE(R21:S21),$AF$1),$AF$1) -> 0.25 | AB21: 3 | AC21: =IF($A21="","\I:","NCAP_CHPR") -> NCAP_CHPR | AD21: FX | AH21: ANZ | AI21: EP_Oil-CHP | AJ21: 2 | AK21: 3 | AL21: NCAP_CHPR | AM21: UP
A22: ANZ | B22: EP_Oil_DST-CHP | S22: 1.5 | Y22: =IF($A22="","\I:",A22) -> ANZ | Z22: =B22 -> EP_Oil_DST-CHP | AA22: =MAX(IFERROR(AVERAGE(R22:S22),$AF$1),$AF$1) -> 1.5 | AB22: 3 | AC22: =IF($A22="","\I:","NCAP_CHPR") -> NCAP_CHPR | AD22: FX | AH22: ANZ | AI22: EP_Oil_DST-CHP | AJ22: 2 | AK22: 3 | AL22: NCAP_CHPR | AM22: UP
A23: ANZ | B23: EP_Was-CHP | C23: 0 | D23: 0 | E23: 0 | F23: 0 | G23: 0 | H23: 0 | I23: 0 | J23: 0 | K23: 0 | L23: 0 | M23: 0 | N23: 0 | O23: 0 | P23: 0 | Q23: 0 | R23: 0 | S23: 0 | Y23: =IF($A23="","\I:",A23) -> ANZ | Z23: =B23 -> EP_Was-CHP | AA23: =MAX(IFERROR(AVERAGE(R23:S23),$AF$1),$AF$1) -> 0.25 | AB23: 3 | AC23: =IF($A23="","\I:","NCAP_CHPR") -> NCAP_CHPR | AD23: FX | AH23: ANZ | AI23: EP_Was-CHP | AJ23: 2 | AK23: 3 | AL23: NCAP_CHPR | AM23: UP
A24: BRZ | B24: EP_Bio-CHP | C24: 0 | D24: 0 | E24: 0 | F24: 0 | G24: 0 | H24: 0 | I24: 0 | J24: 0 | K24: 0 | L24: 0 | M24: 0 | N24: 0 | O24: 0 | P24: 0 | Q24: 0 | R24: 0 | S24: 0 | Y24: =IF($A24="","\I:",A24) -> BRZ | Z24: =B24 -> EP_Bio-CHP | AA24: =MAX(IFERROR(AVERAGE(R24:S24),$AF$1),$AF$1) -> 0.25 | AB24: 3 | AC24: =IF($A24="","\I:","NCAP_CHPR") -> NCAP_CHPR | AD24: FX | AH24: BRZ | AI24: EP_Bio-CHP | AJ24: 2 | AK24: 3 | AL24: NCAP_CHPR | AM24: UP
A25: BRZ | B25: EP_Coa-CHP | C25: 0 | D25: 0 | E25: 0 | F25: 0 | G25: 0 | H25: 0 | I25: 0 | J25: 0 | K25: 0 | L25: 0 | M25: 0 | N25: 0 | O25: 0 | P25: 0 | Q25: 0 | R25: 0 | S25: 0 | Y25: =IF($A25="","\I:",A25) -> BRZ | Z25: =B25 -> EP_Coa-CHP | AA25: =MAX(IFERROR(AVERAGE(R25:S25),$AF$1),$AF$1) -> 0.25 | AB25: 3 | AC25: =IF($A25="","\I:","NCAP_CHPR") -> NCAP_CHPR | AD25: FX | AH25: BRZ | AI25: EP_Coa-CHP | AJ25: 2 | AK25: 3 | AL25: NCAP_CHPR | AM25: UP
A26: BRZ | B26: EP_Gas-CHP | C26: 0 | D26: 0 | E26: 0 | F26: 0 | G26: 0 | H26: 0 | I26: 0 | J26: 0 | K26: 0 | L26: 0 | M26: 0 | N26: 0 | O26: 0 | P26: 0 | Q26: 0 | R26: 0 | S26: 0 | Y26: =IF($A26="","\I:",A26) -> BRZ | Z26: =B26 -> EP_Gas-CHP | AA26: =MAX(IFERROR(AVERAGE(R26:S26),$AF$1),$AF$1) -> 0.25 | AB26: 3 | AC26: =IF($A26="","\I:","NCAP_CHPR") -> NCAP_CHPR | AD26: FX | AH26: BRZ | AI26: EP_Gas-CHP | AJ26: 2 | AK26: 3 | AL26: NCAP_CHPR | AM26: UP
A27: BRZ | B27: EP_Oil-CHP | C27: 0 | D27: 0 | E27: 0 | F27: 0 | G27: 0 | H27: 0 | I27: 0 | J27: 0 | K27: 0 | L27: 0 | M27: 0 | N27: 0 | O27: 0 | P27: 0 | Q27: 0 | R27: 0 | S27: 0 | Y27: =IF($A27="","\I:",A27) -> BRZ | Z27: =B27 -> EP_Oil-CHP | AA27: =MAX(IFERROR(AVERAGE(R27:S27),$AF$1),$AF$1) -> 0.25 | AB27: 3 | AC27: =IF($A27="","\I:","NCAP_CHPR") -> NCAP_CHPR | AD27: FX | AH27: BRZ | AI27: EP_Oil-CHP | AJ27: 2 | AK27: 3 | AL27: NCAP_CHPR | AM27: UP
A28: BRZ | B28: EP_Oil_DST-CHP | S28: 1.5 | Y28: =IF($A28="","\I:",A28) -> BRZ | Z28: =B28 -> EP_Oil_DST-CHP | AA28: =MAX(IFERROR(AVERAGE(R28:S28),$AF$1),$AF$1) -> 1.5 | AB28: 3 | AC28: =IF($A28="","\I:","NCAP_CHPR") -> NCAP_CHPR | AD28: FX | AH28: BRZ | AI28: EP_Oil_DST-CHP | AJ28: 2 | AK28: 3 | AL28: NCAP_CHPR | AM28: UP
A29: BRZ | B29: EP_Was-CHP | I29: 0 | J29: 0 | K29: 0 | L29: 0 | M29: 0 | N29: 0 | O29: 0 | P29: 0 | Q29: 0 | R29: 0 | S29: 0 | Y29: =IF($A29="","\I:",A29) -> BRZ | Z29: =B29 -> EP_Was-CHP | AA29: =MAX(IFERROR(AVERAGE(R29:S29),$AF$1),$AF$1) -> 0.25 | AB29: 3 | AC29: =IF($A29="","\I:","NCAP_CHPR") -> NCAP_CHPR | AD29: FX | AH29: BRZ | AI29: EP_Was-CHP | AJ29: 2 | AK29: 3 | AL29: NCAP_CHPR | AM29: UP
A30: CAN | B30: EP_Bio-CHP | S30: 1.5 | Y30: =IF($A30="","\I:",A30) -> CAN | Z30: =B30 -> EP_Bio-CHP | AA30: =MAX(IFERROR(AVERAGE(R30:S30),$AF$1),$AF$1) -> 1.5 | AB30: 3 | AC30: =IF($A30="","\I:","NCAP_CHPR") -> NCAP_CHPR | AD30: FX | AH30: CAN | AI30: EP_Bio-CHP | AJ30: 2 | AK30: 3 | AL30: NCAP_CHPR | AM30: UP
A31: CAN | B31: EP_Coa-CHP | S31: 1.5 | Y31: =IF($A31="","\I:",A31) -> CAN | Z31: =B31 -> EP_Coa-CHP | AA31: =MAX(IFERROR(AVERAGE(R31:S31),$AF$1),$AF$1) -> 1.5 | AB31: 3 | AC31: =IF($A31="","\I:","NCAP_CHPR") -> NCAP_CHPR | AD31: FX | AH31: CAN | AI31: EP_Coa-CHP | AJ31: 2 | AK31: 3 | AL31: NCAP_CHPR | AM31: UP
A32: CAN | B32: EP_Gas-CHP | C32: 0.82841265 | D32: 1.0581963 | E32: 1.0534876 | F32: 0.6297745 | G32: 0.5817523 | H32: 0.51861817 | I32: 0.54356345 | J32: 0.61551816 | K32: 0.48765402 | L32: 0.43122379 | M32: 0.59309997 | N32: 0.55434397 | O32: 0.57165667 | P32: 0.38824558 | Q32: 0.34523891 | R32: 0.70948672 | S32: 0.43722235 | Y32: =IF($A32="","\I:",A32) -> CAN | Z32: =B32 -> EP_Gas-CHP | AA32: =MAX(IFERROR(AVERAGE(R32:S32),$AF$1),$AF$1) -> 0.57335453 | AB32: 3 | AC32: =IF($A32="","\I:","NCAP_CHPR") -> NCAP_CHPR | AD32: FX | AH32: CAN | AI32: EP_Gas-CHP | AJ32: 2 | AK32: 3 | AL32: NCAP_CHPR | AM32: UP
A33: CAN | B33: EP_Oil-CHP | C33: 84.407686 | D33: 110.86956 | E33: 122.2173 | F33: 86.553513 | G33: 93.304074 | H33: 59.306003 | I33: 29.76613 | J33: 48.287167 | K33: 39.059154 | L33: 12.656845 | M33: 2.4907948 | N33: 1.2483861 | O33: 1.2761539 | P33: 1.2598847 | Q33: 6.29693 | R33: 1.2595705 | S33: 1.2601508 | Y33: =IF($A33="","\I:",A33) -> CAN | Z33: =B33 -> EP_Oil-CHP | AA33: =MAX(IFERROR(AVERAGE(R33:S33),$AF$1),$AF$1) -> 1.2598607 | AB33: 3 | AC33: =IF($A33="","\I:","NCAP_CHPR") -> NCAP_CHPR | AD33: FX | AH33: CAN | AI33: EP_Oil-CHP | AJ33: 2 | AK33: 3 | AL33: NCAP_CHPR | AM33: UP
A34: CAN | B34: EP_Oil_DST-CHP | S34: 1.5 | Y34: =IF($A34="","\I:",A34) -> CAN | Z34: =B34 -> EP_Oil_DST-CHP | AA34: =MAX(IFERROR(AVERAGE(R34:S34),$AF$1),$AF$1) -> 1.5 | AB34: 3 | AC34: =IF($A34="","\I:","NCAP_CHPR") -> NCAP_CHPR | AD34: FX | AH34: CAN | AI34: EP_Oil_DST-CHP | AJ34: 2 | AK34: 3 | AL34: NCAP_CHPR | AM34: UP
A35: CAN | B35: EP_Was-CHP | C35: 0.42672896 | D35: 0.41439134 | E35: 0.43989327 | F35: 0.38876075 | G35: 0.41674339 | H35: 0.25959255 | I35: 0.35244949 | J35: 0.37106304 | K35: 0.4170237 | L35: 0.49395544 | M35: 0.49510774 | N35: 0.37509629 | O35: 0.36546592 | P35: 0.36997063 | Q35: 0.37819849 | R35: 0.39078981 | S35: 0.39072003 | Y35: =IF($A35="","\I:",A35) -> CAN | Z35: =B35 -> EP_Was-CHP | AA35: =MAX(IFERROR(AVERAGE(R35:S35),$AF$1),$AF$1) -> 0.39075492 | AB35: 3 | AC35: =IF($A35="","\I:","NCAP_CHPR") -> NCAP_CHPR | AD35: FX | AH35: CAN | AI35: EP_Was-CHP | AJ35: 2 | AK35: 3 | AL35: NCAP_CHPR | AM35: UP
A36: CHI | B36: EP_Bio-CHP | S36: 1.5 | Y36: =IF($A36="","\I:",A36) -> CHI | Z36: =B36 -> EP_Bio-CHP | AA36: =MAX(IFERROR(AVERAGE(R36:S36),$AF$1),$AF$1) -> 1.5 | AB36: 3 | AC36: =IF($A36="","\I:","NCAP_CHPR") -> NCAP_CHPR | AD36: FX | AH36: CHI | AI36: EP_Bio-CHP | AJ36: 2 | AK36: 3 | AL36: NCAP_CHPR | AM36: UP
A37: CHI | B37: EP_Coa-CHP | F37: 0.71033416 | G37: 0.33409619 | H37: 0.3174545 | I37: 0.28149032 | J37: 0.26202453 | K37: 0.27340156 | L37: 0.26762468 | M37: 0.30915167 | N37: 0.31696165 | O37: 0.31637705 | P37: 0.3353857 | Q37: 0.34453828 | R37: 0.60388 | S37: 0.63024724 | Y37: =IF($A37="","\I:",A37) -> CHI | Z37: =B37 -> EP_Coa-CHP | AA37: =MAX(IFERROR(AVERAGE(R37:S37),$AF$1),$AF$1) -> 0.61706362 | AB37: 3 | AC37: =IF($A37="","\I:","NCAP_CHPR") -> NCAP_CHPR | AD37: FX | AH37: CHI | AI37: EP_Coa-CHP | AJ37: 2 | AK37: 3 | AL37: NCAP_CHPR | AM37: UP
A38: CHI | B38: EP_CoaG-CHP | S38: 1.5 | Y38: =IF($A38="","\I:",A38) -> CHI | Z38: =B38 -> EP_CoaG-CHP | AA38: =MAX(IFERROR(AVERAGE(R38:S38),$AF$1),$AF$1) -> 1.5 | AB38: 3 | AC38: =IF($A38="","\I:","NCAP_CHPR") -> NCAP_CHPR | AD38: FX | AH38: CHI | AI38: EP_CoaG-CHP | AJ38: 2 | AK38: 3 | AL38: NCAP_CHPR | AM38: UP
A39: CHI | B39: EP_Gas-CHP | F39: 2.6908562 | G39: 0.91169929 | H39: 0.90707577 | I39: 0.87443423 | J39: 0.82746323 | K39: 0.8032448 | L39: 0.81711845 | M39: 0.78912823 | N39: 0.78268761 | O39: 0.83086921 | P39: 0.84006733 | Q39: 0.83926647 | R39: 2.4228868 | S39: 2.4092225 | Y39: =IF($A39="","\I:",A39) -> CHI | Z39: =B39 -> EP_Gas-CHP | AA39: =MAX(IFERROR(AVERAGE(R39:S39),$AF$1),$AF$1) -> 2.4160546 | AB39: 3 | AC39: =IF($A39="","\I:","NCAP_CHPR") -> NCAP_CHPR | AD39: FX | AH39: CHI | AI39: EP_Gas-CHP | AJ39: 2 | AK39: 3 | AL39: NCAP_CHPR | AM39: UP
A40: CHI | B40: EP_Nuc-CHP | S40: 1.5 | Y40: =IF($A40="","\I:",A40) -> CHI | Z40: =B40 -> EP_Nuc-CHP | AA40: =MAX(IFERROR(AVERAGE(R40:S40),$AF$1),$AF$1) -> 1.5 | AB40: 3 | AC40: =IF($A40="","\I:","NCAP_CHPR") -> NCAP_CHPR | AD40: FX | AH40: CHI | AI40: EP_Nuc-CHP | AJ40: 2 | AK40: 3 | AL40: NCAP_CHPR | AM40: UP
...

Sheet CHP_shares
B3: ~TFM_INS-TS
B4: attribute | C4: Region | D4: Other_indexes | E4: PSET_CI | F4: PSET_CO | G4: CSET_CN | H4: limtype | I4: 2025 | J4: 2050 | K4: 0
B5: PRC_MARK | C5: CAN | D5: shugnbm-3 | E5: ELCBIO,ELCWAS | F5: HET | G5: HET | H5: LO | I5: 0 | J5: 0 | K5: 3
B6: PRC_MARK | C6: CAN | D6: shugncl-3 | E6: ELCCOA* | F6: HET | G6: HET | H6: LO | I6: 0 | J6: 0 | K6: 3
B7: PRC_MARK | C7: CAN | D7: shugnds-3 | E7: ELCOIL_DST | F7: HET | G7: HET | H7: LO | I7: 0 | J7: 0 | K7: 3
B8: PRC_MARK | C8: CAN | D8: shugnng-3 | E8: ELCGAS | F8: HET | G8: HET | H8: LO | I8: 0.89739092 | J8: 0.19942021 | K8: 3
B9: PRC_MARK | C9: CAN | D9: shugnrs-3 | E9: ELCOIL | F9: HET | G9: HET | H9: LO | I9: 0.0026090761 | J9: 0.00057979469 | K9: 3
B10: PRC_MARK | C10: CHI | D10: shugnbm-3 | E10: ELCBIO,ELCWAS | F10: HET | G10: HET | H10: LO | I10: 0 | J10: 0 | K10: 3
B11: PRC_MARK | C11: CHI | D11: shugncl-3 | E11: ELCCOA* | F11: HET | G11: HET | H11: LO | I11: 0.78661783 | J11: 0.17480396 | K11: 3
B12: PRC_MARK | C12: CHI | D12: shugnds-3 | E12: ELCOIL_DST | F12: HET | G12: HET | H12: LO | I12: 0 | J12: 0 | K12: 3
B13: PRC_MARK | C13: CHI | D13: shugnng-3 | E13: ELCGAS | F13: HET | G13: HET | H13: LO | I13: 0.11338217 | J13: 0.025196038 | K13: 3
B14: PRC_MARK | C14: CHI | D14: shugnrs-3 | E14: ELCOIL | F14: HET | G14: HET | H14: LO | I14: 0 | J14: 0 | K14: 3
B15: PRC_MARK | C15: EUR | D15: shugnbm-3 | E15: ELCBIO,ELCWAS | F15: HET | G15: HET | H15: LO | I15: 0.1474035 | J15: 0.032756332 | K15: 3
... B49: PRC_MARK | C49: \I: | D49: shugnrs-3 | E49: ELCOIL | F49: HET | G49: HET | H49: LO | I49: 0.018948025 | J49: 0.0042106722 | K49: 3
