Workbook

Sheet Readme
A1: Workbook purpose:
A2: Places a number of restrictions on model behavior for reference case development, as follows:
A4: Data source/modifiable?
A5: Cap decay limits: unbounds steps 12 and 21 of fossil supply curves; limits decay of existing fossil capacity. User assumptions. May be modified.
A6: monetize ILED: despite the sheet name, ILED is no longer monetized. It is set here by user assumption. May be modified.
A7: Remaining sheets: defines the steps of the build rate constraints, based on historical seed values written in the HistoricalBuilds sheet and capital costs popluated by the fill table on sheet togetInvCosts. Users should contact Amit to modify the structure of these constraints.
A9: The build rate constraints will apply at the WEPS region levels irrespective of the regional aggregation in the model
A10: in fact, they should be based more on geograpical location than even WEPS reg definitions. I have put Colombia and Chile in CSA, for example.

Sheet Cap decay limits
A1: Trans - Update
B2: ~TFM_UPD
B3: TimeSlice | C3: LimType | D3: Attribute | E3: Year | F3: Pset_PN | G3: AllRegions
D4: ACT_BND | E4: =HistoricalBuilds!R3 -> 2017,2018 | F4: MIN*10,-*bio* | G4: 99999
D5: ACT_BND | F5: MIN*12,-*bio* | G5: 99999
D6: ACT_BND | F6: MinBio-21 | G6: 99999
D7: *ACT_COST | F7: MinBio-21 | G7: *2
B9: ~TFM_INS
B10: TimeSlice | C10: LimType | D10: Attribute | E10: Year | F10: Attrib_Cond | G10: Val_Cond | H10: CHI | I10: Pset_Set | J10: Pset_PN
C11: LO | D11: AFA | H11: 0.2 | I11: ELECOA,ELEGAS | J11: -*CT*,-*GT*
C12: LO | D12: AFA | E12: 0 | H12: 3 | I12: ELECOA,ELEGAS | J12: -*CT*,-*GT*
B15: ~UC_Sets: R_E: AllRegions
F17: ="~UC_T: "&HistoricalBuilds!$N$1-1 -> ~UC_T: 2018
A18: CSET_CN | B18: UC_N | C18: *UC_ATTR | D18: PSET_SET | E18: PSET_CI | F18: LimType | G18: UC_CAP | H18: UC_CAP~RHS | I18: UC_RHSRT | J18: UC_RHSRT~0 | K18: UC_Desc | L18: UC_FLO | M18: UC_FLO~RHS | N18: UC_DYNBND
B19: UC_Capdecay-OIL | C19: CAP, GROWTH | D19: ELE,CHP | E19: ELCOIL* | F19: LO | G19: 0.925 | H19: -0.2 | J19: 5 | K19: =RIGHT(B19,3)&" capacity annual decay limit - "&TEXT(1-G19,"0.0%") -> OIL capacity annual decay limit - 7.5% | N19: 1
B20: UC_Capdecay-Coa | C20: CAP, GROWTH | D20: ELE,CHP | E20: ELCCOA | F20: LO | G20: 0.925 | H20: -0.6 | J20: 5 | K20: =RIGHT(B20,3)&" capacity annual decay limit - "&TEXT(1-G20,"0.0%") -> Coa capacity annual decay limit - 7.5% | N20: 1
B21: UC_Capdecay-Gas | C21: CAP, GROWTH | D21: ELE,CHP | E21: ELCGAS | F21: LO | G21: 0.98 | H21: -0.1 | J21: 5 | K21: =RIGHT(B21,3)&" capacity annual decay limit - "&TEXT(1-G21,"0.0%") -> Gas capacity annual decay limit - 2.0% | N21: 1
A22: HET | B22: *UC_HeatProddecay | C22: FLO, GROWTH | D22: CHP | F22: N | I22: 0 | J22: 5 | K22: heat production annual decay limit - 0.0% | L22: 1 | M22: 1
F25: deactivated
B26: UC_N | C26: UC_ATTR | D26: PSET_SET | E26: PSET_CI | F26: LimType | G26: UC_ACT | H26: UC_ACT~RHS | I26: UC_RHSRT | J26: UC_RHSRT~0 | K26: UC_Desc
B27: Non-Decreasing_Wind | C27: ACT, GROWTH | D27: ELE | E27: ELCWIN | F27: UP | G27: 1 | H27: 1 | I27: 0 | J27: 5 | K27: non-decreasing wind generation
B28: Non-Decreasing_Solar | C28: ACT, GROWTH | D28: ELE | E28: ELCSOL | F28: UP | G28: 1 | H28: 1 | I28: 0 | J28: 5 | K28: non-decreasing solar generation

Sheet monetize ILED
A2: Technology | B2: ILED | E2: Attribute | F2: PSET_PN | G2: AllRegions | K2: 0.07 | L2: discount rate
A3: EN_COAPUL | B3: 3 | E3: INVCOST | F3: =A3 -> EN_COAPUL | G3: ="*"&(1+$K$2)^B3 -> *1.225043
A4: EN_COAIGCC | B4: 4 | E4: INVCOST | F4: =A4 -> EN_COAIGCC | G4: ="*"&(1+$K$2)^B4 -> *1.31079601
A5: EN_ZCOAIGCC | B5: 4 | E5: INVCOST | F5: =A5 -> EN_ZCOAIGCC | G5: ="*"&(1+$K$2)^B5 -> *1.31079601
A6: EN_ZGasCCAdv | B6: 3 | E6: INVCOST | F6: =A6 -> EN_ZGasCCAdv | G6: ="*"&(1+$K$2)^B6 -> *1.225043
A7: EN_GasCCAdv | B7: 3 | E7: INVCOST | F7: =A7 -> EN_GasCCAdv | G7: ="*"&(1+$K$2)^B7 -> *1.225043
A8: EN_GasCC | B8: 3 | E8: INVCOST | F8: =A8 -> EN_GasCC | G8: ="*"&(1+$K$2)^B8 -> *1.225043
A9: EN_GasCTAdv | B9: 2 | E9: INVCOST | F9: =A9 -> EN_GasCTAdv | G9: ="*"&(1+$K$2)^B9 -> *1.1449
A10: EN_GasCT | B10: 2 | E10: INVCOST | F10: =A10 -> EN_GasCT | G10: ="*"&(1+$K$2)^B10 -> *1.1449
A11: EN_Biomass* | B11: 4 | E11: INVCOST | F11: =A11 -> EN_Biomass* | G11: ="*"&(1+$K$2)^B11 -> *1.31079601
A12: EN_Zbiomass* | B12: 4 | E12: INVCOST | F12: =A12 -> EN_Zbiomass* | G12: ="*"&(1+$K$2)^B12 -> *1.31079601
A13: EN_OilCCAdv | B13: 3 | E13: INVCOST | F13: =A13 -> EN_OilCCAdv | G13: ="*"&(1+$K$2)^B13 -> *1.225043
A14: EN_NuclearAdv | B14: 6 | E14: INVCOST | F14: =A14 -> EN_NuclearAdv | G14: ="*"&(1+$K$2)^B14 -> *1.500730351849
... A19: E[_]WON* | B19: 3 | E19: INVCOST | F19: =A19 -> E[_]WON* | G19: ="*"&(1+$K$2)^B19 -> *1.225043
E22: ~TFM_INS-TS
E23: Attribute | F23: PSET_PN | G23: 2017 | H23: 2018 | I23: 2019 | J23: 0
E24: ILED | F24: =A3 -> EN_COAPUL | I24: =B3 -> 3 | J24: 3
E25: ILED | F25: =A4 -> EN_COAIGCC | I25: =B4 -> 4 | J25: 3
E26: ILED | F26: =A5 -> EN_ZCOAIGCC | I26: =B5 -> 4 | J26: 3
E27: ILED | F27: =A6 -> EN_ZGasCCAdv | I27: =B6 -> 3 | J27: 3
E28: ILED | F28: =A7 -> EN_GasCCAdv | I28: =B7 -> 3 | J28: 3
E29: ILED | F29: =A8 -> EN_GasCC | I29: =B8 -> 3 | J29: 3
E30: ILED | F30: =A9 -> EN_GasCTAdv | I30: =B9 -> 2 | J30: 3
E31: ILED | F31: =A10 -> EN_GasCT | I31: =B10 -> 2 | J31: 3
E32: ILED | F32: =A11 -> EN_Biomass* | G32: 0 | H32: 0 | I32: =B11 -> 4 | J32: 5
E33: ILED | F33: =A12 -> EN_Zbiomass* | I33: =B12 -> 4 | J33: 3
E34: * | F34: =A13 -> EN_OilCCAdv | I34: =B13 -> 3 | J34: 3
E35: ILED | F35: =A14 -> EN_NuclearAdv | I35: =B14 -> 6 | J35: 3
E36: ILED | F36: =A15 -> EN_GeoThermal* | I36: =B15 -> 6 | J36: 3
E37: ILED | F37: =A16 -> EN_Hydro* | I37: =B16 -> 4 | J37: 3
E38: ILED | F38: =A17 -> E_SPV* | I38: =B17 -> 2 | J38: 3
E39: ILED | F39: =A19 -> E[_]WON* | I39: =B19 -> 3 | J39: 3

Sheet AFR
A1: =MID(CELL( "filename",A1),FIND("]",CELL( "filename",A1))+1,10) -> AFR | L1: 1 | M1: scaling
C2: ~UC_Sets: R_S: AllRegions
C3: ~UC_Sets: T_E:
H5: ="~UC_T: UC_RHST~LO~"&HistoricalBuilds!$N$1 -> ~UC_T: UC_RHST~LO~2019
C6: UC_N | D6: PSET_PN | E6: Pset_CI | F6: UC_ATTR | G6: LimType | H6: Attribute | I6: LHS | J6: UC_NCAP | K6: UC_NCAP~RHS | L6: UC_RHST | M6: UC_RHST~0 | N6: UC_Desc
C7: ="UELC-Bld_ELEWIN_"&$A$1 -> UELC-Bld_ELEWIN_AFR | D7: =VLOOKUP("1"&$A$1,'WEPSReg-Countrymap'!$D$2:$E$232,2,FALSE) -> *[_]AGO*,*[_]BDI*,*[_]BEN*,*[_]BFA*,*[_]BWA*,*[_]CAF*,*[_]CIV*,*[_]CMR*,*[_]COG*,*[_]COM*,*[_]CPV*,*[_]DJI*,*[_]DZA*,*[_]EGY*,*[_]ERI*,*[_]ETH*,*[_]GAB*,*[_]GHA*,*[_]GIN*,*[_]GMB*,*[_]GNB*,*[_]GNQ*,*[_]KEN*,*[_]LBR*,*[_]LBY*,*[_]LSO*,*[_]MAR*,*[_]MDG*,*[_]MLI*,*[_]MOZ*,*[_]MRT*,*[_]MUS*,*[_]MWI*,*[_]NAM*,*[_]NER*,*[_]NGA*,*[_]RWA*,*[_]SDN*,*[_]SEN*,*[_]SLE*,*[_]SOM*,*[_]SSD*,*[_]STP*,*[_]SWZ*,*[_]SYC*,*[_]TCD*,*[_]TGO*,*[_]TUN*,*[_]TZA*,*[_]UGA*,*[_]ZAF*,*[_]ZAR*,*[_]ZMB*,*[_]ZWE* | E7: ELCWIN | F7: NCAP,GROWTH | J7: 1.15 | K7: 1 | L7: 0 | M7: 5 | N7: ="Annual build rate (GW/Year) of ELEWIN_"&$A$1 -> Annual build rate (GW/Year) of ELEWIN_AFR
D8: ="EBldRateStep_Win_2_"&$A$1&",EBldRateStep_Win_3_"&$A$1 -> EBldRateStep_Win_2_AFR,EBldRateStep_Win_3_AFR | F8: ACT,NEWFLO | H8: UC_ACT | I8: 1
C9: ="UELC-Bld_ELEWIN-step2_"&$A$1 -> UELC-Bld_ELEWIN-step2_AFR | D9: =$D$7 -> *[_]AGO*,*[_]BDI*,*[_]BEN*,*[_]BFA*,*[_]BWA*,*[_]CAF*,*[_]CIV*,*[_]CMR*,*[_]COG*,*[_]COM*,*[_]CPV*,*[_]DJI*,*[_]DZA*,*[_]EGY*,*[_]ERI*,*[_]ETH*,*[_]GAB*,*[_]GHA*,*[_]GIN*,*[_]GMB*,*[_]GNB*,*[_]GNQ*,*[_]KEN*,*[_]LBR*,*[_]LBY*,*[_]LSO*,*[_]MAR*,*[_]MDG*,*[_]MLI*,*[_]MOZ*,*[_]MRT*,*[_]MUS*,*[_]MWI*,*[_]NAM*,*[_]NER*,*[_]NGA*,*[_]RWA*,*[_]SDN*,*[_]SEN*,*[_]SLE*,*[_]SOM*,*[_]SSD*,*[_]STP*,*[_]SWZ*,*[_]SYC*,*[_]TCD*,*[_]TGO*,*[_]TUN*,*[_]TZA*,*[_]UGA*,*[_]ZAF*,*[_]ZAR*,*[_]ZMB*,*[_]ZWE* | E9: ELCWIN | H9: UC_NCAP | I9: 0.85 | N9: ="step 2 relaxation of build rate - ELEWIN_"&$A$1 -> step 2 relaxation of build rate - ELEWIN_AFR
D10: ="EBldRateStep_Win_2_"&$A$1 -> EBldRateStep_Win_2_AFR | F10: ACT,NEWFLO | H10: UC_ACT | I10: -1 | L10: 0 | M10: 5
C11: ="UELC-Bld_ELEWIN-step3_"&$A$1 -> UELC-Bld_ELEWIN-step3_AFR | D11: =$D$7 -> *[_]AGO*,*[_]BDI*,*[_]BEN*,*[_]BFA*,*[_]BWA*,*[_]CAF*,*[_]CIV*,*[_]CMR*,*[_]COG*,*[_]COM*,*[_]CPV*,*[_]DJI*,*[_]DZA*,*[_]EGY*,*[_]ERI*,*[_]ETH*,*[_]GAB*,*[_]GHA*,*[_]GIN*,*[_]GMB*,*[_]GNB*,*[_]GNQ*,*[_]KEN*,*[_]LBR*,*[_]LBY*,*[_]LSO*,*[_]MAR*,*[_]MDG*,*[_]MLI*,*[_]MOZ*,*[_]MRT*,*[_]MUS*,*[_]MWI*,*[_]NAM*,*[_]NER*,*[_]NGA*,*[_]RWA*,*[_]SDN*,*[_]SEN*,*[_]SLE*,*[_]SOM*,*[_]SSD*,*[_]STP*,*[_]SWZ*,*[_]SYC*,*[_]TCD*,*[_]TGO*,*[_]TUN*,*[_]TZA*,*[_]UGA*,*[_]ZAF*,*[_]ZAR*,*[_]ZMB*,*[_]ZWE* | E11: ELCWIN | H11: UC_NCAP | I11: 1 | N11: ="step 3 relaxation of build rate - ELEWIN_"&$A$1 -> step 3 relaxation of build rate - ELEWIN_AFR
D12: ="EBldRateStep_Win_3_"&$A$1 -> EBldRateStep_Win_3_AFR | F12: ACT,NEWFLO | H12: UC_ACT | I12: -1 | L12: 0 | M12: 5
C13: ="UELC-Bld_ELESOL_"&$A$1 -> UELC-Bld_ELESOL_AFR | D13: =$D$7 -> *[_]AGO*,*[_]BDI*,*[_]BEN*,*[_]BFA*,*[_]BWA*,*[_]CAF*,*[_]CIV*,*[_]CMR*,*[_]COG*,*[_]COM*,*[_]CPV*,*[_]DJI*,*[_]DZA*,*[_]EGY*,*[_]ERI*,*[_]ETH*,*[_]GAB*,*[_]GHA*,*[_]GIN*,*[_]GMB*,*[_]GNB*,*[_]GNQ*,*[_]KEN*,*[_]LBR*,*[_]LBY*,*[_]LSO*,*[_]MAR*,*[_]MDG*,*[_]MLI*,*[_]MOZ*,*[_]MRT*,*[_]MUS*,*[_]MWI*,*[_]NAM*,*[_]NER*,*[_]NGA*,*[_]RWA*,*[_]SDN*,*[_]SEN*,*[_]SLE*,*[_]SOM*,*[_]SSD*,*[_]STP*,*[_]SWZ*,*[_]SYC*,*[_]TCD*,*[_]TGO*,*[_]TUN*,*[_]TZA*,*[_]UGA*,*[_]ZAF*,*[_]ZAR*,*[_]ZMB*,*[_]ZWE* | E13: ELCSOL | F13: NCAP,GROWTH | J13: 1.15 | K13: 1 | L13: 0 | M13: 5 | N13: ="Annual build rate (GW/Year) of ELESOL_"&$A$1 -> Annual build rate (GW/Year) of ELESOL_AFR
D14: ="EBldRateStep_Sol_2_"&$A$1&",EBldRateStep_Sol_3_"&$A$1 -> EBldRateStep_Sol_2_AFR,EBldRateStep_Sol_3_AFR | F14: ACT,NEWFLO | H14: UC_ACT | I14: 1
C15: ="UELC-Bld_ELESOL-step2_"&$A$1 -> UELC-Bld_ELESOL-step2_AFR | D15: =$D$7 -> *[_]AGO*,*[_]BDI*,*[_]BEN*,*[_]BFA*,*[_]BWA*,*[_]CAF*,*[_]CIV*,*[_]CMR*,*[_]COG*,*[_]COM*,*[_]CPV*,*[_]DJI*,*[_]DZA*,*[_]EGY*,*[_]ERI*,*[_]ETH*,*[_]GAB*,*[_]GHA*,*[_]GIN*,*[_]GMB*,*[_]GNB*,*[_]GNQ*,*[_]KEN*,*[_]LBR*,*[_]LBY*,*[_]LSO*,*[_]MAR*,*[_]MDG*,*[_]MLI*,*[_]MOZ*,*[_]MRT*,*[_]MUS*,*[_]MWI*,*[_]NAM*,*[_]NER*,*[_]NGA*,*[_]RWA*,*[_]SDN*,*[_]SEN*,*[_]SLE*,*[_]SOM*,*[_]SSD*,*[_]STP*,*[_]SWZ*,*[_]SYC*,*[_]TCD*,*[_]TGO*,*[_]TUN*,*[_]TZA*,*[_]UGA*,*[_]ZAF*,*[_]ZAR*,*[_]ZMB*,*[_]ZWE* | E15: ELCSOL | H15: UC_NCAP | I15: =I9 -> 0.85 | N15: ="step 2 relaxation of build rate - ELESOL_"&$A$1 -> step 2 relaxation of build rate - ELESOL_AFR
D16: ="EBldRateStep_Sol_2_"&$A$1 -> EBldRateStep_Sol_2_AFR | F16: ACT,NEWFLO | H16: UC_ACT | I16: -1 | L16: 0 | M16: 5
C17: ="UELC-Bld_ELESOL-step3_"&$A$1 -> UELC-Bld_ELESOL-step3_AFR | D17: =$D$7 -> *[_]AGO*,*[_]BDI*,*[_]BEN*,*[_]BFA*,*[_]BWA*,*[_]CAF*,*[_]CIV*,*[_]CMR*,*[_]COG*,*[_]COM*,*[_]CPV*,*[_]DJI*,*[_]DZA*,*[_]EGY*,*[_]ERI*,*[_]ETH*,*[_]GAB*,*[_]GHA*,*[_]GIN*,*[_]GMB*,*[_]GNB*,*[_]GNQ*,*[_]KEN*,*[_]LBR*,*[_]LBY*,*[_]LSO*,*[_]MAR*,*[_]MDG*,*[_]MLI*,*[_]MOZ*,*[_]MRT*,*[_]MUS*,*[_]MWI*,*[_]NAM*,*[_]NER*,*[_]NGA*,*[_]RWA*,*[_]SDN*,*[_]SEN*,*[_]SLE*,*[_]SOM*,*[_]SSD*,*[_]STP*,*[_]SWZ*,*[_]SYC*,*[_]TCD*,*[_]TGO*,*[_]TUN*,*[_]TZA*,*[_]UGA*,*[_]ZAF*,*[_]ZAR*,*[_]ZMB*,*[_]ZWE* | E17: ELCSOL | H17: UC_NCAP | I17: =I11 -> 1 | N17: ="step 3 relaxation of build rate - ELESOL_"&$A$1 -> step 3 relaxation of build rate - ELESOL_AFR
D18: ="EBldRateStep_Sol_3_"&$A$1 -> EBldRateStep_Sol_3_AFR | F18: ACT,NEWFLO | H18: UC_ACT | I18: -1 | L18: 0 | M18: 5
C19: ="UELC-Bld_ELEHYD_"&$A$1 -> UELC-Bld_ELEHYD_AFR | D19: =$D$7 -> *[_]AGO*,*[_]BDI*,*[_]BEN*,*[_]BFA*,*[_]BWA*,*[_]CAF*,*[_]CIV*,*[_]CMR*,*[_]COG*,*[_]COM*,*[_]CPV*,*[_]DJI*,*[_]DZA*,*[_]EGY*,*[_]ERI*,*[_]ETH*,*[_]GAB*,*[_]GHA*,*[_]GIN*,*[_]GMB*,*[_]GNB*,*[_]GNQ*,*[_]KEN*,*[_]LBR*,*[_]LBY*,*[_]LSO*,*[_]MAR*,*[_]MDG*,*[_]MLI*,*[_]MOZ*,*[_]MRT*,*[_]MUS*,*[_]MWI*,*[_]NAM*,*[_]NER*,*[_]NGA*,*[_]RWA*,*[_]SDN*,*[_]SEN*,*[_]SLE*,*[_]SOM*,*[_]SSD*,*[_]STP*,*[_]SWZ*,*[_]SYC*,*[_]TCD*,*[_]TGO*,*[_]TUN*,*[_]TZA*,*[_]UGA*,*[_]ZAF*,*[_]ZAR*,*[_]ZMB*,*[_]ZWE* | E19: ELCHYD | F19: NCAP,GROWTH | J19: 1.15 | K19: 1 | L19: 0 | M19: 5 | N19: ="Annual build rate (GW/Year) of ELEHYD_"&$A$1 -> Annual build rate (GW/Year) of ELEHYD_AFR
D20: ="EBldRateStep_Hyd_2_"&$A$1&",EBldRateStep_Hyd_3_"&$A$1 -> EBldRateStep_Hyd_2_AFR,EBldRateStep_Hyd_3_AFR | F20: ACT,NEWFLO | H20: UC_ACT | I20: 1
C21: ="UELC-Bld_ELEHYD-step2_"&$A$1 -> UELC-Bld_ELEHYD-step2_AFR | D21: =$D$7 -> *[_]AGO*,*[_]BDI*,*[_]BEN*,*[_]BFA*,*[_]BWA*,*[_]CAF*,*[_]CIV*,*[_]CMR*,*[_]COG*,*[_]COM*,*[_]CPV*,*[_]DJI*,*[_]DZA*,*[_]EGY*,*[_]ERI*,*[_]ETH*,*[_]GAB*,*[_]GHA*,*[_]GIN*,*[_]GMB*,*[_]GNB*,*[_]GNQ*,*[_]KEN*,*[_]LBR*,*[_]LBY*,*[_]LSO*,*[_]MAR*,*[_]MDG*,*[_]MLI*,*[_]MOZ*,*[_]MRT*,*[_]MUS*,*[_]MWI*,*[_]NAM*,*[_]NER*,*[_]NGA*,*[_]RWA*,*[_]SDN*,*[_]SEN*,*[_]SLE*,*[_]SOM*,*[_]SSD*,*[_]STP*,*[_]SWZ*,*[_]SYC*,*[_]TCD*,*[_]TGO*,*[_]TUN*,*[_]TZA*,*[_]UGA*,*[_]ZAF*,*[_]ZAR*,*[_]ZMB*,*[_]ZWE* | E21: ELCHYD | H21: UC_NCAP | I21: =I15 -> 0.85 | N21: ="step 2 relaxation of build rate - ELEHYD_"&$A$1 -> step 2 relaxation of build rate - ELEHYD_AFR
D22: ="EBldRateStep_Hyd_2_"&$A$1 -> EBldRateStep_Hyd_2_AFR | F22: ACT,NEWFLO | H22: UC_ACT | I22: -1 | L22: 0 | M22: 5
C23: ="UELC-Bld_ELEHYD-step3_"&$A$1 -> UELC-Bld_ELEHYD-step3_AFR | D23: =$D$7 -> *[_]AGO*,*[_]BDI*,*[_]BEN*,*[_]BFA*,*[_]BWA*,*[_]CAF*,*[_]CIV*,*[_]CMR*,*[_]COG*,*[_]COM*,*[_]CPV*,*[_]DJI*,*[_]DZA*,*[_]EGY*,*[_]ERI*,*[_]ETH*,*[_]GAB*,*[_]GHA*,*[_]GIN*,*[_]GMB*,*[_]GNB*,*[_]GNQ*,*[_]KEN*,*[_]LBR*,*[_]LBY*,*[_]LSO*,*[_]MAR*,*[_]MDG*,*[_]MLI*,*[_]MOZ*,*[_]MRT*,*[_]MUS*,*[_]MWI*,*[_]NAM*,*[_]NER*,*[_]NGA*,*[_]RWA*,*[_]SDN*,*[_]SEN*,*[_]SLE*,*[_]SOM*,*[_]SSD*,*[_]STP*,*[_]SWZ*,*[_]SYC*,*[_]TCD*,*[_]TGO*,*[_]TUN*,*[_]TZA*,*[_]UGA*,*[_]ZAF*,*[_]ZAR*,*[_]ZMB*,*[_]ZWE* | E23: ELCHYD | H23: UC_NCAP | I23: =I17 -> 1 | N23: ="step 3 relaxation of build rate - ELEHYD_"&$A$1 -> step 3 relaxation of build rate - ELEHYD_AFR
D24: ="EBldRateStep_Hyd_3_"&$A$1 -> EBldRateStep_Hyd_3_AFR | F24: ACT,NEWFLO | H24: UC_ACT | I24: -1 | L24: 0 | M24: 5
A25: wn | C25: ="UELC-Inv"&RIGHT(HistoricalBuilds!$N$1,2)&"_"&A25&"_"&$A$1 -> UELC-Inv19_wn_AFR | D25: =$D$7 -> *[_]AGO*,*[_]BDI*,*[_]BEN*,*[_]BFA*,*[_]BWA*,*[_]CAF*,*[_]CIV*,*[_]CMR*,*[_]COG*,*[_]COM*,*[_]CPV*,*[_]DJI*,*[_]DZA*,*[_]EGY*,*[_]ERI*,*[_]ETH*,*[_]GAB*,*[_]GHA*,*[_]GIN*,*[_]GMB*,*[_]GNB*,*[_]GNQ*,*[_]KEN*,*[_]LBR*,*[_]LBY*,*[_]LSO*,*[_]MAR*,*[_]MDG*,*[_]MLI*,*[_]MOZ*,*[_]MRT*,*[_]MUS*,*[_]MWI*,*[_]NAM*,*[_]NER*,*[_]NGA*,*[_]RWA*,*[_]SDN*,*[_]SEN*,*[_]SLE*,*[_]SOM*,*[_]SSD*,*[_]STP*,*[_]SWZ*,*[_]SYC*,*[_]TCD*,*[_]TGO*,*[_]TUN*,*[_]TZA*,*[_]UGA*,*[_]ZAF*,*[_]ZAR*,*[_]ZMB*,*[_]ZWE* | E25: ELCWIN | G25: UP | J25: 1 | L25: =SUMIFS(HistoricalBuilds!$C$2:$C$300,HistoricalBuilds!$A$2:$A$300,AFR!A$1,HistoricalBuilds!$B$2:$B$300,AFR!$A25)*$L$1 -> 0.920831 | M25: 4
A26: sl | C26: ="UELC-Inv"&RIGHT(HistoricalBuilds!$N$1,2)&"_"&A26&"_"&$A$1 -> UELC-Inv19_sl_AFR | D26: =$D$7 -> *[_]AGO*,*[_]BDI*,*[_]BEN*,*[_]BFA*,*[_]BWA*,*[_]CAF*,*[_]CIV*,*[_]CMR*,*[_]COG*,*[_]COM*,*[_]CPV*,*[_]DJI*,*[_]DZA*,*[_]EGY*,*[_]ERI*,*[_]ETH*,*[_]GAB*,*[_]GHA*,*[_]GIN*,*[_]GMB*,*[_]GNB*,*[_]GNQ*,*[_]KEN*,*[_]LBR*,*[_]LBY*,*[_]LSO*,*[_]MAR*,*[_]MDG*,*[_]MLI*,*[_]MOZ*,*[_]MRT*,*[_]MUS*,*[_]MWI*,*[_]NAM*,*[_]NER*,*[_]NGA*,*[_]RWA*,*[_]SDN*,*[_]SEN*,*[_]SLE*,*[_]SOM*,*[_]SSD*,*[_]STP*,*[_]SWZ*,*[_]SYC*,*[_]TCD*,*[_]TGO*,*[_]TUN*,*[_]TZA*,*[_]UGA*,*[_]ZAF*,*[_]ZAR*,*[_]ZMB*,*[_]ZWE* | E26: ELCSOL | G26: UP | J26: 1 | L26: =SUMIFS(HistoricalBuilds!$C$2:$C$300,HistoricalBuilds!$A$2:$A$300,AFR!A$1,HistoricalBuilds!$B$2:$B$300,AFR!$A26)*$L$1 -> 1.872644 | M26: 4
A27: he | C27: ="UELC-Inv"&RIGHT(HistoricalBuilds!$N$1,2)&"_"&A27&"_"&$A$1 -> UELC-Inv19_he_AFR | D27: =$D$7 -> *[_]AGO*,*[_]BDI*,*[_]BEN*,*[_]BFA*,*[_]BWA*,*[_]CAF*,*[_]CIV*,*[_]CMR*,*[_]COG*,*[_]COM*,*[_]CPV*,*[_]DJI*,*[_]DZA*,*[_]EGY*,*[_]ERI*,*[_]ETH*,*[_]GAB*,*[_]GHA*,*[_]GIN*,*[_]GMB*,*[_]GNB*,*[_]GNQ*,*[_]KEN*,*[_]LBR*,*[_]LBY*,*[_]LSO*,*[_]MAR*,*[_]MDG*,*[_]MLI*,*[_]MOZ*,*[_]MRT*,*[_]MUS*,*[_]MWI*,*[_]NAM*,*[_]NER*,*[_]NGA*,*[_]RWA*,*[_]SDN*,*[_]SEN*,*[_]SLE*,*[_]SOM*,*[_]SSD*,*[_]STP*,*[_]SWZ*,*[_]SYC*,*[_]TCD*,*[_]TGO*,*[_]TUN*,*[_]TZA*,*[_]UGA*,*[_]ZAF*,*[_]ZAR*,*[_]ZMB*,*[_]ZWE* | E27: ELCHYD | G27: UP | J27: 1 | L27: =SUMIFS(HistoricalBuilds!$C$2:$C$300,HistoricalBuilds!$A$2:$A$300,AFR!A$1,HistoricalBuilds!$B$2:$B$300,AFR!$A27)*$L$1 -> 4.125 | M27: 4

Sheet CSA
A1: =MID(CELL( "filename",A1),FIND("]",CELL( "filename",A1))+1,10) -> CSA | L1: =AFR!$L$1 -> 1
C2: ~UC_Sets: R_S: AllRegions
C3: ~UC_Sets: T_E:
H5: ="~UC_T: UC_RHST~LO~"&HistoricalBuilds!$N$1 -> ~UC_T: UC_RHST~LO~2019
C6: UC_N | D6: PSET_PN | E6: Pset_CI | F6: UC_ATTR | G6: LimType | H6: Attribute | I6: LHS | J6: UC_NCAP | K6: UC_NCAP~RHS | L6: UC_RHST | M6: UC_RHST~0 | N6: UC_Desc
C7: ="UELC-Bld_ELEWIN_"&$A$1 -> UELC-Bld_ELEWIN_CSA | D7: =VLOOKUP("1"&$A$1,'WEPSReg-Countrymap'!$D$2:$E$232,2,FALSE) -> *[_]ABW*,*[_]ANT*,*[_]ARG*,*[_]ATG*,*[_]BHS*,*[_]BLZ*,*[_]BMU*,*[_]BOL*,*[_]BRB*,*[_]CHL*,*[_]CRI*,*[_]CUB*,*[_]CUW*,*[_]CYM*,*[_]DMA*,*[_]DOM*,*[_]ECU*,*[_]GRD*,*[_]GTM*,*[_]GUF*,*[_]GUY*,*[_]HND*,*[_]HTI*,*[_]JAM*,*[_]KNA*,*[_]LCA*,*[_]MAF*,*[_]MSR*,*[_]NIC*,*[_]PAN*,*[_]PER*,*[_]PRY*,*[_]SLV*,*[_]SUR*,*[_]SXM*,*[_]TCA*,*[_]TTO*,*[_]URY*,*[_]VCT*,*[_]VEN*,*[_]PRI*,*[_]VIR*,*[_]CHL*,*[_]COL* | E7: ELCWIN | F7: NCAP,GROWTH | J7: 1.15 | K7: 1 | L7: 0 | M7: 5 | N7: ="Annual build rate (GW/Year) of ELEWIN_"&$A$1 -> Annual build rate (GW/Year) of ELEWIN_CSA
D8: ="EBldRateStep_Win_2_"&$A$1&",EBldRateStep_Win_3_"&$A$1 -> EBldRateStep_Win_2_CSA,EBldRateStep_Win_3_CSA | F8: ACT,NEWFLO | H8: UC_ACT | I8: 1
C9: ="UELC-Bld_ELEWIN-step2_"&$A$1 -> UELC-Bld_ELEWIN-step2_CSA | D9: =$D$7 -> *[_]ABW*,*[_]ANT*,*[_]ARG*,*[_]ATG*,*[_]BHS*,*[_]BLZ*,*[_]BMU*,*[_]BOL*,*[_]BRB*,*[_]CHL*,*[_]CRI*,*[_]CUB*,*[_]CUW*,*[_]CYM*,*[_]DMA*,*[_]DOM*,*[_]ECU*,*[_]GRD*,*[_]GTM*,*[_]GUF*,*[_]GUY*,*[_]HND*,*[_]HTI*,*[_]JAM*,*[_]KNA*,*[_]LCA*,*[_]MAF*,*[_]MSR*,*[_]NIC*,*[_]PAN*,*[_]PER*,*[_]PRY*,*[_]SLV*,*[_]SUR*,*[_]SXM*,*[_]TCA*,*[_]TTO*,*[_]URY*,*[_]VCT*,*[_]VEN*,*[_]PRI*,*[_]VIR*,*[_]CHL*,*[_]COL* | E9: ELCWIN | H9: UC_NCAP | I9: 0.85 | N9: ="step 2 relaxation of build rate - ELEWIN_"&$A$1 -> step 2 relaxation of build rate - ELEWIN_CSA
D10: ="EBldRateStep_Win_2_"&$A$1 -> EBldRateStep_Win_2_CSA | F10: ACT,NEWFLO | H10: UC_ACT | I10: -1 | L10: 0 | M10: 5
C11: ="UELC-Bld_ELEWIN-step3_"&$A$1 -> UELC-Bld_ELEWIN-step3_CSA | D11: =$D$7 -> *[_]ABW*,*[_]ANT*,*[_]ARG*,*[_]ATG*,*[_]BHS*,*[_]BLZ*,*[_]BMU*,*[_]BOL*,*[_]BRB*,*[_]CHL*,*[_]CRI*,*[_]CUB*,*[_]CUW*,*[_]CYM*,*[_]DMA*,*[_]DOM*,*[_]ECU*,*[_]GRD*,*[_]GTM*,*[_]GUF*,*[_]GUY*,*[_]HND*,*[_]HTI*,*[_]JAM*,*[_]KNA*,*[_]LCA*,*[_]MAF*,*[_]MSR*,*[_]NIC*,*[_]PAN*,*[_]PER*,*[_]PRY*,*[_]SLV*,*[_]SUR*,*[_]SXM*,*[_]TCA*,*[_]TTO*,*[_]URY*,*[_]VCT*,*[_]VEN*,*[_]PRI*,*[_]VIR*,*[_]CHL*,*[_]COL* | E11: ELCWIN | H11: UC_NCAP | I11: 1 | N11: ="step 3 relaxation of build rate - ELEWIN_"&$A$1 -> step 3 relaxation of build rate - ELEWIN_CSA
D12: ="EBldRateStep_Win_3_"&$A$1 -> EBldRateStep_Win_3_CSA | F12: ACT,NEWFLO | H12: UC_ACT | I12: -1 | L12: 0 | M12: 5
C13: ="UELC-Bld_ELESOL_"&$A$1 -> UELC-Bld_ELESOL_CSA | D13: =$D$7 -> *[_]ABW*,*[_]ANT*,*[_]ARG*,*[_]ATG*,*[_]BHS*,*[_]BLZ*,*[_]BMU*,*[_]BOL*,*[_]BRB*,*[_]CHL*,*[_]CRI*,*[_]CUB*,*[_]CUW*,*[_]CYM*,*[_]DMA*,*[_]DOM*,*[_]ECU*,*[_]GRD*,*[_]GTM*,*[_]GUF*,*[_]GUY*,*[_]HND*,*[_]HTI*,*[_]JAM*,*[_]KNA*,*[_]LCA*,*[_]MAF*,*[_]MSR*,*[_]NIC*,*[_]PAN*,*[_]PER*,*[_]PRY*,*[_]SLV*,*[_]SUR*,*[_]SXM*,*[_]TCA*,*[_]TTO*,*[_]URY*,*[_]VCT*,*[_]VEN*,*[_]PRI*,*[_]VIR*,*[_]CHL*,*[_]COL* | E13: ELCSOL | F13: NCAP,GROWTH | J13: 1.15 | K13: 1 | L13: 0 | M13: 5 | N13: ="Annual build rate (GW/Year) of ELESOL_"&$A$1 -> Annual build rate (GW/Year) of ELESOL_CSA
D14: ="EBldRateStep_Sol_2_"&$A$1&",EBldRateStep_Sol_3_"&$A$1 -> EBldRateStep_Sol_2_CSA,EBldRateStep_Sol_3_CSA | F14: ACT,NEWFLO | H14: UC_ACT | I14: 1
C15: ="UELC-Bld_ELESOL-step2_"&$A$1 -> UELC-Bld_ELESOL-step2_CSA | D15: =$D$7 -> *[_]ABW*,*[_]ANT*,*[_]ARG*,*[_]ATG*,*[_]BHS*,*[_]BLZ*,*[_]BMU*,*[_]BOL*,*[_]BRB*,*[_]CHL*,*[_]CRI*,*[_]CUB*,*[_]CUW*,*[_]CYM*,*[_]DMA*,*[_]DOM*,*[_]ECU*,*[_]GRD*,*[_]GTM*,*[_]GUF*,*[_]GUY*,*[_]HND*,*[_]HTI*,*[_]JAM*,*[_]KNA*,*[_]LCA*,*[_]MAF*,*[_]MSR*,*[_]NIC*,*[_]PAN*,*[_]PER*,*[_]PRY*,*[_]SLV*,*[_]SUR*,*[_]SXM*,*[_]TCA*,*[_]TTO*,*[_]URY*,*[_]VCT*,*[_]VEN*,*[_]PRI*,*[_]VIR*,*[_]CHL*,*[_]COL* | E15: ELCSOL | H15: UC_NCAP | I15: =I9 -> 0.85 | N15: ="step 2 relaxation of build rate - ELESOL_"&$A$1 -> step 2 relaxation of build rate - ELESOL_CSA
D16: ="EBldRateStep_Sol_2_"&$A$1 -> EBldRateStep_Sol_2_CSA | F16: ACT,NEWFLO | H16: UC_ACT | I16: -1 | L16: 0 | M16: 5
C17: ="UELC-Bld_ELESOL-step3_"&$A$1 -> UELC-Bld_ELESOL-step3_CSA | D17: =$D$7 -> *[_]ABW*,*[_]ANT*,*[_]ARG*,*[_]ATG*,*[_]BHS*,*[_]BLZ*,*[_]BMU*,*[_]BOL*,*[_]BRB*,*[_]CHL*,*[_]CRI*,*[_]CUB*,*[_]CUW*,*[_]CYM*,*[_]DMA*,*[_]DOM*,*[_]ECU*,*[_]GRD*,*[_]GTM*,*[_]GUF*,*[_]GUY*,*[_]HND*,*[_]HTI*,*[_]JAM*,*[_]KNA*,*[_]LCA*,*[_]MAF*,*[_]MSR*,*[_]NIC*,*[_]PAN*,*[_]PER*,*[_]PRY*,*[_]SLV*,*[_]SUR*,*[_]SXM*,*[_]TCA*,*[_]TTO*,*[_]URY*,*[_]VCT*,*[_]VEN*,*[_]PRI*,*[_]VIR*,*[_]CHL*,*[_]COL* | E17: ELCSOL | H17: UC_NCAP | I17: =I11 -> 1 | N17: ="step 3 relaxation of build rate - ELESOL_"&$A$1 -> step 3 relaxation of build rate - ELESOL_CSA
D18: ="EBldRateStep_Sol_3_"&$A$1 -> EBldRateStep_Sol_3_CSA | F18: ACT,NEWFLO | H18: UC_ACT | I18: -1 | L18: 0 | M18: 5
C19: ="UELC-Bld_ELEHYD_"&$A$1 -> UELC-Bld_ELEHYD_CSA | D19: =$D$7 -> *[_]ABW*,*[_]ANT*,*[_]ARG*,*[_]ATG*,*[_]BHS*,*[_]BLZ*,*[_]BMU*,*[_]BOL*,*[_]BRB*,*[_]CHL*,*[_]CRI*,*[_]CUB*,*[_]CUW*,*[_]CYM*,*[_]DMA*,*[_]DOM*,*[_]ECU*,*[_]GRD*,*[_]GTM*,*[_]GUF*,*[_]GUY*,*[_]HND*,*[_]HTI*,*[_]JAM*,*[_]KNA*,*[_]LCA*,*[_]MAF*,*[_]MSR*,*[_]NIC*,*[_]PAN*,*[_]PER*,*[_]PRY*,*[_]SLV*,*[_]SUR*,*[_]SXM*,*[_]TCA*,*[_]TTO*,*[_]URY*,*[_]VCT*,*[_]VEN*,*[_]PRI*,*[_]VIR*,*[_]CHL*,*[_]COL* | E19: ELCHYD | F19: NCAP,GROWTH | J19: 1.15 | K19: 1 | L19: 0 | M19: 5 | N19: ="Annual build rate (GW/Year) of ELEHYD_"&$A$1 -> Annual build rate (GW/Year) of ELEHYD_CSA
D20: ="EBldRateStep_Hyd_2_"&$A$1&",EBldRateStep_Hyd_3_"&$A$1 -> EBldRateStep_Hyd_2_CSA,EBldRateStep_Hyd_3_CSA | F20: ACT,NEWFLO | H20: UC_ACT | I20: 1
C21: ="UELC-Bld_ELEHYD-step2_"&$A$1 -> UELC-Bld_ELEHYD-step2_CSA | D21: =$D$7 -> *[_]ABW*,*[_]ANT*,*[_]ARG*,*[_]ATG*,*[_]BHS*,*[_]BLZ*,*[_]BMU*,*[_]BOL*,*[_]BRB*,*[_]CHL*,*[_]CRI*,*[_]CUB*,*[_]CUW*,*[_]CYM*,*[_]DMA*,*[_]DOM*,*[_]ECU*,*[_]GRD*,*[_]GTM*,*[_]GUF*,*[_]GUY*,*[_]HND*,*[_]HTI*,*[_]JAM*,*[_]KNA*,*[_]LCA*,*[_]MAF*,*[_]MSR*,*[_]NIC*,*[_]PAN*,*[_]PER*,*[_]PRY*,*[_]SLV*,*[_]SUR*,*[_]SXM*,*[_]TCA*,*[_]TTO*,*[_]URY*,*[_]VCT*,*[_]VEN*,*[_]PRI*,*[_]VIR*,*[_]CHL*,*[_]COL* | E21: ELCHYD | H21: UC_NCAP | I21: =I15 -> 0.85 | N21: ="step 2 relaxation of build rate - ELEHYD_"&$A$1 -> step 2 relaxation of build rate - ELEHYD_CSA
D22: ="EBldRateStep_Hyd_2_"&$A$1 -> EBldRateStep_Hyd_2_CSA | F22: ACT,NEWFLO | H22: UC_ACT | I22: -1 | L22: 0 | M22: 5
C23: ="UELC-Bld_ELEHYD-step3_"&$A$1 -> UELC-Bld_ELEHYD-step3_CSA | D23: =$D$7 -> *[_]ABW*,*[_]ANT*,*[_]ARG*,*[_]ATG*,*[_]BHS*,*[_]BLZ*,*[_]BMU*,*[_]BOL*,*[_]BRB*,*[_]CHL*,*[_]CRI*,*[_]CUB*,*[_]CUW*,*[_]CYM*,*[_]DMA*,*[_]DOM*,*[_]ECU*,*[_]GRD*,*[_]GTM*,*[_]GUF*,*[_]GUY*,*[_]HND*,*[_]HTI*,*[_]JAM*,*[_]KNA*,*[_]LCA*,*[_]MAF*,*[_]MSR*,*[_]NIC*,*[_]PAN*,*[_]PER*,*[_]PRY*,*[_]SLV*,*[_]SUR*,*[_]SXM*,*[_]TCA*,*[_]TTO*,*[_]URY*,*[_]VCT*,*[_]VEN*,*[_]PRI*,*[_]VIR*,*[_]CHL*,*[_]COL* | E23: ELCHYD | H23: UC_NCAP | I23: =I17 -> 1 | N23: ="step 3 relaxation of build rate - ELEHYD_"&$A$1 -> step 3 relaxation of build rate - ELEHYD_CSA
D24: ="EBldRateStep_Hyd_3_"&$A$1 -> EBldRateStep_Hyd_3_CSA | F24: ACT,NEWFLO | H24: UC_ACT | I24: -1 | L24: 0 | M24: 5
A25: wn | C25: ="UELC-Inv"&RIGHT(HistoricalBuilds!$N$1,2)&"_"&A25&"_"&$A$1 -> UELC-Inv19_wn_CSA | D25: =$D$7 -> *[_]ABW*,*[_]ANT*,*[_]ARG*,*[_]ATG*,*[_]BHS*,*[_]BLZ*,*[_]BMU*,*[_]BOL*,*[_]BRB*,*[_]CHL*,*[_]CRI*,*[_]CUB*,*[_]CUW*,*[_]CYM*,*[_]DMA*,*[_]DOM*,*[_]ECU*,*[_]GRD*,*[_]GTM*,*[_]GUF*,*[_]GUY*,*[_]HND*,*[_]HTI*,*[_]JAM*,*[_]KNA*,*[_]LCA*,*[_]MAF*,*[_]MSR*,*[_]NIC*,*[_]PAN*,*[_]PER*,*[_]PRY*,*[_]SLV*,*[_]SUR*,*[_]SXM*,*[_]TCA*,*[_]TTO*,*[_]URY*,*[_]VCT*,*[_]VEN*,*[_]PRI*,*[_]VIR*,*[_]CHL*,*[_]COL* | E25: ELCWIN | G25: UP | J25: 1 | L25: =SUMIFS(HistoricalBuilds!$C$2:$C$300,HistoricalBuilds!$A$2:$A$300,CSA!A$1,HistoricalBuilds!$B$2:$B$300,CSA!$A25)*$L$1 -> 0.8457 | M25: 4
A26: sl | C26: ="UELC-Inv"&RIGHT(HistoricalBuilds!$N$1,2)&"_"&A26&"_"&$A$1 -> UELC-Inv19_sl_CSA | D26: =$D$7 -> *[_]ABW*,*[_]ANT*,*[_]ARG*,*[_]ATG*,*[_]BHS*,*[_]BLZ*,*[_]BMU*,*[_]BOL*,*[_]BRB*,*[_]CHL*,*[_]CRI*,*[_]CUB*,*[_]CUW*,*[_]CYM*,*[_]DMA*,*[_]DOM*,*[_]ECU*,*[_]GRD*,*[_]GTM*,*[_]GUF*,*[_]GUY*,*[_]HND*,*[_]HTI*,*[_]JAM*,*[_]KNA*,*[_]LCA*,*[_]MAF*,*[_]MSR*,*[_]NIC*,*[_]PAN*,*[_]PER*,*[_]PRY*,*[_]SLV*,*[_]SUR*,*[_]SXM*,*[_]TCA*,*[_]TTO*,*[_]URY*,*[_]VCT*,*[_]VEN*,*[_]PRI*,*[_]VIR*,*[_]CHL*,*[_]COL* | E26: ELCSOL | G26: UP | J26: 1 | L26: =SUMIFS(HistoricalBuilds!$C$2:$C$300,HistoricalBuilds!$A$2:$A$300,CSA!A$1,HistoricalBuilds!$B$2:$B$300,CSA!$A26)*$L$1 -> 0.724019 | M26: 4
A27: he | C27: ="UELC-Inv"&RIGHT(HistoricalBuilds!$N$1,2)&"_"&A27&"_"&$A$1 -> UELC-Inv19_he_CSA | D27: =$D$7 -> *[_]ABW*,*[_]ANT*,*[_]ARG*,*[_]ATG*,*[_]BHS*,*[_]BLZ*,*[_]BMU*,*[_]BOL*,*[_]BRB*,*[_]CHL*,*[_]CRI*,*[_]CUB*,*[_]CUW*,*[_]CYM*,*[_]DMA*,*[_]DOM*,*[_]ECU*,*[_]GRD*,*[_]GTM*,*[_]GUF*,*[_]GUY*,*[_]HND*,*[_]HTI*,*[_]JAM*,*[_]KNA*,*[_]LCA*,*[_]MAF*,*[_]MSR*,*[_]NIC*,*[_]PAN*,*[_]PER*,*[_]PRY*,*[_]SLV*,*[_]SUR*,*[_]SXM*,*[_]TCA*,*[_]TTO*,*[_]URY*,*[_]VCT*,*[_]VEN*,*[_]PRI*,*[_]VIR*,*[_]CHL*,*[_]COL* | E27: ELCHYD | G27: UP | J27: 1 | L27: =SUMIFS(HistoricalBuilds!$C$2:$C$300,HistoricalBuilds!$A$2:$A$300,CSA!A$1,HistoricalBuilds!$B$2:$B$300,CSA!$A27)*$L$1 -> 4.403 | M27: 4

Sheet EUR
A1: =MID(CELL( "filename",A1),FIND("]",CELL( "filename",A1))+1,10) -> EUR | L1: =AFR!$L$1 -> 1
C2: ~UC_Sets: R_S: AllRegions
C3: ~UC_Sets: T_E:
H5: ="~UC_T: UC_RHST~LO~"&HistoricalBuilds!$N$1 -> ~UC_T: UC_RHST~LO~2019
C6: UC_N | D6: PSET_PN | E6: Pset_CI | F6: UC_ATTR | G6: LimType | H6: Attribute | I6: LHS | J6: UC_NCAP | K6: UC_NCAP~RHS | L6: UC_RHST | M6: UC_RHST~0 | N6: UC_Desc
C7: ="UELC-Bld_ELEWIN_"&$A$1 -> UELC-Bld_ELEWIN_EUR | D7: =VLOOKUP("1"&$A$1,'WEPSReg-Countrymap'!$D$2:$E$232,2,FALSE) -> *[_]ADO*,*[_]AUT*,*[_]BEL*,*[_]CHE*,*[_]CZE*,*[_]DEU*,*[_]DNK*,*[_]ESP*,*[_]EST*,*[_]FIN*,*[_]FRA*,*[_]GBR*,*[_]GIB*,*[_]GRC*,*[_]GRL*,*[_]HUN*,*[_]IMY*,*[_]IRL*,*[_]ISL*,*[_]ISR*,*[_]ITA*,*[_]LUX*,*[_]MCO*,*[_]NLD*,*[_]NOR*,*[_]POL*,*[_]PRT*,*[_]SMR*,*[_]SVK*,*[_]SVN*,*[_]SWE*,*[_]TUR*,*[_]VAT* | E7: ELCWIN | F7: NCAP,GROWTH | J7: 1.15 | K7: 1 | L7: 0 | M7: 5 | N7: ="Annual build rate (GW/Year) of ELEWIN_"&$A$1 -> Annual build rate (GW/Year) of ELEWIN_EUR
D8: ="EBldRateStep_Win_2_"&$A$1&",EBldRateStep_Win_3_"&$A$1 -> EBldRateStep_Win_2_EUR,EBldRateStep_Win_3_EUR | F8: ACT,NEWFLO | H8: UC_ACT | I8: 1
C9: ="UELC-Bld_ELEWIN-step2_"&$A$1 -> UELC-Bld_ELEWIN-step2_EUR | D9: =$D$7 -> *[_]ADO*,*[_]AUT*,*[_]BEL*,*[_]CHE*,*[_]CZE*,*[_]DEU*,*[_]DNK*,*[_]ESP*,*[_]EST*,*[_]FIN*,*[_]FRA*,*[_]GBR*,*[_]GIB*,*[_]GRC*,*[_]GRL*,*[_]HUN*,*[_]IMY*,*[_]IRL*,*[_]ISL*,*[_]ISR*,*[_]ITA*,*[_]LUX*,*[_]MCO*,*[_]NLD*,*[_]NOR*,*[_]POL*,*[_]PRT*,*[_]SMR*,*[_]SVK*,*[_]SVN*,*[_]SWE*,*[_]TUR*,*[_]VAT* | E9: ELCWIN | H9: UC_NCAP | I9: 0.85 | N9: ="step 2 relaxation of build rate - ELEWIN_"&$A$1 -> step 2 relaxation of build rate - ELEWIN_EUR
D10: ="EBldRateStep_Win_2_"&$A$1 -> EBldRateStep_Win_2_EUR | F10: ACT,NEWFLO | H10: UC_ACT | I10: -1 | L10: 0 | M10: 5
C11: ="UELC-Bld_ELEWIN-step3_"&$A$1 -> UELC-Bld_ELEWIN-step3_EUR | D11: =$D$7 -> *[_]ADO*,*[_]AUT*,*[_]BEL*,*[_]CHE*,*[_]CZE*,*[_]DEU*,*[_]DNK*,*[_]ESP*,*[_]EST*,*[_]FIN*,*[_]FRA*,*[_]GBR*,*[_]GIB*,*[_]GRC*,*[_]GRL*,*[_]HUN*,*[_]IMY*,*[_]IRL*,*[_]ISL*,*[_]ISR*,*[_]ITA*,*[_]LUX*,*[_]MCO*,*[_]NLD*,*[_]NOR*,*[_]POL*,*[_]PRT*,*[_]SMR*,*[_]SVK*,*[_]SVN*,*[_]SWE*,*[_]TUR*,*[_]VAT* | E11: ELCWIN | H11: UC_NCAP | I11: 1 | N11: ="step 3 relaxation of build rate - ELEWIN_"&$A$1 -> step 3 relaxation of build rate - ELEWIN_EUR
D12: ="EBldRateStep_Win_3_"&$A$1 -> EBldRateStep_Win_3_EUR | F12: ACT,NEWFLO | H12: UC_ACT | I12: -1 | L12: 0 | M12: 5
C13: ="UELC-Bld_ELESOL_"&$A$1 -> UELC-Bld_ELESOL_EUR | D13: =$D$7 -> *[_]ADO*,*[_]AUT*,*[_]BEL*,*[_]CHE*,*[_]CZE*,*[_]DEU*,*[_]DNK*,*[_]ESP*,*[_]EST*,*[_]FIN*,*[_]FRA*,*[_]GBR*,*[_]GIB*,*[_]GRC*,*[_]GRL*,*[_]HUN*,*[_]IMY*,*[_]IRL*,*[_]ISL*,*[_]ISR*,*[_]ITA*,*[_]LUX*,*[_]MCO*,*[_]NLD*,*[_]NOR*,*[_]POL*,*[_]PRT*,*[_]SMR*,*[_]SVK*,*[_]SVN*,*[_]SWE*,*[_]TUR*,*[_]VAT* | E13: ELCSOL | F13: NCAP,GROWTH | J13: 1.15 | K13: 1 | L13: 0 | M13: 5 | N13: ="Annual build rate (GW/Year) of ELESOL_"&$A$1 -> Annual build rate (GW/Year) of ELESOL_EUR
D14: ="EBldRateStep_Sol_2_"&$A$1&",EBldRateStep_Sol_3_"&$A$1 -> EBldRateStep_Sol_2_EUR,EBldRateStep_Sol_3_EUR | F14: ACT,NEWFLO | H14: UC_ACT | I14: 1
C15: ="UELC-Bld_ELESOL-step2_"&$A$1 -> UELC-Bld_ELESOL-step2_EUR | D15: =$D$7 -> *[_]ADO*,*[_]AUT*,*[_]BEL*,*[_]CHE*,*[_]CZE*,*[_]DEU*,*[_]DNK*,*[_]ESP*,*[_]EST*,*[_]FIN*,*[_]FRA*,*[_]GBR*,*[_]GIB*,*[_]GRC*,*[_]GRL*,*[_]HUN*,*[_]IMY*,*[_]IRL*,*[_]ISL*,*[_]ISR*,*[_]ITA*,*[_]LUX*,*[_]MCO*,*[_]NLD*,*[_]NOR*,*[_]POL*,*[_]PRT*,*[_]SMR*,*[_]SVK*,*[_]SVN*,*[_]SWE*,*[_]TUR*,*[_]VAT* | E15: ELCSOL | H15: UC_NCAP | I15: =I9 -> 0.85 | N15: ="step 2 relaxation of build rate - ELESOL_"&$A$1 -> step 2 relaxation of build rate - ELESOL_EUR
D16: ="EBldRateStep_Sol_2_"&$A$1 -> EBldRateStep_Sol_2_EUR | F16: ACT,NEWFLO | H16: UC_ACT | I16: -1 | L16: 0 | M16: 5
C17: ="UELC-Bld_ELESOL-step3_"&$A$1 -> UELC-Bld_ELESOL-step3_EUR | D17: =$D$7 -> *[_]ADO*,*[_]AUT*,*[_]BEL*,*[_]CHE*,*[_]CZE*,*[_]DEU*,*[_]DNK*,*[_]ESP*,*[_]EST*,*[_]FIN*,*[_]FRA*,*[_]GBR*,*[_]GIB*,*[_]GRC*,*[_]GRL*,*[_]HUN*,*[_]IMY*,*[_]IRL*,*[_]ISL*,*[_]ISR*,*[_]ITA*,*[_]LUX*,*[_]MCO*,*[_]NLD*,*[_]NOR*,*[_]POL*,*[_]PRT*,*[_]SMR*,*[_]SVK*,*[_]SVN*,*[_]SWE*,*[_]TUR*,*[_]VAT* | E17: ELCSOL | H17: UC_NCAP | I17: =I11 -> 1 | N17: ="step 3 relaxation of build rate - ELESOL_"&$A$1 -> step 3 relaxation of build rate - ELESOL_EUR
D18: ="EBldRateStep_Sol_3_"&$A$1 -> EBldRateStep_Sol_3_EUR | F18: ACT,NEWFLO | H18: UC_ACT | I18: -1 | L18: 0 | M18: 5
C19: ="UELC-Bld_ELEHYD_"&$A$1 -> UELC-Bld_ELEHYD_EUR | D19: =$D$7 -> *[_]ADO*,*[_]AUT*,*[_]BEL*,*[_]CHE*,*[_]CZE*,*[_]DEU*,*[_]DNK*,*[_]ESP*,*[_]EST*,*[_]FIN*,*[_]FRA*,*[_]GBR*,*[_]GIB*,*[_]GRC*,*[_]GRL*,*[_]HUN*,*[_]IMY*,*[_]IRL*,*[_]ISL*,*[_]ISR*,*[_]ITA*,*[_]LUX*,*[_]MCO*,*[_]NLD*,*[_]NOR*,*[_]POL*,*[_]PRT*,*[_]SMR*,*[_]SVK*,*[_]SVN*,*[_]SWE*,*[_]TUR*,*[_]VAT* | E19: ELCHYD | F19: NCAP,GROWTH | J19: 1.15 | K19: 1 | L19: 0 | M19: 5 | N19: ="Annual build rate (GW/Year) of ELEHYD_"&$A$1 -> Annual build rate (GW/Year) of ELEHYD_EUR
D20: ="EBldRateStep_Hyd_2_"&$A$1&",EBldRateStep_Hyd_3_"&$A$1 -> EBldRateStep_Hyd_2_EUR,EBldRateStep_Hyd_3_EUR | F20: ACT,NEWFLO | H20: UC_ACT | I20: 1
C21: ="UELC-Bld_ELEHYD-step2_"&$A$1 -> UELC-Bld_ELEHYD-step2_EUR | D21: =$D$7 -> *[_]ADO*,*[_]AUT*,*[_]BEL*,*[_]CHE*,*[_]CZE*,*[_]DEU*,*[_]DNK*,*[_]ESP*,*[_]EST*,*[_]FIN*,*[_]FRA*,*[_]GBR*,*[_]GIB*,*[_]GRC*,*[_]GRL*,*[_]HUN*,*[_]IMY*,*[_]IRL*,*[_]ISL*,*[_]ISR*,*[_]ITA*,*[_]LUX*,*[_]MCO*,*[_]NLD*,*[_]NOR*,*[_]POL*,*[_]PRT*,*[_]SMR*,*[_]SVK*,*[_]SVN*,*[_]SWE*,*[_]TUR*,*[_]VAT* | E21: ELCHYD | H21: UC_NCAP | I21: =I15 -> 0.85 | N21: ="step 2 relaxation of build rate - ELEHYD_"&$A$1 -> step 2 relaxation of build rate - ELEHYD_EUR
D22: ="EBldRateStep_Hyd_2_"&$A$1 -> EBldRateStep_Hyd_2_EUR | F22: ACT,NEWFLO | H22: UC_ACT | I22: -1 | L22: 0 | M22: 5
C23: ="UELC-Bld_ELEHYD-step3_"&$A$1 -> UELC-Bld_ELEHYD-step3_EUR | D23: =$D$7 -> *[_]ADO*,*[_]AUT*,*[_]BEL*,*[_]CHE*,*[_]CZE*,*[_]DEU*,*[_]DNK*,*[_]ESP*,*[_]EST*,*[_]FIN*,*[_]FRA*,*[_]GBR*,*[_]GIB*,*[_]GRC*,*[_]GRL*,*[_]HUN*,*[_]IMY*,*[_]IRL*,*[_]ISL*,*[_]ISR*,*[_]ITA*,*[_]LUX*,*[_]MCO*,*[_]NLD*,*[_]NOR*,*[_]POL*,*[_]PRT*,*[_]SMR*,*[_]SVK*,*[_]SVN*,*[_]SWE*,*[_]TUR*,*[_]VAT* | E23: ELCHYD | H23: UC_NCAP | I23: =I17 -> 1 | N23: ="step 3 relaxation of build rate - ELEHYD_"&$A$1 -> step 3 relaxation of build rate - ELEHYD_EUR
D24: ="EBldRateStep_Hyd_3_"&$A$1 -> EBldRateStep_Hyd_3_EUR | F24: ACT,NEWFLO | H24: UC_ACT | I24: -1 | L24: 0 | M24: 5
A25: wn | C25: ="UELC-Inv"&RIGHT(HistoricalBuilds!$N$1,2)&"_"&A25&"_"&$A$1 -> UELC-Inv19_wn_EUR | D25: =$D$7 -> *[_]ADO*,*[_]AUT*,*[_]BEL*,*[_]CHE*,*[_]CZE*,*[_]DEU*,*[_]DNK*,*[_]ESP*,*[_]EST*,*[_]FIN*,*[_]FRA*,*[_]GBR*,*[_]GIB*,*[_]GRC*,*[_]GRL*,*[_]HUN*,*[_]IMY*,*[_]IRL*,*[_]ISL*,*[_]ISR*,*[_]ITA*,*[_]LUX*,*[_]MCO*,*[_]NLD*,*[_]NOR*,*[_]POL*,*[_]PRT*,*[_]SMR*,*[_]SVK*,*[_]SVN*,*[_]SWE*,*[_]TUR*,*[_]VAT* | E25: ELCWIN | G25: UP | J25: 1 | L25: =SUMIFS(HistoricalBuilds!$C$2:$C$300,HistoricalBuilds!$A$2:$A$300,EUR!A$1,HistoricalBuilds!$B$2:$B$300,EUR!$A25)*$L$1 -> 15.383 | M25: 4
A26: sl | C26: ="UELC-Inv"&RIGHT(HistoricalBuilds!$N$1,2)&"_"&A26&"_"&$A$1 -> UELC-Inv19_sl_EUR | D26: =$D$7 -> *[_]ADO*,*[_]AUT*,*[_]BEL*,*[_]CHE*,*[_]CZE*,*[_]DEU*,*[_]DNK*,*[_]ESP*,*[_]EST*,*[_]FIN*,*[_]FRA*,*[_]GBR*,*[_]GIB*,*[_]GRC*,*[_]GRL*,*[_]HUN*,*[_]IMY*,*[_]IRL*,*[_]ISL*,*[_]ISR*,*[_]ITA*,*[_]LUX*,*[_]MCO*,*[_]NLD*,*[_]NOR*,*[_]POL*,*[_]PRT*,*[_]SMR*,*[_]SVK*,*[_]SVN*,*[_]SWE*,*[_]TUR*,*[_]VAT* | E26: ELCSOL | G26: UP | J26: 1 | L26: =SUMIFS(HistoricalBuilds!$C$2:$C$300,HistoricalBuilds!$A$2:$A$300,EUR!A$1,HistoricalBuilds!$B$2:$B$300,EUR!$A26)*$L$1 -> 23.0605 | M26: 4
A27: he | C27: ="UELC-Inv"&RIGHT(HistoricalBuilds!$N$1,2)&"_"&A27&"_"&$A$1 -> UELC-Inv19_he_EUR | D27: =$D$7 -> *[_]ADO*,*[_]AUT*,*[_]BEL*,*[_]CHE*,*[_]CZE*,*[_]DEU*,*[_]DNK*,*[_]ESP*,*[_]EST*,*[_]FIN*,*[_]FRA*,*[_]GBR*,*[_]GIB*,*[_]GRC*,*[_]GRL*,*[_]HUN*,*[_]IMY*,*[_]IRL*,*[_]ISL*,*[_]ISR*,*[_]ITA*,*[_]LUX*,*[_]MCO*,*[_]NLD*,*[_]NOR*,*[_]POL*,*[_]PRT*,*[_]SMR*,*[_]SVK*,*[_]SVN*,*[_]SWE*,*[_]TUR*,*[_]VAT* | E27: ELCHYD | G27: UP | J27: 1 | L27: =SUMIFS(HistoricalBuilds!$C$2:$C$300,HistoricalBuilds!$A$2:$A$300,EUR!A$1,HistoricalBuilds!$B$2:$B$300,EUR!$A27)*$L$1 -> 4.711 | M27: 4

Sheet OAS
A1: =MID(CELL( "filename",A1),FIND("]",CELL( "filename",A1))+1,10) -> OAS | L1: =AFR!$L$1 -> 1
C2: ~UC_Sets: R_S: AllRegions
C3: ~UC_Sets: T_E:
H5: ="~UC_T: UC_RHST~LO~"&HistoricalBuilds!$N$1 -> ~UC_T: UC_RHST~LO~2019
C6: UC_N | D6: PSET_PN | E6: Pset_CI | F6: UC_ATTR | G6: LimType | H6: Attribute | I6: LHS | J6: UC_NCAP | K6: UC_NCAP~RHS | L6: UC_RHST | M6: UC_RHST~0 | N6: UC_Desc
C7: ="UELC-Bld_ELEWIN_"&$A$1 -> UELC-Bld_ELEWIN_OAS | D7: =VLOOKUP("1"&$A$1,'WEPSReg-Countrymap'!$D$2:$E$232,2,FALSE) -> *[_]AFG*,*[_]BGD*,*[_]BRN*,*[_]BTN*,*[_]COK*,*[_]FJI*,*[_]HKG*,*[_]IDN*,*[_]KHM*,*[_]KIR*,*[_]LAO*,*[_]LKA*,*[_]MAC*,*[_]MDV*,*[_]MHL*,*[_]MMR*,*[_]MNG*,*[_]MNP*,*[_]MYS*,*[_]NCL*,*[_]NIU*,*[_]NPL*,*[_]NRU*,*[_]PAK*,*[_]PHL*,*[_]PLW*,*[_]PNG*,*[_]PRK*,*[_]PYF*,*[_]SGP*,*[_]SLB*,*[_]THA*,*[_]TMP*,*[_]TON*,*[_]TUV*,*[_]TWN*,*[_]VNM*,*[_]VUT*,*[_]WSM*,*[_]ASM*,*[_]GUM* | E7: ELCWIN | F7: NCAP,GROWTH | J7: 1.15 | K7: 1 | L7: 0 | M7: 5 | N7: ="Annual build rate (GW/Year) of ELEWIN_"&$A$1 -> Annual build rate (GW/Year) of ELEWIN_OAS
D8: ="EBldRateStep_Win_2_"&$A$1&",EBldRateStep_Win_3_"&$A$1 -> EBldRateStep_Win_2_OAS,EBldRateStep_Win_3_OAS | F8: ACT,NEWFLO | H8: UC_ACT | I8: 1
C9: ="UELC-Bld_ELEWIN-step2_"&$A$1 -> UELC-Bld_ELEWIN-step2_OAS | D9: =$D$7 -> *[_]AFG*,*[_]BGD*,*[_]BRN*,*[_]BTN*,*[_]COK*,*[_]FJI*,*[_]HKG*,*[_]IDN*,*[_]KHM*,*[_]KIR*,*[_]LAO*,*[_]LKA*,*[_]MAC*,*[_]MDV*,*[_]MHL*,*[_]MMR*,*[_]MNG*,*[_]MNP*,*[_]MYS*,*[_]NCL*,*[_]NIU*,*[_]NPL*,*[_]NRU*,*[_]PAK*,*[_]PHL*,*[_]PLW*,*[_]PNG*,*[_]PRK*,*[_]PYF*,*[_]SGP*,*[_]SLB*,*[_]THA*,*[_]TMP*,*[_]TON*,*[_]TUV*,*[_]TWN*,*[_]VNM*,*[_]VUT*,*[_]WSM*,*[_]ASM*,*[_]GUM* | E9: ELCWIN | H9: UC_NCAP | I9: 0.85 | N9: ="step 2 relaxation of build rate - ELEWIN_"&$A$1 -> step 2 relaxation of build rate - ELEWIN_OAS
D10: ="EBldRateStep_Win_2_"&$A$1 -> EBldRateStep_Win_2_OAS | F10: ACT,NEWFLO | H10: UC_ACT | I10: -1 | L10: 0 | M10: 5
C11: ="UELC-Bld_ELEWIN-step3_"&$A$1 -> UELC-Bld_ELEWIN-step3_OAS | D11: =$D$7 -> *[_]AFG*,*[_]BGD*,*[_]BRN*,*[_]BTN*,*[_]COK*,*[_]FJI*,*[_]HKG*,*[_]IDN*,*[_]KHM*,*[_]KIR*,*[_]LAO*,*[_]LKA*,*[_]MAC*,*[_]MDV*,*[_]MHL*,*[_]MMR*,*[_]MNG*,*[_]MNP*,*[_]MYS*,*[_]NCL*,*[_]NIU*,*[_]NPL*,*[_]NRU*,*[_]PAK*,*[_]PHL*,*[_]PLW*,*[_]PNG*,*[_]PRK*,*[_]PYF*,*[_]SGP*,*[_]SLB*,*[_]THA*,*[_]TMP*,*[_]TON*,*[_]TUV*,*[_]TWN*,*[_]VNM*,*[_]VUT*,*[_]WSM*,*[_]ASM*,*[_]GUM* | E11: ELCWIN | H11: UC_NCAP | I11: 1 | N11: ="step 3 relaxation of build rate - ELEWIN_"&$A$1 -> step 3 relaxation of build rate - ELEWIN_OAS
D12: ="EBldRateStep_Win_3_"&$A$1 -> EBldRateStep_Win_3_OAS | F12: ACT,NEWFLO | H12: UC_ACT | I12: -1 | L12: 0 | M12: 5
C13: ="UELC-Bld_ELESOL_"&$A$1 -> UELC-Bld_ELESOL_OAS | D13: =$D$7 -> *[_]AFG*,*[_]BGD*,*[_]BRN*,*[_]BTN*,*[_]COK*,*[_]FJI*,*[_]HKG*,*[_]IDN*,*[_]KHM*,*[_]KIR*,*[_]LAO*,*[_]LKA*,*[_]MAC*,*[_]MDV*,*[_]MHL*,*[_]MMR*,*[_]MNG*,*[_]MNP*,*[_]MYS*,*[_]NCL*,*[_]NIU*,*[_]NPL*,*[_]NRU*,*[_]PAK*,*[_]PHL*,*[_]PLW*,*[_]PNG*,*[_]PRK*,*[_]PYF*,*[_]SGP*,*[_]SLB*,*[_]THA*,*[_]TMP*,*[_]TON*,*[_]TUV*,*[_]TWN*,*[_]VNM*,*[_]VUT*,*[_]WSM*,*[_]ASM*,*[_]GUM* | E13: ELCSOL | F13: NCAP,GROWTH | J13: 1.15 | K13: 1 | L13: 0 | M13: 5 | N13: ="Annual build rate (GW/Year) of ELESOL_"&$A$1 -> Annual build rate (GW/Year) of ELESOL_OAS
D14: ="EBldRateStep_Sol_2_"&$A$1&",EBldRateStep_Sol_3_"&$A$1 -> EBldRateStep_Sol_2_OAS,EBldRateStep_Sol_3_OAS | F14: ACT,NEWFLO | H14: UC_ACT | I14: 1
C15: ="UELC-Bld_ELESOL-step2_"&$A$1 -> UELC-Bld_ELESOL-step2_OAS | D15: =$D$7 -> *[_]AFG*,*[_]BGD*,*[_]BRN*,*[_]BTN*,*[_]COK*,*[_]FJI*,*[_]HKG*,*[_]IDN*,*[_]KHM*,*[_]KIR*,*[_]LAO*,*[_]LKA*,*[_]MAC*,*[_]MDV*,*[_]MHL*,*[_]MMR*,*[_]MNG*,*[_]MNP*,*[_]MYS*,*[_]NCL*,*[_]NIU*,*[_]NPL*,*[_]NRU*,*[_]PAK*,*[_]PHL*,*[_]PLW*,*[_]PNG*,*[_]PRK*,*[_]PYF*,*[_]SGP*,*[_]SLB*,*[_]THA*,*[_]TMP*,*[_]TON*,*[_]TUV*,*[_]TWN*,*[_]VNM*,*[_]VUT*,*[_]WSM*,*[_]ASM*,*[_]GUM* | E15: ELCSOL | H15: UC_NCAP | I15: =I9 -> 0.85 | N15: ="step 2 relaxation of build rate - ELESOL_"&$A$1 -> step 2 relaxation of build rate - ELESOL_OAS
D16: ="EBldRateStep_Sol_2_"&$A$1 -> EBldRateStep_Sol_2_OAS | F16: ACT,NEWFLO | H16: UC_ACT | I16: -1 | L16: 0 | M16: 5
C17: ="UELC-Bld_ELESOL-step3_"&$A$1 -> UELC-Bld_ELESOL-step3_OAS | D17: =$D$7 -> *[_]AFG*,*[_]BGD*,*[_]BRN*,*[_]BTN*,*[_]COK*,*[_]FJI*,*[_]HKG*,*[_]IDN*,*[_]KHM*,*[_]KIR*,*[_]LAO*,*[_]LKA*,*[_]MAC*,*[_]MDV*,*[_]MHL*,*[_]MMR*,*[_]MNG*,*[_]MNP*,*[_]MYS*,*[_]NCL*,*[_]NIU*,*[_]NPL*,*[_]NRU*,*[_]PAK*,*[_]PHL*,*[_]PLW*,*[_]PNG*,*[_]PRK*,*[_]PYF*,*[_]SGP*,*[_]SLB*,*[_]THA*,*[_]TMP*,*[_]TON*,*[_]TUV*,*[_]TWN*,*[_]VNM*,*[_]VUT*,*[_]WSM*,*[_]ASM*,*[_]GUM* | E17: ELCSOL | H17: UC_NCAP | I17: =I11 -> 1 | N17: ="step 3 relaxation of build rate - ELESOL_"&$A$1 -> step 3 relaxation of build rate - ELESOL_OAS
D18: ="EBldRateStep_Sol_3_"&$A$1 -> EBldRateStep_Sol_3_OAS | F18: ACT,NEWFLO | H18: UC_ACT | I18: -1 | L18: 0 | M18: 5
C19: ="UELC-Bld_ELEHYD_"&$A$1 -> UELC-Bld_ELEHYD_OAS | D19: =$D$7 -> *[_]AFG*,*[_]BGD*,*[_]BRN*,*[_]BTN*,*[_]COK*,*[_]FJI*,*[_]HKG*,*[_]IDN*,*[_]KHM*,*[_]KIR*,*[_]LAO*,*[_]LKA*,*[_]MAC*,*[_]MDV*,*[_]MHL*,*[_]MMR*,*[_]MNG*,*[_]MNP*,*[_]MYS*,*[_]NCL*,*[_]NIU*,*[_]NPL*,*[_]NRU*,*[_]PAK*,*[_]PHL*,*[_]PLW*,*[_]PNG*,*[_]PRK*,*[_]PYF*,*[_]SGP*,*[_]SLB*,*[_]THA*,*[_]TMP*,*[_]TON*,*[_]TUV*,*[_]TWN*,*[_]VNM*,*[_]VUT*,*[_]WSM*,*[_]ASM*,*[_]GUM* | E19: ELCHYD | F19: NCAP,GROWTH | J19: 1.15 | K19: 1 | L19: 0 | M19: 5 | N19: ="Annual build rate (GW/Year) of ELEHYD_"&$A$1 -> Annual build rate (GW/Year) of ELEHYD_OAS
D20: ="EBldRateStep_Hyd_2_"&$A$1&",EBldRateStep_Hyd_3_"&$A$1 -> EBldRateStep_Hyd_2_OAS,EBldRateStep_Hyd_3_OAS | F20: ACT,NEWFLO | H20: UC_ACT | I20: 1
C21: ="UELC-Bld_ELEHYD-step2_"&$A$1 -> UELC-Bld_ELEHYD-step2_OAS | D21: =$D$7 -> *[_]AFG*,*[_]BGD*,*[_]BRN*,*[_]BTN*,*[_]COK*,*[_]FJI*,*[_]HKG*,*[_]IDN*,*[_]KHM*,*[_]KIR*,*[_]LAO*,*[_]LKA*,*[_]MAC*,*[_]MDV*,*[_]MHL*,*[_]MMR*,*[_]MNG*,*[_]MNP*,*[_]MYS*,*[_]NCL*,*[_]NIU*,*[_]NPL*,*[_]NRU*,*[_]PAK*,*[_]PHL*,*[_]PLW*,*[_]PNG*,*[_]PRK*,*[_]PYF*,*[_]SGP*,*[_]SLB*,*[_]THA*,*[_]TMP*,*[_]TON*,*[_]TUV*,*[_]TWN*,*[_]VNM*,*[_]VUT*,*[_]WSM*,*[_]ASM*,*[_]GUM* | E21: ELCHYD | H21: UC_NCAP | I21: =I15 -> 0.85 | N21: ="step 2 relaxation of build rate - ELEHYD_"&$A$1 -> step 2 relaxation of build rate - ELEHYD_OAS
D22: ="EBldRateStep_Hyd_2_"&$A$1 -> EBldRateStep_Hyd_2_OAS | F22: ACT,NEWFLO | H22: UC_ACT | I22: -1 | L22: 0 | M22: 5
C23: ="UELC-Bld_ELEHYD-step3_"&$A$1 -> UELC-Bld_ELEHYD-step3_OAS | D23: =$D$7 -> *[_]AFG*,*[_]BGD*,*[_]BRN*,*[_]BTN*,*[_]COK*,*[_]FJI*,*[_]HKG*,*[_]IDN*,*[_]KHM*,*[_]KIR*,*[_]LAO*,*[_]LKA*,*[_]MAC*,*[_]MDV*,*[_]MHL*,*[_]MMR*,*[_]MNG*,*[_]MNP*,*[_]MYS*,*[_]NCL*,*[_]NIU*,*[_]NPL*,*[_]NRU*,*[_]PAK*,*[_]PHL*,*[_]PLW*,*[_]PNG*,*[_]PRK*,*[_]PYF*,*[_]SGP*,*[_]SLB*,*[_]THA*,*[_]TMP*,*[_]TON*,*[_]TUV*,*[_]TWN*,*[_]VNM*,*[_]VUT*,*[_]WSM*,*[_]ASM*,*[_]GUM* | E23: ELCHYD | H23: UC_NCAP | I23: =I17 -> 1 | N23: ="step 3 relaxation of build rate - ELEHYD_"&$A$1 -> step 3 relaxation of build rate - ELEHYD_OAS
D24: ="EBldRateStep_Hyd_3_"&$A$1 -> EBldRateStep_Hyd_3_OAS | F24: ACT,NEWFLO | H24: UC_ACT | I24: -1 | L24: 0 | M24: 5
A25: wn | C25: ="UELC-Inv"&RIGHT(HistoricalBuilds!$N$1,2)&"_"&A25&"_"&$A$1 -> UELC-Inv19_wn_OAS | D25: =$D$7 -> *[_]AFG*,*[_]BGD*,*[_]BRN*,*[_]BTN*,*[_]COK*,*[_]FJI*,*[_]HKG*,*[_]IDN*,*[_]KHM*,*[_]KIR*,*[_]LAO*,*[_]LKA*,*[_]MAC*,*[_]MDV*,*[_]MHL*,*[_]MMR*,*[_]MNG*,*[_]MNP*,*[_]MYS*,*[_]NCL*,*[_]NIU*,*[_]NPL*,*[_]NRU*,*[_]PAK*,*[_]PHL*,*[_]PLW*,*[_]PNG*,*[_]PRK*,*[_]PYF*,*[_]SGP*,*[_]SLB*,*[_]THA*,*[_]TMP*,*[_]TON*,*[_]TUV*,*[_]TWN*,*[_]VNM*,*[_]VUT*,*[_]WSM*,*[_]ASM*,*[_]GUM* | E25: ELCWIN | G25: UP | J25: 1 | L25: =SUMIFS(HistoricalBuilds!$C$2:$C$300,HistoricalBuilds!$A$2:$A$300,OAS!A$1,HistoricalBuilds!$B$2:$B$300,OAS!$A25)*$L$1 -> 1.0759 | M25: 4
A26: sl | C26: ="UELC-Inv"&RIGHT(HistoricalBuilds!$N$1,2)&"_"&A26&"_"&$A$1 -> UELC-Inv19_sl_OAS | D26: =$D$7 -> *[_]AFG*,*[_]BGD*,*[_]BRN*,*[_]BTN*,*[_]COK*,*[_]FJI*,*[_]HKG*,*[_]IDN*,*[_]KHM*,*[_]KIR*,*[_]LAO*,*[_]LKA*,*[_]MAC*,*[_]MDV*,*[_]MHL*,*[_]MMR*,*[_]MNG*,*[_]MNP*,*[_]MYS*,*[_]NCL*,*[_]NIU*,*[_]NPL*,*[_]NRU*,*[_]PAK*,*[_]PHL*,*[_]PLW*,*[_]PNG*,*[_]PRK*,*[_]PYF*,*[_]SGP*,*[_]SLB*,*[_]THA*,*[_]TMP*,*[_]TON*,*[_]TUV*,*[_]TWN*,*[_]VNM*,*[_]VUT*,*[_]WSM*,*[_]ASM*,*[_]GUM* | E26: ELCSOL | G26: UP | J26: 1 | L26: =SUMIFS(HistoricalBuilds!$C$2:$C$300,HistoricalBuilds!$A$2:$A$300,OAS!A$1,HistoricalBuilds!$B$2:$B$300,OAS!$A26)*$L$1 -> 3.00672 | M26: 4
A27: he | C27: ="UELC-Inv"&RIGHT(HistoricalBuilds!$N$1,2)&"_"&A27&"_"&$A$1 -> UELC-Inv19_he_OAS | D27: =$D$7 -> *[_]AFG*,*[_]BGD*,*[_]BRN*,*[_]BTN*,*[_]COK*,*[_]FJI*,*[_]HKG*,*[_]IDN*,*[_]KHM*,*[_]KIR*,*[_]LAO*,*[_]LKA*,*[_]MAC*,*[_]MDV*,*[_]MHL*,*[_]MMR*,*[_]MNG*,*[_]MNP*,*[_]MYS*,*[_]NCL*,*[_]NIU*,*[_]NPL*,*[_]NRU*,*[_]PAK*,*[_]PHL*,*[_]PLW*,*[_]PNG*,*[_]PRK*,*[_]PYF*,*[_]SGP*,*[_]SLB*,*[_]THA*,*[_]TMP*,*[_]TON*,*[_]TUV*,*[_]TWN*,*[_]VNM*,*[_]VUT*,*[_]WSM*,*[_]ASM*,*[_]GUM* | E27: ELCHYD | G27: UP | J27: 1 | L27: =SUMIFS(HistoricalBuilds!$C$2:$C$300,HistoricalBuilds!$A$2:$A$300,OAS!A$1,HistoricalBuilds!$B$2:$B$300,OAS!$A27)*$L$1 -> 5.13697 | M27: 4

Sheet ANZ
A1: =MID(CELL( "filename",A1),FIND("]",CELL( "filename",A1))+1,10) -> ANZ | L1: =AFR!$L$1 -> 1
C2: ~UC_Sets: R_S: AllRegions
C3: ~UC_Sets: T_E:
H5: ="~UC_T: UC_RHST~LO~"&HistoricalBuilds!$N$1 -> ~UC_T: UC_RHST~LO~2019
C6: UC_N | D6: PSET_PN | E6: Pset_CI | F6: UC_ATTR | G6: LimType | H6: Attribute | I6: LHS | J6: UC_NCAP | K6: UC_NCAP~RHS | L6: UC_RHST | M6: UC_RHST~0 | N6: UC_Desc
C7: ="UELC-Bld_ELEWIN_"&$A$1 -> UELC-Bld_ELEWIN_ANZ | D7: =VLOOKUP("1"&$A$1,'WEPSReg-Countrymap'!$D$2:$E$232,2,FALSE) -> *[_]AUS*,*[_]NZL* | E7: ELCWIN | F7: NCAP,GROWTH | J7: 1.15 | K7: 1 | L7: 0 | M7: 5 | N7: ="Annual build rate (GW/Year) of ELEWIN_"&$A$1 -> Annual build rate (GW/Year) of ELEWIN_ANZ
D8: ="EBldRateStep_Win_2_"&$A$1&",EBldRateStep_Win_3_"&$A$1 -> EBldRateStep_Win_2_ANZ,EBldRateStep_Win_3_ANZ | F8: ACT,NEWFLO | H8: UC_ACT | I8: 1
C9: ="UELC-Bld_ELEWIN-step2_"&$A$1 -> UELC-Bld_ELEWIN-step2_ANZ | D9: =$D$7 -> *[_]AUS*,*[_]NZL* | E9: ELCWIN | H9: UC_NCAP | I9: 0.85 | N9: ="step 2 relaxation of build rate - ELEWIN_"&$A$1 -> step 2 relaxation of build rate - ELEWIN_ANZ
D10: ="EBldRateStep_Win_2_"&$A$1 -> EBldRateStep_Win_2_ANZ | F10: ACT,NEWFLO | H10: UC_ACT | I10: -1 | L10: 0 | M10: 5
C11: ="UELC-Bld_ELEWIN-step3_"&$A$1 -> UELC-Bld_ELEWIN-step3_ANZ | D11: =$D$7 -> *[_]AUS*,*[_]NZL* | E11: ELCWIN | H11: UC_NCAP | I11: 1 | N11: ="step 3 relaxation of build rate - ELEWIN_"&$A$1 -> step 3 relaxation of build rate - ELEWIN_ANZ
D12: ="EBldRateStep_Win_3_"&$A$1 -> EBldRateStep_Win_3_ANZ | F12: ACT,NEWFLO | H12: UC_ACT | I12: -1 | L12: 0 | M12: 5
C13: ="UELC-Bld_ELESOL_"&$A$1 -> UELC-Bld_ELESOL_ANZ | D13: =$D$7 -> *[_]AUS*,*[_]NZL* | E13: ELCSOL | F13: NCAP,GROWTH | J13: 1.15 | K13: 1 | L13: 0 | M13: 5 | N13: ="Annual build rate (GW/Year) of ELESOL_"&$A$1 -> Annual build rate (GW/Year) of ELESOL_ANZ
D14: ="EBldRateStep_Sol_2_"&$A$1&",EBldRateStep_Sol_3_"&$A$1 -> EBldRateStep_Sol_2_ANZ,EBldRateStep_Sol_3_ANZ | F14: ACT,NEWFLO | H14: UC_ACT | I14: 1
C15: ="UELC-Bld_ELESOL-step2_"&$A$1 -> UELC-Bld_ELESOL-step2_ANZ | D15: =$D$7 -> *[_]AUS*,*[_]NZL* | E15: ELCSOL | H15: UC_NCAP | I15: =I9 -> 0.85 | N15: ="step 2 relaxation of build rate - ELESOL_"&$A$1 -> step 2 relaxation of build rate - ELESOL_ANZ
D16: ="EBldRateStep_Sol_2_"&$A$1 -> EBldRateStep_Sol_2_ANZ | F16: ACT,NEWFLO | H16: UC_ACT | I16: -1 | L16: 0 | M16: 5
C17: ="UELC-Bld_ELESOL-step3_"&$A$1 -> UELC-Bld_ELESOL-step3_ANZ | D17: =$D$7 -> *[_]AUS*,*[_]NZL* | E17: ELCSOL | H17: UC_NCAP | I17: =I11 -> 1 | N17: ="step 3 relaxation of build rate - ELESOL_"&$A$1 -> step 3 relaxation of build rate - ELESOL_ANZ
D18: ="EBldRateStep_Sol_3_"&$A$1 -> EBldRateStep_Sol_3_ANZ | F18: ACT,NEWFLO | H18: UC_ACT | I18: -1 | L18: 0 | M18: 5
C19: ="UELC-Bld_ELEHYD_"&$A$1 -> UELC-Bld_ELEHYD_ANZ | D19: =$D$7 -> *[_]AUS*,*[_]NZL* | E19: ELCHYD | F19: NCAP,GROWTH | J19: 1.15 | K19: 1 | L19: 0 | M19: 5 | N19: ="Annual build rate (GW/Year) of ELEHYD_"&$A$1 -> Annual build rate (GW/Year) of ELEHYD_ANZ
D20: ="EBldRateStep_Hyd_2_"&$A$1&",EBldRateStep_Hyd_3_"&$A$1 -> EBldRateStep_Hyd_2_ANZ,EBldRateStep_Hyd_3_ANZ | F20: ACT,NEWFLO | H20: UC_ACT | I20: 1
C21: ="UELC-Bld_ELEHYD-step2_"&$A$1 -> UELC-Bld_ELEHYD-step2_ANZ | D21: =$D$7 -> *[_]AUS*,*[_]NZL* | E21: ELCHYD | H21: UC_NCAP | I21: =I15 -> 0.85 | N21: ="step 2 relaxation of build rate - ELEHYD_"&$A$1 -> step 2 relaxation of build rate - ELEHYD_ANZ
D22: ="EBldRateStep_Hyd_2_"&$A$1 -> EBldRateStep_Hyd_2_ANZ | F22: ACT,NEWFLO | H22: UC_ACT | I22: -1 | L22: 0 | M22: 5
C23: ="UELC-Bld_ELEHYD-step3_"&$A$1 -> UELC-Bld_ELEHYD-step3_ANZ | D23: =$D$7 -> *[_]AUS*,*[_]NZL* | E23: ELCHYD | H23: UC_NCAP | I23: =I17 -> 1 | N23: ="step 3 relaxation of build rate - ELEHYD_"&$A$1 -> step 3 relaxation of build rate - ELEHYD_ANZ
D24: ="EBldRateStep_Hyd_3_"&$A$1 -> EBldRateStep_Hyd_3_ANZ | F24: ACT,NEWFLO | H24: UC_ACT | I24: -1 | L24: 0 | M24: 5
A25: wn | C25: ="UELC-Inv"&RIGHT(HistoricalBuilds!$N$1,2)&"_"&A25&"_"&$A$1 -> UELC-Inv19_wn_ANZ | D25: =$D$7 -> *[_]AUS*,*[_]NZL* | E25: ELCWIN | G25: UP | J25: 1 | L25: =SUMIFS(HistoricalBuilds!$C$2:$C$300,HistoricalBuilds!$A$2:$A$300,ANZ!A$1,HistoricalBuilds!$B$2:$B$300,ANZ!$A25)*$L$1 -> 3.1827 | M25: 4
A26: sl | C26: ="UELC-Inv"&RIGHT(HistoricalBuilds!$N$1,2)&"_"&A26&"_"&$A$1 -> UELC-Inv19_sl_ANZ | D26: =$D$7 -> *[_]AUS*,*[_]NZL* | E26: ELCSOL | G26: UP | J26: 1 | L26: =SUMIFS(HistoricalBuilds!$C$2:$C$300,HistoricalBuilds!$A$2:$A$300,ANZ!A$1,HistoricalBuilds!$B$2:$B$300,ANZ!$A26)*$L$1 -> 3.971 | M26: 4
A27: he | C27: ="UELC-Inv"&RIGHT(HistoricalBuilds!$N$1,2)&"_"&A27&"_"&$A$1 -> UELC-Inv19_he_ANZ | D27: =$D$7 -> *[_]AUS*,*[_]NZL* | E27: ELCHYD | G27: UP | J27: 1 | L27: =SUMIFS(HistoricalBuilds!$C$2:$C$300,HistoricalBuilds!$A$2:$A$300,ANZ!A$1,HistoricalBuilds!$B$2:$B$300,ANZ!$A27)*$L$1 -> 1.02765 | M27: 4

Sheet BRZ
A1: =MID(CELL( "filename",A1),FIND("]",CELL( "filename",A1))+1,10) -> BRZ | L1: =AFR!$L$1 -> 1
C2: ~UC_Sets: R_S: AllRegions
C3: ~UC_Sets: T_E:
H5: ="~UC_T: UC_RHST~LO~"&HistoricalBuilds!$N$1 -> ~UC_T: UC_RHST~LO~2019
C6: UC_N | D6: PSET_PN | E6: Pset_CI | F6: UC_ATTR | G6: LimType | H6: Attribute | I6: LHS | J6: UC_NCAP | K6: UC_NCAP~RHS | L6: UC_RHST | M6: UC_RHST~0 | N6: UC_Desc
C7: ="UELC-Bld_ELEWIN_"&$A$1 -> UELC-Bld_ELEWIN_BRZ | D7: =VLOOKUP("1"&$A$1,'WEPSReg-Countrymap'!$D$2:$E$232,2,FALSE) -> *[_]BRA* | E7: ELCWIN | F7: NCAP,GROWTH | J7: 1.15 | K7: 1 | L7: 0 | M7: 5 | N7: ="Annual build rate (GW/Year) of ELEWIN_"&$A$1 -> Annual build rate (GW/Year) of ELEWIN_BRZ
D8: ="EBldRateStep_Win_2_"&$A$1&",EBldRateStep_Win_3_"&$A$1 -> EBldRateStep_Win_2_BRZ,EBldRateStep_Win_3_BRZ | F8: ACT,NEWFLO | H8: UC_ACT | I8: 1
C9: ="UELC-Bld_ELEWIN-step2_"&$A$1 -> UELC-Bld_ELEWIN-step2_BRZ | D9: =$D$7 -> *[_]BRA* | E9: ELCWIN | H9: UC_NCAP | I9: 0.85 | N9: ="step 2 relaxation of build rate - ELEWIN_"&$A$1 -> step 2 relaxation of build rate - ELEWIN_BRZ
D10: ="EBldRateStep_Win_2_"&$A$1 -> EBldRateStep_Win_2_BRZ | F10: ACT,NEWFLO | H10: UC_ACT | I10: -1 | L10: 0 | M10: 5
C11: ="UELC-Bld_ELEWIN-step3_"&$A$1 -> UELC-Bld_ELEWIN-step3_BRZ | D11: =$D$7 -> *[_]BRA* | E11: ELCWIN | H11: UC_NCAP | I11: 1 | N11: ="step 3 relaxation of build rate - ELEWIN_"&$A$1 -> step 3 relaxation of build rate - ELEWIN_BRZ
D12: ="EBldRateStep_Win_3_"&$A$1 -> EBldRateStep_Win_3_BRZ | F12: ACT,NEWFLO | H12: UC_ACT | I12: -1 | L12: 0 | M12: 5
C13: ="UELC-Bld_ELESOL_"&$A$1 -> UELC-Bld_ELESOL_BRZ | D13: =$D$7 -> *[_]BRA* | E13: ELCSOL | F13: NCAP,GROWTH | J13: 1.15 | K13: 1 | L13: 0 | M13: 5 | N13: ="Annual build rate (GW/Year) of ELESOL_"&$A$1 -> Annual build rate (GW/Year) of ELESOL_BRZ
D14: ="EBldRateStep_Sol_2_"&$A$1&",EBldRateStep_Sol_3_"&$A$1 -> EBldRateStep_Sol_2_BRZ,EBldRateStep_Sol_3_BRZ | F14: ACT,NEWFLO | H14: UC_ACT | I14: 1
C15: ="UELC-Bld_ELESOL-step2_"&$A$1 -> UELC-Bld_ELESOL-step2_BRZ | D15: =$D$7 -> *[_]BRA* | E15: ELCSOL | H15: UC_NCAP | I15: =I9 -> 0.85 | N15: ="step 2 relaxation of build rate - ELESOL_"&$A$1 -> step 2 relaxation of build rate - ELESOL_BRZ
D16: ="EBldRateStep_Sol_2_"&$A$1 -> EBldRateStep_Sol_2_BRZ | F16: ACT,NEWFLO | H16: UC_ACT | I16: -1 | L16: 0 | M16: 5
C17: ="UELC-Bld_ELESOL-step3_"&$A$1 -> UELC-Bld_ELESOL-step3_BRZ | D17: =$D$7 -> *[_]BRA* | E17: ELCSOL | H17: UC_NCAP | I17: =I11 -> 1 | N17: ="step 3 relaxation of build rate - ELESOL_"&$A$1 -> step 3 relaxation of build rate - ELESOL_BRZ
D18: ="EBldRateStep_Sol_3_"&$A$1 -> EBldRateStep_Sol_3_BRZ | F18: ACT,NEWFLO | H18: UC_ACT | I18: -1 | L18: 0 | M18: 5
C19: ="UELC-Bld_ELEHYD_"&$A$1 -> UELC-Bld_ELEHYD_BRZ | D19: =$D$7 -> *[_]BRA* | E19: ELCHYD | F19: NCAP,GROWTH | J19: 1.15 | K19: 1 | L19: 0 | M19: 5 | N19: ="Annual build rate (GW/Year) of ELEHYD_"&$A$1 -> Annual build rate (GW/Year) of ELEHYD_BRZ
D20: ="EBldRateStep_Hyd_2_"&$A$1&",EBldRateStep_Hyd_3_"&$A$1 -> EBldRateStep_Hyd_2_BRZ,EBldRateStep_Hyd_3_BRZ | F20: ACT,NEWFLO | H20: UC_ACT | I20: 1
C21: ="UELC-Bld_ELEHYD-step2_"&$A$1 -> UELC-Bld_ELEHYD-step2_BRZ | D21: =$D$7 -> *[_]BRA* | E21: ELCHYD | H21: UC_NCAP | I21: =I15 -> 0.85 | N21: ="step 2 relaxation of build rate - ELEHYD_"&$A$1 -> step 2 relaxation of build rate - ELEHYD_BRZ
D22: ="EBldRateStep_Hyd_2_"&$A$1 -> EBldRateStep_Hyd_2_BRZ | F22: ACT,NEWFLO | H22: UC_ACT | I22: -1 | L22: 0 | M22: 5
C23: ="UELC-Bld_ELEHYD-step3_"&$A$1 -> UELC-Bld_ELEHYD-step3_BRZ | D23: =$D$7 -> *[_]BRA* | E23: ELCHYD | H23: UC_NCAP | I23: =I17 -> 1 | N23: ="step 3 relaxation of build rate - ELEHYD_"&$A$1 -> step 3 relaxation of build rate - ELEHYD_BRZ
D24: ="EBldRateStep_Hyd_3_"&$A$1 -> EBldRateStep_Hyd_3_BRZ | F24: ACT,NEWFLO | H24: UC_ACT | I24: -1 | L24: 0 | M24: 5
A25: wn | C25: ="UELC-Inv"&RIGHT(HistoricalBuilds!$N$1,2)&"_"&A25&"_"&$A$1 -> UELC-Inv19_wn_BRZ | D25: =$D$7 -> *[_]BRA* | E25: ELCWIN | G25: UP | J25: 1 | L25: =SUMIFS(HistoricalBuilds!$C$2:$C$300,HistoricalBuilds!$A$2:$A$300,BRZ!A$1,HistoricalBuilds!$B$2:$B$300,BRZ!$A25)*$L$1 -> 3.10861 | M25: 4
A26: sl | C26: ="UELC-Inv"&RIGHT(HistoricalBuilds!$N$1,2)&"_"&A26&"_"&$A$1 -> UELC-Inv19_sl_BRZ | D26: =$D$7 -> *[_]BRA* | E26: ELCSOL | G26: UP | J26: 1 | L26: =SUMIFS(HistoricalBuilds!$C$2:$C$300,HistoricalBuilds!$A$2:$A$300,BRZ!A$1,HistoricalBuilds!$B$2:$B$300,BRZ!$A26)*$L$1 -> 1.200921 | M26: 4
A27: he | C27: ="UELC-Inv"&RIGHT(HistoricalBuilds!$N$1,2)&"_"&A27&"_"&$A$1 -> UELC-Inv19_he_BRZ | D27: =$D$7 -> *[_]BRA* | E27: ELCHYD | G27: UP | J27: 1 | L27: =SUMIFS(HistoricalBuilds!$C$2:$C$300,HistoricalBuilds!$A$2:$A$300,BRZ!A$1,HistoricalBuilds!$B$2:$B$300,BRZ!$A27)*$L$1 -> 5.28 | M27: 4

Sheet CAN
A1: =MID(CELL( "filename",A1),FIND("]",CELL( "filename",A1))+1,10) -> CAN | L1: =#REF! -> #REF!
C2: ~UC_Sets: R_S: AllRegions
C3: ~UC_Sets: T_E:
H5: ="~UC_T: UC_RHST~LO~"&HistoricalBuilds!$N$1 -> ~UC_T: UC_RHST~LO~2019
C6: UC_N | D6: PSET_PN | E6: Pset_CI | F6: UC_ATTR | G6: LimType | H6: Attribute | I6: LHS | J6: UC_NCAP | K6: UC_NCAP~RHS | L6: UC_RHST | M6: UC_RHST~0 | N6: UC_Desc
C7: ="UELC-Bld_ELEWIN_"&$A$1 -> UELC-Bld_ELEWIN_CAN | D7: =VLOOKUP("1"&$A$1,'WEPSReg-Countrymap'!$D$2:$E$232,2,FALSE) -> *[_]CAN* | E7: ELCWIN | F7: NCAP,GROWTH | J7: 1.15 | K7: 1 | L7: 0 | M7: 5 | N7: ="Annual build rate (GW/Year) of ELEWIN_"&$A$1 -> Annual build rate (GW/Year) of ELEWIN_CAN
D8: ="EBldRateStep_Win_2_"&$A$1&",EBldRateStep_Win_3_"&$A$1 -> EBldRateStep_Win_2_CAN,EBldRateStep_Win_3_CAN | F8: ACT,NEWFLO | H8: UC_ACT | I8: 1
C9: ="UELC-Bld_ELEWIN-step2_"&$A$1 -> UELC-Bld_ELEWIN-step2_CAN | D9: =$D$7 -> *[_]CAN* | E9: ELCWIN | H9: UC_NCAP | I9: 0.85 | N9: ="step 2 relaxation of build rate - ELEWIN_"&$A$1 -> step 2 relaxation of build rate - ELEWIN_CAN
D10: ="EBldRateStep_Win_2_"&$A$1 -> EBldRateStep_Win_2_CAN | F10: ACT,NEWFLO | H10: UC_ACT | I10: -1 | L10: 0 | M10: 5
C11: ="UELC-Bld_ELEWIN-step3_"&$A$1 -> UELC-Bld_ELEWIN-step3_CAN | D11: =$D$7 -> *[_]CAN* | E11: ELCWIN | H11: UC_NCAP | I11: 1 | N11: ="step 3 relaxation of build rate - ELEWIN_"&$A$1 -> step 3 relaxation of build rate - ELEWIN_CAN
D12: ="EBldRateStep_Win_3_"&$A$1 -> EBldRateStep_Win_3_CAN | F12: ACT,NEWFLO | H12: UC_ACT | I12: -1 | L12: 0 | M12: 5
C13: ="UELC-Bld_ELESOL_"&$A$1 -> UELC-Bld_ELESOL_CAN | D13: =$D$7 -> *[_]CAN* | E13: ELCSOL | F13: NCAP,GROWTH | J13: 1.15 | K13: 1 | L13: 0 | M13: 5 | N13: ="Annual build rate (GW/Year) of ELESOL_"&$A$1 -> Annual build rate (GW/Year) of ELESOL_CAN
D14: ="EBldRateStep_Sol_2_"&$A$1&",EBldRateStep_Sol_3_"&$A$1 -> EBldRateStep_Sol_2_CAN,EBldRateStep_Sol_3_CAN | F14: ACT,NEWFLO | H14: UC_ACT | I14: 1
C15: ="UELC-Bld_ELESOL-step2_"&$A$1 -> UELC-Bld_ELESOL-step2_CAN | D15: =$D$7 -> *[_]CAN* | E15: ELCSOL | H15: UC_NCAP | I15: =I9 -> 0.85 | N15: ="step 2 relaxation of build rate - ELESOL_"&$A$1 -> step 2 relaxation of build rate - ELESOL_CAN
D16: ="EBldRateStep_Sol_2_"&$A$1 -> EBldRateStep_Sol_2_CAN | F16: ACT,NEWFLO | H16: UC_ACT | I16: -1 | L16: 0 | M16: 5
C17: ="UELC-Bld_ELESOL-step3_"&$A$1 -> UELC-Bld_ELESOL-step3_CAN | D17: =$D$7 -> *[_]CAN* | E17: ELCSOL | H17: UC_NCAP | I17: =I11 -> 1 | N17: ="step 3 relaxation of build rate - ELESOL_"&$A$1 -> step 3 relaxation of build rate - ELESOL_CAN
D18: ="EBldRateStep_Sol_3_"&$A$1 -> EBldRateStep_Sol_3_CAN | F18: ACT,NEWFLO | H18: UC_ACT | I18: -1 | L18: 0 | M18: 5
C19: ="UELC-Bld_ELEHYD_"&$A$1 -> UELC-Bld_ELEHYD_CAN | D19: =$D$7 -> *[_]CAN* | E19: ELCHYD | F19: NCAP,GROWTH | J19: 1.15 | K19: 1 | L19: 0 | M19: 5 | N19: ="Annual build rate (GW/Year) of ELEHYD_"&$A$1 -> Annual build rate (GW/Year) of ELEHYD_CAN
D20: ="EBldRateStep_Hyd_2_"&$A$1&",EBldRateStep_Hyd_3_"&$A$1 -> EBldRateStep_Hyd_2_CAN,EBldRateStep_Hyd_3_CAN | F20: ACT,NEWFLO | H20: UC_ACT | I20: 1
C21: ="UELC-Bld_ELEHYD-step2_"&$A$1 -> UELC-Bld_ELEHYD-step2_CAN | D21: =$D$7 -> *[_]CAN* | E21: ELCHYD | H21: UC_NCAP | I21: =I15 -> 0.85 | N21: ="step 2 relaxation of build rate - ELEHYD_"&$A$1 -> step 2 relaxation of build rate - ELEHYD_CAN
D22: ="EBldRateStep_Hyd_2_"&$A$1 -> EBldRateStep_Hyd_2_CAN | F22: ACT,NEWFLO | H22: UC_ACT | I22: -1 | L22: 0 | M22: 5
C23: ="UELC-Bld_ELEHYD-step3_"&$A$1 -> UELC-Bld_ELEHYD-step3_CAN | D23: =$D$7 -> *[_]CAN* | E23: ELCHYD | H23: UC_NCAP | I23: =I17 -> 1 | N23: ="step 3 relaxation of build rate - ELEHYD_"&$A$1 -> step 3 relaxation of build rate - ELEHYD_CAN
D24: ="EBldRateStep_Hyd_3_"&$A$1 -> EBldRateStep_Hyd_3_CAN | F24: ACT,NEWFLO | H24: UC_ACT | I24: -1 | L24: 0 | M24: 5
A25: wn | C25: ="UELC-Inv"&RIGHT(HistoricalBuilds!$N$1,2)&"_"&A25&"_"&$A$1 -> UELC-Inv19_wn_CAN | D25: =$D$7 -> *[_]CAN* | E25: ELCWIN | G25: UP | J25: 1 | L25: =SUMIFS(HistoricalBuilds!$C$2:$C$300,HistoricalBuilds!$A$2:$A$300,CAN!A$1,HistoricalBuilds!$B$2:$B$300,CAN!$A25)*$L$1 -> #REF! | M25: 4
A26: sl | C26: ="UELC-Inv"&RIGHT(HistoricalBuilds!$N$1,2)&"_"&A26&"_"&$A$1 -> UELC-Inv19_sl_CAN | D26: =$D$7 -> *[_]CAN* | E26: ELCSOL | G26: UP | J26: 1 | L26: =SUMIFS(HistoricalBuilds!$C$2:$C$300,HistoricalBuilds!$A$2:$A$300,CAN!A$1,HistoricalBuilds!$B$2:$B$300,CAN!$A26)*$L$1 -> #REF! | M26: 4
A27: he | C27: ="UELC-Inv"&RIGHT(HistoricalBuilds!$N$1,2)&"_"&A27&"_"&$A$1 -> UELC-Inv19_he_CAN | D27: =$D$7 -> *[_]CAN* | E27: ELCHYD | G27: UP | J27: 1 | L27: =SUMIFS(HistoricalBuilds!$C$2:$C$300,HistoricalBuilds!$A$2:$A$300,CAN!A$1,HistoricalBuilds!$B$2:$B$300,CAN!$A27)*$L$1 -> #REF! | M27: 4

Sheet CHI
A1: =MID(CELL( "filename",A1),FIND("]",CELL( "filename",A1))+1,10) -> CHI | L1: =AFR!$L$1 -> 1
C2: ~UC_Sets: R_S: AllRegions
C3: ~UC_Sets: T_E:
H5: ="~UC_T: UC_RHST~LO~"&HistoricalBuilds!$N$1 -> ~UC_T: UC_RHST~LO~2019
C6: UC_N | D6: PSET_PN | E6: Pset_CI | F6: UC_ATTR | G6: LimType | H6: Attribute | I6: LHS | J6: UC_NCAP | K6: UC_NCAP~RHS | L6: UC_RHST | M6: UC_RHST~0 | N6: UC_Desc
C7: ="UELC-Bld_ELEWIN_"&$A$1 -> UELC-Bld_ELEWIN_CHI | D7: =VLOOKUP("1"&$A$1,'WEPSReg-Countrymap'!$D$2:$E$232,2,FALSE) -> *[_]CHN* | E7: ELCWIN | F7: NCAP,GROWTH | J7: 1.15 | K7: 1 | L7: 0 | M7: 5 | N7: ="Annual build rate (GW/Year) of ELEWIN_"&$A$1 -> Annual build rate (GW/Year) of ELEWIN_CHI
D8: ="EBldRateStep_Win_2_"&$A$1&",EBldRateStep_Win_3_"&$A$1 -> EBldRateStep_Win_2_CHI,EBldRateStep_Win_3_CHI | F8: ACT,NEWFLO | H8: UC_ACT | I8: 1
C9: ="UELC-Bld_ELEWIN-step2_"&$A$1 -> UELC-Bld_ELEWIN-step2_CHI | D9: =$D$7 -> *[_]CHN* | E9: ELCWIN | H9: UC_NCAP | I9: 0.85 | N9: ="step 2 relaxation of build rate - ELEWIN_"&$A$1 -> step 2 relaxation of build rate - ELEWIN_CHI
D10: ="EBldRateStep_Win_2_"&$A$1 -> EBldRateStep_Win_2_CHI | F10: ACT,NEWFLO | H10: UC_ACT | I10: -1 | L10: 0 | M10: 5
C11: ="UELC-Bld_ELEWIN-step3_"&$A$1 -> UELC-Bld_ELEWIN-step3_CHI | D11: =$D$7 -> *[_]CHN* | E11: ELCWIN | H11: UC_NCAP | I11: 1 | N11: ="step 3 relaxation of build rate - ELEWIN_"&$A$1 -> step 3 relaxation of build rate - ELEWIN_CHI
D12: ="EBldRateStep_Win_3_"&$A$1 -> EBldRateStep_Win_3_CHI | F12: ACT,NEWFLO | H12: UC_ACT | I12: -1 | L12: 0 | M12: 5
C13: ="UELC-Bld_ELESOL_"&$A$1 -> UELC-Bld_ELESOL_CHI | D13: =$D$7 -> *[_]CHN* | E13: ELCSOL | F13: NCAP,GROWTH | J13: 1.15 | K13: 1 | L13: 0 | M13: 5 | N13: ="Annual build rate (GW/Year) of ELESOL_"&$A$1 -> Annual build rate (GW/Year) of ELESOL_CHI
D14: ="EBldRateStep_Sol_2_"&$A$1&",EBldRateStep_Sol_3_"&$A$1 -> EBldRateStep_Sol_2_CHI,EBldRateStep_Sol_3_CHI | F14: ACT,NEWFLO | H14: UC_ACT | I14: 1
C15: ="UELC-Bld_ELESOL-step2_"&$A$1 -> UELC-Bld_ELESOL-step2_CHI | D15: =$D$7 -> *[_]CHN* | E15: ELCSOL | H15: UC_NCAP | I15: =I9 -> 0.85 | N15: ="step 2 relaxation of build rate - ELESOL_"&$A$1 -> step 2 relaxation of build rate - ELESOL_CHI
D16: ="EBldRateStep_Sol_2_"&$A$1 -> EBldRateStep_Sol_2_CHI | F16: ACT,NEWFLO | H16: UC_ACT | I16: -1 | L16: 0 | M16: 5
C17: ="UELC-Bld_ELESOL-step3_"&$A$1 -> UELC-Bld_ELESOL-step3_CHI | D17: =$D$7 -> *[_]CHN* | E17: ELCSOL | H17: UC_NCAP | I17: =I11 -> 1 | N17: ="step 3 relaxation of build rate - ELESOL_"&$A$1 -> step 3 relaxation of build rate - ELESOL_CHI
D18: ="EBldRateStep_Sol_3_"&$A$1 -> EBldRateStep_Sol_3_CHI | F18: ACT,NEWFLO | H18: UC_ACT | I18: -1 | L18: 0 | M18: 5
C19: ="UELC-Bld_ELEHYD_"&$A$1 -> UELC-Bld_ELEHYD_CHI | D19: =$D$7 -> *[_]CHN* | E19: ELCHYD | F19: NCAP,GROWTH | J19: 1.15 | K19: 1 | L19: 0 | M19: 5 | N19: ="Annual build rate (GW/Year) of ELEHYD_"&$A$1 -> Annual build rate (GW/Year) of ELEHYD_CHI
D20: ="EBldRateStep_Hyd_2_"&$A$1&",EBldRateStep_Hyd_3_"&$A$1 -> EBldRateStep_Hyd_2_CHI,EBldRateStep_Hyd_3_CHI | F20: ACT,NEWFLO | H20: UC_ACT | I20: 1
